Workbook

Sheet Batch Coverage v16
A1: CU Batch | B1: P Batch | C1: Strain | D1: Status | E1: Missing (n) | F1: 2 Identification B — Microscopy | G1: 3 Identification C — HPLC | H1: 4 Assay — Total Δ⁹-THC | I1: 5 Assay — Total CBD | J1: 6 Total CBN | K1: 7 Foreign Matter | L1: 8 Loss on Drying | M1: 9 Microbiological Purity | N1: 10 Mycotoxins | O1: 11 Heavy Metals | P1: 12 Pesticide Residues | Q1: Missing parameters | R1: Certificates (n) | S1: Labs present
A2: GG1024_02 | B2: P050012 | C2: Gorilla Glue | D2: ✓ COMPLETE | E2: 0 | F2: ✓ | G2: ✓ | H2: ✓ | I2: ✓ | J2: ✓ | K2: ✓ | L2: ✓ | M2: ✓ | N2: ✓ | O2: ✓ | P2: ✓ | Q2: — | R2: 5.0 | S2: [CNP] 1; [IJZ] 1; [IJZ-MB] 2; [PP] 1
A3: GP0824_02 | B3: P050022 | C3: Grape Pie | D3: ✓ COMPLETE | E3: 0 | F3: ✓ | G3: ✓ | H3: ✓ | I3: ✓ | J3: ✓ | K3: ✓ | L3: ✓ | M3: ✓ | N3: ✓ | O3: ✓ | P3: ✓ | Q3: — | R3: 12.0 | S3: [CNP] 5; [FHM-K] 1; [FHM-M] 1; [IJZ] 2; [IJZ-MB] 2; [PP] 1
A4: MB0824_04 | B4: P050032 | C4: Motor Breath | D4: ✓ COMPLETE | E4: 0 | F4: ✓ | G4: ✓ | H4: ✓ | I4: ✓ | J4: ✓ | K4: ✓ | L4: ✓ | M4: ✓ | N4: ✓ | O4: ✓ | P4: ✓ | Q4: — | R4: 5.0 | S4: [CNP] 1; [IJZ] 1; [IJZ-MB] 2; [PP] 1
A5: OMP1024_01 | B5: P050042 | C5: Orange Punch Mimosa | D5: ✓ COMPLETE | E5: 0 | F5: ✓ | G5: ✓ | H5: ✓ | I5: ✓ | J5: ✓ | K5: ✓ | L5: ✓ | M5: ✓ | N5: ✓ | O5: ✓ | P5: ✓ | Q5: — | R5: 4.0 | S5: [CNP] 1; [IJZ] 1; [IJZ-MB] 1; [PP] 1
A6: HPA1024_01 | B6: P050052 | C6: High Pro Amnesia | D6: ✓ COMPLETE | E6: 0 | F6: ✓ | G6: ✓ | H6: ✓ | I6: ✓ | J6: ✓ | K6: ✓ | L6: ✓ | M6: ✓ | N6: ✓ | O6: ✓ | P6: ✓ | Q6: — | R6: 6.0 | S6: [CNP] 1; [FHM-K] 1; [FHM-M] 1; [IJZ] 1; [IJZ-MB] 1; [PP] 1
A7: OPM1024_02 | B7: P050062 | C7: Orange Punch Mimosa | D7: ✓ COMPLETE | E7: 0 | F7: ✓ | G7: ✓ | H7: ✓ | I7: ✓ | J7: ✓ | K7: ✓ | L7: ✓ | M7: ✓ | N7: ✓ | O7: ✓ | P7: ✓ | Q7: — | R7: 6.0 | S7: [CNP] 1; [FHM-K] 1; [FHM-M] 1; [IJZ] 1; [IJZ-MB] 1; [PP] 1
A8: GP0824_03 | B8: P050072 | C8: Grape Pie | D8: ✓ COMPLETE | E8: 0 | F8: ✓ | G8: ✓ | H8: ✓ | I8: ✓ | J8: ✓ | K8: ✓ | L8: ✓ | M8: ✓ | N8: ✓ | O8: ✓ | P8: ✓ | Q8: — | R8: 7.0 | S8: [CNP] 4; [IJZ] 1; [IJZ-MB] 1; [PP] 1
A9: OPM1024_03 | B9: P050082 | C9: Orange Punch Mimosa | D9: ✓ COMPLETE | E9: 0 | F9: ✓ | G9: ✓ | H9: ✓ | I9: ✓ | J9: ✓ | K9: ✓ | L9: ✓ | M9: ✓ | N9: ✓ | O9: ✓ | P9: ✓ | Q9: — | R9: 4.0 | S9: [CNP] 1; [IJZ] 1; [IJZ-MB] 1; [PP] 1
A10: GG1024_01 | B10: P050092 | C10: Gorilla Glue | D10: ✓ COMPLETE | E10: 0 | F10: ✓ | G10: ✓ | H10: ✓ | I10: ✓ | J10: ✓ | K10: ✓ | L10: ✓ | M10: ✓ | N10: ✓ | O10: ✓ | P10: ✓ | Q10: — | R10: 6.0 | S10: [CNP] 1; [FHM-K] 1; [FHM-M] 1; [IJZ] 1; [IJZ-MB] 1; [PP] 1
A11: GP0824_01 | B11: P050102 | C11: Grape Pie | D11: ✓ COMPLETE | E11: 0 | F11: ✓ | G11: ✓ | H11: ✓ | I11: ✓ | J11: ✓ | K11: ✓ | L11: ✓ | M11: ✓ | N11: ✓ | O11: ✓ | P11: ✓ | Q11: — | R11: 6.0 | S11: [CNP] 1; [IJZ] 1; [IJZ-MB] 3; [PP] 1
A12: MB0824_05 | B12: P050112 | C12: Motor Breath | D12: ✓ COMPLETE | E12: 0 | F12: ✓ | G12: ✓ | H12: ✓ | I12: ✓ | J12: ✓ | K12: ✓ | L12: ✓ | M12: ✓ | N12: ✓ | O12: ✓ | P12: ✓ | Q12: — | R12: 4.0 | S12: [CNP] 1; [IJZ] 1; [IJZ-MB] 1; [PP] 1
... A41: WED102501 | B41: P060102 | C41: Wedding Cake | D41: ✓ COMPLETE | E41: 0 | F41: ✓ | G41: ✓ | H41: ✓ | I41: ✓ | J41: ✓ | K41: ✓ | L41: ✓ | M41: ✓ | N41: ✓ | O41: ✓ | P41: ✓ | Q41: — | R41: 2.0 | S41: [IJZ-MB] 2
A42: PUM102501 | B42: P060112 | C42: Pure Michigan | D42: ⚠ 3 MISSING | E42: 3 | F42: ✗ | G42: ✓ | H42: ✓ | I42: ✓ | J42: ✓ | K42: ✗ | L42: ✓ | M42: ✓ | N42: ✓ | O42: ✓ | P42: ✓ | Q42: #1 Ident. A; #2 Ident. B; #7 Foreign matter | R42: 0
A43: ACC102501 | B43: P060122 | C43: Amnesia Core Cut | D43: ⚠ 3 MISSING | E43: 3 | F43: ✗ | G43: ✓ | H43: ✓ | I43: ✓ | J43: ✓ | K43: ✗ | L43: ✓ | M43: ✓ | N43: ✓ | O43: ✓ | P43: ✓ | Q43: #1 Ident. A; #2 Ident. B; #7 Foreign matter | R43: 0
A44: CF102501 | B44: P060132 | C44: Chem Flyer | D44: ⚠ 3 MISSING | E44: 3 | F44: ✗ | G44: ✓ | H44: ✓ | I44: ✓ | J44: ✓ | K44: ✗ | L44: ✓ | M44: ✓ | N44: ✓ | O44: ✓ | P44: ✓ | Q44: #1 Ident. A; #2 Ident. B; #7 Foreign matter | R44: 0
A45: GRC102501 | B45: P060142 / P060182 | D45: ⚠ 1 MISSING | E45: 1 | F45: ✓ | G45: ✓ | H45: ✓ | I45: ✓ | J45: ✓ | K45: ✓ | L45: ✓ | M45: ✓ | N45: ✗ | O45: ✓ | P45: ✓ | Q45: #10 Mycotoxins | R45: 5.0 | S45: [FHM-K] 2; [IJZ-MB] 1; [PP] 2
A46: J31102501 | B46: P060152 | C46: Jokerz 31 | D46: ✓ COMPLETE | E46: 0 | F46: ✓ | G46: ✓ | H46: ✓ | I46: ✓ | J46: ✓ | K46: ✓ | L46: ✓ | M46: ✓ | N46: ✓ | O46: ✓ | P46: ✓ | Q46: — | R46: 5.0 | S46: [FHM-K] 3; [FHM-M] 1; [PP] 1
A47: SJ102501 | B47: P060162 | C47: Sleepy Joy | D47: ⚠ 2 MISSING | E47: 2 | F47: ✓ | G47: ✓ | H47: ✓ | I47: ✓ | J47: ✓ | K47: ✓ | L47: ✓ | M47: ✓ | N47: ✗ | O47: ✗ | P47: ✓ | Q47: #10 Mycotoxins; #11 Heavy metals | R47: 4.0 | S47: [FHM-K] 2; [IJZ-MB] 1; [PP] 1
A48: KC102501 | B48: P060172 | C48: Kush Crasher | D48: ✓ COMPLETE | E48: 0 | F48: ✓ | G48: ✓ | H48: ✓ | I48: ✓ | J48: ✓ | K48: ✓ | L48: ✓ | M48: ✓ | N48: ✓ | O48: ✓ | P48: ✓ | Q48: — | R48: 3.0 | S48: [FHM-K] 2; [PP] 1
A49: SJ112501 | B49: P060192 | C49: Sleepy Joy | D49: ✓ COMPLETE | E49: 0 | F49: ✓ | G49: ✓ | H49: ✓ | I49: ✓ | J49: ✓ | K49: ✓ | L49: ✓ | M49: ✓ | N49: ✓ | O49: ✓ | P49: ✓ | Q49: — | R49: 3.0 | S49: [FHM-K] 2; [PP] 1
A50: J31112501 | B50: P060202 | C50: Jokerz 31 | D50: ✓ COMPLETE | E50: 0 | F50: ✓ | G50: ✓ | H50: ✓ | I50: ✓ | J50: ✓ | K50: ✓ | L50: ✓ | M50: ✓ | N50: ✓ | O50: ✓ | P50: ✓ | Q50: — | R50: 8.0 | S50: [FHM-K] 6; [IJZ-MB] 1; [PP] 1
A51: JD112501 | B51: P060212 | C51: Jelly Donutz | D51: ✓ COMPLETE | E51: 0 | F51: ✓ | G51: ✓ | H51: ✓ | I51: ✓ | J51: ✓ | K51: ✓ | L51: ✓ | M51: ✓ | N51: ✓ | O51: ✓ | P51: ✓ | Q51: — | R51: 6.0 | S51: [CNP] 1; [FHM-K] 1; [FHM-M] 1; [IJZ] 1; [IJZ-MB] 1; [PP] 1
A52: OPM112501 | B52: P060222 | C52: Orange Punch Mimosa | D52: ⚠ 2 MISSING | E52: 2 | F52: ✓ | G52: ✓ | H52: ✓ | I52: ✓ | J52: ✗ | K52: ✓ | L52: ✓ | M52: ✓ | N52: ✗ | O52: ✓ | P52: ✓ | Q52: #6 CBN; #10 Mycotoxins | R52: 3.0 | S52: [CNP] 1; [IJZ-MB] 1; [PP] 1
A53: PM112501 | B53: P060232 | C53: Permanent Market | D53: ⚠ 1 MISSING | E53: 1 | F53: ✓ | G53: ✓ | H53: ✓ | I53: ✓ | J53: ✓ | K53: ✓ | L53: ✓ | M53: ✓ | N53: ✗ | O53: ✓ | P53: ✓ | Q53: #10 Mycotoxins | R53: 2.0 | S53: [CNP] 1; [PP] 1
A54: OPM122501 | B54: P060242 | C54: Orange Punch Mimosa | D54: ✓ COMPLETE | E54: 0 | F54: ✓ | G54: ✓ | H54: ✓ | I54: ✓ | J54: ✓ | K54: ✓ | L54: ✓ | M54: ✓ | N54: ✓ | O54: ✓ | P54: ✓ | Q54: — | R54: 7.0 | S54: [FHM-K] 3; [FHM-M] 1; [IJZ] 1; [IJZ-MB] 1; [PP] 1
A55: GG112501 | B55: P060252 | C55: Gorilla Glue | D55: ✓ COMPLETE | E55: 0 | F55: ✓ | G55: ✓ | H55: ✓ | I55: ✓ | J55: ✓ | K55: ✓ | L55: ✓ | M55: ✓ | N55: ✓ | O55: ✓ | P55: ✓ | Q55: — | R55: 5.0 | S55: [CNP] 1; [IJZ] 1; [IJZ-MB] 2; [PP] 1
A56: J31122501 | B56: P060262 | C56: Jokerz 31 | D56: ⚠ 1 MISSING | E56: 1 | F56: ✓ | G56: ✓ | H56: ✓ | I56: ✓ | J56: ✓ | K56: ✓ | L56: ✗ | M56: ✓ | N56: ✓ | O56: ✓ | P56: ✓ | Q56: #8 LoD | R56: 8.0 | S56: [FHM-K] 2; [IJZ] 2; [IJZ-MB] 3; [PP] 1
A57: CC112501 | B57: P060272 | C57: CashCow | D57: ✓ COMPLETE | E57: 0 | F57: ✓ | G57: ✓ | H57: ✓ | I57: ✓ | J57: ✓ | K57: ✓ | L57: ✓ | M57: ✓ | N57: ✓ | O57: ✓ | P57: ✓ | Q57: — | R57: 5.0 | S57: [CNP] 1; [IJZ] 1; [IJZ-MB] 2; [PP] 1
... A62: FB012601_1 | B62: P060322 | C62: Fat Bastard | D62: ✓ COMPLETE | E62: 0 | F62: ✓ | G62: ✓ | H62: ✓ | I62: ✓ | J62: ✓ | K62: ✓ | L62: ✓ | M62: ✓ | N62: ✓ | O62: ✓ | P62: ✓ | Q62: — | R62: 4.0 | S62: [CNP] 1; [IJZ] 1; [IJZ-MB] 1; [PP] 1
A63: CC012601/1 | B63: P060332 | D63: ⚠ 3 MISSING | E63: 3 | F63: ✓ | G63: ✓ | H63: ✓ | I63: ✓ | J63: ✓ | K63: ✓ | L63: ✗ | M63: ✓ | N63: ✓ | O63: ✗ | P63: ✗ | Q63: #8 LoD; #11 Heavy metals; #12 Pesticides | R63: 3.0 | S63: [FHM-K] 1; [FHM-M] 1; [PP] 1
A64: SCR012601* | B64: P060342 | C64: Scrambler | D64: ❌ 8 MISSING | E64: 8 | F64: ✓ | G64: ✗ | H64: ✗ | I64: ✗ | J64: ✗ | K64: ✓ | L64: ✗ | M64: ✓ | N64: ✗ | O64: ✗ | P64: ✗ | Q64: #3 Ident. C; #4 Δ⁹-THC; #5 CBD; #6 CBN; #8 LoD; #10 Mycotoxins; #11 Heavy metals; #12 Pesticides | R64: 2.0 | S64: [IJZ-MB] 2
A65: FB012602* | B65: P060352 | C65: Fat Bastard | D65: ⚠ 3 MISSING | E65: 3 | F65: ✓ | G65: ✓ | H65: ✓ | I65: ✓ | J65: ✓ | K65: ✓ | L65: ✗ | M65: ✓ | N65: ✓ | O65: ✗ | P65: ✗ | Q65: #8 LoD; #11 Heavy metals; #12 Pesticides | R65: 3.0 | S65: [FHM-K] 1; [FHM-M] 1; [PP] 1
A66: JD012603 | B66: P060362 / P060412 / P060422 | D66: ✓ COMPLETE | E66: 0 | F66: ✓ | G66: ✓ | H66: ✓ | I66: ✓ | J66: ✓ | K66: ✓ | L66: ✓ | M66: ✓ | N66: ✓ | O66: ✓ | P66: ✓ | Q66: — | R66: 2.0 | S66: [CNP] 2
A67: CC012603 | B67: P060372 | C67: Cash Cow | D67: ❌ 7 MISSING | E67: 7 | F67: ✗ | G67: ✓ | H67: ✓ | I67: ✓ | J67: ✓ | K67: ✗ | L67: ✗ | M67: ✓ | N67: ✗ | O67: ✗ | P67: ✗ | Q67: #1 Ident. A; #2 Ident. B; #7 Foreign matter; #8 LoD; #10 Mycotoxins; #11 Heavy metals; #12 Pesticides | R67: 0
A68: SCR012603 | B68: P060382 | C68: Scrambler | D68: ⚠ 3 MISSING | E68: 3 | F68: ✓ | G68: ✓ | H68: ✓ | I68: ✓ | J68: ✓ | K68: ✓ | L68: ✗ | M68: ✓ | N68: ✓ | O68: ✗ | P68: ✗ | Q68: #8 LoD; #11 Heavy metals; #12 Pesticides | R68: 3.0 | S68: [FHM-K] 1; [FHM-M] 1; [PP] 1
A69: FB012603V | B69: P060392 | C69: Fat Bastard | D69: ✓ COMPLETE | E69: 0 | F69: ✓ | G69: ✓ | H69: ✓ | I69: ✓ | J69: ✓ | K69: ✓ | L69: ✓ | M69: ✓ | N69: ✓ | O69: ✓ | P69: ✓ | Q69: — | R69: 2.0 | S69: [CNP] 1; [IJZ-MB] 1
A70: GG012603 | B70: P060402 | C70: Gorilla Glue | D70: ✓ COMPLETE | E70: 0 | F70: ✓ | G70: ✓ | H70: ✓ | I70: ✓ | J70: ✓ | K70: ✓ | L70: ✓ | M70: ✓ | N70: ✓ | O70: ✓ | P70: ✓ | Q70: — | R70: 3.0 | S70: [CNP] 1; [FHM-K] 1; [FHM-M] 1
A71: FB012603 | B71: P060432 | C71: Fat Bastard | D71: ✓ COMPLETE | E71: 0 | F71: ✓ | G71: ✓ | H71: ✓ | I71: ✓ | J71: ✓ | K71: ✓ | L71: ✓ | M71: ✓ | N71: ✓ | O71: ✓ | P71: ✓ | Q71: — | R71: 2.0 | S71: [CNP] 1; [IJZ-MB] 1
A72: SCR022601 | B72: P060442 | C72: Scrambler | D72: ✓ COMPLETE | E72: 0 | F72: ✓ | G72: ✓ | H72: ✓ | I72: ✓ | J72: ✓ | K72: ✓ | L72: ✓ | M72: ✓ | N72: ✓ | O72: ✓ | P72: ✓ | Q72: — | R72: 2.0 | S72: [CNP] 1; [IJZ-MB] 1
...

Sheet CoQ Parameter Tracker v13
A1: BATCH IDENTIFICATION | D1: IDENTIFICATION 1–3 | M1: CANNABINOID ASSAY 4–6 | V1: PHYSICAL 7–8 | AB1: MICROBIOLOGY 9 | AH1: CONTAMINANTS 10–12
A2: CU Batch | B2: P Batch | C2: STATUS | D2: #1 Identification A Appearance · Ph. Eur. mon. 3028 | G2: #2 Identification B Microscopy · Ph. Eur. 2.8.23 | J2: #3 Identification C HPLC · Ph. Eur. 2.2.29 | M2: #4 Assay — Total Δ⁹-THC* Ph. Eur. 2.2.29 (HPLC) | P2: #5 Assay — Total CBD Ph. Eur. 2.2.29 · CBD + CBDA×0.877 | S2: #6 Total CBN Ph. Eur. 2.2.29 · CBN + CBNA×0.876 | V2: #7 Foreign Matter Ph. Eur. 2.8.2 / in-house | Y2: #8 Loss on Drying Ph. Eur. 2.2.32 · 40 °C, 24 h, 15–25 mbar | AB2: #9 Microbiological Purity Ph. Eur. 2.6.12 / 2.6.13 / 2.6.31 · cat. C | AH2: #10 Mycotoxins Ph. Eur. 2.8.18 / 2.8.22 (HPLC-FLD) | AL2: #11 Heavy Metals Ph. Eur. 2.4.27 (ICP-MS) | AQ2: #12 Pesticide Residues Ph. Eur. 2.8.13 (LC-MS/MS) · CUMCS equivalency
D3: A.C.: Conforms to Ph. Eur. monograph 3028 (Cannabis flos) | G3: A.C.: Conforms to Ph. Eur. monograph 3028 (Cannabis flos) | J3: A.C.: Conforms to Ph. Eur. monograph 3028 (Cannabis flos) | M3: A.C.: Per target grade (CoQ §01) | P3: A.C.: ≤ 1.0 % w/w | S3: A.C.: ≤ 1.0 % w/w | V3: A.C.: ≤ 2.0 % (25–50 g); leaves < 1 cm; no seeds | Y3: A.C.: ≤ 12.0 % | AB3: A.C.: ≤ 10⁵ CFU/g | AC3: A.C.: ≤ 10⁴ CFU/g | AD3: A.C.: ≤ 10⁴ CFU/g | AE3: A.C.: Absence / 25 g | AF3: A.C.: Absence / 1 g | AH3: A.C.: ≤ 2 µg/kg | AI3: A.C.: ≤ 4 µg/kg | AJ3: A.C.: ≤ 20 µg/kg | AL3: A.C.: ≤ 0.5 mg/kg | AM3: A.C.: ≤ 0.3 mg/kg | AN3: A.C.: ≤ 0.2 mg/kg | AO3: A.C.: ≤ 0.1 mg/kg | AQ3: A.C.: ≤ LOQ (Ph. Eur. 2.8.13 / CUMCS equivalency)
D4: Result | E4: [eCOA code],[date],[Lab] | F4: ✓ ✗ | G4: Result | H4: [eCOA code],[date],[Lab] | I4: ✓ ✗ | J4: Result | K4: [eCOA code],[date],[Lab] | L4: ✓ ✗ | M4: Result | N4: [eCOA code],[date],[Lab] | O4: ✓ ✗ | P4: Result | Q4: [eCOA code],[date],[Lab] | R4: ✓ ✗ | S4: Result | T4: [eCOA code],[date],[Lab] | U4: ✓ ✗ | V4: Result | W4: [eCOA code],[date],[Lab] | X4: ✓ ✗ | Y4: Result | Z4: [eCOA code],[date],[Lab] | AA4: ✓ ✗ | AB4: TAMC | AC4: TYMC | AD4: GNB | AE4: Salm. | AF4: E. coli | AG4: ✓ ✗ | AH4: AfB₁ | AI4: ΣAf | AJ4: OTA | AK4: ✓ ✗ | AL4: Pb | AM4: Cd | AN4: As | AO4: Hg | AP4: ✓ ✗ | AQ4: Result | AR4: [eCOA code],[date],[Lab] | AS4: ✓ ✗
A5: BG1024 | B5: N/A — no P batch assigned | C5: ✓ COMPLETE 2 testing instances • 2 document(s) on file, not credited | D5: Conforms | E5: {=IFERROR(INDEX('iCoA Register'!$B:$B,MATCH("BG1024|I",'iCoA Register'!$P:$P,0)),"iCoA — at issue")&", (07.03.2025) [PP]"} -> iCoA-PP_26-003, (07.03.2025) [PP] | F5: ✓ | G5: not on this certificate | H5: ППК25050, (26.02.2025) [CNP] · on file, not credited | I5: • | J5: Conforms (ImB spec.) | K5: ППК25050, (26.02.2025) [CNP] | L5: ✓ | M5: 21.80 | N5: ППК25050, (26.02.2025) [CNP] | O5: ✓ | P5: 0.04 | Q5: ППК25050, (26.02.2025) [CNP] | R5: ✓ | S5: 0.02 ᴰ | T5: ППК25050, (26.02.2025) [CNP] | U5: ✓ | V5: Conforms | W5: {=IFERROR(INDEX('iCoA Register'!$B:$B,MATCH("BG1024|I",'iCoA Register'!$P:$P,0)),"iCoA — at issue")&", (07.03.2025) [PP]"} -> iCoA-PP_26-003, (07.03.2025) [PP] | X5: ✓ | Y5: 5.73 | Z5: ППК25050, (26.02.2025) [CNP] | AA5: ✓ | AB5: 1.6 x 10⁴ | AC5: 1 x 10⁴ | AD5: <10² и >10 | AE5: Одговара | AF5: Одговара | AG5: ✓ | AH5: n.r. | AI5: <2 | AJ5: n.r. | AK5: ✓ | AL5: 0.01 | AM5: 0.016 | AN5: 0.014 | AO5: 0.005 | AP5: ✓ | AQ5: ≤ LOQ (all 29 compounds) | AR5: 752-2025, (27.02.2025) [IJZ] | AS5: ✓
AB6: 163-0271-25, (24.02.2025) [IJZ-MB] | AH6: 752-2025, (27.02.2025) [IJZ] | AL6: 752-2025, (27.02.2025) [IJZ]
G7: Conforms | H7: {=IFERROR(INDEX('iCoA Register'!$B:$B,MATCH("BG1024|I",'iCoA Register'!$P:$P,0)),"iCoA — at issue")&", (07.03.2025) [PP]"} -> iCoA-PP_26-003, (07.03.2025) [PP] | I7: ✓ | J7: Conforms (ImB spec.) ᴿ | K7: 197-1-K-26, (07.08.2026) [FHM-K] | L7: ✓ | M7: 26.14 | N7: 197-1-K-26, (07.08.2026) [FHM-K] | O7: ✓ | P7: < LOQ | Q7: 197-1-K-26, (07.08.2026) [FHM-K] | R7: ✓ | S7: 0.28 | T7: 197-1-K-26, (07.08.2026) [FHM-K] | U7: ✓ | Y7: not on this certificate | Z7: 197-1-K-26, (07.08.2026) [FHM-K] · on file, not credited | AA7: • | AH7: ND | AI7: ND ᴿ | AJ7: ND | AK7: ✓
AH8: 197-1-M-26, (10.08.2026) [FHM-M]
A9: BSS1024 | B9: N/A — no P batch assigned | C9: ✓ COMPLETE 2 testing instances • 2 document(s) on file, not credited | D9: Conforms | E9: {=IFERROR(INDEX('iCoA Register'!$B:$B,MATCH("BSS1024|I",'iCoA Register'!$P:$P,0)),"iCoA — at issue")&", (04.03.2025) [PP]"} -> iCoA-PP_26-002, (04.03.2025) [PP] | F9: ✓ | G9: not on this certificate | H9: ППК25051, (26.02.2025) [CNP] · on file, not credited | I9: • | J9: Conforms (ImB spec.) | K9: ППК25051, (26.02.2025) [CNP] | L9: ✓ | M9: 21.03 | N9: ППК25051, (26.02.2025) [CNP] | O9: ✓ | P9: 0.04 | Q9: ППК25051, (26.02.2025) [CNP] | R9: ✓ | S9: 0.02 ᴰ | T9: ППК25051, (26.02.2025) [CNP] | U9: ✓ | V9: Conforms | W9: {=IFERROR(INDEX('iCoA Register'!$B:$B,MATCH("BSS1024|I",'iCoA Register'!$P:$P,0)),"iCoA — at issue")&", (04.03.2025) [PP]"} -> iCoA-PP_26-002, (04.03.2025) [PP] | X9: ✓ | Y9: 5.99 | Z9: ППК25051, (26.02.2025) [CNP] | AA9: ✓ | AB9: 1.5×10⁴ | AC9: 2.2×10³ | AD9: <10^2 и >10 | AE9: Одговара | AF9: Одговара | AG9: ✓ | AH9: n.r. | AI9: <2 | AJ9: n.r. | AK9: ✓ | AL9: 0.071 | AM9: 0.014 | AN9: 0.081 | AO9: 0.014 | AP9: ✓ | AQ9: ≤ LOQ (all 29 compounds) | AR9: 751-2025, (27.02.2025) [IJZ] | AS9: ✓
AB10: 161-0269-25, (24.02.2025) [IJZ-MB] | AH10: 751-2025, (27.02.2025) [IJZ] | AL10: 751-2025, (27.02.2025) [IJZ]
G11: Conforms | H11: {=IFERROR(INDEX('iCoA Register'!$B:$B,MATCH("BSS1024|I",'iCoA Register'!$P:$P,0)),"iCoA — at issue")&", (04.03.2025) [PP]"} -> iCoA-PP_26-002, (04.03.2025) [PP] | I11: ✓ | J11: Conforms (ImB spec.) | K11: 197-2-K-26, (07.08.2026) [FHM-K] | L11: ✓ | M11: 25.01 | N11: 197-2-K-26, (07.08.2026) [FHM-K] | O11: ✓ | P11: < LOQ | Q11: 197-2-K-26, (07.08.2026) [FHM-K] | R11: ✓ | S11: < LOQ | T11: 197-2-K-26, (07.08.2026) [FHM-K] | U11: ✓ | Y11: not on this certificate | Z11: 197-2-K-26, (07.08.2026) [FHM-K] · on file, not credited | AA11: • | AH11: ND | AI11: ND ᴿ | AJ11: ND | AK11: ✓
AH12: 197-2-M-26, (10.08.2026) [FHM-M]
A13: CC112501 | B13: P060272 | C13: ✓ COMPLETE 2 testing instances • 1 document(s) on file, not credited | D13: Conforms | E13: {=IFERROR(INDEX('iCoA Register'!$B:$B,MATCH("P060272|I",'iCoA Register'!$P:$P,0)),"iCoA — at issue")&", (18.05.2026) [PP]"} -> iCoA-PP_26-060, (18.05.2026) [PP] | F13: ✓ | G13: not on this certificate | H13: ППК26068, (11.05.2026) [CNP] · on file, not credited | I13: • | J13: Conforms (ImB spec.) | K13: ППК26068, (11.05.2026) [CNP] | L13: ✓ | M13: 13.35 | N13: ППК26068, (11.05.2026) [CNP] | O13: ✓ | P13: 0.04 | Q13: ППК26068, (11.05.2026) [CNP] | R13: ✓ | S13: BLQ ᴰ | T13: ППК26068, (11.05.2026) [CNP] | U13: ✓ | V13: Conforms | W13: {=IFERROR(INDEX('iCoA Register'!$B:$B,MATCH("P060272|I",'iCoA Register'!$P:$P,0)),"iCoA — at issue")&", (18.05.2026) [PP]"} -> iCoA-PP_26-060, (18.05.2026) [PP] | X13: ✓ | Y13: 7.39 | Z13: ППК26068, (11.05.2026) [CNP] | AA13: ✓ | AB13: 3.8 x 10³ | AC13: 2.7 x 10³ | AD13: <10³ и >10² | AE13: отсуства/25 | AF13: отсуства/g | AG13: ✓ | AH13: n.r. | AI13: <2 | AJ13: n.r. | AK13: ✓ | AL13: 0.0289 | AM13: 0.0119 | AN13: 0.016 | AO13: 0.0102 | AP13: ✓ | AQ13: ≤ LOQ (all 29 compounds) | AR13: 2359-2026, (29.04.2026) [IJZ] | AS13: ✓
AB14: 311-0555-26, (28.04.2026) [IJZ-MB] | AH14: 2359-2026, (29.04.2026) [IJZ] | AL14: 2359-2026, (29.04.2026) [IJZ]
G15: Conforms | H15: {=IFERROR(INDEX('iCoA Register'!$B:$B,MATCH("P060272|I",'iCoA Register'!$P:$P,0)),"iCoA — at issue")&", (18.05.2026) [PP]"} -> iCoA-PP_26-060, (18.05.2026) [PP] | I15: ✓ | AB15: 1.6×10³ | AC15: 1×10³ | AD15: <10³ и >10² | AE15: absent | AF15: absent | AG15: ✓
AB16: 543-1074-26, (31.08.2026) [IJZ-MB]
A17: CJ1024 | B17: N/A — no P batch assigned | C17: ✓ COMPLETE 2 testing instances • 1 document(s) on file, not credited | D17: Conforms | E17: {=IFERROR(INDEX('iCoA Register'!$B:$B,MATCH("CJ1024|I",'iCoA Register'!$P:$P,0)),"iCoA — at issue")&", (03.03.2025) [PP]"} -> iCoA-PP_26-001, (03.03.2025) [PP] | F17: ✓ | G17: not on this certificate | H17: ППК25052, (26.02.2025) [CNP] · on file, not credited | I17: • | J17: Conforms (ImB spec.) | K17: ППК25052, (26.02.2025) [CNP] | L17: ✓ | M17: 23.00 | N17: ППК25052, (26.02.2025) [CNP] | O17: ✓ | P17: 0.05 | Q17: ППК25052, (26.02.2025) [CNP] | R17: ✓ | S17: 0.02 ᴰ | T17: ППК25052, (26.02.2025) [CNP] | U17: ✓ | V17: Conforms | W17: {=IFERROR(INDEX('iCoA Register'!$B:$B,MATCH("CJ1024|I",'iCoA Register'!$P:$P,0)),"iCoA — at issue")&", (03.03.2025) [PP]"} -> iCoA-PP_26-001, (03.03.2025) [PP] | X17: ✓ | Y17: 5.91 | Z17: ППК25052, (26.02.2025) [CNP] | AA17: ✓ | AB17: 8.4 x 10³ | AC17: <10 | AD17: <10 | AE17: Одговара | AF17: Одговара | AG17: ✓ | AH17: n.r. | AI17: <2 | AJ17: n.r. | AK17: ✓ | AL17: 0.036 | AM17: 0.013 | AN17: 0.063 | AO17: 0.006 | AP17: ✓ | AQ17: ≤ LOQ (all 29 compounds) | AR17: 750-2025, (27.02.2025) [IJZ] | AS17: ✓
AB18: 164-0272-25, (24.02.2025) [IJZ-MB] | AH18: 750-2025, (27.02.2025) [IJZ] | AL18: 750-2025, (27.02.2025) [IJZ]
G19: Conforms | H19: {=IFERROR(INDEX('iCoA Register'!$B:$B,MATCH("CJ1024|I",'iCoA Register'!$P:$P,0)),"iCoA — at issue")&", (03.03.2025) [PP]"} -> iCoA-PP_26-001, (03.03.2025) [PP] | I19: ✓ | AB19: <10 | AC19: 10 | AD19: <10 | AE19: absent | AF19: absent | AG19: ✓
AB20: 565-1096-26, (01.09.2026) [IJZ-MB]
A21: FB012601_1 | B21: P060322 | C21: ✓ COMPLETE 2 testing instances • 1 document(s) on file, not credited | D21: Conforms | E21: {=IFERROR(INDEX('iCoA Register'!$B:$B,MATCH("P060322|I",'iCoA Register'!$P:$P,0)),"iCoA — at issue")&", (22.05.2026) [PP]"} -> iCoA-PP_26-066, (22.05.2026) [PP] | F21: ✓ | G21: not on this certificate | H21: ППК26067, (11.05.2026) [CNP] · on file, not credited | I21: • | J21: Conforms (ImB spec.) | K21: ППК26067, (11.05.2026) [CNP] | L21: ✓ | M21: 14.68 | N21: ППК26067, (11.05.2026) [CNP] | O21: ✓ | P21: 0.04 | Q21: ППК26067, (11.05.2026) [CNP] | R21: ✓ | S21: BLQ ᴰ | T21: ППК26067, (11.05.2026) [CNP] | U21: ✓ | V21: Conforms | W21: {=IFERROR(INDEX('iCoA Register'!$B:$B,MATCH("P060322|I",'iCoA Register'!$P:$P,0)),"iCoA — at issue")&", (22.05.2026) [PP]"} -> iCoA-PP_26-066, (22.05.2026) [PP] | X21: ✓ | Y21: 7.67 | Z21: ППК26067, (11.05.2026) [CNP] | AA21: ✓ | AB21: 2 x 10³ | AC21: 2.1 x 10³ | AD21: <10 | AE21: отсутна/25 g | AF21: отсутна/g | AG21: ✓ | AH21: n.r. | AI21: <2 | AJ21: n.r. | AK21: ✓ | AL21: 0.0114 | AM21: 0.017 | AN21: 0.0144 | AO21: 0.0155 | AP21: ✓ | AQ21: ≤ LOQ (all 26 compounds) | AR21: 2362-2026, (30.04.2026) [IJZ] | AS21: ✓
AB22: 308-0552-26, (28.04.2026) [IJZ-MB] | AH22: 2362-2026, (30.04.2026) [IJZ] | AL22: 2362-2026, (30.04.2026) [IJZ]
G23: Conforms | H23: {=IFERROR(INDEX('iCoA Register'!$B:$B,MATCH("P060322|I",'iCoA Register'!$P:$P,0)),"iCoA — at issue")&", (22.05.2026) [PP]"} -> iCoA-PP_26-066, (22.05.2026) [PP] | I23: ✓
A25: FB012603 | B25: P060432 | C25: ⚠ 3 NO RESULT (3 no cert / 0 cert w/o result) | D25: Одговара | E25: ППК26112, (30.06.2026) [CNP] | F25: ✓ | G25: Одговара | H25: ППК26112, (30.06.2026) [CNP] | I25: ✓ | J25: Conforms (ImB spec.) | K25: ППК26112, (30.06.2026) [CNP] | L25: ✓ | M25: 20.83 | N25: ППК26112, (30.06.2026) [CNP] | O25: ✓ | P25: 0.21 | Q25: ППК26112, (30.06.2026) [CNP] | R25: ✓ | S25: 0.06 | T25: ППК26112, (30.06.2026) [CNP] | U25: ✓ | V25: / (Одговара) | W25: ППК26112, (30.06.2026) [CNP] | X25: ✓ | Y25: 7.04 | Z25: ППК26112, (30.06.2026) [CNP] | AA25: ✓ | AB25: 9.8×10³ | AC25: 2.5×10³ | AD25: <10² и >10 | AE25: absent | AF25: absent | AG25: ✓ | AH25: — MISSING — | AI25: — MISSING — | AJ25: — MISSING — | AK25: ✗ | AL25: — MISSING — | AM25: — MISSING — | AN25: — MISSING — | AO25: — MISSING — | AP25: ✗ | AQ25: — MISSING — | AR25: — no certificate — | AS25: ✗
AB26: 537-1068-26, (31.08.2026) [IJZ-MB] | AH26: — no certificate — | AL26: — no certificate —
A27: FB012603V | B27: P060392 | C27: ⚠ 3 NO RESULT (3 no cert / 0 cert w/o result) | D27: Одговара | E27: ППК26110, (30.06.2026) [CNP] | F27: ✓ | G27: Одговара | H27: ППК26110, (30.06.2026) [CNP] | I27: ✓ | J27: Conforms (ImB spec.) | K27: ППК26110, (30.06.2026) [CNP] | L27: ✓ | M27: 18.29 | N27: ППК26110, (30.06.2026) [CNP] | O27: ✓ | P27: 0.16 | Q27: ППК26110, (30.06.2026) [CNP] | R27: ✓ | S27: 0.06 | T27: ППК26110, (30.06.2026) [CNP] | U27: ✓ | V27: / (Одговара) | W27: ППК26110, (30.06.2026) [CNP] | X27: ✓ | Y27: 6.36 | Z27: ППК26110, (30.06.2026) [CNP] | AA27: ✓ | AB27: 2.9×10³ | AC27: 2.5×10³ | AD27: <10 | AE27: absent | AF27: absent | AG27: ✓ | AH27: — MISSING — | AI27: — MISSING — | AJ27: — MISSING — | AK27: ✗ | AL27: — MISSING — | AM27: — MISSING — | AN27: — MISSING — | AO27: — MISSING — | AP27: ✗ | AQ27: — MISSING — | AR27: — no certificate — | AS27: ✗
AB28: 538-1069-26, (31.08.2026) [IJZ-MB] | AH28: — no certificate — | AL28: — no certificate —
A29: FB032601 | B29: P060452 | C29: ✗ 4 NO RESULT (4 no cert / 0 cert w/o result) | D29: Одговара | E29: ППК26127, (21.07.2026) [CNP] | F29: ✓ | G29: Одговара | H29: ППК26127, (21.07.2026) [CNP] | I29: ✓ | J29: Conforms (ImB spec.) | K29: ППК26127, (21.07.2026) [CNP] | L29: ✓ | M29: 12.39 | N29: ППК26127, (21.07.2026) [CNP] | O29: ✓ | P29: 0.06 | Q29: ППК26127, (21.07.2026) [CNP] | R29: ✓ | S29: 0.04 | T29: ППК26127, (21.07.2026) [CNP] | U29: ✓ | V29: 0.08% (Не одговара) | W29: ППК26127, (21.07.2026) [CNP] | X29: ✓ | Y29: 7.77 | Z29: ППК26127, (21.07.2026) [CNP] | AA29: ✓ | AB29: — MISSING — | AC29: — MISSING — | AD29: — MISSING — | AE29: — MISSING — | AF29: — MISSING — | AG29: ✗ | AH29: — MISSING — | AI29: — MISSING — | AJ29: — MISSING — | AK29: ✗ | AL29: — MISSING — | AM29: — MISSING — | AN29: — MISSING — | AO29: — MISSING — | AP29: ✗ | AQ29: — MISSING — | AR29: — no certificate — | AS29: ✗
AB30: — no certificate — | AH30: — no certificate — | AL30: — no certificate —
A31: FB112501 | B31: P060292 | C31: ✓ COMPLETE 2 testing instances • 1 document(s) on file, not credited | D31: Conforms | E31: {=IFERROR(INDEX('iCoA Register'!$B:$B,MATCH("P060292|I",'iCoA Register'!$P:$P,0)),"iCoA — at issue")&", (19.05.2026) [PP]"} -> iCoA-PP_26-062, (19.05.2026) [PP] | F31: ✓ | G31: not on this certificate | H31: ППК26066, (11.05.2026) [CNP] · on file, not credited | I31: • | J31: Conforms (ImB spec.) | K31: ППК26066, (11.05.2026) [CNP] | L31: ✓ | M31: 16.69 | N31: ППК26066, (11.05.2026) [CNP] | O31: ✓ | P31: 0.05 | Q31: ППК26066, (11.05.2026) [CNP] | R31: ✓ | S31: BLQ ᴰ | T31: ППК26066, (11.05.2026) [CNP] | U31: ✓ | V31: Conforms | W31: {=IFERROR(INDEX('iCoA Register'!$B:$B,MATCH("P060292|I",'iCoA Register'!$P:$P,0)),"iCoA — at issue")&", (19.05.2026) [PP]"} -> iCoA-PP_26-062, (19.05.2026) [PP] | X31: ✓ | Y31: 6.09 | Z31: ППК26066, (11.05.2026) [CNP] | AA31: ✓ | AB31: 3.9 x 10³ | AC31: 2.4 x 10³ | AD31: <10 | AE31: отсутна/25 | AF31: отсутна/g | AG31: ✓ | AH31: n.r. | AI31: <2 | AJ31: n.r. | AK31: ✓ | AL31: 0.0215 | AM31: 0.0108 | AN31: 0.0199 | AO31: 0.0078 | AP31: ✓ | AQ31: ≤ LOQ (all 29 compounds) | AR31: 2357-2026, (29.04.2026) [IJZ] | AS31: ✓
AB32: 312-0556-26, (28.04.2026) [IJZ-MB] | AH32: 2357-2026, (29.04.2026) [IJZ] | AL32: 2357-2026, (29.04.2026) [IJZ]
G33: Conforms | H33: {=IFERROR(INDEX('iCoA Register'!$B:$B,MATCH("P060292|I",'iCoA Register'!$P:$P,0)),"iCoA — at issue")&", (19.05.2026) [PP]"} -> iCoA-PP_26-062, (19.05.2026) [PP] | I33: ✓ | AB33: 3×10³ | AC33: 5.2×10² | AD33: <10² и >10 | AE33: absent | AF33: absent | AG33: ✓
AB34: 542-1073-26, (31.08.2026) [IJZ-MB]
A35: GG012601＊ | B35: P060302 | C35: ✓ COMPLETE 2 testing instances • 1 document(s) on file, not credited | D35: Conforms | E35: {=IFERROR(INDEX('iCoA Register'!$B:$B,MATCH("P060302|I",'iCoA Register'!$P:$P,0)),"iCoA — at issue")&", (20.05.2026) [PP]"} -> iCoA-PP_26-063, (20.05.2026) [PP] | F35: ✓ | G35: not on this certificate | H35: ППК26062, (11.05.2026) [CNP] · on file, not credited | I35: • | J35: Conforms (ImB spec.) | K35: ППК26062, (11.05.2026) [CNP] | L35: ✓ | M35: 15.35 | N35: ППК26062, (11.05.2026) [CNP] | O35: ✓ | P35: 0.06 | Q35: ППК26062, (11.05.2026) [CNP] | R35: ✓ | S35: BLQ ᴰ | T35: ППК26062, (11.05.2026) [CNP] | U35: ✓ | V35: Conforms | W35: {=IFERROR(INDEX('iCoA Register'!$B:$B,MATCH("P060302|I",'iCoA Register'!$P:$P,0)),"iCoA — at issue")&", (20.05.2026) [PP]"} -> iCoA-PP_26-063, (20.05.2026) [PP] | X35: ✓ | Y35: 6.13 | Z35: ППК26062, (11.05.2026) [CNP] | AA35: ✓ | AB35: 1 x 10⁴ | AC35: 1 x 10⁴ | AD35: <10 | AE35: отсутна/25 | AF35: отсутна/g | AG35: ✓ | AH35: n.r. | AI35: <2 | AJ35: n.r. | AK35: ✓ | AL35: 0.0227 | AM35: 0.0179 | AN35: 0.0163 | AO35: 0.031 | AP35: ✓ | AQ35: ≤ LOQ (all 29 compounds) | AR35: 2364-2026, (30.04.2026) [IJZ] | AS35: ✓
AB36: 310-0554-26, (28.04.2026) [IJZ-MB] | AH36: 2364-2026, (30.04.2026) [IJZ] | AL36: 2364-2026, (30.04.2026) [IJZ]
G37: Conforms | H37: {=IFERROR(INDEX('iCoA Register'!$B:$B,MATCH("P060302|I",'iCoA Register'!$P:$P,0)),"iCoA — at issue")&", (20.05.2026) [PP]"} -> iCoA-PP_26-063, (20.05.2026) [PP] | I37: ✓ | AB37: 2.2×10³ | AC37: 2.1×10³ | AD37: <10 | AE37: absent | AF37: absent | AG37: ✓
AB38: 541-1072-26, (31.08.2026) [IJZ-MB]
A39: GG012603 | B39: P060402 | C39: ⚠ 3 NO RESULT (3 no cert / 0 cert w/o result) 2 testing instances • 1 document(s) on file, not credited | D39: Одговара | E39: ППК26114, (30.06.2026) [CNP] | F39: ✓ | G39: Одговара | H39: ППК26114, (30.06.2026) [CNP] | I39: ✓ | J39: Conforms (ImB spec.) | K39: ППК26114, (30.06.2026) [CNP] | L39: ✓ | M39: 17.59 | N39: ППК26114, (30.06.2026) [CNP] | O39: ✓ | P39: 0.05 | Q39: ППК26114, (30.06.2026) [CNP] | R39: ✓ | S39: 0.15 | T39: ППК26114, (30.06.2026) [CNP] | U39: ✓ | V39: 0.09 % (Одговара) | W39: ППК26114, (30.06.2026) [CNP] | X39: ✓ | Y39: 6.48 | Z39: ППК26114, (30.06.2026) [CNP] | AA39: ✓ | AB39: — MISSING — | AC39: — MISSING — | AD39: — MISSING — | AE39: — MISSING — | AF39: — MISSING — | AG39: ✗ | AH39: ND | AI39: ND ᴿ | AJ39: ND | AK39: ✓ | AL39: — MISSING — | AM39: — MISSING — | AN39: — MISSING — | AO39: — MISSING — | AP39: ✗ | AQ39: — MISSING — | AR39: — no certificate — | AS39: ✗
AB40: — no certificate — | AH40: 197-8-M-26, (10.08.2026) [FHM-M] | AL40: — no certificate —
J41: Conforms (ImB spec.) ᴿ | K41: 197-8-K-26, (07.08.2026) [FHM-K] | L41: ✓ | M41: 16.70 | N41: 197-8-K-26, (07.08.2026) [FHM-K] | O41: ✓ | P41: < LOQ | Q41: 197-8-K-26, (07.08.2026) [FHM-K] | R41: ✓ | S41: < LOQ | T41: 197-8-K-26, (07.08.2026) [FHM-K] | U41: ✓ | Y41: not on this certificate | Z41: 197-8-K-26, (07.08.2026) [FHM-K] · on file, not credited | AA41: •
...

Sheet iCoA Register
A1: No. | B1: iCoA code | C1: Issuable | D1: Issue date (planned) | E1: Test date (packaging) | F1: Packaging complete | G1: Group | H1: Series | I1: CU Batch | J1: P Batch | K1: Strain | L1: iCoA scope | M1: CNP reference | N1: CoQ (register) | O1: Plan reference (31.08.2026) | P1: Key | Q1: Status
A2: =IF(C2="yes",COUNT(A$1:A1)+1,"") -> 1 | B2: =IF(A2<>"","iCoA-PP_26-"&TEXT(A2,"000"),IF(C2="n/a","not needed","— at issue —")) -> iCoA-PP_26-001 | C2: yes | D2: =IF(A2="","",IF(G2="legacy",DATE(2026,5,15),IF(ISNUMBER(F2),(F2+5)+CHOOSE(WEEKDAY(F2+5,2),0,0,0,0,0,2,1),""))) -> 46157 | E2: {=IFERROR(INDEX('Batch Dates'!$F:$F,MATCH(J2,'Batch Dates'!$C:$C,0)),IFERROR(INDEX('Batch Dates'!$F:$F,MATCH(I2,'Batch Dates'!$B:$B,0)),""))} -> 45719 | F2: {=IFERROR(INDEX('Batch Dates'!$G:$G,MATCH(J2,'Batch Dates'!$C:$C,0)),IFERROR(INDEX('Batch Dates'!$G:$G,MATCH(I2,'Batch Dates'!$B:$B,0)),""))} -> 45719 | G2: legacy | H2: initial release | I2: CJ1024 | J2: N/A — no P batch assigned | K2: Cap Junky | L2: Ident A + Ident B + Foreign matter | M2: — | N2: {=IFERROR(INDEX('CoQ Register'!$B:$B,MATCH("CJ1024|I",'CoQ Register'!$S:$S,0)),"—")} -> CoQ-PP_26-001 | O2: — | P2: CJ1024|I | Q2: registered — issued with the legacy series on 15.05.2026
A3: =IF(C3="yes",COUNT(A$1:A2)+1,"") -> 2 | B3: =IF(A3<>"","iCoA-PP_26-"&TEXT(A3,"000"),IF(C3="n/a","not needed","— at issue —")) -> iCoA-PP_26-002 | C3: yes | D3: =IF(A3="","",IF(G3="legacy",DATE(2026,5,15),IF(ISNUMBER(F3),(F3+5)+CHOOSE(WEEKDAY(F3+5,2),0,0,0,0,0,2,1),""))) -> 46157 | E3: {=IFERROR(INDEX('Batch Dates'!$F:$F,MATCH(J3,'Batch Dates'!$C:$C,0)),IFERROR(INDEX('Batch Dates'!$F:$F,MATCH(I3,'Batch Dates'!$B:$B,0)),""))} -> 45720 | F3: {=IFERROR(INDEX('Batch Dates'!$G:$G,MATCH(J3,'Batch Dates'!$C:$C,0)),IFERROR(INDEX('Batch Dates'!$G:$G,MATCH(I3,'Batch Dates'!$B:$B,0)),""))} -> 45720 | G3: legacy | H3: initial release | I3: BSS1024 | J3: N/A — no P batch assigned | K3: Blue Sunset Sherbet | L3: Ident A + Ident B + Foreign matter | M3: — | N3: {=IFERROR(INDEX('CoQ Register'!$B:$B,MATCH("BSS1024|I",'CoQ Register'!$S:$S,0)),"—")} -> CoQ-PP_26-002 | O3: iCoA-PP-2025-0001 | P3: BSS1024|I | Q3: registered — issued with the legacy series on 15.05.2026
A4: =IF(C4="yes",COUNT(A$1:A3)+1,"") -> 3 | B4: =IF(A4<>"","iCoA-PP_26-"&TEXT(A4,"000"),IF(C4="n/a","not needed","— at issue —")) -> iCoA-PP_26-003 | C4: yes | D4: =IF(A4="","",IF(G4="legacy",DATE(2026,5,15),IF(ISNUMBER(F4),(F4+5)+CHOOSE(WEEKDAY(F4+5,2),0,0,0,0,0,2,1),""))) -> 46157 | E4: {=IFERROR(INDEX('Batch Dates'!$F:$F,MATCH(J4,'Batch Dates'!$C:$C,0)),IFERROR(INDEX('Batch Dates'!$F:$F,MATCH(I4,'Batch Dates'!$B:$B,0)),""))} -> 45723 | F4: {=IFERROR(INDEX('Batch Dates'!$G:$G,MATCH(J4,'Batch Dates'!$C:$C,0)),IFERROR(INDEX('Batch Dates'!$G:$G,MATCH(I4,'Batch Dates'!$B:$B,0)),""))} -> 45723 | G4: legacy | H4: initial release | I4: BG1024 | J4: N/A — no P batch assigned | K4: Blue Gelato | L4: Ident A + Ident B + Foreign matter | M4: — | N4: {=IFERROR(INDEX('CoQ Register'!$B:$B,MATCH("BG1024|I",'CoQ Register'!$S:$S,0)),"—")} -> CoQ-PP_26-003 | O4: iCoA-PP-2025-0002 | P4: BG1024|I | Q4: registered — issued with the legacy series on 15.05.2026
A5: =IF(C5="yes",COUNT(A$1:A4)+1,"") -> 4 | B5: =IF(A5<>"","iCoA-PP_26-"&TEXT(A5,"000"),IF(C5="n/a","not needed","— at issue —")) -> iCoA-PP_26-004 | C5: yes | D5: =IF(A5="","",IF(G5="legacy",DATE(2026,5,15),IF(ISNUMBER(F5),(F5+5)+CHOOSE(WEEKDAY(F5+5,2),0,0,0,0,0,2,1),""))) -> 46157 | E5: {=IFERROR(INDEX('Batch Dates'!$F:$F,MATCH(J5,'Batch Dates'!$C:$C,0)),IFERROR(INDEX('Batch Dates'!$F:$F,MATCH(I5,'Batch Dates'!$B:$B,0)),""))} -> 45727 | F5: {=IFERROR(INDEX('Batch Dates'!$G:$G,MATCH(J5,'Batch Dates'!$C:$C,0)),IFERROR(INDEX('Batch Dates'!$G:$G,MATCH(I5,'Batch Dates'!$B:$B,0)),""))} -> 45727 | G5: legacy | H5: initial release | I5: GG1024 | J5: N/A — no P batch assigned | K5: Gorilla Glue | L5: Ident A + Ident B + Foreign matter | M5: — | N5: {=IFERROR(INDEX('CoQ Register'!$B:$B,MATCH("GG1024|I",'CoQ Register'!$S:$S,0)),"—")} -> CoQ-PP_26-004 | O5: iCoA-PP-2025-0003 | P5: GG1024|I | Q5: registered — issued with the legacy series on 15.05.2026
A6: =IF(C6="yes",COUNT(A$1:A5)+1,"") -> 5 | B6: =IF(A6<>"","iCoA-PP_26-"&TEXT(A6,"000"),IF(C6="n/a","not needed","— at issue —")) -> iCoA-PP_26-005 | C6: yes | D6: =IF(A6="","",IF(G6="legacy",DATE(2026,5,15),IF(ISNUMBER(F6),(F6+5)+CHOOSE(WEEKDAY(F6+5,2),0,0,0,0,0,2,1),""))) -> 46157 | E6: {=IFERROR(INDEX('Batch Dates'!$F:$F,MATCH(J6,'Batch Dates'!$C:$C,0)),IFERROR(INDEX('Batch Dates'!$F:$F,MATCH(I6,'Batch Dates'!$B:$B,0)),""))} -> 45758 | F6: {=IFERROR(INDEX('Batch Dates'!$G:$G,MATCH(J6,'Batch Dates'!$C:$C,0)),IFERROR(INDEX('Batch Dates'!$G:$G,MATCH(I6,'Batch Dates'!$B:$B,0)),""))} -> 45758 | G6: legacy | H6: initial release | I6: HPA1024 | J6: N/A — no P batch assigned | K6: HighProAmnesia | L6: Ident A + Ident B + Foreign matter | M6: — | N6: {=IFERROR(INDEX('CoQ Register'!$B:$B,MATCH("HPA1024|I",'CoQ Register'!$S:$S,0)),"—")} -> CoQ-PP_26-005 | O6: iCoA-PP-2025-0004 | P6: HPA1024|I | Q6: registered — issued with the legacy series on 15.05.2026
A7: =IF(C7="yes",COUNT(A$1:A6)+1,"") -> 6 | B7: =IF(A7<>"","iCoA-PP_26-"&TEXT(A7,"000"),IF(C7="n/a","not needed","— at issue —")) -> iCoA-PP_26-006 | C7: yes | D7: =IF(A7="","",IF(G7="legacy",DATE(2026,5,15),IF(ISNUMBER(F7),(F7+5)+CHOOSE(WEEKDAY(F7+5,2),0,0,0,0,0,2,1),""))) -> 46157 | E7: {=IFERROR(INDEX('Batch Dates'!$F:$F,MATCH(J7,'Batch Dates'!$C:$C,0)),IFERROR(INDEX('Batch Dates'!$F:$F,MATCH(I7,'Batch Dates'!$B:$B,0)),""))} -> 45771 | F7: {=IFERROR(INDEX('Batch Dates'!$G:$G,MATCH(J7,'Batch Dates'!$C:$C,0)),IFERROR(INDEX('Batch Dates'!$G:$G,MATCH(I7,'Batch Dates'!$B:$B,0)),""))} -> 45772 | G7: legacy | H7: initial release | I7: OPM1024 | J7: N/A — no P batch assigned | K7: OrangePunchMimosa | L7: Ident A + Ident B + Foreign matter | M7: — | N7: {=IFERROR(INDEX('CoQ Register'!$B:$B,MATCH("OPM1024|I",'CoQ Register'!$S:$S,0)),"—")} -> CoQ-PP_26-006 | O7: iCoA-PP-2025-0005 | P7: OPM1024|I | Q7: registered — issued with the legacy series on 15.05.2026
A8: =IF(C8="yes",COUNT(A$1:A7)+1,"") -> 7 | B8: =IF(A8<>"","iCoA-PP_26-"&TEXT(A8,"000"),IF(C8="n/a","not needed","— at issue —")) -> iCoA-PP_26-007 | C8: yes | D8: =IF(A8="","",IF(G8="legacy",DATE(2026,5,15),IF(ISNUMBER(F8),(F8+5)+CHOOSE(WEEKDAY(F8+5,2),0,0,0,0,0,2,1),""))) -> 46157 | E8: {=IFERROR(INDEX('Batch Dates'!$F:$F,MATCH(J8,'Batch Dates'!$C:$C,0)),IFERROR(INDEX('Batch Dates'!$F:$F,MATCH(I8,'Batch Dates'!$B:$B,0)),""))} -> 45811 | F8: {=IFERROR(INDEX('Batch Dates'!$G:$G,MATCH(J8,'Batch Dates'!$C:$C,0)),IFERROR(INDEX('Batch Dates'!$G:$G,MATCH(I8,'Batch Dates'!$B:$B,0)),""))} -> 45819 | G8: legacy | H8: initial release | I8: GP0824_02 | J8: P050022 | K8: Grape Pie | L8: Ident A + Ident B + Foreign matter | M8: — | N8: {=IFERROR(INDEX('CoQ Register'!$B:$B,MATCH("P050022|I",'CoQ Register'!$S:$S,0)),"—")} -> CoQ-PP_26-007 | O8: iCoA-PP-2025-0006 | P8: P050022|I | Q8: registered — issued with the legacy series on 15.05.2026
A9: =IF(C9="yes",COUNT(A$1:A8)+1,"") -> 8 | B9: =IF(A9<>"","iCoA-PP_26-"&TEXT(A9,"000"),IF(C9="n/a","not needed","— at issue —")) -> iCoA-PP_26-008 | C9: yes | D9: =IF(A9="","",IF(G9="legacy",DATE(2026,5,15),IF(ISNUMBER(F9),(F9+5)+CHOOSE(WEEKDAY(F9+5,2),0,0,0,0,0,2,1),""))) -> 46157 | E9: {=IFERROR(INDEX('Batch Dates'!$F:$F,MATCH(J9,'Batch Dates'!$C:$C,0)),IFERROR(INDEX('Batch Dates'!$F:$F,MATCH(I9,'Batch Dates'!$B:$B,0)),""))} -> 45819 | F9: {=IFERROR(INDEX('Batch Dates'!$G:$G,MATCH(J9,'Batch Dates'!$C:$C,0)),IFERROR(INDEX('Batch Dates'!$G:$G,MATCH(I9,'Batch Dates'!$B:$B,0)),""))} -> 45824 | G9: legacy | H9: initial release | I9: GG1024_02 | J9: P050012 | K9: Gorilla Glue | L9: Ident A + Ident B + Foreign matter | M9: — | N9: {=IFERROR(INDEX('CoQ Register'!$B:$B,MATCH("P050012|I",'CoQ Register'!$S:$S,0)),"—")} -> CoQ-PP_26-008 | O9: — | P9: P050012|I | Q9: registered — issued with the legacy series on 15.05.2026
A10: =IF(C10="yes",COUNT(A$1:A9)+1,"") -> 9 | B10: =IF(A10<>"","iCoA-PP_26-"&TEXT(A10,"000"),IF(C10="n/a","not needed","— at issue —")) -> iCoA-PP_26-009 | C10: yes | D10: =IF(A10="","",IF(G10="legacy",DATE(2026,5,15),IF(ISNUMBER(F10),(F10+5)+CHOOSE(WEEKDAY(F10+5,2),0,0,0,0,0,2,1),""))) -> 46157 | E10: {=IFERROR(INDEX('Batch Dates'!$F:$F,MATCH(J10,'Batch Dates'!$C:$C,0)),IFERROR(INDEX('Batch Dates'!$F:$F,MATCH(I10,'Batch Dates'!$B:$B,0)),""))} -> 45824 | F10: {=IFERROR(INDEX('Batch Dates'!$G:$G,MATCH(J10,'Batch Dates'!$C:$C,0)),IFERROR(INDEX('Batch Dates'!$G:$G,MATCH(I10,'Batch Dates'!$B:$B,0)),""))} -> 45827 | G10: legacy | H10: initial release | I10: MB0824_04 | J10: P050032 | K10: Motor Breath | L10: Ident A + Ident B + Foreign matter | M10: — | N10: {=IFERROR(INDEX('CoQ Register'!$B:$B,MATCH("P050032|I",'CoQ Register'!$S:$S,0)),"—")} -> CoQ-PP_26-009 | O10: — | P10: P050032|I | Q10: registered — issued with the legacy series on 15.05.2026
A11: =IF(C11="yes",COUNT(A$1:A10)+1,"") -> 10 | B11: =IF(A11<>"","iCoA-PP_26-"&TEXT(A11,"000"),IF(C11="n/a","not needed","— at issue —")) -> iCoA-PP_26-010 | C11: yes | D11: =IF(A11="","",IF(G11="legacy",DATE(2026,5,15),IF(ISNUMBER(F11),(F11+5)+CHOOSE(WEEKDAY(F11+5,2),0,0,0,0,0,2,1),""))) -> 46157 | E11: {=IFERROR(INDEX('Batch Dates'!$F:$F,MATCH(J11,'Batch Dates'!$C:$C,0)),IFERROR(INDEX('Batch Dates'!$F:$F,MATCH(I11,'Batch Dates'!$B:$B,0)),""))} -> 45828 | F11: {=IFERROR(INDEX('Batch Dates'!$G:$G,MATCH(J11,'Batch Dates'!$C:$C,0)),IFERROR(INDEX('Batch Dates'!$G:$G,MATCH(I11,'Batch Dates'!$B:$B,0)),""))} -> 45828 | G11: legacy | H11: initial release | I11: OMP1024_01 | J11: P050042 | K11: Orange Punch Mimosa | L11: Ident A + Ident B + Foreign matter | M11: — | N11: {=IFERROR(INDEX('CoQ Register'!$B:$B,MATCH("P050042|I",'CoQ Register'!$S:$S,0)),"—")} -> CoQ-PP_26-010 | O11: iCoA-PP-2025-0007 | P11: P050042|I | Q11: registered — issued with the legacy series on 15.05.2026
A12: =IF(C12="yes",COUNT(A$1:A11)+1,"") -> 11 | B12: =IF(A12<>"","iCoA-PP_26-"&TEXT(A12,"000"),IF(C12="n/a","not needed","— at issue —")) -> iCoA-PP_26-011 | C12: yes | D12: =IF(A12="","",IF(G12="legacy",DATE(2026,5,15),IF(ISNUMBER(F12),(F12+5)+CHOOSE(WEEKDAY(F12+5,2),0,0,0,0,0,2,1),""))) -> 46157 | E12: {=IFERROR(INDEX('Batch Dates'!$F:$F,MATCH(J12,'Batch Dates'!$C:$C,0)),IFERROR(INDEX('Batch Dates'!$F:$F,MATCH(I12,'Batch Dates'!$B:$B,0)),""))} -> 45835 | F12: {=IFERROR(INDEX('Batch Dates'!$G:$G,MATCH(J12,'Batch Dates'!$C:$C,0)),IFERROR(INDEX('Batch Dates'!$G:$G,MATCH(I12,'Batch Dates'!$B:$B,0)),""))} -> 45842 | G12: legacy | H12: initial release | I12: HPA1024_01 | J12: P050052 | K12: High Pro Amnesia | L12: Ident A + Ident B + Foreign matter | M12: — | N12: {=IFERROR(INDEX('CoQ Register'!$B:$B,MATCH("P050052|I",'CoQ Register'!$S:$S,0)),"—")} -> CoQ-PP_26-011 | O12: iCoA-PP-2025-0008 | P12: P050052|I | Q12: registered — issued with the legacy series on 15.05.2026
A13: =IF(C13="yes",COUNT(A$1:A12)+1,"") -> 12 | B13: =IF(A13<>"","iCoA-PP_26-"&TEXT(A13,"000"),IF(C13="n/a","not needed","— at issue —")) -> iCoA-PP_26-012 | C13: yes | D13: =IF(A13="","",IF(G13="legacy",DATE(2026,5,15),IF(ISNUMBER(F13),(F13+5)+CHOOSE(WEEKDAY(F13+5,2),0,0,0,0,0,2,1),""))) -> 46157 | E13: {=IFERROR(INDEX('Batch Dates'!$F:$F,MATCH(J13,'Batch Dates'!$C:$C,0)),IFERROR(INDEX('Batch Dates'!$F:$F,MATCH(I13,'Batch Dates'!$B:$B,0)),""))} -> 45842 | F13: {=IFERROR(INDEX('Batch Dates'!$G:$G,MATCH(J13,'Batch Dates'!$C:$C,0)),IFERROR(INDEX('Batch Dates'!$G:$G,MATCH(I13,'Batch Dates'!$B:$B,0)),""))} -> 45848 | G13: legacy | H13: initial release | I13: OPM1024_02 | J13: P050062 | K13: Orange Punch Mimosa | L13: Ident A + Ident B + Foreign matter | M13: — | N13: {=IFERROR(INDEX('CoQ Register'!$B:$B,MATCH("P050062|I",'CoQ Register'!$S:$S,0)),"—")} -> CoQ-PP_26-012 | O13: iCoA-PP-2025-0009 | P13: P050062|I | Q13: registered — issued with the legacy series on 15.05.2026
A14: =IF(C14="yes",COUNT(A$1:A13)+1,"") -> 13 | B14: =IF(A14<>"","iCoA-PP_26-"&TEXT(A14,"000"),IF(C14="n/a","not needed","— at issue —")) -> iCoA-PP_26-013 | C14: yes | D14: =IF(A14="","",IF(G14="legacy",DATE(2026,5,15),IF(ISNUMBER(F14),(F14+5)+CHOOSE(WEEKDAY(F14+5,2),0,0,0,0,0,2,1),""))) -> 46157 | E14: {=IFERROR(INDEX('Batch Dates'!$F:$F,MATCH(J14,'Batch Dates'!$C:$C,0)),IFERROR(INDEX('Batch Dates'!$F:$F,MATCH(I14,'Batch Dates'!$B:$B,0)),""))} -> 45852 | F14: {=IFERROR(INDEX('Batch Dates'!$G:$G,MATCH(J14,'Batch Dates'!$C:$C,0)),IFERROR(INDEX('Batch Dates'!$G:$G,MATCH(I14,'Batch Dates'!$B:$B,0)),""))} -> 45855 | G14: legacy | H14: initial release | I14: GP0824_03 | J14: P050072 | K14: Grape Pie | L14: Ident A + Ident B + Foreign matter | M14: — | N14: {=IFERROR(INDEX('CoQ Register'!$B:$B,MATCH("P050072|I",'CoQ Register'!$S:$S,0)),"—")} -> CoQ-PP_26-013 | O14: iCoA-PP-2025-0010 | P14: P050072|I | Q14: registered — issued with the legacy series on 15.05.2026
A15: =IF(C15="yes",COUNT(A$1:A14)+1,"") -> 14 | B15: =IF(A15<>"","iCoA-PP_26-"&TEXT(A15,"000"),IF(C15="n/a","not needed","— at issue —")) -> iCoA-PP_26-014 | C15: yes | D15: =IF(A15="","",IF(G15="legacy",DATE(2026,5,15),IF(ISNUMBER(F15),(F15+5)+CHOOSE(WEEKDAY(F15+5,2),0,0,0,0,0,2,1),""))) -> 46157 | E15: {=IFERROR(INDEX('Batch Dates'!$F:$F,MATCH(J15,'Batch Dates'!$C:$C,0)),IFERROR(INDEX('Batch Dates'!$F:$F,MATCH(I15,'Batch Dates'!$B:$B,0)),""))} -> 45860 | F15: {=IFERROR(INDEX('Batch Dates'!$G:$G,MATCH(J15,'Batch Dates'!$C:$C,0)),IFERROR(INDEX('Batch Dates'!$G:$G,MATCH(I15,'Batch Dates'!$B:$B,0)),""))} -> 45868 | G15: legacy | H15: initial release | I15: OPM1024_03 | J15: P050082 | K15: Orange Punch Mimosa | L15: Ident A + Ident B + Foreign matter | M15: — | N15: {=IFERROR(INDEX('CoQ Register'!$B:$B,MATCH("P050082|I",'CoQ Register'!$S:$S,0)),"—")} -> CoQ-PP_26-014 | O15: iCoA-PP-2025-0011 | P15: P050082|I | Q15: registered — issued with the legacy series on 15.05.2026
A16: =IF(C16="yes",COUNT(A$1:A15)+1,"") -> 15 | B16: =IF(A16<>"","iCoA-PP_26-"&TEXT(A16,"000"),IF(C16="n/a","not needed","— at issue —")) -> iCoA-PP_26-015 | C16: yes | D16: =IF(A16="","",IF(G16="legacy",DATE(2026,5,15),IF(ISNUMBER(F16),(F16+5)+CHOOSE(WEEKDAY(F16+5,2),0,0,0,0,0,2,1),""))) -> 46157 | E16: {=IFERROR(INDEX('Batch Dates'!$F:$F,MATCH(J16,'Batch Dates'!$C:$C,0)),IFERROR(INDEX('Batch Dates'!$F:$F,MATCH(I16,'Batch Dates'!$B:$B,0)),""))} -> 45869 | F16: {=IFERROR(INDEX('Batch Dates'!$G:$G,MATCH(J16,'Batch Dates'!$C:$C,0)),IFERROR(INDEX('Batch Dates'!$G:$G,MATCH(I16,'Batch Dates'!$B:$B,0)),""))} -> 45874 | G16: legacy | H16: initial release | I16: GG1024_01 | J16: P050092 | K16: Gorilla Glue | L16: Ident A + Ident B + Foreign matter | M16: — | N16: {=IFERROR(INDEX('CoQ Register'!$B:$B,MATCH("P050092|I",'CoQ Register'!$S:$S,0)),"—")} -> CoQ-PP_26-015 | O16: iCoA-PP-2025-0012 | P16: P050092|I | Q16: registered — issued with the legacy series on 15.05.2026
A17: =IF(C17="yes",COUNT(A$1:A16)+1,"") -> 16 | B17: =IF(A17<>"","iCoA-PP_26-"&TEXT(A17,"000"),IF(C17="n/a","not needed","— at issue —")) -> iCoA-PP_26-016 | C17: yes | D17: =IF(A17="","",IF(G17="legacy",DATE(2026,5,15),IF(ISNUMBER(F17),(F17+5)+CHOOSE(WEEKDAY(F17+5,2),0,0,0,0,0,2,1),""))) -> 46157 | E17: {=IFERROR(INDEX('Batch Dates'!$F:$F,MATCH(J17,'Batch Dates'!$C:$C,0)),IFERROR(INDEX('Batch Dates'!$F:$F,MATCH(I17,'Batch Dates'!$B:$B,0)),""))} -> 45874 | F17: {=IFERROR(INDEX('Batch Dates'!$G:$G,MATCH(J17,'Batch Dates'!$C:$C,0)),IFERROR(INDEX('Batch Dates'!$G:$G,MATCH(I17,'Batch Dates'!$B:$B,0)),""))} -> 45876 | G17: legacy | H17: initial release | I17: GP0824_01 | J17: P050102 | K17: Grape Pie | L17: Ident A + Ident B + Foreign matter | M17: — | N17: {=IFERROR(INDEX('CoQ Register'!$B:$B,MATCH("P050102|I",'CoQ Register'!$S:$S,0)),"—")} -> CoQ-PP_26-016 | O17: — | P17: P050102|I | Q17: registered — issued with the legacy series on 15.05.2026
A18: =IF(C18="yes",COUNT(A$1:A17)+1,"") -> 17 | B18: =IF(A18<>"","iCoA-PP_26-"&TEXT(A18,"000"),IF(C18="n/a","not needed","— at issue —")) -> iCoA-PP_26-017 | C18: yes | D18: =IF(A18="","",IF(G18="legacy",DATE(2026,5,15),IF(ISNUMBER(F18),(F18+5)+CHOOSE(WEEKDAY(F18+5,2),0,0,0,0,0,2,1),""))) -> 46157 | E18: {=IFERROR(INDEX('Batch Dates'!$F:$F,MATCH(J18,'Batch Dates'!$C:$C,0)),IFERROR(INDEX('Batch Dates'!$F:$F,MATCH(I18,'Batch Dates'!$B:$B,0)),""))} -> 45894 | F18: {=IFERROR(INDEX('Batch Dates'!$G:$G,MATCH(J18,'Batch Dates'!$C:$C,0)),IFERROR(INDEX('Batch Dates'!$G:$G,MATCH(I18,'Batch Dates'!$B:$B,0)),""))} -> 45900 | G18: legacy | H18: initial release | I18: MB0824_05 | J18: P050112 | K18: Motor Breath | L18: Ident A + Ident B + Foreign matter | M18: — | N18: {=IFERROR(INDEX('CoQ Register'!$B:$B,MATCH("P050112|I",'CoQ Register'!$S:$S,0)),"—")} -> CoQ-PP_26-017 | O18: iCoA-PP-2025-0013 | P18: P050112|I | Q18: registered — issued with the legacy series on 15.05.2026
A19: =IF(C19="yes",COUNT(A$1:A18)+1,"") -> 18 | B19: =IF(A19<>"","iCoA-PP_26-"&TEXT(A19,"000"),IF(C19="n/a","not needed","— at issue —")) -> iCoA-PP_26-018 | C19: yes | D19: =IF(A19="","",IF(G19="legacy",DATE(2026,5,15),IF(ISNUMBER(F19),(F19+5)+CHOOSE(WEEKDAY(F19+5,2),0,0,0,0,0,2,1),""))) -> 46157 | E19: {=IFERROR(INDEX('Batch Dates'!$F:$F,MATCH(J19,'Batch Dates'!$C:$C,0)),IFERROR(INDEX('Batch Dates'!$F:$F,MATCH(I19,'Batch Dates'!$B:$B,0)),""))} -> 45901 | F19: {=IFERROR(INDEX('Batch Dates'!$G:$G,MATCH(J19,'Batch Dates'!$C:$C,0)),IFERROR(INDEX('Batch Dates'!$G:$G,MATCH(I19,'Batch Dates'!$B:$B,0)),""))} -> 45909 | G19: legacy | H19: initial release | I19: BSS1024_01/1 | J19: P050122 | K19: Blue Sunset Sherbet | L19: Ident A + Ident B + Foreign matter | M19: — | N19: {=IFERROR(INDEX('CoQ Register'!$B:$B,MATCH("P050122|I",'CoQ Register'!$S:$S,0)),"—")} -> CoQ-PP_26-018 | O19: — | P19: P050122|I | Q19: registered — issued with the legacy series on 15.05.2026
A20: =IF(C20="yes",COUNT(A$1:A19)+1,"") -> 19 | B20: =IF(A20<>"","iCoA-PP_26-"&TEXT(A20,"000"),IF(C20="n/a","not needed","— at issue —")) -> iCoA-PP_26-019 | C20: yes | D20: =IF(A20="","",IF(G20="legacy",DATE(2026,5,15),IF(ISNUMBER(F20),(F20+5)+CHOOSE(WEEKDAY(F20+5,2),0,0,0,0,0,2,1),""))) -> 46157 | E20: {=IFERROR(INDEX('Batch Dates'!$F:$F,MATCH(J20,'Batch Dates'!$C:$C,0)),IFERROR(INDEX('Batch Dates'!$F:$F,MATCH(I20,'Batch Dates'!$B:$B,0)),""))} -> 45909 | F20: {=IFERROR(INDEX('Batch Dates'!$G:$G,MATCH(J20,'Batch Dates'!$C:$C,0)),IFERROR(INDEX('Batch Dates'!$G:$G,MATCH(I20,'Batch Dates'!$B:$B,0)),""))} -> 45915 | G20: legacy | H20: initial release | I20: OPM052501 | J20: P050132 | K20: Orange Punch Mimosa | L20: Ident A + Ident B + Foreign matter | M20: — | N20: {=IFERROR(INDEX('CoQ Register'!$B:$B,MATCH("P050132|I",'CoQ Register'!$S:$S,0)),"—")} -> CoQ-PP_26-019 | O20: — | P20: P050132|I | Q20: registered — issued with the legacy series on 15.05.2026
A21: =IF(C21="yes",COUNT(A$1:A20)+1,"") -> 20 | B21: =IF(A21<>"","iCoA-PP_26-"&TEXT(A21,"000"),IF(C21="n/a","not needed","— at issue —")) -> iCoA-PP_26-020 | C21: yes | D21: =IF(A21="","",IF(G21="legacy",DATE(2026,5,15),IF(ISNUMBER(F21),(F21+5)+CHOOSE(WEEKDAY(F21+5,2),0,0,0,0,0,2,1),""))) -> 46157 | E21: {=IFERROR(INDEX('Batch Dates'!$F:$F,MATCH(J21,'Batch Dates'!$C:$C,0)),IFERROR(INDEX('Batch Dates'!$F:$F,MATCH(I21,'Batch Dates'!$B:$B,0)),""))} -> 45925 | F21: {=IFERROR(INDEX('Batch Dates'!$G:$G,MATCH(J21,'Batch Dates'!$C:$C,0)),IFERROR(INDEX('Batch Dates'!$G:$G,MATCH(I21,'Batch Dates'!$B:$B,0)),""))} -> 45925 | G21: legacy | H21: initial release | I21: GP052501 | J21: P050152 | K21: Grape Pie | L21: Ident A + Ident B + Foreign matter | M21: — | N21: {=IFERROR(INDEX('CoQ Register'!$B:$B,MATCH("P050152|I",'CoQ Register'!$S:$S,0)),"—")} -> CoQ-PP_26-020 | O21: iCoA-PP-2025-0014 | P21: P050152|I | Q21: registered — issued with the legacy series on 15.05.2026
A22: =IF(C22="yes",COUNT(A$1:A21)+1,"") -> 21 | B22: =IF(A22<>"","iCoA-PP_26-"&TEXT(A22,"000"),IF(C22="n/a","not needed","— at issue —")) -> iCoA-PP_26-021 | C22: yes | D22: =IF(A22="","",IF(G22="legacy",DATE(2026,5,15),IF(ISNUMBER(F22),(F22+5)+CHOOSE(WEEKDAY(F22+5,2),0,0,0,0,0,2,1),""))) -> 46157 | E22: {=IFERROR(INDEX('Batch Dates'!$F:$F,MATCH(J22,'Batch Dates'!$C:$C,0)),IFERROR(INDEX('Batch Dates'!$F:$F,MATCH(I22,'Batch Dates'!$B:$B,0)),""))} -> 45930 | F22: {=IFERROR(INDEX('Batch Dates'!$G:$G,MATCH(J22,'Batch Dates'!$C:$C,0)),IFERROR(INDEX('Batch Dates'!$G:$G,MATCH(I22,'Batch Dates'!$B:$B,0)),""))} -> 45930 | G22: legacy | H22: initial release | I22: BSS1024_01/2 | J22: P050142 | K22: Blue Sunset Sherbet | L22: Ident A + Ident B + Foreign matter | M22: — | N22: {=IFERROR(INDEX('CoQ Register'!$B:$B,MATCH("P050142|I",'CoQ Register'!$S:$S,0)),"—")} -> CoQ-PP_26-021 | O22: — | P22: P050142|I | Q22: registered — issued with the legacy series on 15.05.2026
A23: =IF(C23="yes",COUNT(A$1:A22)+1,"") -> 22 | B23: =IF(A23<>"","iCoA-PP_26-"&TEXT(A23,"000"),IF(C23="n/a","not needed","— at issue —")) -> iCoA-PP_26-022 | C23: yes | D23: =IF(A23="","",IF(G23="legacy",DATE(2026,5,15),IF(ISNUMBER(F23),(F23+5)+CHOOSE(WEEKDAY(F23+5,2),0,0,0,0,0,2,1),""))) -> 46157 | E23: {=IFERROR(INDEX('Batch Dates'!$F:$F,MATCH(J23,'Batch Dates'!$C:$C,0)),IFERROR(INDEX('Batch Dates'!$F:$F,MATCH(I23,'Batch Dates'!$B:$B,0)),""))} -> 45930 | F23: {=IFERROR(INDEX('Batch Dates'!$G:$G,MATCH(J23,'Batch Dates'!$C:$C,0)),IFERROR(INDEX('Batch Dates'!$G:$G,MATCH(I23,'Batch Dates'!$B:$B,0)),""))} -> 45931 | G23: legacy | H23: initial release | I23: CJ052501/01 | J23: P050162 | K23: Cup Junky | L23: Ident A + Ident B + Foreign matter | M23: — | N23: {=IFERROR(INDEX('CoQ Register'!$B:$B,MATCH("P050162|I",'CoQ Register'!$S:$S,0)),"—")} -> CoQ-PP_26-022 | O23: iCoA-PP-2025-0015 | P23: P050162|I | Q23: registered — issued with the legacy series on 15.05.2026
A24: =IF(C24="yes",COUNT(A$1:A23)+1,"") -> 23 | B24: =IF(A24<>"","iCoA-PP_26-"&TEXT(A24,"000"),IF(C24="n/a","not needed","— at issue —")) -> iCoA-PP_26-023 | C24: yes | D24: =IF(A24="","",IF(G24="legacy",DATE(2026,5,15),IF(ISNUMBER(F24),(F24+5)+CHOOSE(WEEKDAY(F24+5,2),0,0,0,0,0,2,1),""))) -> 46157 | E24: {=IFERROR(INDEX('Batch Dates'!$F:$F,MATCH(J24,'Batch Dates'!$C:$C,0)),IFERROR(INDEX('Batch Dates'!$F:$F,MATCH(I24,'Batch Dates'!$B:$B,0)),""))} -> 45931 | F24: {=IFERROR(INDEX('Batch Dates'!$G:$G,MATCH(J24,'Batch Dates'!$C:$C,0)),IFERROR(INDEX('Batch Dates'!$G:$G,MATCH(I24,'Batch Dates'!$B:$B,0)),""))} -> 45932 | G24: legacy | H24: initial release | I24: CJ052501/02 | J24: P050172 | K24: Cap Junky | L24: Ident A + Ident B + Foreign matter | M24: — | N24: {=IFERROR(INDEX('CoQ Register'!$B:$B,MATCH("P050172|I",'CoQ Register'!$S:$S,0)),"—")} -> CoQ-PP_26-023 | O24: — | P24: P050172|I | Q24: registered — issued with the legacy series on 15.05.2026
A25: =IF(C25="yes",COUNT(A$1:A24)+1,"") -> 24 | B25: =IF(A25<>"","iCoA-PP_26-"&TEXT(A25,"000"),IF(C25="n/a","not needed","— at issue —")) -> iCoA-PP_26-024 | C25: yes | D25: =IF(A25="","",IF(G25="legacy",DATE(2026,5,15),IF(ISNUMBER(F25),(F25+5)+CHOOSE(WEEKDAY(F25+5,2),0,0,0,0,0,2,1),""))) -> 46157 | E25: {=IFERROR(INDEX('Batch Dates'!$F:$F,MATCH(J25,'Batch Dates'!$C:$C,0)),IFERROR(INDEX('Batch Dates'!$F:$F,MATCH(I25,'Batch Dates'!$B:$B,0)),""))} -> 45933 | F25: {=IFERROR(INDEX('Batch Dates'!$G:$G,MATCH(J25,'Batch Dates'!$C:$C,0)),IFERROR(INDEX('Batch Dates'!$G:$G,MATCH(I25,'Batch Dates'!$B:$B,0)),""))} -> 45939 | G25: legacy | H25: initial release | I25: HPA052501 | J25: P050182 | K25: High Pro Amnesia | L25: Ident A + Ident B + Foreign matter | M25: — | N25: {=IFERROR(INDEX('CoQ Register'!$B:$B,MATCH("P050182|I",'CoQ Register'!$S:$S,0)),"—")} -> CoQ-PP_26-024 | O25: iCoA-PP-2025-0016 | P25: P050182|I | Q25: registered — issued with the legacy series on 15.05.2026
A26: =IF(C26="yes",COUNT(A$1:A25)+1,"") -> 25 | B26: =IF(A26<>"","iCoA-PP_26-"&TEXT(A26,"000"),IF(C26="n/a","not needed","— at issue —")) -> iCoA-PP_26-025 | C26: yes | D26: =IF(A26="","",IF(G26="legacy",DATE(2026,5,15),IF(ISNUMBER(F26),(F26+5)+CHOOSE(WEEKDAY(F26+5,2),0,0,0,0,0,2,1),""))) -> 46157 | E26: {=IFERROR(INDEX('Batch Dates'!$F:$F,MATCH(J26,'Batch Dates'!$C:$C,0)),IFERROR(INDEX('Batch Dates'!$F:$F,MATCH(I26,'Batch Dates'!$B:$B,0)),""))} -> 45940 | F26: {=IFERROR(INDEX('Batch Dates'!$G:$G,MATCH(J26,'Batch Dates'!$C:$C,0)),IFERROR(INDEX('Batch Dates'!$G:$G,MATCH(I26,'Batch Dates'!$B:$B,0)),""))} -> 45951 | G26: legacy | H26: initial release | I26: BSS052501 | J26: P050192 | K26: Sleepy Joe | L26: Ident A + Ident B + Foreign matter | M26: — | N26: {=IFERROR(INDEX('CoQ Register'!$B:$B,MATCH("P050192|I",'CoQ Register'!$S:$S,0)),"—")} -> CoQ-PP_26-025 | O26: iCoA-PP-2025-0017 | P26: P050192|I | Q26: registered — issued with the legacy series on 15.05.2026
A27: =IF(C27="yes",COUNT(A$1:A26)+1,"") -> 26 | B27: =IF(A27<>"","iCoA-PP_26-"&TEXT(A27,"000"),IF(C27="n/a","not needed","— at issue —")) -> iCoA-PP_26-026 | C27: yes | D27: =IF(A27="","",IF(G27="legacy",DATE(2026,5,15),IF(ISNUMBER(F27),(F27+5)+CHOOSE(WEEKDAY(F27+5,2),0,0,0,0,0,2,1),""))) -> 46157 | E27: {=IFERROR(INDEX('Batch Dates'!$F:$F,MATCH(J27,'Batch Dates'!$C:$C,0)),IFERROR(INDEX('Batch Dates'!$F:$F,MATCH(I27,'Batch Dates'!$B:$B,0)),""))} -> 45960 | F27: {=IFERROR(INDEX('Batch Dates'!$G:$G,MATCH(J27,'Batch Dates'!$C:$C,0)),IFERROR(INDEX('Batch Dates'!$G:$G,MATCH(I27,'Batch Dates'!$B:$B,0)),""))} -> 45968 | G27: legacy | H27: initial release | I27: GP062501 | J27: P050202 | K27: Grape Pie | L27: Ident A + Ident B + Foreign matter | M27: — | N27: {=IFERROR(INDEX('CoQ Register'!$B:$B,MATCH("P050202|I",'CoQ Register'!$S:$S,0)),"—")} -> CoQ-PP_26-026 | O27: — | P27: P050202|I | Q27: registered — issued with the legacy series on 15.05.2026
A28: =IF(C28="yes",COUNT(A$1:A27)+1,"") -> 27 | B28: =IF(A28<>"","iCoA-PP_26-"&TEXT(A28,"000"),IF(C28="n/a","not needed","— at issue —")) -> iCoA-PP_26-027 | C28: yes | D28: =IF(A28="","",IF(G28="legacy",DATE(2026,5,15),IF(ISNUMBER(F28),(F28+5)+CHOOSE(WEEKDAY(F28+5,2),0,0,0,0,0,2,1),""))) -> 46157 | E28: {=IFERROR(INDEX('Batch Dates'!$F:$F,MATCH(J28,'Batch Dates'!$C:$C,0)),IFERROR(INDEX('Batch Dates'!$F:$F,MATCH(I28,'Batch Dates'!$B:$B,0)),""))} -> 45979 | F28: {=IFERROR(INDEX('Batch Dates'!$G:$G,MATCH(J28,'Batch Dates'!$C:$C,0)),IFERROR(INDEX('Batch Dates'!$G:$G,MATCH(I28,'Batch Dates'!$B:$B,0)),""))} -> 45985 | G28: legacy | H28: initial release | I28: CJ062501/2 | J28: P050212 | K28: Cap Junkie | L28: Ident A + Ident B + Foreign matter | M28: — | N28: {=IFERROR(INDEX('CoQ Register'!$B:$B,MATCH("P050212|I",'CoQ Register'!$S:$S,0)),"—")} -> CoQ-PP_26-027 | O28: — | P28: P050212|I | Q28: registered — issued with the legacy series on 15.05.2026
A29: =IF(C29="yes",COUNT(A$1:A28)+1,"") -> 28 | B29: =IF(A29<>"","iCoA-PP_26-"&TEXT(A29,"000"),IF(C29="n/a","not needed","— at issue —")) -> iCoA-PP_26-028 | C29: yes | D29: =IF(A29="","",IF(G29="legacy",DATE(2026,5,15),IF(ISNUMBER(F29),(F29+5)+CHOOSE(WEEKDAY(F29+5,2),0,0,0,0,0,2,1),""))) -> 46157 | E29: {=IFERROR(INDEX('Batch Dates'!$F:$F,MATCH(J29,'Batch Dates'!$C:$C,0)),IFERROR(INDEX('Batch Dates'!$F:$F,MATCH(I29,'Batch Dates'!$B:$B,0)),""))} -> 45985 | F29: {=IFERROR(INDEX('Batch Dates'!$G:$G,MATCH(J29,'Batch Dates'!$C:$C,0)),IFERROR(INDEX('Batch Dates'!$G:$G,MATCH(I29,'Batch Dates'!$B:$B,0)),""))} -> 45986 | G29: legacy | H29: initial release | I29: CJ062501/1 | J29: P050222 | K29: Cap Junkie | L29: Ident A + Ident B + Foreign matter | M29: — | N29: {=IFERROR(INDEX('CoQ Register'!$B:$B,MATCH("P050222|I",'CoQ Register'!$S:$S,0)),"—")} -> CoQ-PP_26-028 | O29: iCoA-PP-2025-0018 | P29: P050222|I | Q29: registered — issued with the legacy series on 15.05.2026
A30: =IF(C30="yes",COUNT(A$1:A29)+1,"") -> 29 | B30: =IF(A30<>"","iCoA-PP_26-"&TEXT(A30,"000"),IF(C30="n/a","not needed","— at issue —")) -> iCoA-PP_26-029 | C30: yes | D30: =IF(A30="","",IF(G30="legacy",DATE(2026,5,15),IF(ISNUMBER(F30),(F30+5)+CHOOSE(WEEKDAY(F30+5,2),0,0,0,0,0,2,1),""))) -> 46157 | E30: {=IFERROR(INDEX('Batch Dates'!$F:$F,MATCH(J30,'Batch Dates'!$C:$C,0)),IFERROR(INDEX('Batch Dates'!$F:$F,MATCH(I30,'Batch Dates'!$B:$B,0)),""))} -> 45988 | F30: {=IFERROR(INDEX('Batch Dates'!$G:$G,MATCH(J30,'Batch Dates'!$C:$C,0)),IFERROR(INDEX('Batch Dates'!$G:$G,MATCH(I30,'Batch Dates'!$B:$B,0)),""))} -> 45989 | G30: legacy | H30: initial release | I30: CJ072501 | J30: P050252 | K30: Cap Junky | L30: Ident A + Ident B + Foreign matter | M30: — | N30: {=IFERROR(INDEX('CoQ Register'!$B:$B,MATCH("P050252|I",'CoQ Register'!$S:$S,0)),"—")} -> CoQ-PP_26-029 | O30: — | P30: P050252|I | Q30: registered — issued with the legacy series on 15.05.2026
A31: =IF(C31="yes",COUNT(A$1:A30)+1,"") -> 30 | B31: =IF(A31<>"","iCoA-PP_26-"&TEXT(A31,"000"),IF(C31="n/a","not needed","— at issue —")) -> iCoA-PP_26-030 | C31: yes | D31: =IF(A31="","",IF(G31="legacy",DATE(2026,5,15),IF(ISNUMBER(F31),(F31+5)+CHOOSE(WEEKDAY(F31+5,2),0,0,0,0,0,2,1),""))) -> 46157 | E31: {=IFERROR(INDEX('Batch Dates'!$F:$F,MATCH(J31,'Batch Dates'!$C:$C,0)),IFERROR(INDEX('Batch Dates'!$F:$F,MATCH(I31,'Batch Dates'!$B:$B,0)),""))} -> 45992 | F31: {=IFERROR(INDEX('Batch Dates'!$G:$G,MATCH(J31,'Batch Dates'!$C:$C,0)),IFERROR(INDEX('Batch Dates'!$G:$G,MATCH(I31,'Batch Dates'!$B:$B,0)),""))} -> 45992 | G31: legacy | H31: initial release | I31: WC072501 | J31: P050262 | K31: Wedding Crusher | L31: Ident A + Ident B + Foreign matter | M31: — | N31: {=IFERROR(INDEX('CoQ Register'!$B:$B,MATCH("P050262|I",'CoQ Register'!$S:$S,0)),"—")} -> CoQ-PP_26-030 | O31: — | P31: P050262|I | Q31: registered — issued with the legacy series on 15.05.2026
A32: =IF(C32="yes",COUNT(A$1:A31)+1,"") -> 31 | B32: =IF(A32<>"","iCoA-PP_26-"&TEXT(A32,"000"),IF(C32="n/a","not needed","— at issue —")) -> iCoA-PP_26-031 | C32: yes | D32: =IF(A32="","",IF(G32="legacy",DATE(2026,5,15),IF(ISNUMBER(F32),(F32+5)+CHOOSE(WEEKDAY(F32+5,2),0,0,0,0,0,2,1),""))) -> 46157 | E32: {=IFERROR(INDEX('Batch Dates'!$F:$F,MATCH(J32,'Batch Dates'!$C:$C,0)),IFERROR(INDEX('Batch Dates'!$F:$F,MATCH(I32,'Batch Dates'!$B:$B,0)),""))} -> 45993 | F32: {=IFERROR(INDEX('Batch Dates'!$G:$G,MATCH(J32,'Batch Dates'!$C:$C,0)),IFERROR(INDEX('Batch Dates'!$G:$G,MATCH(I32,'Batch Dates'!$B:$B,0)),""))} -> 45994 | G32: legacy | H32: initial release | I32: PM072501 | J32: P050272 | K32: Permanent Marker | L32: Ident A + Ident B + Foreign matter | M32: — | N32: {=IFERROR(INDEX('CoQ Register'!$B:$B,MATCH("P050272|I",'CoQ Register'!$S:$S,0)),"—")} -> CoQ-PP_26-031 | O32: — | P32: P050272|I | Q32: registered — issued with the legacy series on 15.05.2026
A33: =IF(C33="yes",COUNT(A$1:A32)+1,"") -> 32 | B33: =IF(A33<>"","iCoA-PP_26-"&TEXT(A33,"000"),IF(C33="n/a","not needed","— at issue —")) -> iCoA-PP_26-032 | C33: yes | D33: =IF(A33="","",IF(G33="legacy",DATE(2026,5,15),IF(ISNUMBER(F33),(F33+5)+CHOOSE(WEEKDAY(F33+5,2),0,0,0,0,0,2,1),""))) -> 46157 | E33: {=IFERROR(INDEX('Batch Dates'!$F:$F,MATCH(J33,'Batch Dates'!$C:$C,0)),IFERROR(INDEX('Batch Dates'!$F:$F,MATCH(I33,'Batch Dates'!$B:$B,0)),""))} -> 45994 | F33: {=IFERROR(INDEX('Batch Dates'!$G:$G,MATCH(J33,'Batch Dates'!$C:$C,0)),IFERROR(INDEX('Batch Dates'!$G:$G,MATCH(I33,'Batch Dates'!$B:$B,0)),""))} -> 45995 | G33: legacy | H33: initial release | I33: CLE072501 | J33: P050282 | K33: Clemosa a bud | L33: Ident A + Ident B + Foreign matter | M33: — | N33: {=IFERROR(INDEX('CoQ Register'!$B:$B,MATCH("P050282|I",'CoQ Register'!$S:$S,0)),"—")} -> CoQ-PP_26-032 | O33: iCoA-PP-2025-0019 | P33: P050282|I | Q33: registered — issued with the legacy series on 15.05.2026
