Workbook

Sheet Read Me
A1: CoQ Analysis Master — v25
A2: What it is | B2: Built 11.09.2026 on the owner's CoQ_Analysis_Master. Which certificate is credited to which parameter is the owner's; results, dates and laboratories are the desk's record: the release register, the page reads and the two-read extraction of every certificate in eCOA_DB. Nothing is invented; a value the reads disagreed on is held until a person rules on the page.
A4: SHEETS
A5: Read Me | B5: This sheet.
A6: Batch Coverage | B6: One row per lot: ✓/✗/○ for each of the 12 parameters, the missing list, and two pairs of document columns — the certificates the tracker actually cites with their laboratories, and separately the documents on file from the 09.09.2026 pass that the desk has not recorded. Both pairs are derived here from the tracker rather than carried forward, which is what let them drift apart. ○ counts as missing: nothing can be cited until the desk records the document. A grey ✓ is covered by the in-house iCoA.
A7: Delivery T1–T3 | B7: The 78 cultivation batches delivered in the three tranches of 31.07, 14.08 and 28.08.2026, each against its row on Batch Coverage: the P lot, the CoQ status, what is missing, and the potency the batch was delivered under beside the potency its own certificate reports.
A8: ImB Register | B8: The customer's certificate register, scanned 04.09.2026: 43 certificates for the earliest production, each against its desk lot — the strain as printed and as ruled, the manufacturing and retest dates, and the four lots the register skips inside the span it covers.
A9: Reconciliation 09.09 | B9: The owner's 09.09.2026 pass over the 387 certificates in eCoA_DATABASE against the desk, cell by cell: the parameters it closed on Batch Coverage, the cells the two records disagree about, and why the identity determinations stay blank on almost every lot — the iCoA that carries them has not been issued, and the in-house documents that do exist print no microscopy and no foreign-matter percentage.
A10: CoQ Parameter Tracker v25 | B10: One lot per block of two rows per testing instance: the result of each determination on the top row, the certificate that reports it (code, date, laboratory) beneath; acceptance criteria in row 3 and enforced; out-of-specification results in red and named in STATUS; the in-house iCoA cells cite the iCoA Register by key.
A11: Credit Audit | B11: Certificates credited on the owner's tracker that the desk holds no value from, with the reason.
A12: Credit Corrections | B12: The two corrections applied to the owner's credits (the Farmahem pair, CNP identification B), one row each; nothing written back to the owner's workbook.
A13: Work Order | B13: What a person must do next: certificates to ingest, values to read on the page, lots to record.
A14: Open Items | B14: The standing register of what the desk cannot decide: every finding raised and left to the owner, with what was found, what the desk did with it, the decision being asked for, and the evidence behind it. STATE is open (waiting, nothing printed), marked (the certificate prints the field bracketed in red and unticked) or ruled (kept for the record with the ruling). Built from open_items.py, which also writes OPEN_ITEMS.md.
A15: iCoA Issuance | B15: One row per P lot and series (initial release, retest): what its iCoA carries, the CNP references, the cannabinoid-assay eCoA that covers identification C, the codes and planned dates looked up on the registers.
A16: Batch Dates | B16: The Head of QC's harvest and packaging dates per batch (04.09.2026), as dates; the registers look their packaging dates up here.
... A20: Summary Dashboard | B20: Counts recomputed from Batch Coverage: lots, documents, complete / partial / incomplete, missing-parameter frequency.
A22: LEGEND (tracker and coverage)
A23: ✓ green | B23: A certificate is on file and its value is on the desk: an outsourced certificate (eCoA) or the in-house iCoA.
A24: ✓ grey | B24: Covered by the in-house iCoA only (identification A, identification B, foreign matter, tested at Purely Plant at packaging): coverage for the release CoQ (Head of QC, 04.09.2026).
A25: ✓ orange | B25: Stability-timepoint certificate — its value is not a release result.
A26: ✗ amber | B26: Certificate credited on the tracker, but the desk holds no value for this determination from it — the determination is not on that certificate, or the certificate never entered the record.
A27: ✗ red | B27: No certificate credited for the parameter.
A28: • | B28: A document on file that is not credited for the parameter (an old in-house Report of Analysis, an NGP form, the QCCoA 001 certificate): shown, not coverage.
A29: Conforms (ImB spec.) | B29: Identification C: conforms to the ImB specification on the certificate that carries the cannabinoid assay; the CoQ cites that eCoA (Head of QC, 04.09.2026).
A30: Red result | B30: Out of specification against the global acceptance criterion (row 3). Orange: undetermined (a Ph. Eur. band the result sits in).
A32: CONVENTIONS
A33: Batch names | B33: CU batch as the owner names it; a sub-lot digit belongs to the batch (FB012601_1), never to the certificate code; an asterisk (JD112501＊) marks a lot of its own. The laboratory prints the zero of a P-number as a letter O (PO60052); it is folded to P060052.
A34: Certificate codes | B34: As printed on the certificate (Cyrillic ППК codes kept). [Lab]: CNP (Faculty of Pharmacy, Center for Natural Products), IJZ-MB / IPH (Institute of Public Health), FHM-K / FHM-M (Farmahem), PP (Purely Plant, in-house).
A35: Dates | B35: DD.MM.YYYY. The Batch Dates and register sheets hold real dates; the tracker prints them as text inside the reference.
A36: Results | B36: Numeric results with the certificate's printed precision; qualitative results as text (Conforms, absent, <LOQ, ND). A microbiological range (< 10³ и > 10²) is judged by its upper bound.
A37: OOS check | B37: A result is flagged only when it provably exceeds its criterion; ND, <LOQ, <10 and absent pass; a value that cannot be parsed is never flagged.
A38: Formulas | B38: On the two registers the number, the code and the dates are formulas, and the iCoA Issuance sheet and the tracker's in-house cells look the registers up by key: insert a row and every code beneath moves by one.
A39: Print | B39: Every sheet: landscape, A3, one page wide, the header rows repeated; panes frozen under the header.
A40: Do not | B40: read counts from the eCOA_DB text layer. On five of six certificates checked it read the exponent or a digit too low, every time in the direction of a conforming result.
A42: RULINGS IN FORCE (Head of QC)
A43: 04.09.2026 · iCoA | B43: Identification A and B are tested at Purely Plant together with foreign matter at packaging (the first day, when the sample is taken before primary packaging), and ONE iCoA per P lot carries the three results for the release CoQ. Where a CNP certificate reports one of them, the CNP document code is the reference; where CNP reports all three, no iCoA is needed.
A44: 04.09.2026 · Ident C | B44: Identification C is 'Conforms', referenced to the eCoA that covers Total THC (the cannabinoid assay); for a Farmahem lot the K certificate.
A45: 04.09.2026 · decisions | B45: The two bile-tolerant gram-negative rows the reads disagreed on: P060262 < 10³ и > 10² CFU/g, P060432 < 10² и > 10 CFU/g (decisions_2026-09-04.tsv).
A46: 05.09.2026 · issuance | B46: Legacy lots (packed before the SOP floor of 11.05.2026, or holding an old in-house QCCoA 001 certificate): iCoAs issued together on 15.05.2026, CoQs (CoQ-PP_26-nnn, superseding the old certificate) on 27.05.2026, both in chronological order of packaging. Post-SOP lots: the iCoA on the first working day 5 days after packaging, the CoQ on the first working day 7 days after the latest eCoA it cites, never before 27.05.2026. Codes iCoA-PP_26-nnn and CoQ-PP_26-nnn, one series each for the year of issue.
A47: 05.09.2026 · retest | B47: The QP's retest campaign, sampled by tranche from July 2026: identification A, B and foreign matter in-house on every bag of the representative sample (one iCoA), cannabinoids with identification C and mycotoxins at Farmahem, microbiology at IJZ-MB; the reissued CoQ carries those results and the initial certificates for the rest. A retest certificate never certifies the initial CoQ; the IJZ-MB delivery of 25/26.08.2026 is campaign sampling for every lot.
...

Sheet Batch Coverage
A1: CU Batch | B1: P Batch | C1: Strain | D1: Status | E1: 1 Identification A — Appearance | F1: 2 Identification B — Microscopy | G1: 3 Identification C — HPLC | H1: 4 Assay — Total Δ⁹-THC | I1: 5 Assay — Total CBD | J1: 6 Total CBN | K1: 7 Foreign Matter | L1: 8 Loss on Drying | M1: 9 Microbiological Purity | N1: 10 Mycotoxins | O1: 11 Heavy Metals | P1: 12 Pesticide Residues | Q1: Missing (n) | R1: Missing parameters | S1: Certificates (n) | T1: Labs present | U1: On file, not recorded (n) | V1: Labs on file, not recorded
A2: BG1024 | B2: — not assigned — | C2: Blue Gelato | D2: ✓ COMPLETE | E2: ✓ | F2: ✓ | G2: ✓ | H2: ✓ | I2: ✓ | J2: ✓ | K2: ✓ | L2: ✓ | M2: ✓ | N2: ✓ | O2: ✓ | P2: ✓ | Q2: 0 | R2: — | S2: 6 | T2: [CNP] 1; [FHM-K] 1; [FHM-M] 1; [IJZ] 1; [IJZ-MB] 1; [PP] 1 | U2: 0 | V2: —
A3: BSS1024 | B3: — not assigned — | C3: Blue Sunset Sherbet | D3: ✓ COMPLETE | E3: ✓ | F3: ✓ | G3: ✓ | H3: ✓ | I3: ✓ | J3: ✓ | K3: ✓ | L3: ✓ | M3: ✓ | N3: ✓ | O3: ✓ | P3: ✓ | Q3: 0 | R3: — | S3: 6 | T3: [CNP] 1; [FHM-K] 1; [FHM-M] 1; [IJZ] 1; [IJZ-MB] 1; [PP] 1 | U3: 0 | V3: —
A4: CC112501 | B4: P060272 | C4: CashCow | D4: ✓ COMPLETE | E4: ✓ | F4: ✓ | G4: ✓ | H4: ✓ | I4: ✓ | J4: ✓ | K4: ✓ | L4: ✓ | M4: ✓ | N4: ✓ | O4: ✓ | P4: ✓ | Q4: 0 | R4: — | S4: 5 | T4: [CNP] 1; [IJZ] 1; [IJZ-MB] 2; [PP] 1 | U4: 0 | V4: —
A5: CJ1024 | B5: — not assigned — | C5: Cap Junky | D5: ✓ COMPLETE | E5: ✓ | F5: ✓ | G5: ✓ | H5: ✓ | I5: ✓ | J5: ✓ | K5: ✓ | L5: ✓ | M5: ✓ | N5: ✓ | O5: ✓ | P5: ✓ | Q5: 0 | R5: — | S5: 5 | T5: [CNP] 1; [IJZ] 1; [IJZ-MB] 2; [PP] 1 | U5: 0 | V5: —
A6: FB012601_1 | B6: P060322 | C6: Fat Bastard | D6: ✓ COMPLETE | E6: ✓ | F6: ✓ | G6: ✓ | H6: ✓ | I6: ✓ | J6: ✓ | K6: ✓ | L6: ✓ | M6: ✓ | N6: ✓ | O6: ✓ | P6: ✓ | Q6: 0 | R6: — | S6: 4 | T6: [CNP] 1; [IJZ] 1; [IJZ-MB] 1; [PP] 1 | U6: 0 | V6: —
A7: FB012603 | B7: P060432 | C7: Fat Bastard | D7: ○ 3 ON FILE, NOT RECORDED | E7: ✓ | F7: ✓ | G7: ✓ | H7: ✓ | I7: ✓ | J7: ✓ | K7: ✓ | L7: ✓ | M7: ✓ | N7: ○ | O7: ○ | P7: ○ | Q7: 3 | R7: #10 Mycotoxins (on file 09.09, not recorded); #11 Heavy metals (on file 09.09, not recorded); #12 Pesticides (on file 09.09, not recorded) | S7: 2 | T7: [CNP] 1; [IJZ-MB] 1 | U7: 1 | V7: [IJZ] 1
A8: FB012603V | B8: P060392 | C8: Fat Bastard | D8: ○ 3 ON FILE, NOT RECORDED | E8: ✓ | F8: ✓ | G8: ✓ | H8: ✓ | I8: ✓ | J8: ✓ | K8: ✓ | L8: ✓ | M8: ✓ | N8: ○ | O8: ○ | P8: ○ | Q8: 3 | R8: #10 Mycotoxins (on file 09.09, not recorded); #11 Heavy metals (on file 09.09, not recorded); #12 Pesticides (on file 09.09, not recorded) | S8: 2 | T8: [CNP] 1; [IJZ-MB] 1 | U8: 1 | V8: [IJZ] 1
A9: FB032601 | B9: P060452 | C9: Fat Bastard | D9: ○ 4 ON FILE, NOT RECORDED | E9: ✓ | F9: ✓ | G9: ✓ | H9: ✓ | I9: ✓ | J9: ✓ | K9: ✓ | L9: ✓ | M9: ○ | N9: ○ | O9: ○ | P9: ○ | Q9: 4 | R9: #9 Microbiology (on file 09.09, not recorded); #10 Mycotoxins (on file 09.09, not recorded); #11 Heavy metals (on file 09.09, not recorded); #12 Pesticides (on file 09.09, not recorded) | S9: 1 | T9: [CNP] 1 | U9: 2 | V9: [IJZ] 1; [IJZ-MB] 1
A10: FB112501 | B10: P060292 | C10: Fat Bastard | D10: ✓ COMPLETE | E10: ✓ | F10: ✓ | G10: ✓ | H10: ✓ | I10: ✓ | J10: ✓ | K10: ✓ | L10: ✓ | M10: ✓ | N10: ✓ | O10: ✓ | P10: ✓ | Q10: 0 | R10: — | S10: 5 | T10: [CNP] 1; [IJZ] 1; [IJZ-MB] 2; [PP] 1 | U10: 0 | V10: —
A11: GG012601＊ | B11: P060302 | C11: Gorilla Glue | D11: ✓ COMPLETE | E11: ✓ | F11: ✓ | G11: ✓ | H11: ✓ | I11: ✓ | J11: ✓ | K11: ✓ | L11: ✓ | M11: ✓ | N11: ✓ | O11: ✓ | P11: ✓ | Q11: 0 | R11: — | S11: 5 | T11: [CNP] 1; [IJZ] 1; [IJZ-MB] 2; [PP] 1 | U11: 0 | V11: —
A12: GG012603 | B12: P060402 | C12: Gorilla Glue | D12: ○ 3 ON FILE, NOT RECORDED | E12: ✓ | F12: ✓ | G12: ✓ | H12: ✓ | I12: ✓ | J12: ✓ | K12: ✓ | L12: ✓ | M12: ○ | N12: ✓ | O12: ○ | P12: ○ | Q12: 3 | R12: #9 Microbiology (on file 09.09, not recorded); #11 Heavy metals (on file 09.09, not recorded); #12 Pesticides (on file 09.09, not recorded) | S12: 3 | T12: [CNP] 1; [FHM-K] 1; [FHM-M] 1 | U12: 2 | V12: [IJZ] 1; [IJZ-MB] 1
A13: GG032601 | B13: P060462 | C13: Gorilla Glue | D13: ❌ 4 MISSING | E13: ✓ | F13: ✓ | G13: ✓ | H13: ✓ | I13: ✓ | J13: ✓ | K13: ✓ | L13: ✓ | M13: ✗ | N13: ○ | O13: ✗ | P13: ○ | Q13: 4 | R13: #9 Microbiology; #10 Mycotoxins (on file 09.09, not recorded); #11 Heavy metals; #12 Pesticides (on file 09.09, not recorded) | S13: 1 | T13: [CNP] 1 | U13: 1 | V13: [IJZ] 1
... A15: GG112501 | B15: P060252 | C15: Gorilla Glue | D15: ✓ COMPLETE | E15: ✓ | F15: ✓ | G15: ✓ | H15: ✓ | I15: ✓ | J15: ✓ | K15: ✓ | L15: ✓ | M15: ✓ | N15: ✓ | O15: ✓ | P15: ✓ | Q15: 0 | R15: — | S15: 5 | T15: [CNP] 1; [IJZ] 1; [IJZ-MB] 2; [PP] 1 | U15: 0 | V15: —
A16: GRC102501 | B16: P060142 / P060182 | D16: ⚠ 3 MISSING | E16: ✓ | F16: ✓ | G16: ✓ | H16: ✓ | I16: ✓ | J16: ✓ | K16: ✓ | L16: ✓ | M16: ✓ | N16: ✗ | O16: ○ | P16: ○ | Q16: 3 | R16: #10 Mycotoxins; #11 Heavy metals (on file 09.09, not recorded); #12 Pesticides (on file 09.09, not recorded) | S16: 5 | T16: [FHM-K] 2; [IJZ-MB] 1; [PP] 2 | U16: 1 | V16: [IJZ] 1
A17: HPA1024 | B17: — not assigned — | C17: High Pro Amnesia | D17: ❌ 4 MISSING | E17: ✓ | F17: ✓ | G17: ✓ | H17: ✓ | I17: ✓ | J17: ✓ | K17: ✓ | L17: ✗ | M17: ✗ | N17: ✓ | O17: ✗ | P17: ✗ | Q17: 4 | R17: #8 LoD; #9 Microbiology; #11 Heavy metals; #12 Pesticides | S17: 4 | T17: [FHM-K] 1; [FHM-M] 1; [PP] 2 | U17: 0 | V17: —
A18: J31102501 | B18: P060152 | C18: Jokerz 31 | D18: ○ 3 ON FILE, NOT RECORDED | E18: ✓ | F18: ✓ | G18: ✓ | H18: ✓ | I18: ✓ | J18: ✓ | K18: ✓ | L18: ✓ | M18: ○ | N18: ✓ | O18: ○ | P18: ○ | Q18: 3 | R18: #9 Microbiology (on file 09.09, not recorded); #11 Heavy metals (on file 09.09, not recorded); #12 Pesticides (on file 09.09, not recorded) | S18: 5 | T18: [FHM-K] 3; [FHM-M] 1; [PP] 1 | U18: 2 | V18: [IJZ] 1; [IJZ-MB] 1
A19: J31112501 | B19: P060202 | C19: Jokerz 31 | D19: ○ 3 ON FILE, NOT RECORDED | E19: ✓ | F19: ✓ | G19: ✓ | H19: ✓ | I19: ✓ | J19: ✓ | K19: ✓ | L19: ✓ | M19: ✓ | N19: ○ | O19: ○ | P19: ○ | Q19: 3 | R19: #10 Mycotoxins (on file 09.09, not recorded); #11 Heavy metals (on file 09.09, not recorded); #12 Pesticides (on file 09.09, not recorded) | S19: 8 | T19: [FHM-K] 6; [IJZ-MB] 1; [PP] 1 | U19: 1 | V19: [IJZ] 1
A20: J31122501 | B20: P060262 | C20: Jokerz 31 | D20: ⚠ 1 MISSING | E20: ✓ | F20: ✓ | G20: ✓ | H20: ✓ | I20: ✓ | J20: ✓ | K20: ✓ | L20: ✗ | M20: ✓ | N20: ✓ | O20: ✓ | P20: ✓ | Q20: 1 | R20: #8 LoD | S20: 8 | T20: [FHM-K] 2; [IJZ] 2; [IJZ-MB] 3; [PP] 1 | U20: 0 | V20: —
A21: JD012601＊ | B21: P060312 | C21: Jelly Donutz | D21: ✓ COMPLETE | E21: ✓ | F21: ✓ | G21: ✓ | H21: ✓ | I21: ✓ | J21: ✓ | K21: ✓ | L21: ✓ | M21: ✓ | N21: ✓ | O21: ✓ | P21: ✓ | Q21: 0 | R21: — | S21: 5 | T21: [CNP] 1; [IJZ] 1; [IJZ-MB] 2; [PP] 1 | U21: 0 | V21: —
A22: JD012603 | B22: P060362 / P060412 / P060422 | D22: ○ 4 ON FILE, NOT RECORDED | E22: ✓ | F22: ✓ | G22: ✓ | H22: ✓ | I22: ✓ | J22: ✓ | K22: ✓ | L22: ✓ | M22: ○ | N22: ○ | O22: ○ | P22: ○ | Q22: 4 | R22: #9 Microbiology (on file 09.09, not recorded); #10 Mycotoxins (on file 09.09, not recorded); #11 Heavy metals (on file 09.09, not recorded); #12 Pesticides (on file 09.09, not recorded) | S22: 2 | T22: [CNP] 2 | U22: 5 | V22: [IJZ] 2; [IJZ-MB] 3
A23: JD022601 | B23: P060482 | C23: JellyDonutz | D23: ○ 4 ON FILE, NOT RECORDED | E23: ✓ | F23: ✓ | G23: ✓ | H23: ✓ | I23: ✓ | J23: ✓ | K23: ✓ | L23: ✓ | M23: ○ | N23: ○ | O23: ○ | P23: ○ | Q23: 4 | R23: #9 Microbiology (on file 09.09, not recorded); #10 Mycotoxins (on file 09.09, not recorded); #11 Heavy metals (on file 09.09, not recorded); #12 Pesticides (on file 09.09, not recorded) | S23: 1 | T23: [CNP] 1 | U23: 2 | V23: [IJZ] 1; [IJZ-MB] 1
A24: JD112501 | B24: P060212 | C24: Jelly Donutz | D24: ✓ COMPLETE | E24: ✓ | F24: ✓ | G24: ✓ | H24: ✓ | I24: ✓ | J24: ✓ | K24: ✓ | L24: ✓ | M24: ✓ | N24: ✓ | O24: ✓ | P24: ✓ | Q24: 0 | R24: — | S24: 6 | T24: [CNP] 1; [FHM-K] 1; [FHM-M] 1; [IJZ] 1; [IJZ-MB] 1; [PP] 1 | U24: 0 | V24: —
A25: JD112501＊ | B25: — not assigned — | C25: Jelly Donutz | D25: ✓ COMPLETE | E25: ✓ | F25: ✓ | G25: ✓ | H25: ✓ | I25: ✓ | J25: ✓ | K25: ✓ | L25: ✓ | M25: ✓ | N25: ✓ | O25: ✓ | P25: ✓ | Q25: 0 | R25: — | S25: 4 | T25: [CNP] 1; [IJZ] 1; [IJZ-MB] 1; [PP] 1 | U25: 0 | V25: —
A26: KC102501 | B26: P060172 | C26: Kush Crasher | D26: ○ 4 ON FILE, NOT RECORDED | E26: ✓ | F26: ✓ | G26: ✓ | H26: ✓ | I26: ✓ | J26: ✓ | K26: ✓ | L26: ✓ | M26: ○ | N26: ○ | O26: ○ | P26: ○ | Q26: 4 | R26: #9 Microbiology (on file 09.09, not recorded); #10 Mycotoxins (on file 09.09, not recorded); #11 Heavy metals (on file 09.09, not recorded); #12 Pesticides (on file 09.09, not recorded) | S26: 3 | T26: [FHM-K] 2; [PP] 1 | U26: 2 | V26: [IJZ] 1; [IJZ-MB] 1
A27: OPM1024 | B27: — not assigned — | C27: Orange Punch Mimosa | D27: ❌ 4 MISSING | E27: ✓ | F27: ✓ | G27: ✓ | H27: ✓ | I27: ✓ | J27: ✓ | K27: ✓ | L27: ✗ | M27: ✗ | N27: ✓ | O27: ✗ | P27: ✗ | Q27: 4 | R27: #8 LoD; #9 Microbiology; #11 Heavy metals; #12 Pesticides | S27: 4 | T27: [FHM-K] 1; [FHM-M] 1; [PP] 2 | U27: 0 | V27: —
A28: OPM112501 | B28: P060222 | C28: Orange Punch Mimosa | D28: ❌ 4 MISSING | E28: ✓ | F28: ✓ | G28: ✓ | H28: ✓ | I28: ✓ | J28: ✗ | K28: ✓ | L28: ✓ | M28: ✓ | N28: ✗ | O28: ○ | P28: ○ | Q28: 4 | R28: #6 CBN; #10 Mycotoxins; #11 Heavy metals (on file 09.09, not recorded); #12 Pesticides (on file 09.09, not recorded) | S28: 3 | T28: [CNP] 1; [IJZ-MB] 1; [PP] 1 | U28: 1 | V28: [IJZ] 1
A29: OPM122501 | B29: P060242 | C29: Orange Punch Mimosa | D29: ✓ COMPLETE | E29: ✓ | F29: ✓ | G29: ✓ | H29: ✓ | I29: ✓ | J29: ✓ | K29: ✓ | L29: ✓ | M29: ✓ | N29: ✓ | O29: ✓ | P29: ✓ | Q29: 0 | R29: — | S29: 7 | T29: [FHM-K] 3; [FHM-M] 1; [IJZ] 1; [IJZ-MB] 1; [PP] 1 | U29: 0 | V29: —
A30: GG1024_02 | B30: P050012 | C30: Gorilla Glue | D30: ✓ COMPLETE | E30: ✓ | F30: ✓ | G30: ✓ | H30: ✓ | I30: ✓ | J30: ✓ | K30: ✓ | L30: ✓ | M30: ✓ | N30: ✓ | O30: ✓ | P30: ✓ | Q30: 0 | R30: — | S30: 5 | T30: [CNP] 1; [IJZ] 1; [IJZ-MB] 2; [PP] 1 | U30: 0 | V30: —
A31: GP0824_02 | B31: P050022 | C31: Grape Pie | D31: ✓ COMPLETE | E31: ✓ | F31: ✓ | G31: ✓ | H31: ✓ | I31: ✓ | J31: ✓ | K31: ✓ | L31: ✓ | M31: ✓ | N31: ✓ | O31: ✓ | P31: ✓ | Q31: 0 | R31: — | S31: 12 | T31: [CNP] 5; [FHM-K] 1; [FHM-M] 1; [IJZ] 2; [IJZ-MB] 2; [PP] 1 | U31: 0 | V31: —
A32: MB0824_04 | B32: P050032 | C32: Motor Breath | D32: ⚠ 1 MISSING | E32: ✓ | F32: ✓ | G32: ✓ | H32: ✓ | I32: ✓ | J32: ✗ | K32: ✓ | L32: ✓ | M32: ✓ | N32: ✓ | O32: ✓ | P32: ✓ | Q32: 1 | R32: #6 CBN | S32: 5 | T32: [CNP] 1; [IJZ] 1; [IJZ-MB] 2; [PP] 1 | U32: 0 | V32: —
A33: OMP1024_01 | B33: P050042 | C33: Orange Punch Mimosa | D33: ✓ COMPLETE | E33: ✓ | F33: ✓ | G33: ✓ | H33: ✓ | I33: ✓ | J33: ✓ | K33: ✓ | L33: ✓ | M33: ✓ | N33: ✓ | O33: ✓ | P33: ✓ | Q33: 0 | R33: — | S33: 4 | T33: [CNP] 1; [IJZ] 1; [IJZ-MB] 1; [PP] 1 | U33: 0 | V33: —
A34: HPA1024_01 | B34: P050052 | C34: High Pro Amnesia | D34: ✓ COMPLETE | E34: ✓ | F34: ✓ | G34: ✓ | H34: ✓ | I34: ✓ | J34: ✓ | K34: ✓ | L34: ✓ | M34: ✓ | N34: ✓ | O34: ✓ | P34: ✓ | Q34: 0 | R34: — | S34: 6 | T34: [CNP] 1; [FHM-K] 1; [FHM-M] 1; [IJZ] 1; [IJZ-MB] 1; [PP] 1 | U34: 0 | V34: —
... A67: GP092501 | B67: P060092 | C67: Grape Pie | D67: ✓ COMPLETE | E67: ✓ | F67: ✓ | G67: ✓ | H67: ✓ | I67: ✓ | J67: ✓ | K67: ✓ | L67: ✓ | M67: ✓ | N67: ✓ | O67: ✓ | P67: ✓ | Q67: 0 | R67: — | S67: 4 | T67: [CNP] 1; [IJZ] 1; [IJZ-MB] 1; [PP] 1 | U67: 0 | V67: —
A68: CC012601/1 | B68: P060332 | D68: ❌ 4 MISSING | E68: ✓ | F68: ✓ | G68: ✓ | H68: ✓ | I68: ✓ | J68: ✓ | K68: ✓ | L68: ✗ | M68: ○ | N68: ✓ | O68: ✗ | P68: ✗ | Q68: 4 | R68: #8 LoD; #9 Microbiology (on file 09.09, not recorded); #11 Heavy metals; #12 Pesticides | S68: 3 | T68: [FHM-K] 1; [FHM-M] 1; [PP] 1 | U68: 1 | V68: [IJZ-MB] 1
A69: FB012602* | B69: P060352 | C69: Fat Bastard | D69: ❌ 4 MISSING | E69: ✓ | F69: ✓ | G69: ✓ | H69: ✓ | I69: ✓ | J69: ✓ | K69: ✓ | L69: ✗ | M69: ○ | N69: ✓ | O69: ✗ | P69: ✗ | Q69: 4 | R69: #8 LoD; #9 Microbiology (on file 09.09, not recorded); #11 Heavy metals; #12 Pesticides | S69: 3 | T69: [FHM-K] 1; [FHM-M] 1; [PP] 1 | U69: 1 | V69: [IJZ-MB] 1
A70: SCR012603 | B70: P060382 | C70: Scrambler | D70: ❌ 4 MISSING | E70: ✓ | F70: ✓ | G70: ✓ | H70: ✓ | I70: ✓ | J70: ✓ | K70: ✓ | L70: ✗ | M70: ○ | N70: ✓ | O70: ✗ | P70: ✗ | Q70: 4 | R70: #8 LoD; #9 Microbiology (on file 09.09, not recorded); #11 Heavy metals; #12 Pesticides | S70: 3 | T70: [FHM-K] 1; [FHM-M] 1; [PP] 1 | U70: 1 | V70: [IJZ-MB] 1
A71: — not recorded — (P160012) | B71: P160012 | D71: ○ 4 ON FILE, NOT RECORDED | E71: ✓ | F71: ✓ | G71: ✓ | H71: ✓ | I71: ✓ | J71: ✓ | K71: ✓ | L71: ✓ | M71: ○ | N71: ○ | O71: ○ | P71: ○ | Q71: 4 | R71: #9 Microbiology (on file 09.09, not recorded); #10 Mycotoxins (on file 09.09, not recorded); #11 Heavy metals (on file 09.09, not recorded); #12 Pesticides (on file 09.09, not recorded) | S71: 1 | T71: [CNP] 1 | U71: 2 | V71: [IJZ] 1; [IJZ-MB] 1
A72: — not recorded — (P160022) | B72: P160022 | D72: ○ 4 ON FILE, NOT RECORDED | E72: ✓ | F72: ✓ | G72: ✓ | H72: ✓ | I72: ✓ | J72: ✓ | K72: ✓ | L72: ✓ | M72: ○ | N72: ○ | O72: ○ | P72: ○ | Q72: 4 | R72: #9 Microbiology (on file 09.09, not recorded); #10 Mycotoxins (on file 09.09, not recorded); #11 Heavy metals (on file 09.09, not recorded); #12 Pesticides (on file 09.09, not recorded) | S72: 1 | T72: [CNP] 1 | U72: 2 | V72: [IJZ] 1; [IJZ-MB] 1
A73: — not recorded — (P160032) | B73: P160032 | D73: ○ 4 ON FILE, NOT RECORDED | E73: ✓ | F73: ✓ | G73: ✓ | H73: ✓ | I73: ✓ | J73: ✓ | K73: ✓ | L73: ✓ | M73: ○ | N73: ○ | O73: ○ | P73: ○ | Q73: 4 | R73: #9 Microbiology (on file 09.09, not recorded); #10 Mycotoxins (on file 09.09, not recorded); #11 Heavy metals (on file 09.09, not recorded); #12 Pesticides (on file 09.09, not recorded) | S73: 1 | T73: [CNP] 1 | U73: 2 | V73: [IJZ] 1; [IJZ-MB] 1
...

Sheet Delivery T1–T3
A1: Tranche | B1: Delivered | C1: Batch (as delivered) | D1: Strain | E1: kg | F1: Bracket | G1: Declared | H1: P lot | I1: Desk lot | J1: CoQ status | K1: Missing | L1: Total THC on the eCoA | M1: Certificate | N1: Δ | O1: Ready to issue
A2: 1 | B2: 31.07.2026 | C2: BG1024 | D2: Blue Gelato | E2: 43.87 | F2: 19–22% | G2: 0.218 | H2: — | I2: BG1024 | J2: ✓ COMPLETE | K2: — | L2: 0.218 | M2: ППК25050 | N2: 0 | O2: yes — all 12 determinations covered
A3: 1 | B3: 31.07.2026 | C3: BSS1024 | D3: Blue Sunset Sherbet | E3: 50.2 | F3: 19–22% | G3: 0.21 | H3: — | I3: BSS1024 | J3: ✓ COMPLETE | K3: — | L3: 0.2103 | M3: ППК25051 | N3: 0.0003 | O3: yes — all 12 determinations covered
A4: 1 | B4: 31.07.2026 | C4: CC012601/1 | D4: CashCow | E4: 9.15 | F4: 13–16% | G4: 0.1563 | H4: P060332 | I4: CC012601/1 | J4: ❌ 4 MISSING | K4: #8 LoD; #9 Microbiology (on file 09.09, not recorded); #11 Heavy metals; #12 Pesticides | L4: — none on the desk — | M4: — | N4: — | O4: no — 4 missing
A5: 1 | B5: 31.07.2026 | C5: CJ052501/01 | D5: Cap Junky | E5: 64.53 | F5: 19–22% | G5: 0.2029 | H5: P050162 | I5: CJ052501/01 | J5: ✓ COMPLETE | K5: — | L5: 0.2029 | M5: None | N5: 0 | O5: yes — all 12 determinations covered
A6: 1 | B6: 31.07.2026 | C6: CJ062501/2 | D6: Cap Junky | E6: 146.52 | F6: 16–19% | G6: 0.1656 | H6: P050212 | I6: CJ062501/2 | J6: ✓ COMPLETE | K6: — | L6: 0.1656 | M6: ППК25322 | N6: 0 | O6: yes — all 12 determinations covered
A7: 1 | B7: 31.07.2026 | C7: CJ082501/2 | D7: Cap Junky | E7: 14.75 | F7: 19–22% | G7: 0.2084 | H7: P060032 | I7: CJ082501/2 | J7: ✓ COMPLETE | K7: — | L7: 0.2084 | M7: ППК26003 | N7: 0 | O7: yes — all 12 determinations covered
A8: 1 | B8: 31.07.2026 | C8: FB012602 | D8: Fat Bastard | E8: 75.92 | F8: 19–22% | G8: 0.1977 | H8: P060352 | I8: FB012602* (the desk writes it FB012602*) | J8: ❌ 4 MISSING | K8: #8 LoD; #9 Microbiology (on file 09.09, not recorded); #11 Heavy metals; #12 Pesticides | L8: — none on the desk — | M8: — | N8: — | O8: no — 4 missing
A9: 1 | B9: 31.07.2026 | C9: GG012603 | D9: GG4 | E9: 40 | F9: 13–16% | G9: 0.1559 | H9: P060402 | I9: GG012603 | J9: ○ 3 ON FILE, NOT RECORDED | K9: #9 Microbiology (on file 09.09, not recorded); #11 Heavy metals (on file 09.09, not recorded); #12 Pesticides (on file 09.09, not recorded) | L9: 0.1759 | M9: ППК26114 | N9: 0.02 | O9: no — 3 on file, not recorded | POTENCY: the certificate reads 17.59 %, outside the 13–16% it was delivered under
A10: 1 | B10: 31.07.2026 | C10: GG1024_01 | D10: Gorilla Glue | E10: 0.87 | F10: 16–19% | G10: 0.17 | H10: P050092 | I10: GG1024_01 | J10: ✓ COMPLETE | K10: — | L10: 0.1722 | M10: ППК25104 | N10: 0.0022 | O10: yes — all 12 determinations covered
A11: 1 | B11: 31.07.2026 | C11: GP052501 | D11: Grape Pie | E11: 151.14 | F11: 16–19% | G11: 0.1898 | H11: P050152 | I11: GP052501 | J11: ✓ COMPLETE | K11: — | L11: 0.1898 | M11: ППК25279 | N11: 0 | O11: yes — all 12 determinations covered
A12: 1 | B12: 31.07.2026 | C12: GP0824_02 | D12: Grape Pie | E12: 208.46 | F12: 22–25% | G12: 0.2379 | H12: P050022 | I12: GP0824_02 | J12: ✓ COMPLETE | K12: — | L12: 0.2379 | M12: ППК25139 | N12: 0 | O12: yes — all 12 determinations covered
A13: 1 | B13: 31.07.2026 | C13: GP082501/2 | D13: Grape Pie | E13: 22.84 | F13: 13–16% | G13: 0.1483 | H13: P050322 | I13: GP082501/2 | J13: ✓ COMPLETE | K13: — | L13: 0.1483 | M13: ППК25381 | N13: 0 | O13: yes — all 12 determinations covered
A14: 1 | B14: 31.07.2026 | C14: HPA1024 | D14: High Pro Amnesia | E14: 40.83 | F14: 13–16% | G14: 0.1497 | H14: — | I14: HPA1024 | J14: ❌ 4 MISSING | K14: #8 LoD; #9 Microbiology; #11 Heavy metals; #12 Pesticides | L14: 0.1497 | M14: None | N14: 0 | O14: no — 4 missing
A15: 1 | B15: 31.07.2026 | C15: HPA1024_01 | D15: High Pro Amnesia | E15: 140.5 | F15: 22–25% | G15: 0.2243 | H15: P050052 | I15: HPA1024_01 | J15: ✓ COMPLETE | K15: — | L15: 0.2243 | M15: None | N15: 0 | O15: yes — all 12 determinations covered
A16: 1 | B16: 31.07.2026 | C16: J31102501 | D16: Jokerz 31 | E16: 23.64 | F16: 19–22% | G16: 0.1914 | H16: P060152 | I16: J31102501 | J16: ○ 3 ON FILE, NOT RECORDED | K16: #9 Microbiology (on file 09.09, not recorded); #11 Heavy metals (on file 09.09, not recorded); #12 Pesticides (on file 09.09, not recorded) | L16: 0.1914 | M16: 051-1-К/26 | N16: 0 | O16: no — 3 on file, not recorded
A17: 1 | B17: 31.07.2026 | C17: JD112501 | D17: Jelly Donuts | E17: 41.54 | F17: 19–22% | G17: 0.1964 | H17: P060212 | I17: JD112501 | J17: ✓ COMPLETE | K17: — | L17: 0.1964 | M17: ППК26063 | N17: 0 | O17: yes — all 12 determinations covered
A18: 1 | B18: 31.07.2026 | C18: OPM1024 | D18: Orange Punch Mimosa | E18: 45.46 | F18: 19–22% | G18: 0.1996 | H18: — | I18: OPM1024 | J18: ❌ 4 MISSING | K18: #8 LoD; #9 Microbiology; #11 Heavy metals; #12 Pesticides | L18: 0.1996 | M18: None | N18: 0 | O18: no — 4 missing
A19: 1 | B19: 31.07.2026 | C19: OPM1024_02 | D19: Orange Punch Mimosa | E19: 156.14 | F19: 16–19% | G19: 0.1827 | H19: P050062 | I19: OPM1024_02 | J19: ✓ COMPLETE | K19: — | L19: 0.1827 | M19: ППК25154 | N19: 0 | O19: yes — all 12 determinations covered
A20: 1 | B20: 31.07.2026 | C20: OPM122501 | D20: Orange Punch Mimosa | E20: 104.26 | F20: 10–13% | G20: 0.11 | H20: P060242 | I20: OPM122501 | J20: ✓ COMPLETE | K20: — | L20: 0.0809 | M20: 100-4-К/26 | N20: -0.0291 | O20: yes — all 12 determinations covered | POTENCY: the certificate reads 8.09 %, outside the 10–13% it was delivered under
A21: 1 | B21: 31.07.2026 | C21: PM092501 | D21: Permanent Marker | E21: 20.23 | F21: 13–16% | G21: 0.1406 | H21: P060062 | I21: PM092501 | J21: ✓ COMPLETE | K21: — | L21: — none on the desk — | M21: — | N21: — | O21: yes — all 12 determinations covered
A22: 1 | B22: 31.07.2026 | C22: SCR012603 | D22: Scrambler | E22: 79.81 | F22: 16–19% | G22: 0.17 | H22: P060382 | I22: SCR012603 | J22: ❌ 4 MISSING | K22: #8 LoD; #9 Microbiology (on file 09.09, not recorded); #11 Heavy metals; #12 Pesticides | L22: — none on the desk — | M22: — | N22: — | O22: no — 4 missing
A23: 2 | B23: 14.08.2026 | C23: ACC102501 | D23: Amnesia Core Cut | E23: 38.88 | F23: 10–13% | G23: 0.1291 | H23: P060122 | I23: — | J23: — CERTIFICATES ON FILE, NO TRACKER ROW — | K23: no lot on the tracker for this batch; certificates found on 09.09.2026 cover #3 Identification C; #4 Total Δ⁹-THC; #5 Total CBD; #6 Total CBN; #8 Loss on drying; #9 Microbiological purity; #10 Mycotoxins; #11 Heavy metals; #12 Pesticide residues — see Reconciliation 09.09 | L23: — none on the desk — | M23: — | N23: — | O23: NO — certificates are on file but the batch is on no tracker lot; add the lot, then re-run
A24: 2 | B24: 14.08.2026 | C24: BSS052501 | D24: Blue Sunset Sherbet | E24: 345.71 | F24: 19–22% | G24: 0.2047 | H24: P050192 | I24: BSS052501 | J24: ⚠ 2 MISSING | K24: #6 CBN; #8 LoD | L24: 0.2039 | M24: 2025/ | N24: -0.0008 | O24: no — 2 missing
A25: 2 | B25: 14.08.2026 | C25: CC012603 | D25: CashCow | E25: 56.18 | F25: 10–13% | G25: 0.1232 | H25: P060372 | I25: — | J25: — CERTIFICATES ON FILE, NO TRACKER ROW — | K25: no lot on the tracker for this batch; certificates found on 09.09.2026 cover #9 Microbiological purity — see Reconciliation 09.09 | L25: — none on the desk — | M25: — | N25: — | O25: NO — certificates are on file but the batch is on no tracker lot; add the lot, then re-run
A26: 2 | B26: 14.08.2026 | C26: CF102501 | D26: Chem Flyer | E26: 48.35 | F26: 7–10% | G26: 0.0983 | H26: P060132 | I26: — | J26: — CERTIFICATES ON FILE, NO TRACKER ROW — | K26: no lot on the tracker for this batch; certificates found on 09.09.2026 cover #3 Identification C; #4 Total Δ⁹-THC; #5 Total CBD; #6 Total CBN; #8 Loss on drying; #9 Microbiological purity; #10 Mycotoxins; #11 Heavy metals; #12 Pesticide residues — see Reconciliation 09.09 | L26: — none on the desk — | M26: — | N26: — | O26: NO — certificates are on file but the batch is on no tracker lot; add the lot, then re-run
A27: 2 | B27: 14.08.2026 | C27: CJ062501/1 | D27: Cap Junky | E27: 77.72 | F27: 19–22% | G27: 0.2151 | H27: P050222 | I27: CJ062501/1 | J27: ✓ COMPLETE | K27: — | L27: 0.2151 | M27: ППК25321 | N27: 0 | O27: yes — all 12 determinations covered
A28: 2 | B28: 14.08.2026 | C28: CJ082501/1 | D28: Cap Junky | E28: 115.6 | F28: 22–25% | G28: 0.2496 | H28: P060022 | I28: CJ082501/1 | J28: ✓ COMPLETE | K28: — | L28: 0.2496 | M28: ППК26002 | N28: 0 | O28: yes — all 12 determinations covered
A29: 2 | B29: 14.08.2026 | C29: CJ092501 | D29: Cap Junky | E29: 28.38 | F29: 22–25% | G29: 0.223 | H29: P060072 | I29: CJ092501 | J29: ✓ COMPLETE | K29: — | L29: 0.223 | M29: ППК26007 | N29: 0 | O29: yes — all 12 determinations covered
A30: 2 | B30: 14.08.2026 | C30: CLE072501 | D30: Clemosa | E30: 27.07 | F30: 7–10% | G30: 0.0802 | H30: P050282 | I30: CLE072501 | J30: ✓ COMPLETE | K30: — | L30: 0.0802 | M30: ППК25370 | N30: 0 | O30: yes — all 12 determinations covered
A31: 2 | B31: 14.08.2026 | C31: FB012601/1 | D31: Fat Bastard | E31: 8.85 | F31: 13–16% | G31: 0.1468 | H31: P060322 | I31: FB012601_1 | J31: ✓ COMPLETE | K31: — | L31: 0.1468 | M31: ППК26067 | N31: 0 | O31: yes — all 12 determinations covered
A32: 2 | B32: 14.08.2026 | C32: GG1024 | D32: Gorilla Glue | E32: 44.84 | F32: 13–16% | G32: 0.1334 | H32: — | I32: GG1024 | J32: ❌ 9 MISSING | K32: #3 Ident. C (on file 09.09, not recorded); #4 Δ⁹-THC (on file 09.09, not recorded); #5 CBD (on file 09.09, not recorded); #6 CBN; #8 LoD (on file 09.09, not recorded); #9 Microbiology (on file 09.09, not recorded); #10 Mycotoxins (on file 09.09, not recorded); #11 Heavy metals (on file 09.09, not recorded); #12 Pesticides (on file 09.09, not recorded) | L32: 0.1334 | M32: None | N32: 0 | O32: no — 9 missing
A33: 2 | B33: 14.08.2026 | C33: GP072501/2 | D33: Grape Pie | E33: 13.63 | F33: 19–22% | G33: 0.1981 | H33: P050302 | I33: GP072501/2 | J33: ✓ COMPLETE | K33: — | L33: 0.1981 | M33: ППК25379 | N33: 0 | O33: yes — all 12 determinations covered
A34: 2 | B34: 14.08.2026 | C34: GP0824_03 | D34: Grape Pie | E34: 237.67 | F34: ≥ 25% | G34: 0.2545 | H34: P050072 | I34: GP0824_03 | J34: ✓ COMPLETE | K34: — | L34: 0.2545 | M34: ППК25175 | N34: 0 | O34: yes — all 12 determinations covered
A35: 2 | B35: 14.08.2026 | C35: GP082501/1 | D35: Grape Pie | E35: 200.42 | F35: 19–22% | G35: 0.2129 | H35: P050312 | I35: GP082501/1 | J35: ✓ COMPLETE | K35: — | L35: 0.2129 | M35: ППК25380 | N35: 0 | O35: yes — all 12 determinations covered
A36: 2 | B36: 14.08.2026 | C36: GP092501 | D36: Grape Pie | E36: 171.03 | F36: ≥ 25% | G36: 0.2573 | H36: P060092 | I36: GP092501 | J36: ✓ COMPLETE | K36: — | L36: 0.2573 | M36: ППК26009 | N36: 0 | O36: yes — all 12 determinations covered
A37: 2 | B37: 14.08.2026 | C37: GRC102501/2 | D37: Grapes and Cream | E37: 20.17 | F37: 10–13% | G37: 0.1153 | H37: P060182 | I37: GRC102501 (through its P lot; the desk row is the roll-up GRC102501) | J37: ⚠ 3 MISSING | K37: #10 Mycotoxins; #11 Heavy metals (on file 09.09, not recorded); #12 Pesticides (on file 09.09, not recorded) | L37: 0.1153 | M37: None | N37: 0 | O37: no — 3 missing
A38: 2 | B38: 14.08.2026 | C38: HPA052501 | D38: High Pro Amnesia | E38: 249.95 | F38: 19–22% | G38: 0.2039 | H38: P050182 | I38: HPA052501 | J38: ✓ COMPLETE | K38: — | L38: 0.2039 | M38: ППК25278 | N38: 0 | O38: yes — all 12 determinations covered
A39: 2 | B39: 14.08.2026 | C39: JD012603/01 | D39: Jelly Donuts | E39: 12 | F39: 16–19% | G39: 0.1671 | H39: P060362 | I39: JD012603 (through its P lot; the desk row is the roll-up JD012603) | J39: ○ 4 ON FILE, NOT RECORDED | K39: #9 Microbiology (on file 09.09, not recorded); #10 Mycotoxins (on file 09.09, not recorded); #11 Heavy metals (on file 09.09, not recorded); #12 Pesticides (on file 09.09, not recorded) | L39: — none on the desk — | M39: — | N39: — | O39: no — 4 on file, not recorded
A40: 2 | B40: 14.08.2026 | C40: JD012603/02 | D40: Jelly Donuts | E40: 46 | F40: 13–16% | G40: 0.133 | H40: P060412 | I40: JD012603 (through its P lot; the desk row is the roll-up JD012603) | J40: ○ 4 ON FILE, NOT RECORDED | K40: #9 Microbiology (on file 09.09, not recorded); #10 Mycotoxins (on file 09.09, not recorded); #11 Heavy metals (on file 09.09, not recorded); #12 Pesticides (on file 09.09, not recorded) | L40: 0.2054 | M40: ППК26113 | N40: 0.0724 | O40: no — 4 on file, not recorded | POTENCY: the certificate reads 20.54 %, outside the 13–16% it was delivered under
...

Sheet ImB Register
A1: Cert No | B1: Strain (as printed) | C1: Strain (ruled) | D1: Batch | E1: Manufactured | F1: Retest | G1: Desk lot | H1: CoQ status | I1: Note
A2: 041 | B2: Cap Junky | C2: Cap Junky | D2: P060022 | E2: December 2025 | F2: July 2026 | G2: CJ082501/1 | H2: ✓ COMPLETE
A3: 040 | B3: Orange Punch Mimosa | C3: Orange Punch Mimosa | D3: P060042 | E3: December 2026 | F3: July 2026 | G3: OPM092501 | H3: ✓ COMPLETE
A4: 039 | B4: Cap Junky | C4: Cap Junky | D4: P060072 | E4: December 2026 | F4: July 2026 | G4: CJ092501 | H4: ✓ COMPLETE
A5: 038 | B5: Sleepy Joy | C5: Sleepy Joy | D5: P060082 | E5: December 2025 | F5: July 2026 | G5: SJ0925021 | H5: ✓ COMPLETE | I5: strain unresolved: Sleepy Joe (delivery sheet) vs Sleepy Joy (certificate register, P060082)
A6: 037 | B6: Apple and Banana | C6: Apple and Banana | D6: P060052 | E6: December 2025 | F6: July 2026 | G6: AB092501 | H6: ✓ COMPLETE | I6: strain unresolved: Appels & Bananas (delivery sheet) vs Apple and Banana (certificate register, P060052)
A7: 036 | B7: Permanent Market | C7: Permanent Market | D7: P060062 | E7: December 2026 | F7: July 2026 | G7: PM092501 | H7: ✓ COMPLETE | I7: strain unresolved: Permanent Marker (delivery sheet) vs Permanent Market (certificate register, P060062 and P050272)
A8: 035 | B8: Wedding Crasher | C8: Wedding Crasher | D8: P060012 | E8: December 2026 | F8: July 2026 | G8: WC082501 | H8: ✓ COMPLETE | I8: strain unresolved: Wedding Crusher (delivery sheet) vs Wedding Crasher (certificate register, P060012 and P050262)
A9: 034 | B9: Cap Junky | C9: Cap Junky | D9: P060032 | E9: December 2025 | F9: July 2026 | G9: CJ082501/2 | H9: ✓ COMPLETE
A10: 033 | B10: Grape Pie | C10: Grape Pie | D10: P060092 | E10: December 2025 | F10: July 2026 | G10: GP092501 | H10: ✓ COMPLETE
A11: 032 | B11: Cap Junky | C11: Cap Junky | D11: P050222 | E11: September 2025 | F11: April 2026 | G11: CJ062501/1 | H11: ✓ COMPLETE
A12: 031 | B12: Cap Junky | C12: Cap Junky | D12: P050252 | E12: October 2025 | F12: May 2026 | G12: CJ072501 | H12: ✓ COMPLETE
A13: 030 | B13: Wedding Crasher | C13: Wedding Crasher | D13: P050262 | E13: October 2025 | F13: May 2026 | G13: WC072501 | H13: ✓ COMPLETE | I13: strain unresolved: Wedding Crusher (delivery sheet) vs Wedding Crasher (certificate register, P060012 and P050262)
A14: 029 | B14: Grape Pie | C14: Grape Pie | D14: P050152 | E14: August 2025 | F14: March 2026 | G14: GP052501 | H14: ✓ COMPLETE
A15: 028 | B15: Cap Junkie | C15: Cap Junky | D15: P050212 | E15: September 2025 | F15: April 2026 | G15: CJ062501/2 | H15: ✓ COMPLETE | I15: strain ruled Cap Junky; the register prints Cap Junkie
A16: 027 | B16: Clemosa a Bud | C16: Clemosa a Bud | D16: P050282 | E16: October 2025 | F16: May 2026 | G16: CLE072501 | H16: ✓ COMPLETE | I16: strain unresolved: Clemosa (delivery sheet) vs Clemosa a Bud (certificate register, P050282)
A17: 026 | B17: Permanent Market | C17: Permanent Market | D17: P050272 | E17: October 2025 | F17: May 2026 | G17: PM072501 | H17: ⚠ 1 MISSING | I17: strain unresolved: Permanent Marker (delivery sheet) vs Permanent Market (certificate register, P060062 and P050272)
A18: 025 | B18: Motor Breath | C18: Motor Breath | D18: P050112 | E18: July 2025 | F18: February 2025 | G18: MB0824_05 | H18: ✓ COMPLETE
A19: 024 | B19: Orange Punch Mimosa | C19: Orange Punch Mimosa | D19: P050132 | E19: August 2025 | F19: March 2026 | G19: OPM052501 | H19: ⚠ 1 MISSING
A20: 023 | B20: Orange Punch Mimosa | C20: Orange Punch Mimosa | D20: P050082 | E20: June 2025 | F20: January 2026 | G20: OPM1024_03 | H20: ✓ COMPLETE
A21: 022 | B21: Cap Junky | C21: Cap Junky | D21: P050172 | E21: August 2025 | F21: March 2026 | G21: CJ052501/02 | H21: ✓ COMPLETE
A22: 020 | B22: Grape Pie | C22: Grape Pie | D22: P050312 | E22: November 2025 | F22: June 2026 | G22: GP082501/1 | H22: ✓ COMPLETE
A23: 021 | B23: Grape Pie | C23: Grape Pie | D23: P050322 | E23: November 2025 | F23: June 2026 | G23: GP082501/2 | H23: ✓ COMPLETE
A24: 019 | B24: Grape Pie | C24: Grape Pie | D24: P050302 | E24: November 2025 | F24: June 2026 | G24: GP072501/2 | H24: ✓ COMPLETE
A25: 018 | B25: Grape Pie | C25: Grape Pie | D25: P050292 | E25: November 2025 | F25: June 2026 | G25: GP072501/1 | H25: ✓ COMPLETE
A26: 017 | B26: Blue Sunset Sherbet | C26: Blue Sunset Sherbet | D26: P050192 | E26: August 2025 | F26: — none printed — | G26: BSS052501 | H26: ⚠ 2 MISSING
A27: — not read — | B27: Cup Junkie | C27: Cap Junky | D27: P050162 | E27: August 2025 | F27: — none printed — | G27: CJ052501/01 | H27: ✓ COMPLETE | I27: strain ruled Cap Junky; the register prints Cup Junkie
A28: — not read — | B28: High Pro Amnesia | C28: High Pro Amnesia | D28: P050182 | E28: August 2025 | F28: — none printed — | G28: HPA052501 | H28: ✓ COMPLETE
A29: — not read — | B29: Blue Sunset Sherbet | C29: Blue Sunset Sherbet | D29: P050122 | E29: June 2025 | F29: — none printed — | G29: BSS1024_01/1 | H29: ✓ COMPLETE
A30: — not read — | B30: Gorilla Glue | C30: Gorilla Glue | D30: P050092 | E30: March 2025 | F30: — none printed — | G30: GG1024_01 | H30: ✓ COMPLETE
A31: — not read — | B31: Grape Pie | C31: Grape Pie | D31: P050102 | E31: March 2025 | F31: October 2025 | G31: GP0824_01 | H31: ✓ COMPLETE
A32: — not read — | B32: Grape Pie | C32: Grape Pie | D32: P050072 | E32: June 2025 | F32: January 2026 | G32: GP0824_03 | H32: ✓ COMPLETE
A33: — not read — | B33: Orange Punch Mimosa | C33: Orange Punch Mimosa | D33: P050062 | E33: May 2025 | F33: December 2025 | G33: OPM1024_02 | H33: ✓ COMPLETE
A34: — not read — | B34: High Pro Amnesia | C34: High Pro Amnesia | D34: P050052 | E34: May 2025 | F34: December 2025 | G34: HPA1024_01 | H34: ✓ COMPLETE
A35: — not read — | B35: Grape Pie | C35: Grape Pie | D35: P050022 | E35: May 2025 | F35: December 2025 | G35: GP0824_02 | H35: ✓ COMPLETE
A36: — not read — | B36: Orange Punch Mimosa | C36: Orange Punch Mimosa | D36: P050042 | E36: March 2025 | F36: November 2025 | G36: OMP1024_01 | H36: ✓ COMPLETE
A37: — not read — | B37: Motor Breath | C37: Motor Breath | D37: P050032 | E37: April 2025 | F37: November 2025 | G37: MB0824_04 | H37: ⚠ 1 MISSING
A38: — not read — | B38: Gorilla Glue | C38: Gorilla Glue | D38: P050012 | E38: April 2025 | F38: November 2025 | G38: GG1024_02 | H38: ✓ COMPLETE
A39: — not read — | B39: Blue Gelato | C39: Blue Gelato | D39: BG1024 | E39: January 2025 | F39: June 2025 | G39: BG1024 | H39: ✓ COMPLETE
... A44: — not read — | B44: High Pro Amnesia | C44: High Pro Amnesia | D44: HPA1024 | E44: January 2025 | F44: — none printed — | G44: HPA1024 | H44: ❌ 4 MISSING
...

Sheet Reconciliation 09.09
A1: THE PASS THIS BUILD READ
A3: Source | B3: CoQ_Analysis_Master_v20_owner.xlsx | D3: the owner's workbook of 09.09.2026, vendored beside this one; the three sheets it was read from are Cell Resolution 09.09, Coverage Update 09.09 and Identity Problem 09.09
A4: Certificates it read | B4: 387 | D4: eCoA_DATABASE, name for name
A5: Determinations it resolved | B5: 600 | D5: 50 lots of Tranches 1 and 2 x 12
A7: WHAT IT CLOSED ON BATCH COVERAGE
A9: Parameters closed | B9: 84 | D9: a certificate on file that this sheet still marked missing
A10: Lots affected | B10: 24
A11: Closures not applied | B11: 13 | D11: already covered, or the lot has no row on Batch Coverage — listed below
A13: WHAT THE TWO RECORDS SAY ABOUT THE SAME 600 CELLS
A15: agree | B15: 147 | D15: both hold a value and it is the same value
A16: values | B16: 202 | D16: both hold a value and the values differ — a finding
A17: order | B17: 3 | D17: the same values against different analytes — a finding
A18: fill | B18: 14 | D18: the desk held nothing and the pass holds a printable result
A19: blocked | B19: 10 | D19: the only document is an in-house iCoA that has not been issued
A20: ambiguous | B20: 51 | D20: the pass holds a list of values it does not label
A21: basis note | B21: 25 | D21: the pass names where identity comes from, not a result
A22: none | B22: 39 | D22: neither record holds anything
A23: not comparable | B23: 86 | D23: the two records hold different numbers of lines
A24: no desk lot | B24: 23 | D24: the desk carries no initial-release CoQ for the batch
A26: THE DISAGREEMENTS
A28: Batch | B28: Determination | C28: Kind | D28: The desk holds | E28: The 09.09 pass reads
A29: BG1024 | B29: #1 | C29: different values | D29: Conforms | Одговара | E29: Conforms
A30: BG1024 | B30: #2 | C30: different values | D30: Conforms | Одговара | E30: Conforms
A31: BG1024 | B31: #7 | C31: different values | D31: Conforms | Одговара | E31: Conforms
A32: BG1024 | B32: #9 | C32: different values | D32: 1.6 × 10⁴; 1 × 10⁴; < 10² and > 10; Absent | Отсутна; Absent | Отсутна | E32: 1,6 x 10⁴ CFU/g; 1 x 10⁴ CFU/g; < 10² и > 10 CFU/g; Одговара; Одговара
A33: BSS1024 | B33: #1 | C33: different values | D33: Conforms | Одговара | E33: Conforms
A34: BSS1024 | B34: #2 | C34: different values | D34: Conforms | Одговара | E34: Conforms
A35: BSS1024 | B35: #7 | C35: different values | D35: Conforms | Одговара | E35: Conforms
A36: BSS1024 | B36: #9 | C36: different values | D36: 1.5 × 10⁴; 2.2 × 10³; < 10² and > 10; Absent | Отсутна; Absent | Отсутна | E36: 1,5 x 10⁴ CFU/g; 2,2 x 10³ CFU/g; < 10² и > 10 CFU/g; Одговара; Одговара
A37: BSS1024 | B37: #11 | C37: same values, other order | D37: 0.071; 0.014; 0.081; 0.014 | E37: 0,081 mg/kg(l); 0,071 mg/kg(l); 0,014 mg/kg(l); 0,014 mg/kg(l)
A38: CJ052501/01 | B38: #1 | C38: different values | D38: Conforms | Одговара | E38: Conforms
A39: CJ052501/01 | B39: #2 | C39: different values | D39: Conforms | Одговара | E39: Conforms
... A233: WC082501 | B233: #12 | C233: different values | D233: ND | E233: ≤ LOQ (all 29 compounds)
A235: THE IDENTITY DETERMINATIONS ARE NOT A TRANSCRIPTION PROBLEM
A237: Identification A, Identification B and foreign matter are blank on almost every lot in both tranches, and the reason is not that nobody transcribed them. 118 of the 600 cells cite an in-house iCoA-PP_26-nnn whose issue date is PLANNED, on 40 of the 50 batches: the certificate that carries the result has not been issued, so there is nothing to cite. What the in-house documents that DO exist carry is worse than missing. Appearance is the single word “Confirms” with no description. Foreign matter is “Confirms” against a < 2.0 % specification with NO PERCENTAGE PRINTED — Ph. Eur. 2.8.2 is gravimetric and EudraLex Vol. 4 Ch. 6 §6.7 requires the result. Microscopy was NOT PERFORMED on any of the five documents read. Three Report of Analysis documents carry no document code, no version and no report number (EudraLex Vol. 4 Ch. 4 §4.9), and this build refuses to cite them. Issuing the iCoAs does not by itself fix this: the microscopy has to be done and the foreign-matter percentage has to be printed.
A245: CLOSURES THAT FOUND NO ROW
A247: CU batch | B247: P batch | D247: Parameters now covered | E247: From
A248: CC012603 | B248: P060372 | D248: #9 Microbiological purity | E248: 363/0693/26 (01.06.2026) [IJZ-MB]
A249: JD032601 | B249: — not assigned — | D249: #9 Microbiological purity; #10 Mycotoxins; #11 Heavy metals; #12 Pesticide residues | E249: 4374/2026 (11.08.2026) [IJZ]; 477/0929/26 (04.08.2026) [IJZ-MB]
A250: CF102501 | B250: P060132 | D250: #3 Identification C; #4 Total Δ⁹-THC; #5 Total CBD; #6 Total CBN; #8 Loss on drying; #9 Microbiological purity; #10 Mycotoxins; #11 Heavy metals; #12 Pesticide residues | E250: 031-4-K/26 (10.02.2026) [FHM]; 031-4-LoD/26 (12.02.2026) [FHM]; 330/2026 (11.02.2026) [IJZ]; 73/0116/26 (09.02.2026) [IJZ-MB]
...

Sheet CoQ Parameter Tracker v25
A1: BATCH IDENTIFICATION | D1: IDENTIFICATION 1–3 | M1: CANNABINOID ASSAY 4–6 | V1: PHYSICAL 7–8 | AB1: MICROBIOLOGY 9 | AH1: CONTAMINANTS 10–12
A2: CU Batch | B2: P Batch | C2: STATUS | D2: #1 Identification A Appearance · Ph. Eur. mon. 3028 | G2: #2 Identification B Microscopy · Ph. Eur. 2.8.23 | J2: #3 Identification C HPLC · Ph. Eur. 2.2.29 | M2: #4 Assay — Total Δ⁹-THC* Ph. Eur. 2.2.29 (HPLC) | P2: #5 Assay — Total CBD Ph. Eur. 2.2.29 · CBD + CBDA×0.877 | S2: #6 Total CBN Ph. Eur. 2.2.29 · CBN + CBNA×0.876 | V2: #7 Foreign Matter Ph. Eur. 2.8.2 / in-house | Y2: #8 Loss on Drying Ph. Eur. 2.2.32 · 40 °C, 24 h, 15–25 mbar | AB2: #9 Microbiological Purity Ph. Eur. 2.6.12 / 2.6.13 / 2.6.31 · cat. C | AH2: #10 Mycotoxins Ph. Eur. 2.8.18 / 2.8.22 (HPLC-FLD) | AL2: #11 Heavy Metals Ph. Eur. 2.4.27 (ICP-MS) | AQ2: #12 Pesticide Residues Ph. Eur. 2.8.13 (LC-MS/MS) · CUMCS equivalency
D3: A.C.: Conforms to Ph. Eur. monograph 3028 (Cannabis flos) | G3: A.C.: Conforms to Ph. Eur. monograph 3028 (Cannabis flos) | J3: A.C.: Conforms to Ph. Eur. monograph 3028 (Cannabis flos) | M3: A.C.: Per target grade (CoQ §01) | P3: A.C.: ≤ 1.0 % w/w | S3: A.C.: ≤ 1.0 % w/w | V3: A.C.: ≤ 2.0 % (25–50 g); leaves < 1 cm; no seeds | Y3: A.C.: ≤ 12.0 % | AB3: A.C.: ≤ 10⁵ CFU/g | AC3: A.C.: ≤ 10⁴ CFU/g | AD3: A.C.: ≤ 10⁴ CFU/g | AE3: A.C.: Absence / 25 g | AF3: A.C.: Absence / 1 g | AH3: A.C.: ≤ 2 µg/kg | AI3: A.C.: ≤ 4 µg/kg | AJ3: A.C.: ≤ 20 µg/kg | AL3: A.C.: ≤ 0.5 mg/kg | AM3: A.C.: ≤ 0.3 mg/kg | AN3: A.C.: ≤ 0.2 mg/kg | AO3: A.C.: ≤ 0.1 mg/kg | AQ3: A.C.: ≤ LOQ (Ph. Eur. 2.8.13 / CUMCS equivalency)
D4: Result | E4: [eCOA code],[date],[Lab] | F4: ✓ ✗ | G4: Result | H4: [eCOA code],[date],[Lab] | I4: ✓ ✗ | J4: Result | K4: [eCOA code],[date],[Lab] | L4: ✓ ✗ | M4: Result | N4: [eCOA code],[date],[Lab] | O4: ✓ ✗ | P4: Result | Q4: [eCOA code],[date],[Lab] | R4: ✓ ✗ | S4: Result | T4: [eCOA code],[date],[Lab] | U4: ✓ ✗ | V4: Result | W4: [eCOA code],[date],[Lab] | X4: ✓ ✗ | Y4: Result | Z4: [eCOA code],[date],[Lab] | AA4: ✓ ✗ | AB4: TAMC | AC4: TYMC | AD4: GNB | AE4: Salm. | AF4: E. coli | AG4: ✓ ✗ | AH4: AfB₁ | AI4: ΣAf | AJ4: OTA | AK4: ✓ ✗ | AL4: Pb | AM4: Cd | AN4: As | AO4: Hg | AP4: ✓ ✗ | AQ4: Result | AR4: [eCOA code],[date],[Lab] | AS4: ✓ ✗
A5: BG1024 | B5: N/A — no P batch assigned | C5: ✓ COMPLETE 2 testing instances • 2 document(s) on file, not credited | D5: Conforms | E5: =IFERROR(INDEX('iCoA Register'!$B:$B,MATCH("BG1024|I",'iCoA Register'!$P:$P,0)),"iCoA — at issue")&", (07.03.2025) [PP]" | F5: ✓ | G5: not on this certificate | H5: ППК25050, (26.02.2025) [CNP] · on file, not credited | I5: • | J5: Conforms (ImB spec.) | K5: ППК25050, (26.02.2025) [CNP] | L5: ✓ | M5: 21.80 | N5: ППК25050, (26.02.2025) [CNP] | O5: ✓ | P5: 0.04 | Q5: ППК25050, (26.02.2025) [CNP] | R5: ✓ | S5: 0.02 ᴰ | T5: ППК25050, (26.02.2025) [CNP] | U5: ✓ | V5: Conforms | W5: =IFERROR(INDEX('iCoA Register'!$B:$B,MATCH("BG1024|I",'iCoA Register'!$P:$P,0)),"iCoA — at issue")&", (07.03.2025) [PP]" | X5: ✓ | Y5: 5.73 | Z5: ППК25050, (26.02.2025) [CNP] | AA5: ✓ | AB5: 1.6 × 10⁴ | AC5: 1 × 10⁴ | AD5: < 10² and > 10 | AE5: Absent | AF5: Absent | AG5: ✓ | AH5: ND | AI5: < 2 | AJ5: ND | AK5: ✓ | AL5: 0.01 | AM5: 0.016 | AN5: 0.014 | AO5: 0.005 | AP5: ✓ | AQ5: ≤ LOQ (all 29 compounds) | AR5: 752-2025, (27.02.2025) [IJZ] | AS5: ✓
AB6: 163-0271-25, (24.02.2025) [IJZ-MB] | AH6: 752-2025, (27.02.2025) [IJZ] | AL6: 752-2025, (27.02.2025) [IJZ]
G7: Conforms | H7: =IFERROR(INDEX('iCoA Register'!$B:$B,MATCH("BG1024|I",'iCoA Register'!$P:$P,0)),"iCoA — at issue")&", (07.03.2025) [PP]" | I7: ✓ | J7: Conforms (ImB spec.) ᴿ | K7: 197-1-K-26, (07.08.2026) [FHM-K] | L7: ✓ | M7: 26.14 | N7: 197-1-K-26, (07.08.2026) [FHM-K] | O7: ✓ | P7: < LOQ | Q7: 197-1-K-26, (07.08.2026) [FHM-K] | R7: ✓ | S7: 0.28 | T7: 197-1-K-26, (07.08.2026) [FHM-K] | U7: ✓ | Y7: not on this certificate | Z7: 197-1-K-26, (07.08.2026) [FHM-K] · on file, not credited | AA7: • | AH7: ND | AI7: ND | AJ7: ND | AK7: ✓
AH8: 197-1-M-26, (10.08.2026) [FHM-M]
A9: BSS1024 | B9: N/A — no P batch assigned | C9: ✓ COMPLETE 2 testing instances • 2 document(s) on file, not credited | D9: Conforms | E9: =IFERROR(INDEX('iCoA Register'!$B:$B,MATCH("BSS1024|I",'iCoA Register'!$P:$P,0)),"iCoA — at issue")&", (04.03.2025) [PP]" | F9: ✓ | G9: not on this certificate | H9: ППК25051, (26.02.2025) [CNP] · on file, not credited | I9: • | J9: Conforms (ImB spec.) | K9: ППК25051, (26.02.2025) [CNP] | L9: ✓ | M9: 21.03 | N9: ППК25051, (26.02.2025) [CNP] | O9: ✓ | P9: 0.04 | Q9: ППК25051, (26.02.2025) [CNP] | R9: ✓ | S9: 0.02 ᴰ | T9: ППК25051, (26.02.2025) [CNP] | U9: ✓ | V9: Conforms | W9: =IFERROR(INDEX('iCoA Register'!$B:$B,MATCH("BSS1024|I",'iCoA Register'!$P:$P,0)),"iCoA — at issue")&", (04.03.2025) [PP]" | X9: ✓ | Y9: 5.99 | Z9: ППК25051, (26.02.2025) [CNP] | AA9: ✓ | AB9: 1.5 × 10⁴ | AC9: 2.2 × 10³ | AD9: < 10² and > 10 | AE9: Absent | AF9: Absent | AG9: ✓ | AH9: ND | AI9: < 2 | AJ9: ND | AK9: ✓ | AL9: 0.071 | AM9: 0.014 | AN9: 0.081 | AO9: 0.014 | AP9: ✓ | AQ9: ≤ LOQ (all 29 compounds) | AR9: 751-2025, (27.02.2025) [IJZ] | AS9: ✓
AB10: 161-0269-25, (24.02.2025) [IJZ-MB] | AH10: 751-2025, (27.02.2025) [IJZ] | AL10: 751-2025, (27.02.2025) [IJZ]
G11: Conforms | H11: =IFERROR(INDEX('iCoA Register'!$B:$B,MATCH("BSS1024|I",'iCoA Register'!$P:$P,0)),"iCoA — at issue")&", (04.03.2025) [PP]" | I11: ✓ | J11: Conforms (ImB spec.) | K11: 197-2-K-26, (07.08.2026) [FHM-K] | L11: ✓ | M11: 25.01 | N11: 197-2-K-26, (07.08.2026) [FHM-K] | O11: ✓ | P11: < LOQ | Q11: 197-2-K-26, (07.08.2026) [FHM-K] | R11: ✓ | S11: < LOQ | T11: 197-2-K-26, (07.08.2026) [FHM-K] | U11: ✓ | Y11: not on this certificate | Z11: 197-2-K-26, (07.08.2026) [FHM-K] · on file, not credited | AA11: • | AH11: ND | AI11: ND | AJ11: ND | AK11: ✓
AH12: 197-2-M-26, (10.08.2026) [FHM-M]
A13: CC112501 | B13: P060272 | C13: ✓ COMPLETE 2 testing instances • 1 document(s) on file, not credited | D13: Conforms | E13: =IFERROR(INDEX('iCoA Register'!$B:$B,MATCH("P060272|I",'iCoA Register'!$P:$P,0)),"iCoA — at issue")&", (18.05.2026) [PP]" | F13: ✓ | G13: not on this certificate | H13: ППК26068, (11.05.2026) [CNP] · on file, not credited | I13: • | J13: Conforms (ImB spec.) | K13: ППК26068, (11.05.2026) [CNP] | L13: ✓ | M13: 13.35 | N13: ППК26068, (11.05.2026) [CNP] | O13: ✓ | P13: 0.04 | Q13: ППК26068, (11.05.2026) [CNP] | R13: ✓ | S13: < LOQ ᴰ | T13: ППК26068, (11.05.2026) [CNP] | U13: ✓ | V13: Conforms | W13: =IFERROR(INDEX('iCoA Register'!$B:$B,MATCH("P060272|I",'iCoA Register'!$P:$P,0)),"iCoA — at issue")&", (18.05.2026) [PP]" | X13: ✓ | Y13: 7.39 | Z13: ППК26068, (11.05.2026) [CNP] | AA13: ✓ | AB13: 3.8 × 10³ | AC13: 2.7 × 10³ | AD13: < 10³ and > 10² | AE13: Absent | AF13: Absent | AG13: ✓ | AH13: ND | AI13: < 2 | AJ13: ND | AK13: ✓ | AL13: 0.0289 | AM13: 0.0119 | AN13: 0.016 | AO13: 0.0102 | AP13: ✓ | AQ13: ≤ LOQ (all 29 compounds) | AR13: 2359-2026, (29.04.2026) [IJZ] | AS13: ✓
AB14: 311-0555-26, (28.04.2026) [IJZ-MB] | AH14: 2359-2026, (29.04.2026) [IJZ] | AL14: 2359-2026, (29.04.2026) [IJZ]
G15: Conforms | H15: =IFERROR(INDEX('iCoA Register'!$B:$B,MATCH("P060272|I",'iCoA Register'!$P:$P,0)),"iCoA — at issue")&", (18.05.2026) [PP]" | I15: ✓ | AB15: 1.6 × 10³ | AC15: 1 × 10³ | AD15: < 10³ and > 10² | AE15: Absent | AF15: Absent | AG15: ✓
AB16: 543-1074-26, (31.08.2026) [IJZ-MB]
A17: CJ1024 | B17: N/A — no P batch assigned | C17: ✓ COMPLETE 2 testing instances • 1 document(s) on file, not credited | D17: Conforms | E17: =IFERROR(INDEX('iCoA Register'!$B:$B,MATCH("CJ1024|I",'iCoA Register'!$P:$P,0)),"iCoA — at issue")&", (03.03.2025) [PP]" | F17: ✓ | G17: not on this certificate | H17: ППК25052, (26.02.2025) [CNP] · on file, not credited | I17: • | J17: Conforms (ImB spec.) | K17: ППК25052, (26.02.2025) [CNP] | L17: ✓ | M17: 23.00 | N17: ППК25052, (26.02.2025) [CNP] | O17: ✓ | P17: 0.05 | Q17: ППК25052, (26.02.2025) [CNP] | R17: ✓ | S17: 0.02 ᴰ | T17: ППК25052, (26.02.2025) [CNP] | U17: ✓ | V17: Conforms | W17: =IFERROR(INDEX('iCoA Register'!$B:$B,MATCH("CJ1024|I",'iCoA Register'!$P:$P,0)),"iCoA — at issue")&", (03.03.2025) [PP]" | X17: ✓ | Y17: 5.91 | Z17: ППК25052, (26.02.2025) [CNP] | AA17: ✓ | AB17: 8.4 × 10³ | AC17: < 10 | AD17: < 10 | AE17: Absent | AF17: Absent | AG17: ✓ | AH17: ND | AI17: < 2 | AJ17: ND | AK17: ✓ | AL17: 0.036 | AM17: 0.013 | AN17: 0.063 | AO17: 0.006 | AP17: ✓ | AQ17: ≤ LOQ (all 29 compounds) | AR17: 750-2025, (27.02.2025) [IJZ] | AS17: ✓
AB18: 164-0272-25, (24.02.2025) [IJZ-MB] | AH18: 750-2025, (27.02.2025) [IJZ] | AL18: 750-2025, (27.02.2025) [IJZ]
G19: Conforms | H19: =IFERROR(INDEX('iCoA Register'!$B:$B,MATCH("CJ1024|I",'iCoA Register'!$P:$P,0)),"iCoA — at issue")&", (03.03.2025) [PP]" | I19: ✓ | AB19: < 10 | AC19: 10 | AD19: < 10 | AE19: Absent | AF19: Absent | AG19: ✓
AB20: 565-1096-26, (01.09.2026) [IJZ-MB]
A21: FB012601_1 | B21: P060322 | C21: ✓ COMPLETE 2 testing instances • 1 document(s) on file, not credited | D21: Conforms | E21: =IFERROR(INDEX('iCoA Register'!$B:$B,MATCH("P060322|I",'iCoA Register'!$P:$P,0)),"iCoA — at issue")&", (22.05.2026) [PP]" | F21: ✓ | G21: not on this certificate | H21: ППК26067, (11.05.2026) [CNP] · on file, not credited | I21: • | J21: Conforms (ImB spec.) | K21: ППК26067, (11.05.2026) [CNP] | L21: ✓ | M21: 14.68 | N21: ППК26067, (11.05.2026) [CNP] | O21: ✓ | P21: 0.04 | Q21: ППК26067, (11.05.2026) [CNP] | R21: ✓ | S21: < LOQ ᴰ | T21: ППК26067, (11.05.2026) [CNP] | U21: ✓ | V21: Conforms | W21: =IFERROR(INDEX('iCoA Register'!$B:$B,MATCH("P060322|I",'iCoA Register'!$P:$P,0)),"iCoA — at issue")&", (22.05.2026) [PP]" | X21: ✓ | Y21: 7.67 | Z21: ППК26067, (11.05.2026) [CNP] | AA21: ✓ | AB21: 2 × 10³ | AC21: 2.1 × 10³ | AD21: < 10 | AE21: Absent | AF21: Absent | AG21: ✓ | AH21: ND | AI21: < 2 | AJ21: ND | AK21: ✓ | AL21: 0.0114 | AM21: 0.017 | AN21: 0.0144 | AO21: 0.0155 | AP21: ✓ | AQ21: ≤ LOQ (all 26 compounds) | AR21: 2362-2026, (30.04.2026) [IJZ] | AS21: ✓
AB22: 308-0552-26, (28.04.2026) [IJZ-MB] | AH22: 2362-2026, (30.04.2026) [IJZ] | AL22: 2362-2026, (30.04.2026) [IJZ]
G23: Conforms | H23: =IFERROR(INDEX('iCoA Register'!$B:$B,MATCH("P060322|I",'iCoA Register'!$P:$P,0)),"iCoA — at issue")&", (22.05.2026) [PP]" | I23: ✓
A25: FB012603 | B25: P060432 | C25: ⚠ 3 NO RESULT (3 no cert / 0 cert w/o result) | D25: Conforms | E25: ППК26112, (30.06.2026) [CNP] | F25: ✓ | G25: Conforms | H25: ППК26112, (30.06.2026) [CNP] | I25: ✓ | J25: Conforms (ImB spec.) | K25: ППК26112, (30.06.2026) [CNP] | L25: ✓ | M25: 20.83 | N25: ППК26112, (30.06.2026) [CNP] | O25: ✓ | P25: 0.21 | Q25: ППК26112, (30.06.2026) [CNP] | R25: ✓ | S25: 0.06 | T25: ППК26112, (30.06.2026) [CNP] | U25: ✓ | V25: Conforms (no value printed) | W25: ППК26112, (30.06.2026) [CNP] | X25: ✓ | Y25: 7.04 | Z25: ППК26112, (30.06.2026) [CNP] | AA25: ✓ | AB25: 9.8 × 10³ | AC25: 2.5 × 10³ | AD25: < 10² and > 10 | AE25: Absent | AF25: Absent | AG25: ✓ | AH25: — MISSING — | AI25: — MISSING — | AJ25: — MISSING — | AK25: ✗ | AL25: — MISSING — | AM25: — MISSING — | AN25: — MISSING — | AO25: — MISSING — | AP25: ✗ | AQ25: — MISSING — | AR25: — no certificate — | AS25: ✗
AB26: 537-1068-26, (31.08.2026) [IJZ-MB] | AH26: — no certificate — | AL26: — no certificate —
A27: FB012603V | B27: P060392 | C27: ⚠ 3 NO RESULT (3 no cert / 0 cert w/o result) | D27: Conforms | E27: ППК26110, (30.06.2026) [CNP] | F27: ✓ | G27: Conforms | H27: ППК26110, (30.06.2026) [CNP] | I27: ✓ | J27: Conforms (ImB spec.) | K27: ППК26110, (30.06.2026) [CNP] | L27: ✓ | M27: 18.29 | N27: ППК26110, (30.06.2026) [CNP] | O27: ✓ | P27: 0.16 | Q27: ППК26110, (30.06.2026) [CNP] | R27: ✓ | S27: 0.06 | T27: ППК26110, (30.06.2026) [CNP] | U27: ✓ | V27: Conforms (no value printed) | W27: ППК26110, (30.06.2026) [CNP] | X27: ✓ | Y27: 6.36 | Z27: ППК26110, (30.06.2026) [CNP] | AA27: ✓ | AB27: 2.9 × 10³ | AC27: 2.5 × 10³ | AD27: < 10 | AE27: Absent | AF27: Absent | AG27: ✓ | AH27: — MISSING — | AI27: — MISSING — | AJ27: — MISSING — | AK27: ✗ | AL27: — MISSING — | AM27: — MISSING — | AN27: — MISSING — | AO27: — MISSING — | AP27: ✗ | AQ27: — MISSING — | AR27: — no certificate — | AS27: ✗
AB28: 538-1069-26, (31.08.2026) [IJZ-MB] | AH28: — no certificate — | AL28: — no certificate —
A29: FB032601 | B29: P060452 | C29: ✗ 4 NO RESULT (4 no cert / 0 cert w/o result) ✗ OUT OF SPECIFICATION: #7 | D29: Conforms | E29: ППК26127, (21.07.2026) [CNP] | F29: ✓ | G29: Conforms | H29: ППК26127, (21.07.2026) [CNP] | I29: ✓ | J29: Conforms (ImB spec.) | K29: ППК26127, (21.07.2026) [CNP] | L29: ✓ | M29: 12.39 | N29: ППК26127, (21.07.2026) [CNP] | O29: ✓ | P29: 0.06 | Q29: ППК26127, (21.07.2026) [CNP] | R29: ✓ | S29: 0.04 | T29: ППК26127, (21.07.2026) [CNP] | U29: ✓ | V29: 0.08 % (Does not conform) | W29: ППК26127, (21.07.2026) [CNP] | X29: ✓ | Y29: 7.77 | Z29: ППК26127, (21.07.2026) [CNP] | AA29: ✓ | AB29: — MISSING — | AC29: — MISSING — | AD29: — MISSING — | AE29: — MISSING — | AF29: — MISSING — | AG29: ✗ | AH29: — MISSING — | AI29: — MISSING — | AJ29: — MISSING — | AK29: ✗ | AL29: — MISSING — | AM29: — MISSING — | AN29: — MISSING — | AO29: — MISSING — | AP29: ✗ | AQ29: — MISSING — | AR29: — no certificate — | AS29: ✗
AB30: — no certificate — | AH30: — no certificate — | AL30: — no certificate —
