Workbook
Name _fold_Read_Me: Reference!$A$2:$A$84
Name _fold_Issuance_Methodology: Reference!$A$88:$A$202
Name _fold_Delivery_T1_T3: Reference!$A$206:$A$286
Name _fold_ImB_Register: Reference!$A$290:$A$335
Name _fold_Mikro_CoQ_Parameter: Reference!$A$339:$A$485
Name _fold_Reconciliation_09_09: Reference!$A$489:$A$762
Name _fold_Credit_Audit: Reference!$A$766:$A$779
Name _fold_Credit_Corrections: Reference!$A$783:$A$916
Name _fold_Work_Order: Reference!$A$920:$A$961
Name _fold_Open_Items: Reference!$A$965:$A$1025
Name _fold_Not_Tested_Review: Reference!$A$1029:$A$1282
Name _fold_Summary_Dashboard: Reference!$A$1286:$A$1306

Sheet Batch Coverage
A1: CU Batch | B1: P Batch | C1: Strain | D1: Status | E1: 1 Identification A — Appearance | F1: 2 Identification B — Microscopy | G1: 3 Identification C — HPLC | H1: 4 Assay — Total Δ⁹-THC | I1: 5 Assay — Total CBD | J1: 6 Total CBN | K1: 7 Foreign Matter | L1: 8 Loss on Drying | M1: 9 Microbiological Purity | N1: 10 Mycotoxins | O1: 11 Heavy Metals | P1: 12 Pesticide Residues | Q1: Missing (n) | R1: Missing parameters | S1: Certificates (n) | T1: Labs present | U1: On file, not recorded (n) | V1: Labs on file, not recorded
A2: BG1024 | B2: — not assigned — | C2: Blue Gelato | D2: ✓ COMPLETE | E2: ✓ | F2: ✓ | G2: ✓ | H2: ✓ | I2: ✓ | J2: ✓ | K2: ✓ | L2: ✓ | M2: ✓ | N2: ✓ | O2: ✓ | P2: ✓ | Q2: 0 | R2: — | S2: 6 | T2: [CNP] 1; [FHM-K] 1; [FHM-M] 1; [IJZ] 1; [IJZ-MB] 1; [PP] 1 | U2: 0 | V2: —
A3: BSS1024 | B3: — not assigned — | C3: Blue Sunset Sherbet | D3: ✓ COMPLETE | E3: ✓ | F3: ✓ | G3: ✓ | H3: ✓ | I3: ✓ | J3: ✓ | K3: ✓ | L3: ✓ | M3: ✓ | N3: ✓ | O3: ✓ | P3: ✓ | Q3: 0 | R3: — | S3: 6 | T3: [CNP] 1; [FHM-K] 1; [FHM-M] 1; [IJZ] 1; [IJZ-MB] 1; [PP] 1 | U3: 0 | V3: —
A4: CC112501 | B4: P060272 | C4: Cash Cow | D4: ✓ COMPLETE | E4: ✓ | F4: ✓ | G4: ✓ | H4: ✓ | I4: ✓ | J4: ✓ | K4: ✓ | L4: ✓ | M4: ✓ | N4: ✓ | O4: ✓ | P4: ✓ | Q4: 0 | R4: — | S4: 6 | T4: [CNP] 1; [FHM-K] 1; [IJZ] 1; [IJZ-MB] 2; [PP] 1 | U4: 0 | V4: —
A5: CJ1024 | B5: — not assigned — | C5: Cap Junky | D5: ✓ COMPLETE | E5: ✓ | F5: ✓ | G5: ✓ | H5: ✓ | I5: ✓ | J5: ✓ | K5: ✓ | L5: ✓ | M5: ✓ | N5: ✓ | O5: ✓ | P5: ✓ | Q5: 0 | R5: — | S5: 6 | T5: [CNP] 1; [FHM-K] 1; [IJZ] 1; [IJZ-MB] 2; [PP] 1 | U5: 0 | V5: —
A6: FB012601_1 | B6: P060322 | C6: Fat Bastard | D6: ✓ COMPLETE | E6: ✓ | F6: ✓ | G6: ✓ | H6: ✓ | I6: ✓ | J6: ✓ | K6: ✓ | L6: ✓ | M6: ✓ | N6: ✓ | O6: ✓ | P6: ✓ | Q6: 0 | R6: — | S6: 6 | T6: [CNP] 1; [FHM-K] 1; [FHM-M] 1; [IJZ] 1; [IJZ-MB] 1; [PP] 1 | U6: 0 | V6: —
A7: FB012603 | B7: P060432 | C7: Fat Bastard | D7: ○ 3 ON FILE, NOT RECORDED | E7: ✓ | F7: ✓ | G7: ✓ | H7: ✓ | I7: ✓ | J7: ✓ | K7: ✓ | L7: ✓ | M7: ✓ | N7: ○ | O7: ○ | P7: ○ | Q7: 3 | R7: #10 Mycotoxins (on file 09.09, not recorded); #11 Heavy metals (on file 09.09, not recorded); #12 Pesticides (on file 09.09, not recorded) | S7: 3 | T7: [CNP] 1; [FHM-K] 1; [IJZ-MB] 1 | U7: 1 | V7: [IJZ] 1
A8: FB012603V | B8: P060392 | C8: Fat Bastard | D8: ○ 3 ON FILE, NOT RECORDED | E8: ✓ | F8: ✓ | G8: ✓ | H8: ✓ | I8: ✓ | J8: ✓ | K8: ✓ | L8: ✓ | M8: ✓ | N8: ○ | O8: ○ | P8: ○ | Q8: 3 | R8: #10 Mycotoxins (on file 09.09, not recorded); #11 Heavy metals (on file 09.09, not recorded); #12 Pesticides (on file 09.09, not recorded) | S8: 3 | T8: [CNP] 1; [FHM-K] 1; [IJZ-MB] 1 | U8: 1 | V8: [IJZ] 1
A9: FB032601 | B9: P060452 | C9: Fat Bastard | D9: ○ 4 ON FILE, NOT RECORDED | E9: ✓ | F9: ✓ | G9: ✓ | H9: ✓ | I9: ✓ | J9: ✓ | K9: ✓ | L9: ✓ | M9: ○ | N9: ○ | O9: ○ | P9: ○ | Q9: 4 | R9: #9 Microbiology (on file 09.09, not recorded); #10 Mycotoxins (on file 09.09, not recorded); #11 Heavy metals (on file 09.09, not recorded); #12 Pesticides (on file 09.09, not recorded) | S9: 1 | T9: [CNP] 1 | U9: 2 | V9: [IJZ] 1; [IJZ-MB] 1
A10: FB112501 | B10: P060292 | C10: Fat Bastard | D10: ✓ COMPLETE | E10: ✓ | F10: ✓ | G10: ✓ | H10: ✓ | I10: ✓ | J10: ✓ | K10: ✓ | L10: ✓ | M10: ✓ | N10: ✓ | O10: ✓ | P10: ✓ | Q10: 0 | R10: — | S10: 6 | T10: [CNP] 1; [FHM-K] 1; [IJZ] 1; [IJZ-MB] 2; [PP] 1 | U10: 0 | V10: —
A11: GG012601＊ | B11: P060302 | C11: Gorilla Glue | D11: ✓ COMPLETE | E11: ✓ | F11: ✓ | G11: ✓ | H11: ✓ | I11: ✓ | J11: ✓ | K11: ✓ | L11: ✓ | M11: ✓ | N11: ✓ | O11: ✓ | P11: ✓ | Q11: 0 | R11: — | S11: 6 | T11: [CNP] 1; [FHM-K] 1; [IJZ] 1; [IJZ-MB] 2; [PP] 1 | U11: 0 | V11: —
A12: GG012603 | B12: P060402 | C12: Gorilla Glue | D12: ○ 3 ON FILE, NOT RECORDED | E12: ✓ | F12: ✓ | G12: ✓ | H12: ✓ | I12: ✓ | J12: ✓ | K12: ✓ | L12: ✓ | M12: ○ | N12: ✓ | O12: ○ | P12: ○ | Q12: 3 | R12: #9 Microbiology (on file 09.09, not recorded); #11 Heavy metals (on file 09.09, not recorded); #12 Pesticides (on file 09.09, not recorded) | S12: 3 | T12: [CNP] 1; [FHM-K] 1; [FHM-M] 1 | U12: 2 | V12: [IJZ] 1; [IJZ-MB] 1
A13: GG032601 | B13: P060462 | C13: Gorilla Glue | D13: ❌ 4 MISSING | E13: ✓ | F13: ✓ | G13: ✓ | H13: ✓ | I13: ✓ | J13: ✓ | K13: ✓ | L13: ✓ | M13: ✗ | N13: ○ | O13: ✗ | P13: ○ | Q13: 4 | R13: #9 Microbiology; #10 Mycotoxins (on file 09.09, not recorded); #11 Heavy metals; #12 Pesticides (on file 09.09, not recorded) | S13: 1 | T13: [CNP] 1 | U13: 1 | V13: [IJZ] 1
... A15: GG112501 | B15: P060252 | C15: Gorilla Glue | D15: ✓ COMPLETE | E15: ✓ | F15: ✓ | G15: ✓ | H15: ✓ | I15: ✓ | J15: ✓ | K15: ✓ | L15: ✓ | M15: ✓ | N15: ✓ | O15: ✓ | P15: ✓ | Q15: 0 | R15: — | S15: 6 | T15: [CNP] 1; [FHM-K] 1; [IJZ] 1; [IJZ-MB] 2; [PP] 1 | U15: 0 | V15: —
A16: GRC102501 | B16: P060142 / P060182 | D16: ○ 2 ON FILE, NOT RECORDED | E16: ✓ | F16: ✓ | G16: ✓ | H16: ✓ | I16: ✓ | J16: ✓ | K16: ✓ | L16: ✓ | M16: ✓ | N16: ✓ | O16: ○ | P16: ○ | Q16: 2 | R16: #11 Heavy metals (on file 09.09, not recorded); #12 Pesticides (on file 09.09, not recorded) | S16: 8 | T16: [FHM-K] 4; [FHM-M] 1; [IJZ-MB] 1; [PP] 2 | U16: 1 | V16: [IJZ] 1
A17: HPA1024 | B17: — not assigned — | C17: High Pro Amnesia | D17: ❌ 4 MISSING | E17: ✓ | F17: ✓ | G17: ✓ | H17: ✓ | I17: ✓ | J17: ✓ | K17: ✓ | L17: ✗ | M17: ✗ | N17: ✓ | O17: ✗ | P17: ✗ | Q17: 4 | R17: #8 LoD; #9 Microbiology; #11 Heavy metals; #12 Pesticides | S17: 4 | T17: [FHM-K] 1; [FHM-M] 1; [PP] 2 | U17: 0 | V17: —
A18: J31102501 | B18: P060152 | C18: Jokerz 31 | D18: ○ 3 ON FILE, NOT RECORDED | E18: ✓ | F18: ✓ | G18: ✓ | H18: ✓ | I18: ✓ | J18: ✓ | K18: ✓ | L18: ✓ | M18: ○ | N18: ✓ | O18: ○ | P18: ○ | Q18: 3 | R18: #9 Microbiology (on file 09.09, not recorded); #11 Heavy metals (on file 09.09, not recorded); #12 Pesticides (on file 09.09, not recorded) | S18: 5 | T18: [FHM-K] 3; [FHM-M] 1; [PP] 1 | U18: 2 | V18: [IJZ] 1; [IJZ-MB] 1
A19: J31112501 | B19: P060202 | C19: Jokerz 31 | D19: ○ 3 ON FILE, NOT RECORDED | E19: ✓ | F19: ✓ | G19: ✓ | H19: ✓ | I19: ✓ | J19: ✓ | K19: ✓ | L19: ✓ | M19: ✓ | N19: ○ | O19: ○ | P19: ○ | Q19: 3 | R19: #10 Mycotoxins (on file 09.09, not recorded); #11 Heavy metals (on file 09.09, not recorded); #12 Pesticides (on file 09.09, not recorded) | S19: 9 | T19: [FHM-K] 7; [IJZ-MB] 1; [PP] 1 | U19: 1 | V19: [IJZ] 1
A20: J31122501 | B20: P060262 | C20: Jokerz 31 | D20: ⚠ 1 MISSING | E20: ✓ | F20: ✓ | G20: ✓ | H20: ✓ | I20: ✓ | J20: ✓ | K20: ✓ | L20: ✗ | M20: ✓ | N20: ✓ | O20: ✓ | P20: ✓ | Q20: 1 | R20: #8 LoD | S20: 9 | T20: [FHM-K] 3; [IJZ] 2; [IJZ-MB] 3; [PP] 1 | U20: 0 | V20: —
A21: JD012601＊ | B21: P060312 | C21: Jelly Donuts | D21: ✓ COMPLETE | E21: ✓ | F21: ✓ | G21: ✓ | H21: ✓ | I21: ✓ | J21: ✓ | K21: ✓ | L21: ✓ | M21: ✓ | N21: ✓ | O21: ✓ | P21: ✓ | Q21: 0 | R21: — | S21: 6 | T21: [CNP] 1; [FHM-K] 1; [IJZ] 1; [IJZ-MB] 2; [PP] 1 | U21: 0 | V21: —
A22: JD012603 | B22: P060362 / P060412 / P060422 | D22: ○ 3 ON FILE, NOT RECORDED | E22: ✓ | F22: ✓ | G22: ✓ | H22: ✓ | I22: ✓ | J22: ✓ | K22: ✓ | L22: ✓ | M22: ○ | N22: ✓ | O22: ○ | P22: ○ | Q22: 3 | R22: #9 Microbiology (on file 09.09, not recorded); #11 Heavy metals (on file 09.09, not recorded); #12 Pesticides (on file 09.09, not recorded) | S22: 8 | T22: [CNP] 2; [FHM-K] 3; [FHM-M] 3 | U22: 5 | V22: [IJZ] 2; [IJZ-MB] 3
A23: JD022601 | B23: P060482 | C23: Jelly Donuts | D23: ○ 4 ON FILE, NOT RECORDED | E23: ✓ | F23: ✓ | G23: ✓ | H23: ✓ | I23: ✓ | J23: ✓ | K23: ✓ | L23: ✓ | M23: ○ | N23: ○ | O23: ○ | P23: ○ | Q23: 4 | R23: #9 Microbiology (on file 09.09, not recorded); #10 Mycotoxins (on file 09.09, not recorded); #11 Heavy metals (on file 09.09, not recorded); #12 Pesticides (on file 09.09, not recorded) | S23: 1 | T23: [CNP] 1 | U23: 2 | V23: [IJZ] 1; [IJZ-MB] 1
A24: JD112501 | B24: P060212 | C24: Jelly Donuts | D24: ✓ COMPLETE | E24: ✓ | F24: ✓ | G24: ✓ | H24: ✓ | I24: ✓ | J24: ✓ | K24: ✓ | L24: ✓ | M24: ✓ | N24: ✓ | O24: ✓ | P24: ✓ | Q24: 0 | R24: — | S24: 6 | T24: [CNP] 1; [FHM-K] 1; [FHM-M] 1; [IJZ] 1; [IJZ-MB] 1; [PP] 1 | U24: 0 | V24: —
A25: KC102501 | B25: P060172 | C25: Kush Crasher | D25: ○ 3 ON FILE, NOT RECORDED | E25: ✓ | F25: ✓ | G25: ✓ | H25: ✓ | I25: ✓ | J25: ✓ | K25: ✓ | L25: ✓ | M25: ○ | N25: ✓ | O25: ○ | P25: ○ | Q25: 3 | R25: #9 Microbiology (on file 09.09, not recorded); #11 Heavy metals (on file 09.09, not recorded); #12 Pesticides (on file 09.09, not recorded) | S25: 5 | T25: [FHM-K] 3; [FHM-M] 1; [PP] 1 | U25: 2 | V25: [IJZ] 1; [IJZ-MB] 1
A26: OPM1024 | B26: — not assigned — | C26: Orange Punch Mimosa | D26: ❌ 4 MISSING | E26: ✓ | F26: ✓ | G26: ✓ | H26: ✓ | I26: ✓ | J26: ✓ | K26: ✓ | L26: ✗ | M26: ✗ | N26: ✓ | O26: ✗ | P26: ✗ | Q26: 4 | R26: #8 LoD; #9 Microbiology; #11 Heavy metals; #12 Pesticides | S26: 4 | T26: [FHM-K] 1; [FHM-M] 1; [PP] 2 | U26: 0 | V26: —
A27: OPM112501 | B27: P060222 | C27: Orange Punch Mimosa | D27: ⚠ 3 MISSING | E27: ✓ | F27: ✓ | G27: ✓ | H27: ✓ | I27: ✓ | J27: ✓ | K27: ✓ | L27: ✓ | M27: ✓ | N27: ✗ | O27: ○ | P27: ○ | Q27: 3 | R27: #10 Mycotoxins; #11 Heavy metals (on file 09.09, not recorded); #12 Pesticides (on file 09.09, not recorded) | S27: 4 | T27: [CNP] 1; [FHM-K] 1; [IJZ-MB] 1; [PP] 1 | U27: 1 | V27: [IJZ] 1
A28: OPM122501 | B28: P060242 | C28: Orange Punch Mimosa | D28: ✓ COMPLETE | E28: ✓ | F28: ✓ | G28: ✓ | H28: ✓ | I28: ✓ | J28: ✓ | K28: ✓ | L28: ✓ | M28: ✓ | N28: ✓ | O28: ✓ | P28: ✓ | Q28: 0 | R28: — | S28: 7 | T28: [FHM-K] 3; [FHM-M] 1; [IJZ] 1; [IJZ-MB] 1; [PP] 1 | U28: 0 | V28: —
A29: GG1024_02 | B29: P050012 | C29: Gorilla Glue | D29: ✓ COMPLETE | E29: ✓ | F29: ✓ | G29: ✓ | H29: ✓ | I29: ✓ | J29: ✓ | K29: ✓ | L29: ✓ | M29: ✓ | N29: ✓ | O29: ✓ | P29: ✓ | Q29: 0 | R29: — | S29: 6 | T29: [CNP] 1; [FHM-K] 1; [IJZ] 1; [IJZ-MB] 2; [PP] 1 | U29: 0 | V29: —
A30: GP0824_02 | B30: P050022 | C30: Grape Pie | D30: ✓ COMPLETE | E30: ✓ | F30: ✓ | G30: ✓ | H30: ✓ | I30: ✓ | J30: ✓ | K30: ✓ | L30: ✓ | M30: ✓ | N30: ✓ | O30: ✓ | P30: ✓ | Q30: 0 | R30: — | S30: 12 | T30: [CNP] 5; [FHM-K] 1; [FHM-M] 1; [IJZ] 2; [IJZ-MB] 2; [PP] 1 | U30: 0 | V30: —
A31: MB0824_04 | B31: P050032 | C31: Motor Breath | D31: ✓ COMPLETE | E31: ✓ | F31: ✓ | G31: ✓ | H31: ✓ | I31: ✓ | J31: ✓ | K31: ✓ | L31: ✓ | M31: ✓ | N31: ✓ | O31: ✓ | P31: ✓ | Q31: 0 | R31: — | S31: 6 | T31: [CNP] 1; [FHM-K] 1; [IJZ] 1; [IJZ-MB] 2; [PP] 1 | U31: 0 | V31: —
A32: OMP1024_01 | B32: P050042 | C32: Orange Punch Mimosa | D32: ✓ COMPLETE | E32: ✓ | F32: ✓ | G32: ✓ | H32: ✓ | I32: ✓ | J32: ✓ | K32: ✓ | L32: ✓ | M32: ✓ | N32: ✓ | O32: ✓ | P32: ✓ | Q32: 0 | R32: — | S32: 6 | T32: [CNP] 1; [FHM-K] 1; [FHM-M] 1; [IJZ] 1; [IJZ-MB] 1; [PP] 1 | U32: 0 | V32: —
A33: HPA1024_01 | B33: P050052 | C33: High Pro Amnesia | D33: ✓ COMPLETE | E33: ✓ | F33: ✓ | G33: ✓ | H33: ✓ | I33: ✓ | J33: ✓ | K33: ✓ | L33: ✓ | M33: ✓ | N33: ✓ | O33: ✓ | P33: ✓ | Q33: 0 | R33: — | S33: 6 | T33: [CNP] 1; [FHM-K] 1; [FHM-M] 1; [IJZ] 1; [IJZ-MB] 1; [PP] 1 | U33: 0 | V33: —
A34: OPM1024_02 | B34: P050062 | C34: Orange Punch Mimosa | D34: ✓ COMPLETE | E34: ✓ | F34: ✓ | G34: ✓ | H34: ✓ | I34: ✓ | J34: ✓ | K34: ✓ | L34: ✓ | M34: ✓ | N34: ✓ | O34: ✓ | P34: ✓ | Q34: 0 | R34: — | S34: 6 | T34: [CNP] 1; [FHM-K] 1; [FHM-M] 1; [IJZ] 1; [IJZ-MB] 1; [PP] 1 | U34: 0 | V34: —
... A66: GP092501 | B66: P060092 | C66: Grape Pie | D66: ✓ COMPLETE | E66: ✓ | F66: ✓ | G66: ✓ | H66: ✓ | I66: ✓ | J66: ✓ | K66: ✓ | L66: ✓ | M66: ✓ | N66: ✓ | O66: ✓ | P66: ✓ | Q66: 0 | R66: — | S66: 6 | T66: [CNP] 1; [FHM-K] 1; [FHM-M] 1; [IJZ] 1; [IJZ-MB] 1; [PP] 1 | U66: 0 | V66: —
A67: CC012601/1 | B67: P060332 | D67: ❌ 4 MISSING | E67: ✓ | F67: ✓ | G67: ✓ | H67: ✓ | I67: ✓ | J67: ✓ | K67: ✓ | L67: ✗ | M67: ○ | N67: ✓ | O67: ✗ | P67: ✗ | Q67: 4 | R67: #8 LoD; #9 Microbiology (on file 09.09, not recorded); #11 Heavy metals; #12 Pesticides | S67: 3 | T67: [FHM-K] 1; [FHM-M] 1; [PP] 1 | U67: 1 | V67: [IJZ-MB] 1
A68: FB012602* | B68: P060352 | C68: Fat Bastard | D68: ❌ 4 MISSING | E68: ✓ | F68: ✓ | G68: ✓ | H68: ✓ | I68: ✓ | J68: ✓ | K68: ✓ | L68: ✗ | M68: ○ | N68: ✓ | O68: ✗ | P68: ✗ | Q68: 4 | R68: #8 LoD; #9 Microbiology (on file 09.09, not recorded); #11 Heavy metals; #12 Pesticides | S68: 3 | T68: [FHM-K] 1; [FHM-M] 1; [PP] 1 | U68: 1 | V68: [IJZ-MB] 1
A69: SCR012603 | B69: P060382 | C69: Scrambler | D69: ❌ 4 MISSING | E69: ✓ | F69: ✓ | G69: ✓ | H69: ✓ | I69: ✓ | J69: ✓ | K69: ✓ | L69: ✗ | M69: ○ | N69: ✓ | O69: ✗ | P69: ✗ | Q69: 4 | R69: #8 LoD; #9 Microbiology (on file 09.09, not recorded); #11 Heavy metals; #12 Pesticides | S69: 3 | T69: [FHM-K] 1; [FHM-M] 1; [PP] 1 | U69: 1 | V69: [IJZ-MB] 1
A70: — not recorded — (P160012) | B70: P160012 | D70: ○ 4 ON FILE, NOT RECORDED | E70: ✓ | F70: ✓ | G70: ✓ | H70: ✓ | I70: ✓ | J70: ✓ | K70: ✓ | L70: ✓ | M70: ○ | N70: ○ | O70: ○ | P70: ○ | Q70: 4 | R70: #9 Microbiology (on file 09.09, not recorded); #10 Mycotoxins (on file 09.09, not recorded); #11 Heavy metals (on file 09.09, not recorded); #12 Pesticides (on file 09.09, not recorded) | S70: 1 | T70: [CNP] 1 | U70: 2 | V70: [IJZ] 1; [IJZ-MB] 1
A71: — not recorded — (P160022) | B71: P160022 | D71: ○ 4 ON FILE, NOT RECORDED | E71: ✓ | F71: ✓ | G71: ✓ | H71: ✓ | I71: ✓ | J71: ✓ | K71: ✓ | L71: ✓ | M71: ○ | N71: ○ | O71: ○ | P71: ○ | Q71: 4 | R71: #9 Microbiology (on file 09.09, not recorded); #10 Mycotoxins (on file 09.09, not recorded); #11 Heavy metals (on file 09.09, not recorded); #12 Pesticides (on file 09.09, not recorded) | S71: 1 | T71: [CNP] 1 | U71: 2 | V71: [IJZ] 1; [IJZ-MB] 1
A72: — not recorded — (P160032) | B72: P160032 | D72: ○ 4 ON FILE, NOT RECORDED | E72: ✓ | F72: ✓ | G72: ✓ | H72: ✓ | I72: ✓ | J72: ✓ | K72: ✓ | L72: ✓ | M72: ○ | N72: ○ | O72: ○ | P72: ○ | Q72: 4 | R72: #9 Microbiology (on file 09.09, not recorded); #10 Mycotoxins (on file 09.09, not recorded); #11 Heavy metals (on file 09.09, not recorded); #12 Pesticides (on file 09.09, not recorded) | S72: 1 | T72: [CNP] 1 | U72: 2 | V72: [IJZ] 1; [IJZ-MB] 1
...

Sheet CoQ Parameter Tracker v52
A1: BATCH IDENTIFICATION | D1: THIS BLOCK | G1: IDENTIFICATION 1–3 | P1: CANNABINOID ASSAY 4–6 | Y1: PHYSICAL 7–8 | AE1: MICROBIOLOGY 9 | AK1: CONTAMINANTS 10–12
A2: CU Batch | B2: P Batch | C2: STATUS | D2: Testing instance | E2: Round / campaign | F2: Certificate of analysis Certificate of quality | G2: #1 Identification A Appearance · Ph. Eur. mon. 3028 | J2: #2 Identification B Microscopy · Ph. Eur. 2.8.23 | M2: #3 Identification C HPLC · Ph. Eur. 2.2.29 | P2: #4 Assay — Total Δ⁹-THC* Ph. Eur. 2.2.29 (HPLC) | S2: #5 Assay — Total CBD Ph. Eur. 2.2.29 · CBD + CBDA×0.877 | V2: #6 Total CBN Ph. Eur. 2.2.29 · CBN + CBNA×0.876 | Y2: #7 Foreign Matter Ph. Eur. 2.8.2 / in-house | AB2: #8 Loss on Drying Ph. Eur. 2.2.32 · 40 °C, 24 h, 15–25 mbar | AE2: #9 Microbiological Purity Ph. Eur. 2.6.12 / 2.6.13 / 2.6.31 · cat. C | AK2: #10 Mycotoxins Ph. Eur. 2.8.18 / 2.8.22 (HPLC-FLD) | AO2: #11 Heavy Metals Ph. Eur. 2.4.27 (ICP-MS) | AT2: #12 Pesticide Residues Ph. Eur. 2.8.13 (LC-MS/MS) · CUMCS equivalency
G3: A.C.: Conforms to Ph. Eur. monograph 3028 (Cannabis flos) | J3: A.C.: Conforms to Ph. Eur. monograph 3028 (Cannabis flos) | M3: A.C.: Conforms to Ph. Eur. monograph 3028 (Cannabis flos) | P3: A.C.: Per target grade (CoQ §01) | S3: A.C.: ≤ 1.0 % w/w | V3: A.C.: ≤ 1.0 % w/w | Y3: A.C.: ≤ 2.0 % (25–50 g); leaves < 1 cm; no seeds | AB3: A.C.: ≤ 12.0 % | AE3: A.C.: ≤ 10⁵ CFU/g | AF3: A.C.: ≤ 10⁴ CFU/g | AG3: A.C.: ≤ 10⁴ CFU/g | AH3: A.C.: Absence / 25 g | AI3: A.C.: Absence / 1 g | AK3: A.C.: ≤ 2 µg/kg | AL3: A.C.: ≤ 4 µg/kg | AM3: A.C.: ≤ 20 µg/kg | AO3: A.C.: ≤ 0.5 mg/kg | AP3: A.C.: ≤ 0.3 mg/kg | AQ3: A.C.: ≤ 0.2 mg/kg | AR3: A.C.: ≤ 0.1 mg/kg | AT3: A.C.: ≤ LOQ (Ph. Eur. 2.8.13 / CUMCS equivalency)
G4: Result | H4: [eCOA code],[date],[Lab] | I4: ✓ ✗ | J4: Result | K4: [eCOA code],[date],[Lab] | L4: ✓ ✗ | M4: Result | N4: [eCOA code],[date],[Lab] | O4: ✓ ✗ | P4: Result | Q4: [eCOA code],[date],[Lab] | R4: ✓ ✗ | S4: Result | T4: [eCOA code],[date],[Lab] | U4: ✓ ✗ | V4: Result | W4: [eCOA code],[date],[Lab] | X4: ✓ ✗ | Y4: Result | Z4: [eCOA code],[date],[Lab] | AA4: ✓ ✗ | AB4: Result | AC4: [eCOA code],[date],[Lab] | AD4: ✓ ✗ | AE4: TAMC | AF4: TYMC | AG4: GNB | AH4: Salm. | AI4: E. coli | AJ4: ✓ ✗ | AK4: AfB₁ | AL4: ΣAf | AM4: OTA | AN4: ✓ ✗ | AO4: Pb | AP4: Cd | AQ4: As | AR4: Hg | AS4: ✓ ✗ | AT4: Result | AU4: [eCOA code],[date],[Lab] | AV4: ✓ ✗
A5: BG1024 | B5: N/A — no P batch assigned | C5: ✓ COMPLETE 2 testing instances • 2 document(s) on file, not credited | D5: 1 of 2 | E5: release testing | F5: iCoA-PP_26-003 CoQ-PP_26-003 · initial release | G5: Conforms | H5: =IFERROR(INDEX('iCoA Register'!$B:$B,MATCH("BG1024|I",'iCoA Register'!$AA:$AA,0)),"iCoA — at issue")&", (07.03.2025) [PP]" | I5: ✓ | J5: not on this certificate | K5: ППК25050, (26.02.2025) [CNP] · on file, not credited | L5: • | M5: Conforms (ImB spec.) | N5: ППК25050, (26.02.2025) [CNP] | O5: ✓ | P5: 21.80 | Q5: ППК25050, (26.02.2025) [CNP] | R5: ✓ | S5: 0.04 | T5: ППК25050, (26.02.2025) [CNP] | U5: ✓ | V5: 0.02 ᴰ | W5: ППК25050, (26.02.2025) [CNP] | X5: ✓ | Y5: Conforms | Z5: =IFERROR(INDEX('iCoA Register'!$B:$B,MATCH("BG1024|I",'iCoA Register'!$AA:$AA,0)),"iCoA — at issue")&", (07.03.2025) [PP]" | AA5: ✓ | AB5: 5.73 | AC5: ППК25050, (26.02.2025) [CNP] | AD5: ✓ | AE5: 1.6 × 10⁴ | AF5: 1 × 10⁴ | AG5: < 10² and > 10 | AH5: Absent | AI5: Absent | AJ5: ✓ | AK5: not reported | AL5: < 2 | AM5: not reported | AN5: ✓ | AO5: 0.01 | AP5: 0.016 | AQ5: 0.014 | AR5: 0.005 | AS5: ✓ | AT5: ≤ LOQ (all 29 compounds) | AU5: 752-2025, (27.02.2025) [IJZ] | AV5: ✓
AE6: 163-0271-25, (24.02.2025) [IJZ-MB] | AK6: 752-2025, (27.02.2025) [IJZ] | AO6: 752-2025, (27.02.2025) [IJZ]
D7: 2 of 2 | E7: release testing + re-analysis 197 | F7: iCoA-PP_26-003 CoQ-PP_26-003 · initial release iCoA-PP_26-088 CoQ-PP_26-085 · retest | J7: Conforms | K7: =IFERROR(INDEX('iCoA Register'!$B:$B,MATCH("BG1024|I",'iCoA Register'!$AA:$AA,0)),"iCoA — at issue")&", (07.03.2025) [PP]" | L7: ✓ | M7: Conforms (ImB spec.) ᴿ | N7: 197-1-К-26, (07.08.2026) [FHM-K] | O7: ✓ | P7: 26.14 | Q7: 197-1-К-26, (07.08.2026) [FHM-K] | R7: ✓ | S7: < LOQ | T7: 197-1-К-26, (07.08.2026) [FHM-K] | U7: ✓ | V7: 0.28 | W7: 197-1-К-26, (07.08.2026) [FHM-K] | X7: ✓ | AB7: not on this certificate | AC7: 197-1-К-26, (07.08.2026) [FHM-K] · on file, not credited | AD7: • | AK7: ND | AL7: ND | AM7: ND | AN7: ✓
AK8: 197-1-М-26, (10.08.2026) [FHM-M]
A9: BSS1024 | B9: N/A — no P batch assigned | C9: ✓ COMPLETE 2 testing instances • 2 document(s) on file, not credited | D9: 1 of 2 | E9: release testing | F9: iCoA-PP_26-002 CoQ-PP_26-002 · initial release | G9: Conforms | H9: =IFERROR(INDEX('iCoA Register'!$B:$B,MATCH("BSS1024|I",'iCoA Register'!$AA:$AA,0)),"iCoA — at issue")&", (04.03.2025) [PP]" | I9: ✓ | J9: not on this certificate | K9: ППК25051, (26.02.2025) [CNP] · on file, not credited | L9: • | M9: Conforms (ImB spec.) | N9: ППК25051, (26.02.2025) [CNP] | O9: ✓ | P9: 21.03 | Q9: ППК25051, (26.02.2025) [CNP] | R9: ✓ | S9: 0.04 | T9: ППК25051, (26.02.2025) [CNP] | U9: ✓ | V9: 0.02 ᴰ | W9: ППК25051, (26.02.2025) [CNP] | X9: ✓ | Y9: Conforms | Z9: =IFERROR(INDEX('iCoA Register'!$B:$B,MATCH("BSS1024|I",'iCoA Register'!$AA:$AA,0)),"iCoA — at issue")&", (04.03.2025) [PP]" | AA9: ✓ | AB9: 5.99 | AC9: ППК25051, (26.02.2025) [CNP] | AD9: ✓ | AE9: 1.5 × 10⁴ | AF9: 2.2 × 10³ | AG9: < 10² and > 10 | AH9: Absent | AI9: Absent | AJ9: ✓ | AK9: not reported | AL9: < 2 | AM9: not reported | AN9: ✓ | AO9: 0.071 | AP9: 0.014 | AQ9: 0.081 | AR9: 0.014 | AS9: ✓ | AT9: ≤ LOQ (all 29 compounds) | AU9: 751-2025, (27.02.2025) [IJZ] | AV9: ✓
AE10: 161-0269-25, (24.02.2025) [IJZ-MB] | AK10: 751-2025, (27.02.2025) [IJZ] | AO10: 751-2025, (27.02.2025) [IJZ]
D11: 2 of 2 | E11: release testing + re-analysis 197 | F11: iCoA-PP_26-002 CoQ-PP_26-002 · initial release iCoA-PP_26-089 CoQ-PP_26-086 · retest | J11: Conforms | K11: =IFERROR(INDEX('iCoA Register'!$B:$B,MATCH("BSS1024|I",'iCoA Register'!$AA:$AA,0)),"iCoA — at issue")&", (04.03.2025) [PP]" | L11: ✓ | M11: Conforms (ImB spec.) | N11: 197-2-К-26, (07.08.2026) [FHM-K] | O11: ✓ | P11: 25.01 | Q11: 197-2-К-26, (07.08.2026) [FHM-K] | R11: ✓ | S11: < LOQ | T11: 197-2-К-26, (07.08.2026) [FHM-K] | U11: ✓ | V11: < LOQ | W11: 197-2-К-26, (07.08.2026) [FHM-K] | X11: ✓ | AB11: not on this certificate | AC11: 197-2-К-26, (07.08.2026) [FHM-K] · on file, not credited | AD11: • | AK11: ND | AL11: ND | AM11: ND | AN11: ✓
AK12: 197-2-М-26, (10.08.2026) [FHM-M]
A13: CC112501 | B13: P060272 | C13: ✓ COMPLETE 2 testing instances • 1 document(s) on file, not credited | D13: 1 of 2 | E13: release testing | F13: iCoA-PP_26-061 CoQ-PP_26-063 · initial release | G13: Conforms | H13: =IFERROR(INDEX('iCoA Register'!$B:$B,MATCH("P060272|I",'iCoA Register'!$AA:$AA,0)),"iCoA — at issue")&", (18.05.2026) [PP]" | I13: ✓ | J13: not on this certificate | K13: ППК26068, (11.05.2026) [CNP] · on file, not credited | L13: • | M13: Conforms (ImB spec.) | N13: ППК26068, (11.05.2026) [CNP] | O13: ✓ | P13: 13.35 | Q13: ППК26068, (11.05.2026) [CNP] | R13: ✓ | S13: 0.04 | T13: ППК26068, (11.05.2026) [CNP] | U13: ✓ | V13: < LOQ ᴰ | W13: ППК26068, (11.05.2026) [CNP] | X13: ✓ | Y13: Conforms | Z13: =IFERROR(INDEX('iCoA Register'!$B:$B,MATCH("P060272|I",'iCoA Register'!$AA:$AA,0)),"iCoA — at issue")&", (18.05.2026) [PP]" | AA13: ✓ | AB13: 7.39 | AC13: ППК26068, (11.05.2026) [CNP] | AD13: ✓ | AE13: 3.8 × 10³ | AF13: 2.7 × 10³ | AG13: < 10³ and > 10² | AH13: Absent | AI13: Absent | AJ13: ✓ | AK13: not reported | AL13: < 2 | AM13: not reported | AN13: ✓ | AO13: 0.0289 | AP13: 0.0119 | AQ13: 0.016 | AR13: 0.0102 | AS13: ✓ | AT13: ≤ LOQ (all 29 compounds) | AU13: 2359-2026, (29.04.2026) [IJZ] | AV13: ✓
AE14: 311-0555-26, (28.04.2026) [IJZ-MB] | AK14: 2359-2026, (29.04.2026) [IJZ] | AO14: 2359-2026, (29.04.2026) [IJZ]
D15: 2 of 2 | E15: release testing + re-analysis 227 + re-test campaign (IJZ-MB) | F15: iCoA-PP_26-061 CoQ-PP_26-063 · initial release iCoA-PP_26-165 CoQ-PP_26-139 · retest | J15: Conforms | K15: =IFERROR(INDEX('iCoA Register'!$B:$B,MATCH("P060272|I",'iCoA Register'!$AA:$AA,0)),"iCoA — at issue")&", (18.05.2026) [PP]" | L15: ✓ | M15: Conforms (ImB spec.) | N15: 227-25-К-26, (11.09.2026) [FHM-K] | O15: ✓ | P15: 16.36 | Q15: 227-25-К-26, (11.09.2026) [FHM-K] | R15: ✓ | S15: < LOQ | T15: 227-25-К-26, (11.09.2026) [FHM-K] | U15: ✓ | V15: < LOQ | W15: 227-25-К-26, (11.09.2026) [FHM-K] | X15: ✓ | AE15: 1.6 × 10³ | AF15: 1 × 10³ | AG15: < 10³ and > 10² | AH15: Absent | AI15: Absent | AJ15: ✓
AE16: 543-1074-26, (31.08.2026) [IJZ-MB]
A17: CJ1024 | B17: N/A — no P batch assigned | C17: ✓ COMPLETE 2 testing instances • 1 document(s) on file, not credited | D17: 1 of 2 | E17: release testing | F17: iCoA-PP_26-001 CoQ-PP_26-001 · initial release | G17: Conforms | H17: =IFERROR(INDEX('iCoA Register'!$B:$B,MATCH("CJ1024|I",'iCoA Register'!$AA:$AA,0)),"iCoA — at issue")&", (03.03.2025) [PP]" | I17: ✓ | J17: not on this certificate | K17: ППК25052, (26.02.2025) [CNP] · on file, not credited | L17: • | M17: Conforms (ImB spec.) | N17: ППК25052, (26.02.2025) [CNP] | O17: ✓ | P17: 23.00 | Q17: ППК25052, (26.02.2025) [CNP] | R17: ✓ | S17: 0.05 | T17: ППК25052, (26.02.2025) [CNP] | U17: ✓ | V17: 0.02 ᴰ | W17: ППК25052, (26.02.2025) [CNP] | X17: ✓ | Y17: Conforms | Z17: =IFERROR(INDEX('iCoA Register'!$B:$B,MATCH("CJ1024|I",'iCoA Register'!$AA:$AA,0)),"iCoA — at issue")&", (03.03.2025) [PP]" | AA17: ✓ | AB17: 5.91 | AC17: ППК25052, (26.02.2025) [CNP] | AD17: ✓ | AE17: 8.4 × 10³ | AF17: < 10 | AG17: < 10 | AH17: Absent | AI17: Absent | AJ17: ✓ | AK17: not reported | AL17: < 2 | AM17: not reported | AN17: ✓ | AO17: 0.036 | AP17: 0.013 | AQ17: 0.063 | AR17: 0.006 | AS17: ✓ | AT17: ≤ LOQ (all 29 compounds) | AU17: 750-2025, (27.02.2025) [IJZ] | AV17: ✓
AE18: 164-0272-25, (24.02.2025) [IJZ-MB] | AK18: 750-2025, (27.02.2025) [IJZ] | AO18: 750-2025, (27.02.2025) [IJZ]
D19: 2 of 2 | E19: release testing + re-analysis 227 + re-test campaign (IJZ-MB) | F19: iCoA-PP_26-001 CoQ-PP_26-001 · initial release iCoA-PP_26-168 CoQ-PP_26-142 · retest | J19: Conforms | K19: =IFERROR(INDEX('iCoA Register'!$B:$B,MATCH("CJ1024|I",'iCoA Register'!$AA:$AA,0)),"iCoA — at issue")&", (03.03.2025) [PP]" | L19: ✓ | M19: Conforms (ImB spec.) | N19: 227-26-К-26, (11.09.2026) [FHM-K] | O19: ✓ | P19: 28.12 | Q19: 227-26-К-26, (11.09.2026) [FHM-K] | R19: ✓ | S19: < LOQ | T19: 227-26-К-26, (11.09.2026) [FHM-K] | U19: ✓ | V19: 0.20 | W19: 227-26-К-26, (11.09.2026) [FHM-K] | X19: ✓ | AE19: < 10 | AF19: 10 | AG19: < 10 | AH19: Absent | AI19: Absent | AJ19: ✓
AE20: 565-1096-26, (01.09.2026) [IJZ-MB]
A21: FB012601_1 | B21: P060322 | C21: ✓ COMPLETE 2 testing instances • 1 document(s) on file, not credited | D21: 1 of 2 | E21: release testing | F21: iCoA-PP_26-066 CoQ-PP_26-069 · initial release | G21: Conforms | H21: =IFERROR(INDEX('iCoA Register'!$B:$B,MATCH("P060322|I",'iCoA Register'!$AA:$AA,0)),"iCoA — at issue")&", (22.05.2026) [PP]" | I21: ✓ | J21: not on this certificate | K21: ППК26067, (11.05.2026) [CNP] · on file, not credited | L21: • | M21: Conforms (ImB spec.) | N21: ППК26067, (11.05.2026) [CNP] | O21: ✓ | P21: 14.68 | Q21: ППК26067, (11.05.2026) [CNP] | R21: ✓ | S21: 0.04 | T21: ППК26067, (11.05.2026) [CNP] | U21: ✓ | V21: < LOQ ᴰ | W21: ППК26067, (11.05.2026) [CNP] | X21: ✓ | Y21: Conforms | Z21: =IFERROR(INDEX('iCoA Register'!$B:$B,MATCH("P060322|I",'iCoA Register'!$AA:$AA,0)),"iCoA — at issue")&", (22.05.2026) [PP]" | AA21: ✓ | AB21: 7.67 | AC21: ППК26067, (11.05.2026) [CNP] | AD21: ✓ | AE21: 2 × 10³ | AF21: 2.1 × 10³ | AG21: < 10 | AH21: Absent | AI21: Absent | AJ21: ✓ | AK21: not reported | AL21: < 2 | AM21: not reported | AN21: ✓ | AO21: 0.0114 | AP21: 0.017 | AQ21: 0.0144 | AR21: 0.0155 | AS21: ✓ | AT21: ≤ LOQ (all 26 compounds) | AU21: 2362-2026, (30.04.2026) [IJZ] | AV21: ✓
AE22: 308-0552-26, (28.04.2026) [IJZ-MB] | AK22: 2362-2026, (30.04.2026) [IJZ] | AO22: 2362-2026, (30.04.2026) [IJZ]
D23: 2 of 2 | E23: release testing + re-analysis 220 | F23: iCoA-PP_26-066 CoQ-PP_26-069 · initial release iCoA-PP_26-118 CoQ-PP_26-114 · retest | J23: Conforms | K23: =IFERROR(INDEX('iCoA Register'!$B:$B,MATCH("P060322|I",'iCoA Register'!$AA:$AA,0)),"iCoA — at issue")&", (22.05.2026) [PP]" | L23: ✓ | M23: Conforms (ImB spec.) | N23: 220-8-К-26, (25.08.2026) [FHM-K] | O23: ✓ | P23: 17.99 | Q23: 220-8-К-26, (25.08.2026) [FHM-K] | R23: ✓ | S23: < LOQ | T23: 220-8-К-26, (25.08.2026) [FHM-K] | U23: ✓ | V23: < LOQ | W23: 220-8-К-26, (25.08.2026) [FHM-K] | X23: ✓ | AK23: ND | AL23: ND | AM23: ND | AN23: ✓
AK24: 220-8-М-26, (11.09.2026) [FHM-M]
A25: FB012603 | B25: P060432 | C25: ⚠ 3 NO RESULT (3 no cert / 0 cert w/o result) 2 testing instances | D25: 1 of 2 | E25: release testing + re-test campaign (IJZ-MB) | F25: iCoA-PP_26-081 CoQ-PP_26-079 · initial release iCoA-PP_26-169 CoQ-PP_26-143 · retest | G25: Conforms | H25: ППК26112, (30.06.2026) [CNP] | I25: ✓ | J25: Conforms | K25: ППК26112, (30.06.2026) [CNP] | L25: ✓ | M25: Conforms (ImB spec.) | N25: ППК26112, (30.06.2026) [CNP] | O25: ✓ | P25: 20.83 | Q25: ППК26112, (30.06.2026) [CNP] | R25: ✓ | S25: 0.21 | T25: ППК26112, (30.06.2026) [CNP] | U25: ✓ | V25: 0.06 | W25: ППК26112, (30.06.2026) [CNP] | X25: ✓ | Y25: Conforms (no value printed) | Z25: ППК26112, (30.06.2026) [CNP] | AA25: ✓ | AB25: 7.04 | AC25: ППК26112, (30.06.2026) [CNP] | AD25: ✓ | AE25: 9.8 × 10³ | AF25: 2.5 × 10³ | AG25: < 10² and > 10 | AH25: Absent | AI25: Absent | AJ25: ✓ | AK25: — MISSING — | AL25: — MISSING — | AM25: — MISSING — | AN25: ✗ | AO25: — MISSING — | AP25: — MISSING — | AQ25: — MISSING — | AR25: — MISSING — | AS25: ✗ | AT25: — MISSING — | AU25: — no certificate — | AV25: ✗
AE26: 537-1068-26, (31.08.2026) [IJZ-MB] | AK26: — no certificate — | AO26: — no certificate —
D27: 2 of 2 | E27: re-analysis 227 | F27: iCoA-PP_26-169 CoQ-PP_26-143 · retest | M27: Conforms (ImB spec.) | N27: 227-24-К-26, (11.09.2026) [FHM-K] | O27: ✓ | P27: 20.00 | Q27: 227-24-К-26, (11.09.2026) [FHM-K] | R27: ✓ | S27: 0.21 | T27: 227-24-К-26, (11.09.2026) [FHM-K] | U27: ✓ | V27: < LOQ | W27: 227-24-К-26, (11.09.2026) [FHM-K] | X27: ✓
A29: FB012603V | B29: P060392 | C29: ⚠ 3 NO RESULT (3 no cert / 0 cert w/o result) 2 testing instances | D29: 1 of 2 | E29: release testing + re-test campaign (IJZ-MB) | F29: iCoA-PP_26-068 CoQ-PP_26-075 · initial release iCoA-PP_26-170 CoQ-PP_26-144 · retest | G29: Conforms | H29: ППК26110, (30.06.2026) [CNP] | I29: ✓ | J29: Conforms | K29: ППК26110, (30.06.2026) [CNP] | L29: ✓ | M29: Conforms (ImB spec.) | N29: ППК26110, (30.06.2026) [CNP] | O29: ✓ | P29: 18.29 | Q29: ППК26110, (30.06.2026) [CNP] | R29: ✓ | S29: 0.16 | T29: ППК26110, (30.06.2026) [CNP] | U29: ✓ | V29: 0.06 | W29: ППК26110, (30.06.2026) [CNP] | X29: ✓ | Y29: Conforms (no value printed) | Z29: ППК26110, (30.06.2026) [CNP] | AA29: ✓ | AB29: 6.36 | AC29: ППК26110, (30.06.2026) [CNP] | AD29: ✓ | AE29: 2.9 × 10³ | AF29: 2.5 × 10³ | AG29: < 10 | AH29: Absent | AI29: Absent | AJ29: ✓ | AK29: — MISSING — | AL29: — MISSING — | AM29: — MISSING — | AN29: ✗ | AO29: — MISSING — | AP29: — MISSING — | AQ29: — MISSING — | AR29: — MISSING — | AS29: ✗ | AT29: — MISSING — | AU29: — no certificate — | AV29: ✗
AE30: 538-1069-26, (31.08.2026) [IJZ-MB] | AK30: — no certificate — | AO30: — no certificate —
D31: 2 of 2 | E31: re-analysis 227 | F31: iCoA-PP_26-170 CoQ-PP_26-144 · retest | M31: Conforms (ImB spec.) | N31: 227-23-К-26, (11.09.2026) [FHM-K] | O31: ✓ | P31: 19.31 | Q31: 227-23-К-26, (11.09.2026) [FHM-K] | R31: ✓ | S31: < LOQ | T31: 227-23-К-26, (11.09.2026) [FHM-K] | U31: ✓ | V31: < LOQ | W31: 227-23-К-26, (11.09.2026) [FHM-K] | X31: ✓
A33: FB032601 | B33: P060452 | C33: ✗ 4 NO RESULT (4 no cert / 0 cert w/o result) ✗ OUT OF SPECIFICATION: #7 | D33: 1 of 1 | E33: release testing | F33: iCoA-PP_26-083 CoQ-PP_26-081 · initial release | G33: Conforms | H33: ППК26127, (21.07.2026) [CNP] | I33: ✓ | J33: Conforms | K33: ППК26127, (21.07.2026) [CNP] | L33: ✓ | M33: Conforms (ImB spec.) | N33: ППК26127, (21.07.2026) [CNP] | O33: ✓ | P33: 12.39 | Q33: ППК26127, (21.07.2026) [CNP] | R33: ✓ | S33: 0.06 | T33: ППК26127, (21.07.2026) [CNP] | U33: ✓ | V33: 0.04 | W33: ППК26127, (21.07.2026) [CNP] | X33: ✓ | Y33: 0.08 % (Does not conform) | Z33: ППК26127, (21.07.2026) [CNP] | AA33: ✓ | AB33: 7.77 | AC33: ППК26127, (21.07.2026) [CNP] | AD33: ✓ | AE33: — MISSING — | AF33: — MISSING — | AG33: — MISSING — | AH33: — MISSING — | AI33: — MISSING — | AJ33: ✗ | AK33: — MISSING — | AL33: — MISSING — | AM33: — MISSING — | AN33: ✗ | AO33: — MISSING — | AP33: — MISSING — | AQ33: — MISSING — | AR33: — MISSING — | AS33: ✗ | AT33: — MISSING — | AU33: — no certificate — | AV33: ✗
AE34: — no certificate — | AK34: — no certificate — | AO34: — no certificate —
A35: FB112501 | B35: P060292 | C35: ✓ COMPLETE 2 testing instances • 1 document(s) on file, not credited | D35: 1 of 2 | E35: release testing | F35: iCoA-PP_26-063 CoQ-PP_26-065 · initial release | G35: Conforms | H35: =IFERROR(INDEX('iCoA Register'!$B:$B,MATCH("P060292|I",'iCoA Register'!$AA:$AA,0)),"iCoA — at issue")&", (19.05.2026) [PP]" | I35: ✓ | J35: not on this certificate | K35: ППК26066, (11.05.2026) [CNP] · on file, not credited | L35: • | M35: Conforms (ImB spec.) | N35: ППК26066, (11.05.2026) [CNP] | O35: ✓ | P35: 16.69 | Q35: ППК26066, (11.05.2026) [CNP] | R35: ✓ | S35: 0.05 | T35: ППК26066, (11.05.2026) [CNP] | U35: ✓ | V35: < LOQ ᴰ | W35: ППК26066, (11.05.2026) [CNP] | X35: ✓ | Y35: Conforms | Z35: =IFERROR(INDEX('iCoA Register'!$B:$B,MATCH("P060292|I",'iCoA Register'!$AA:$AA,0)),"iCoA — at issue")&", (19.05.2026) [PP]" | AA35: ✓ | AB35: 6.09 | AC35: ППК26066, (11.05.2026) [CNP] | AD35: ✓ | AE35: 3.9 × 10³ | AF35: 2.4 × 10³ | AG35: < 10 | AH35: Absent | AI35: Absent | AJ35: ✓ | AK35: not reported | AL35: < 2 | AM35: not reported | AN35: ✓ | AO35: 0.0215 | AP35: 0.0108 | AQ35: 0.0199 | AR35: 0.0078 | AS35: ✓ | AT35: ≤ LOQ (all 29 compounds) | AU35: 2357-2026, (29.04.2026) [IJZ] | AV35: ✓
AE36: 312-0556-26, (28.04.2026) [IJZ-MB] | AK36: 2357-2026, (29.04.2026) [IJZ] | AO36: 2357-2026, (29.04.2026) [IJZ]
D37: 2 of 2 | E37: release testing + re-analysis 227 + re-test campaign (IJZ-MB) | F37: iCoA-PP_26-063 CoQ-PP_26-065 · initial release iCoA-PP_26-171 CoQ-PP_26-145 · retest | J37: Conforms | K37: =IFERROR(INDEX('iCoA Register'!$B:$B,MATCH("P060292|I",'iCoA Register'!$AA:$AA,0)),"iCoA — at issue")&", (19.05.2026) [PP]" | L37: ✓ | M37: Conforms (ImB spec.) | N37: 227-22-К-26, (11.09.2026) [FHM-K] | O37: ✓ | P37: 18.75 | Q37: 227-22-К-26, (11.09.2026) [FHM-K] | R37: ✓ | S37: < LOQ | T37: 227-22-К-26, (11.09.2026) [FHM-K] | U37: ✓ | V37: < LOQ | W37: 227-22-К-26, (11.09.2026) [FHM-K] | X37: ✓ | AE37: 3 × 10³ | AF37: 5.2 × 10² | AG37: < 10² and > 10 | AH37: Absent | AI37: Absent | AJ37: ✓
AE38: 542-1073-26, (31.08.2026) [IJZ-MB]
A39: GG012601＊ | B39: P060302 | C39: ✓ COMPLETE 2 testing instances • 1 document(s) on file, not credited | D39: 1 of 2 | E39: release testing | F39: no certificate of quality cites this block | G39: Conforms | H39: =IFERROR(INDEX('iCoA Register'!$B:$B,MATCH("P060302|I",'iCoA Register'!$AA:$AA,0)),"iCoA — at issue")&", (20.05.2026) [PP]" | I39: ✓ | J39: not on this certificate | K39: ППК26062, (11.05.2026) [CNP] · on file, not credited | L39: • | M39: Conforms (ImB spec.) | N39: ППК26062, (11.05.2026) [CNP] | O39: ✓ | P39: 15.35 | Q39: ППК26062, (11.05.2026) [CNP] | R39: ✓ | S39: 0.06 | T39: ППК26062, (11.05.2026) [CNP] | U39: ✓ | V39: < LOQ ᴰ | W39: ППК26062, (11.05.2026) [CNP] | X39: ✓ | Y39: Conforms | Z39: =IFERROR(INDEX('iCoA Register'!$B:$B,MATCH("P060302|I",'iCoA Register'!$AA:$AA,0)),"iCoA — at issue")&", (20.05.2026) [PP]" | AA39: ✓ | AB39: 6.13 | AC39: ППК26062, (11.05.2026) [CNP] | AD39: ✓ | AE39: 1 × 10⁴ | AF39: 1 × 10⁴ | AG39: < 10 | AH39: Absent | AI39: Absent | AJ39: ✓ | AK39: not reported | AL39: < 2 | AM39: not reported | AN39: ✓ | AO39: 0.0227 | AP39: 0.0179 | AQ39: 0.0163 | AR39: 0.031 | AS39: ✓ | AT39: ≤ LOQ (all 29 compounds) | AU39: 2364-2026, (30.04.2026) [IJZ] | AV39: ✓
AE40: 310-0554-26, (28.04.2026) [IJZ-MB] | AK40: 2364-2026, (30.04.2026) [IJZ] | AO40: 2364-2026, (30.04.2026) [IJZ]
D41: 2 of 2 | E41: release testing + re-analysis 227 + re-test campaign (IJZ-MB) | F41: no certificate of quality cites this block | J41: Conforms | K41: =IFERROR(INDEX('iCoA Register'!$B:$B,MATCH("P060302|I",'iCoA Register'!$AA:$AA,0)),"iCoA — at issue")&", (20.05.2026) [PP]" | L41: ✓ | M41: Conforms (ImB spec.) | N41: 227-21-К-26, (11.09.2026) [FHM-K] | O41: ✓ | P41: 19.16 | Q41: 227-21-К-26, (11.09.2026) [FHM-K] | R41: ✓ | S41: < LOQ | T41: 227-21-К-26, (11.09.2026) [FHM-K] | U41: ✓ | V41: < LOQ | W41: 227-21-К-26, (11.09.2026) [FHM-K] | X41: ✓ | AE41: 2.2 × 10³ | AF41: 2.1 × 10³ | AG41: < 10 | AH41: Absent | AI41: Absent | AJ41: ✓
AE42: 541-1072-26, (31.08.2026) [IJZ-MB]
...

Sheet Batch Dates
A1: Seq | B1: Batch (as listed) | C1: P Batch | D1: Harvest from | E1: Harvest to | F1: Packaging from | G1: Packaging to | H1: iCoA basis (first day of packaging) | I1: Tracker lot | J1: Note
A2: 1 | B2: CJ1024 | D2: 45677 | E2: 45677 | F2: 45719 | G2: 45719 | H2: =F2 | I2: CJ1024 | J2: listed as 'CJ1024 - R&D'
A3: 2 | B3: GG1024 | D3: 45677 | E3: 45677 | F3: 45727 | G3: 45727 | H3: =F3 | I3: GG1024 | J3: listed as 'GG1024- R&D'
A4: 3 | B4: OPM1024 | D4: 45678 | E4: 45678 | F4: 45771 | G4: 45772 | H4: =F4 | I4: OPM1024 | J4: listed as 'OPM1024- R&D'
A5: 4 | B5: BG1024 | D5: 45678 | E5: 45678 | F5: 45723 | G5: 45723 | H5: =F5 | I5: BG1024 | J5: listed as 'BG1024- R&D'
A6: 5 | B6: BSS1024 | D6: 45679 | E6: 45679 | F6: 45720 | G6: 45720 | H6: =F6 | I6: BSS1024 | J6: listed as 'BSS1024- R&D'
A7: 6 | B7: HPA1024 | D7: 45679 | E7: 45679 | F7: 45758 | G7: 45758 | H7: =F7 | I7: HPA1024 | J7: listed as 'HPA1024- R&D'
A8: 7 | B8: GG1024_01 | C8: P050092 | D8: 45733 | E8: 45734 | F8: 45869 | G8: 45874 | H8: =F8 | I8: GG1024_01 | J8: packaging: year 2025 inferred (not printed)
A9: 8 | B9: GP0824_01 | C9: P050102 | D9: 45736 | E9: 45737 | F9: 45874 | G9: 45876 | H9: =F9 | I9: GP0824_01 | J9: packaging: year 2025 inferred (not printed)
A10: 9 | B10: OMP1024_01 | C10: P050042 | D10: 45742 | E10: 45743 | F10: 45828 | G10: 45828 | H10: =F10 | I10: OMP1024_01
A11: 10 | B11: MB0824_04 | C11: P050032 | D11: 45749 | E11: 45750 | F11: 45824 | G11: 45827 | H11: =F11 | I11: MB0824_04
A12: 11 | B12: GG1024_02 | C12: P050012 | D12: 45761 | E12: 45762 | F12: 45819 | G12: 45824 | H12: =F12 | I12: GG1024_02
A13: 12 | B13: GP0824_02 | C13: P050022 | D13: 45769 | E13: 45770 | F13: 45811 | G13: 45819 | H13: =F13 | I13: GP0824_02
A14: 13 | B14: HPA1024_01 | C14: P050052 | D14: 45804 | E14: 45805 | F14: 45835 | G14: 45842 | H14: =F14 | I14: HPA1024_01
A15: 14 | B15: OPM1024_02 | C15: P050062 | D15: 45806 | E15: 45807 | F15: 45842 | G15: 45848 | H15: =F15 | I15: OPM1024_02
A16: 15 | B16: BSS1024_01/1 | C16: P050122 | D16: 45812 | E16: 45813 | F16: 45901 | G16: 45909 | H16: =F16 | I16: BSS1024_01/1 | J16: packaging: year 2025 inferred (not printed)
A17: 16 | B17: BSS1024_01/2 | C17: P050142 | D17: — not given — | E17: — not given — | F17: 45930 | G17: 45930 | H17: =F17 | I17: BSS1024_01/2 | J17: harvest: no date given; packaging: year 2025 inferred (not printed)
A18: 17 | B18: GP0824_03 | C18: P050072 | D18: 45817 | E18: 45818 | F18: 45852 | G18: 45855 | H18: =F18 | I18: GP0824_03 | J18: packaging: year 2025 inferred (not printed)
A19: 18 | B19: OPM1024_03 | C19: P050082 | D19: 45839 | E19: 45840 | F19: 45860 | G19: 45868 | H19: =F19 | I19: OPM1024_03
A20: 19 | B20: MB0824_05 | C20: P050112 | D20: 45846 | E20: 45847 | F20: 45894 | G20: 45900 | H20: =F20 | I20: MB0824_05 | J20: packaging: year 2025 inferred (not printed)
A21: 20 | B21: OPM052501 | C21: P050132 | D21: 45880 | E21: 45882 | F21: 45909 | G21: 45915 | H21: =F21 | I21: OPM052501 | J21: packaging: year 2025 inferred (not printed)
A22: 21 | B22: GP052501 | C22: P050152 | D22: — not given — | E22: — not given — | F22: 45925 | G22: 45925 | H22: =F22 | I22: GP052501 | J22: harvest: no date given
A23: 22 | B23: CJ052501/01 | C23: P050162 | D23: 45889 | E23: 45889 | F23: 45930 | G23: 45931 | H23: =F23 | I23: CJ052501/01
A24: 23 | B24: CJ052501/02 | C24: P050172 | D24: 45889 | E24: 45889 | F24: 45931 | G24: 45932 | H24: =F24 | I24: CJ052501/02
A25: 24 | B25: HPA052501 | C25: P050182 | D25: 45890 | E25: 45892 | F25: 45933 | G25: 45939 | H25: =F25 | I25: HPA052501
A26: 25 | B26: BSS052501 | C26: P050192 | D26: 45901 | E26: 45903 | F26: 45940 | G26: 45951 | H26: =F26 | I26: BSS052501
A27: 26 | B27: GP062501 | C27: P050202 | D27: 45915 | E27: 45917 | F27: 45960 | G27: 45968 | H27: =F27 | I27: GP062501
A28: 27 | B28: SC062501 | C28: P050242 | D28: 45917 | E28: 45917 | F28: 45988 | G28: 45988 | H28: =F28 | I28: — not on the tracker —
A29: 28 | B29: GOG062501 | C29: P050232 | D29: 45917 | E29: 45917 | F29: 45988 | G29: 45988 | H29: =F29 | I29: — not on the tracker —
A30: 29 | B30: CJ062501/1 | C30: P050222 | D30: 45923 | E30: 45923 | F30: 45985 | G30: 45986 | H30: =F30 | I30: CJ062501/1
A31: 30 | B31: CJ062501/2 | C31: P050212 | D31: 45923 | E31: 45924 | F31: 45979 | G31: 45985 | H31: =F31 | I31: CJ062501/2
A32: 31 | B32: CJ072501 | C32: P050252 | D32: 45957 | E32: 45957 | F32: 45988 | G32: 45989 | H32: =F32 | I32: CJ072501
A33: 32 | B33: PM072501 | C33: P050272 | D33: 45957 | E33: 45957 | F33: 45993 | G33: 45994 | H33: =F33 | I33: PM072501
A34: 33 | B34: WC072501 | C34: P050262 | D34: 45957 | E34: 45958 | F34: 45992 | G34: 45992 | H34: =F34 | I34: WC072501
A35: 34 | B35: CLE072501 | C35: P050282 | D35: 45958 | E35: 45958 | F35: 45994 | G35: 45995 | H35: =F35 | I35: CLE072501
A36: 35 | B36: GP072501/1 | C36: P050292 | D36: 45972 | E36: 45974 | F36: 46006 | G36: 46012 | H36: =F36 | I36: GP072501/1 | J36: harvest: printed 11-13-11.2025, read as 11-13.11.2025
A37: 36 | B37: GP072501/2 | C37: P050302 | D37: 45974 | E37: 45974 | F37: 46013 | G37: 46013 | H37: =F37 | I37: GP072501/2
A38: 37 | B38: GP082501/1 | C38: P050312 | D38: 45980 | E38: 45981 | F38: 46014 | G38: 46017 | H38: =F38 | I38: GP082501/1
A39: 38 | B39: GP082501/2 | C39: P050322 | D39: 45981 | E39: 45981 | F39: 46017 | G39: 46017 | H39: =F39 | I39: GP082501/2
A40: 39 | B40: WC082501 | C40: P060012 | D40: 46000 | E40: 46000 | F40: 46035 | G40: 46036 | H40: =F40 | I40: WC082501
...

Sheet iCoA Register
A1: No. | B1: iCoA code | C1: Issuable | D1: Issue date (planned) | E1: Test date (packaging) | F1: Packaging complete | G1: Group | H1: Series | I1: CU Batch | J1: P Batch | K1: Strain | L1: iCoA scope | M1: CNP reference | N1: CoQ (register) | O1: Plan reference (31.08.2026) | P1: Basis date | Q1: Harvest | R1: Packaging | S1: CoQ issue (planned) | T1: #1 Ident. A | U1: #2 Ident. B | V1: #7 Foreign matter | W1: Ident C — covered by (eCoA) | X1: Retest assay #4–#6 (eCoA) | Y1: Retest mycotoxins #10 (eCoA) | Z1: Carried forward | AA1: Key | AB1: Status
A2: 1 | B2: iCoA-PP_26-001 | C2: yes | D2: =IF(A2="","",IF(ISNUMBER(E2),MAX(DATE(2026,6,3),E2),DATE(2026,6,3))) | E2: =IFERROR(INDEX('Batch Dates'!$F:$F,MATCH(J2,'Batch Dates'!$C:$C,0)),IFERROR(INDEX('Batch Dates'!$F:$F,MATCH(I2,'Batch Dates'!$B:$B,0)),"")) | F2: =IFERROR(INDEX('Batch Dates'!$G:$G,MATCH(J2,'Batch Dates'!$C:$C,0)),IFERROR(INDEX('Batch Dates'!$G:$G,MATCH(I2,'Batch Dates'!$B:$B,0)),"")) | G2: legacy | H2: initial release | I2: CJ1024 | J2: N/A — no P batch assigned | K2: Cap Junky | L2: Ident A + Ident B + Foreign matter | M2: — | N2: =IFERROR(INDEX('CoQ Register'!$B:$B,MATCH("CJ1024|I",'CoQ Register'!$S:$S,0)),"—") | O2: — | P2: 27.02.2025 | Q2: 20.01.2025 | R2: 03.03.2025 (the issuance plan's basis: 27.02.2025) | S2: =IFERROR(INDEX('CoQ Register'!$D:$D,MATCH("CJ1024|I",'CoQ Register'!$S:$S,0)),"") | T2: Conforms | U2: Conforms | V2: Conforms | W2: ППК25052, (26.02.2025) [CNP] | X2: — | Y2: — | Z2: — | AA2: CJ1024|I | AB2: registered — initial release, issued 03.06.2026
A3: 2 | B3: iCoA-PP_26-002 | C3: yes | D3: =IF(A3="","",IF(ISNUMBER(E3),MAX(DATE(2026,6,3),E3),DATE(2026,6,3))) | E3: =IFERROR(INDEX('Batch Dates'!$F:$F,MATCH(J3,'Batch Dates'!$C:$C,0)),IFERROR(INDEX('Batch Dates'!$F:$F,MATCH(I3,'Batch Dates'!$B:$B,0)),"")) | F3: =IFERROR(INDEX('Batch Dates'!$G:$G,MATCH(J3,'Batch Dates'!$C:$C,0)),IFERROR(INDEX('Batch Dates'!$G:$G,MATCH(I3,'Batch Dates'!$B:$B,0)),"")) | G3: legacy | H3: initial release | I3: BSS1024 | J3: N/A — no P batch assigned | K3: Blue Sunset Sherbet | L3: Ident A + Ident B + Foreign matter | M3: — | N3: =IFERROR(INDEX('CoQ Register'!$B:$B,MATCH("BSS1024|I",'CoQ Register'!$S:$S,0)),"—") | O3: iCoA-PP-2025-0001 | P3: 04.03.2025 | Q3: 22.01.2025 | R3: 04.03.2025 | S3: =IFERROR(INDEX('CoQ Register'!$D:$D,MATCH("BSS1024|I",'CoQ Register'!$S:$S,0)),"") | T3: Conforms | U3: Conforms | V3: Conforms | W3: ППК25051, (26.02.2025) [CNP] | X3: — | Y3: — | Z3: — | AA3: BSS1024|I | AB3: registered — initial release, issued 03.06.2026
A4: 3 | B4: iCoA-PP_26-003 | C4: yes | D4: =IF(A4="","",IF(ISNUMBER(E4),MAX(DATE(2026,6,3),E4),DATE(2026,6,3))) | E4: =IFERROR(INDEX('Batch Dates'!$F:$F,MATCH(J4,'Batch Dates'!$C:$C,0)),IFERROR(INDEX('Batch Dates'!$F:$F,MATCH(I4,'Batch Dates'!$B:$B,0)),"")) | F4: =IFERROR(INDEX('Batch Dates'!$G:$G,MATCH(J4,'Batch Dates'!$C:$C,0)),IFERROR(INDEX('Batch Dates'!$G:$G,MATCH(I4,'Batch Dates'!$B:$B,0)),"")) | G4: legacy | H4: initial release | I4: BG1024 | J4: N/A — no P batch assigned | K4: Blue Gelato | L4: Ident A + Ident B + Foreign matter | M4: — | N4: =IFERROR(INDEX('CoQ Register'!$B:$B,MATCH("BG1024|I",'CoQ Register'!$S:$S,0)),"—") | O4: iCoA-PP-2025-0002 | P4: 07.03.2025 | Q4: 21.01.2025 | R4: 07.03.2025 | S4: =IFERROR(INDEX('CoQ Register'!$D:$D,MATCH("BG1024|I",'CoQ Register'!$S:$S,0)),"") | T4: Conforms | U4: Conforms | V4: Conforms | W4: ППК25050, (26.02.2025) [CNP] | X4: — | Y4: — | Z4: — | AA4: BG1024|I | AB4: registered — initial release, issued 03.06.2026
A5: 4 | B5: iCoA-PP_26-004 | C5: yes | D5: =IF(A5="","",IF(ISNUMBER(E5),MAX(DATE(2026,6,3),E5),DATE(2026,6,3))) | E5: =IFERROR(INDEX('Batch Dates'!$F:$F,MATCH(J5,'Batch Dates'!$C:$C,0)),IFERROR(INDEX('Batch Dates'!$F:$F,MATCH(I5,'Batch Dates'!$B:$B,0)),"")) | F5: =IFERROR(INDEX('Batch Dates'!$G:$G,MATCH(J5,'Batch Dates'!$C:$C,0)),IFERROR(INDEX('Batch Dates'!$G:$G,MATCH(I5,'Batch Dates'!$B:$B,0)),"")) | G5: legacy | H5: initial release | I5: GG1024 | J5: N/A — no P batch assigned | K5: Gorilla Glue | L5: Ident A + Ident B + Foreign matter | M5: — | N5: =IFERROR(INDEX('CoQ Register'!$B:$B,MATCH("GG1024|I",'CoQ Register'!$S:$S,0)),"—") | O5: iCoA-PP-2025-0003 | P5: 11.03.2025 | Q5: 20.01.2025 | R5: 11.03.2025 | S5: =IFERROR(INDEX('CoQ Register'!$D:$D,MATCH("GG1024|I",'CoQ Register'!$S:$S,0)),"") | T5: Conforms | U5: Conforms | V5: Conforms | W5: — no cannabinoid certificate from the initial testing — | X5: — | Y5: — | Z5: — | AA5: GG1024|I | AB5: registered — initial release, issued 03.06.2026
A6: 5 | B6: iCoA-PP_26-005 | C6: yes | D6: =IF(A6="","",IF(ISNUMBER(E6),MAX(DATE(2026,6,3),E6),DATE(2026,6,3))) | E6: =IFERROR(INDEX('Batch Dates'!$F:$F,MATCH(J6,'Batch Dates'!$C:$C,0)),IFERROR(INDEX('Batch Dates'!$F:$F,MATCH(I6,'Batch Dates'!$B:$B,0)),"")) | F6: =IFERROR(INDEX('Batch Dates'!$G:$G,MATCH(J6,'Batch Dates'!$C:$C,0)),IFERROR(INDEX('Batch Dates'!$G:$G,MATCH(I6,'Batch Dates'!$B:$B,0)),"")) | G6: legacy | H6: initial release | I6: HPA1024 | J6: N/A — no P batch assigned | K6: High Pro Amnesia | L6: Ident A + Ident B + #4 + #5 + Foreign matter + #9.1 + #9.2 + #9.3 + #9.4 + #9.5 + #10.2 + #11.1 + #11.2 + #11.3 + #11.4 + #12 | M6: — | N6: =IFERROR(INDEX('CoQ Register'!$B:$B,MATCH("HPA1024|I",'CoQ Register'!$S:$S,0)),"—") | O6: iCoA-PP-2025-0004 | P6: 11.04.2025 | Q6: 22.01.2025 | R6: 11.04.2025 | S6: =IFERROR(INDEX('CoQ Register'!$D:$D,MATCH("HPA1024|I",'CoQ Register'!$S:$S,0)),"") | T6: Conforms | U6: Conforms | V6: Conforms | W6: — no cannabinoid certificate from the initial testing — | X6: — | Y6: — | Z6: — | AA6: HPA1024|I | AB6: registered — initial release, issued 03.06.2026
A7: 6 | B7: iCoA-PP_26-006 | C7: yes | D7: =IF(A7="","",IF(ISNUMBER(E7),MAX(DATE(2026,6,3),E7),DATE(2026,6,3))) | E7: =IFERROR(INDEX('Batch Dates'!$F:$F,MATCH(J7,'Batch Dates'!$C:$C,0)),IFERROR(INDEX('Batch Dates'!$F:$F,MATCH(I7,'Batch Dates'!$B:$B,0)),"")) | F7: =IFERROR(INDEX('Batch Dates'!$G:$G,MATCH(J7,'Batch Dates'!$C:$C,0)),IFERROR(INDEX('Batch Dates'!$G:$G,MATCH(I7,'Batch Dates'!$B:$B,0)),"")) | G7: legacy | H7: initial release | I7: OPM1024 | J7: N/A — no P batch assigned | K7: Orange Punch Mimosa | L7: Ident A + Ident B + #4 + #5 + Foreign matter + #9.1 + #9.2 + #9.3 + #9.4 + #9.5 + #10.2 + #11.1 + #11.2 + #11.3 + #11.4 + #12 | M7: — | N7: =IFERROR(INDEX('CoQ Register'!$B:$B,MATCH("OPM1024|I",'CoQ Register'!$S:$S,0)),"—") | O7: iCoA-PP-2025-0005 | P7: 24.04.2025 | Q7: 21.01.2025 | R7: 24.04.2025 – 25.04.2025 | S7: =IFERROR(INDEX('CoQ Register'!$D:$D,MATCH("OPM1024|I",'CoQ Register'!$S:$S,0)),"") | T7: Conforms | U7: Conforms | V7: Conforms | W7: — no cannabinoid certificate from the initial testing — | X7: — | Y7: — | Z7: — | AA7: OPM1024|I | AB7: registered — initial release, issued 03.06.2026
A8: 7 | B8: iCoA-PP_26-007 | C8: yes | D8: =IF(A8="","",IF(ISNUMBER(E8),MAX(DATE(2026,6,3),E8),DATE(2026,6,3))) | E8: =IFERROR(INDEX('Batch Dates'!$F:$F,MATCH(J8,'Batch Dates'!$C:$C,0)),IFERROR(INDEX('Batch Dates'!$F:$F,MATCH(I8,'Batch Dates'!$B:$B,0)),"")) | F8: =IFERROR(INDEX('Batch Dates'!$G:$G,MATCH(J8,'Batch Dates'!$C:$C,0)),IFERROR(INDEX('Batch Dates'!$G:$G,MATCH(I8,'Batch Dates'!$B:$B,0)),"")) | G8: legacy | H8: initial release | I8: GP0824_02 | J8: P050022 | K8: Grape Pie | L8: Ident A + Ident B + Foreign matter | M8: — | N8: =IFERROR(INDEX('CoQ Register'!$B:$B,MATCH("P050022|I",'CoQ Register'!$S:$S,0)),"—") | O8: iCoA-PP-2025-0006 | P8: 03.06.2025 | Q8: 22.04.2025 – 23.04.2025 | R8: 03.06.2025 – 11.06.2025 | S8: =IFERROR(INDEX('CoQ Register'!$D:$D,MATCH("P050022|I",'CoQ Register'!$S:$S,0)),"") | T8: Conforms | U8: Conforms | V8: Conforms | W8: ППК25139, (22.05.2025) [CNP] | X8: — | Y8: — | Z8: — | AA8: P050022|I | AB8: registered — initial release, issued 03.06.2026
A9: 8 | B9: iCoA-PP_26-008 | C9: yes | D9: =IF(A9="","",IF(ISNUMBER(E9),MAX(DATE(2026,6,3),E9),DATE(2026,6,3))) | E9: =IFERROR(INDEX('Batch Dates'!$F:$F,MATCH(J9,'Batch Dates'!$C:$C,0)),IFERROR(INDEX('Batch Dates'!$F:$F,MATCH(I9,'Batch Dates'!$B:$B,0)),"")) | F9: =IFERROR(INDEX('Batch Dates'!$G:$G,MATCH(J9,'Batch Dates'!$C:$C,0)),IFERROR(INDEX('Batch Dates'!$G:$G,MATCH(I9,'Batch Dates'!$B:$B,0)),"")) | G9: legacy | H9: initial release | I9: GG1024_02 | J9: P050012 | K9: Gorilla Glue | L9: Ident A + Ident B + Foreign matter | M9: — | N9: =IFERROR(INDEX('CoQ Register'!$B:$B,MATCH("P050012|I",'CoQ Register'!$S:$S,0)),"—") | O9: — | P9: 30.05.2025 | Q9: 14.04.2025 – 15.04.2025 | R9: 11.06.2025 – 16.06.2025 (the issuance plan's basis: 30.05.2025) | S9: =IFERROR(INDEX('CoQ Register'!$D:$D,MATCH("P050012|I",'CoQ Register'!$S:$S,0)),"") | T9: Conforms | U9: Conforms | V9: Conforms | W9: ППК25140, (22.05.2025) [CNP] | X9: — | Y9: — | Z9: — | AA9: P050012|I | AB9: registered — initial release, issued 03.06.2026
A10: 9 | B10: iCoA-PP_26-009 | C10: yes | D10: =IF(A10="","",IF(ISNUMBER(E10),MAX(DATE(2026,6,3),E10),DATE(2026,6,3))) | E10: =IFERROR(INDEX('Batch Dates'!$F:$F,MATCH(J10,'Batch Dates'!$C:$C,0)),IFERROR(INDEX('Batch Dates'!$F:$F,MATCH(I10,'Batch Dates'!$B:$B,0)),"")) | F10: =IFERROR(INDEX('Batch Dates'!$G:$G,MATCH(J10,'Batch Dates'!$C:$C,0)),IFERROR(INDEX('Batch Dates'!$G:$G,MATCH(I10,'Batch Dates'!$B:$B,0)),"")) | G10: legacy | H10: initial release | I10: MB0824_04 | J10: P050032 | K10: Motor Breath | L10: Ident A + Ident B + Foreign matter | M10: — | N10: =IFERROR(INDEX('CoQ Register'!$B:$B,MATCH("P050032|I",'CoQ Register'!$S:$S,0)),"—") | O10: — | P10: 07.05.2025 | Q10: 02.04.2025 – 03.04.2025 | R10: 16.06.2025 – 19.06.2025 (the issuance plan's basis: 07.05.2025) | S10: =IFERROR(INDEX('CoQ Register'!$D:$D,MATCH("P050032|I",'CoQ Register'!$S:$S,0)),"") | T10: Conforms | U10: Conforms | V10: Conforms | W10: ППК25118, (06.05.2025) [CNP] | X10: — | Y10: — | Z10: — | AA10: P050032|I | AB10: registered — initial release, issued 03.06.2026
A11: 10 | B11: iCoA-PP_26-010 | C11: yes | D11: =IF(A11="","",IF(ISNUMBER(E11),MAX(DATE(2026,6,3),E11),DATE(2026,6,3))) | E11: =IFERROR(INDEX('Batch Dates'!$F:$F,MATCH(J11,'Batch Dates'!$C:$C,0)),IFERROR(INDEX('Batch Dates'!$F:$F,MATCH(I11,'Batch Dates'!$B:$B,0)),"")) | F11: =IFERROR(INDEX('Batch Dates'!$G:$G,MATCH(J11,'Batch Dates'!$C:$C,0)),IFERROR(INDEX('Batch Dates'!$G:$G,MATCH(I11,'Batch Dates'!$B:$B,0)),"")) | G11: legacy | H11: initial release | I11: HPA1024_01 | J11: P050052 | K11: High Pro Amnesia | L11: Ident A + Ident B + Foreign matter | M11: — | N11: =IFERROR(INDEX('CoQ Register'!$B:$B,MATCH("P050052|I",'CoQ Register'!$S:$S,0)),"—") | O11: iCoA-PP-2025-0008 | P11: 27.06.2025 | Q11: 27.05.2025 – 28.05.2025 | R11: 27.06.2025 – 04.07.2025 | S11: =IFERROR(INDEX('CoQ Register'!$D:$D,MATCH("P050052|I",'CoQ Register'!$S:$S,0)),"") | T11: Conforms | U11: Conforms | V11: Conforms | W11: ППК25155, (24.06.2025) [CNP] | X11: — | Y11: — | Z11: — | AA11: P050052|I | AB11: registered — initial release, issued 03.06.2026
A12: 11 | B12: iCoA-PP_26-011 | C12: yes | D12: =IF(A12="","",IF(ISNUMBER(E12),MAX(DATE(2026,6,3),E12),DATE(2026,6,3))) | E12: =IFERROR(INDEX('Batch Dates'!$F:$F,MATCH(J12,'Batch Dates'!$C:$C,0)),IFERROR(INDEX('Batch Dates'!$F:$F,MATCH(I12,'Batch Dates'!$B:$B,0)),"")) | F12: =IFERROR(INDEX('Batch Dates'!$G:$G,MATCH(J12,'Batch Dates'!$C:$C,0)),IFERROR(INDEX('Batch Dates'!$G:$G,MATCH(I12,'Batch Dates'!$B:$B,0)),"")) | G12: legacy | H12: initial release | I12: OPM1024_02 | J12: P050062 | K12: Orange Punch Mimosa | L12: Ident A + Ident B + Foreign matter | M12: — | N12: =IFERROR(INDEX('CoQ Register'!$B:$B,MATCH("P050062|I",'CoQ Register'!$S:$S,0)),"—") | O12: iCoA-PP-2025-0009 | P12: 04.07.2025 | Q12: 29.05.2025 – 30.05.2025 | R12: 04.07.2025 – 10.07.2025 | S12: =IFERROR(INDEX('CoQ Register'!$D:$D,MATCH("P050062|I",'CoQ Register'!$S:$S,0)),"") | T12: Conforms | U12: Conforms | V12: Conforms | W12: ППК25154, (24.06.2025) [CNP] | X12: — | Y12: — | Z12: — | AA12: P050062|I | AB12: registered — initial release, issued 03.06.2026
A13: 12 | B13: iCoA-PP_26-012 | C13: yes | D13: =IF(A13="","",IF(ISNUMBER(E13),MAX(DATE(2026,6,3),E13),DATE(2026,6,3))) | E13: =IFERROR(INDEX('Batch Dates'!$F:$F,MATCH(J13,'Batch Dates'!$C:$C,0)),IFERROR(INDEX('Batch Dates'!$F:$F,MATCH(I13,'Batch Dates'!$B:$B,0)),"")) | F13: =IFERROR(INDEX('Batch Dates'!$G:$G,MATCH(J13,'Batch Dates'!$C:$C,0)),IFERROR(INDEX('Batch Dates'!$G:$G,MATCH(I13,'Batch Dates'!$B:$B,0)),"")) | G13: legacy | H13: initial release | I13: GP0824_03 | J13: P050072 | K13: Grape Pie | L13: Ident A + Ident B + Foreign matter | M13: — | N13: =IFERROR(INDEX('CoQ Register'!$B:$B,MATCH("P050072|I",'CoQ Register'!$S:$S,0)),"—") | O13: iCoA-PP-2025-0010 | P13: 14.07.2025 | Q13: 09.06.2025 – 10.06.2025 | R13: 14.07.2025 – 17.07.2025 | S13: =IFERROR(INDEX('CoQ Register'!$D:$D,MATCH("P050072|I",'CoQ Register'!$S:$S,0)),"") | T13: Conforms | U13: Conforms | V13: Conforms | W13: ППК25175, (10.07.2025) [CNP] | X13: — | Y13: — | Z13: — | AA13: P050072|I | AB13: registered — initial release, issued 03.06.2026
A14: 13 | B14: iCoA-PP_26-013 | C14: yes | D14: =IF(A14="","",IF(ISNUMBER(E14),MAX(DATE(2026,6,3),E14),DATE(2026,6,3))) | E14: =IFERROR(INDEX('Batch Dates'!$F:$F,MATCH(J14,'Batch Dates'!$C:$C,0)),IFERROR(INDEX('Batch Dates'!$F:$F,MATCH(I14,'Batch Dates'!$B:$B,0)),"")) | F14: =IFERROR(INDEX('Batch Dates'!$G:$G,MATCH(J14,'Batch Dates'!$C:$C,0)),IFERROR(INDEX('Batch Dates'!$G:$G,MATCH(I14,'Batch Dates'!$B:$B,0)),"")) | G14: legacy | H14: initial release | I14: OPM1024_03 | J14: P050082 | K14: Orange Punch Mimosa | L14: Ident A + Ident B + Foreign matter | M14: — | N14: =IFERROR(INDEX('CoQ Register'!$B:$B,MATCH("P050082|I",'CoQ Register'!$S:$S,0)),"—") | O14: iCoA-PP-2025-0011 | P14: 22.07.2025 | Q14: 01.07.2025 – 02.07.2025 | R14: 22.07.2025 – 30.07.2025 | S14: =IFERROR(INDEX('CoQ Register'!$D:$D,MATCH("P050082|I",'CoQ Register'!$S:$S,0)),"") | T14: Conforms | U14: Conforms | V14: Conforms | W14: ППК25210, (28.07.2025) [CNP] | X14: — | Y14: — | Z14: — | AA14: P050082|I | AB14: registered — initial release, issued 03.06.2026
A15: 14 | B15: iCoA-PP_26-014 | C15: yes | D15: =IF(A15="","",IF(ISNUMBER(E15),MAX(DATE(2026,6,3),E15),DATE(2026,6,3))) | E15: =IFERROR(INDEX('Batch Dates'!$F:$F,MATCH(J15,'Batch Dates'!$C:$C,0)),IFERROR(INDEX('Batch Dates'!$F:$F,MATCH(I15,'Batch Dates'!$B:$B,0)),"")) | F15: =IFERROR(INDEX('Batch Dates'!$G:$G,MATCH(J15,'Batch Dates'!$C:$C,0)),IFERROR(INDEX('Batch Dates'!$G:$G,MATCH(I15,'Batch Dates'!$B:$B,0)),"")) | G15: legacy | H15: initial release | I15: GG1024_01 | J15: P050092 | K15: Gorilla Glue | L15: Ident A + Ident B + Foreign matter | M15: — | N15: =IFERROR(INDEX('CoQ Register'!$B:$B,MATCH("P050092|I",'CoQ Register'!$S:$S,0)),"—") | O15: iCoA-PP-2025-0012 | P15: 31.07.2025 | Q15: 17.03.2025 – 18.03.2025 | R15: 31.07.2025 – 05.08.2025 | S15: =IFERROR(INDEX('CoQ Register'!$D:$D,MATCH("P050092|I",'CoQ Register'!$S:$S,0)),"") | T15: Conforms | U15: Conforms | V15: Conforms | W15: ППК25104, (17.04.2025) [CNP] | X15: — | Y15: — | Z15: — | AA15: P050092|I | AB15: registered — initial release, issued 03.06.2026
A16: 15 | B16: iCoA-PP_26-015 | C16: yes | D16: =IF(A16="","",IF(ISNUMBER(E16),MAX(DATE(2026,6,3),E16),DATE(2026,6,3))) | E16: =IFERROR(INDEX('Batch Dates'!$F:$F,MATCH(J16,'Batch Dates'!$C:$C,0)),IFERROR(INDEX('Batch Dates'!$F:$F,MATCH(I16,'Batch Dates'!$B:$B,0)),"")) | F16: =IFERROR(INDEX('Batch Dates'!$G:$G,MATCH(J16,'Batch Dates'!$C:$C,0)),IFERROR(INDEX('Batch Dates'!$G:$G,MATCH(I16,'Batch Dates'!$B:$B,0)),"")) | G16: legacy | H16: initial release | I16: GP0824_01 | J16: P050102 | K16: Grape Pie | L16: Ident A + Ident B + Foreign matter | M16: — | N16: =IFERROR(INDEX('CoQ Register'!$B:$B,MATCH("P050102|I",'CoQ Register'!$S:$S,0)),"—") | O16: — | P16: 17.04.2025 | Q16: 20.03.2025 – 21.03.2025 | R16: 05.08.2025 – 07.08.2025 (the issuance plan's basis: 17.04.2025) | S16: =IFERROR(INDEX('CoQ Register'!$D:$D,MATCH("P050102|I",'CoQ Register'!$S:$S,0)),"") | T16: Conforms | U16: Conforms | V16: Conforms | W16: ППК25105, (17.04.2025) [CNP] | X16: — | Y16: — | Z16: — | AA16: P050102|I | AB16: registered — initial release, issued 03.06.2026
A17: 16 | B17: iCoA-PP_26-016 | C17: yes | D17: =IF(A17="","",IF(ISNUMBER(E17),MAX(DATE(2026,6,3),E17),DATE(2026,6,3))) | E17: =IFERROR(INDEX('Batch Dates'!$F:$F,MATCH(J17,'Batch Dates'!$C:$C,0)),IFERROR(INDEX('Batch Dates'!$F:$F,MATCH(I17,'Batch Dates'!$B:$B,0)),"")) | F17: =IFERROR(INDEX('Batch Dates'!$G:$G,MATCH(J17,'Batch Dates'!$C:$C,0)),IFERROR(INDEX('Batch Dates'!$G:$G,MATCH(I17,'Batch Dates'!$B:$B,0)),"")) | G17: legacy | H17: initial release | I17: MB0824_05 | J17: P050112 | K17: Motor Breath | L17: Ident A + Ident B + Foreign matter | M17: — | N17: =IFERROR(INDEX('CoQ Register'!$B:$B,MATCH("P050112|I",'CoQ Register'!$S:$S,0)),"—") | O17: iCoA-PP-2025-0013 | P17: 25.08.2025 | Q17: 08.07.2025 – 09.07.2025 | R17: 25.08.2025 – 31.08.2025 | S17: =IFERROR(INDEX('CoQ Register'!$D:$D,MATCH("P050112|I",'CoQ Register'!$S:$S,0)),"") | T17: Conforms | U17: Conforms | V17: Conforms | W17: ППК25211, (28.07.2025) [CNP] | X17: — | Y17: — | Z17: — | AA17: P050112|I | AB17: registered — initial release, issued 03.06.2026
A18: 17 | B18: iCoA-PP_26-017 | C18: yes | D18: =IF(A18="","",IF(ISNUMBER(E18),MAX(DATE(2026,6,3),E18),DATE(2026,6,3))) | E18: =IFERROR(INDEX('Batch Dates'!$F:$F,MATCH(J18,'Batch Dates'!$C:$C,0)),IFERROR(INDEX('Batch Dates'!$F:$F,MATCH(I18,'Batch Dates'!$B:$B,0)),"")) | F18: =IFERROR(INDEX('Batch Dates'!$G:$G,MATCH(J18,'Batch Dates'!$C:$C,0)),IFERROR(INDEX('Batch Dates'!$G:$G,MATCH(I18,'Batch Dates'!$B:$B,0)),"")) | G18: legacy | H18: initial release | I18: OPM052501 | J18: P050132 | K18: Orange Punch Mimosa | L18: Ident A + Ident B + Foreign matter | M18: — | N18: =IFERROR(INDEX('CoQ Register'!$B:$B,MATCH("P050132|I",'CoQ Register'!$S:$S,0)),"—") | O18: — | P18: 05.09.2025 | Q18: 11.08.2025 – 13.08.2025 | R18: 09.09.2025 – 15.09.2025 (the issuance plan's basis: 05.09.2025) | S18: =IFERROR(INDEX('CoQ Register'!$D:$D,MATCH("P050132|I",'CoQ Register'!$S:$S,0)),"") | T18: Conforms | U18: Conforms | V18: Conforms | W18: ППК25257, (05.09.2025) [CNP] | X18: — | Y18: — | Z18: — | AA18: P050132|I | AB18: registered — initial release, issued 03.06.2026
A19: 18 | B19: iCoA-PP_26-018 | C19: yes | D19: =IF(A19="","",IF(ISNUMBER(E19),MAX(DATE(2026,6,3),E19),DATE(2026,6,3))) | E19: =IFERROR(INDEX('Batch Dates'!$F:$F,MATCH(J19,'Batch Dates'!$C:$C,0)),IFERROR(INDEX('Batch Dates'!$F:$F,MATCH(I19,'Batch Dates'!$B:$B,0)),"")) | F19: =IFERROR(INDEX('Batch Dates'!$G:$G,MATCH(J19,'Batch Dates'!$C:$C,0)),IFERROR(INDEX('Batch Dates'!$G:$G,MATCH(I19,'Batch Dates'!$B:$B,0)),"")) | G19: legacy | H19: initial release | I19: GP052501 | J19: P050152 | K19: Grape Pie | L19: Ident A + Ident B + Foreign matter | M19: — | N19: =IFERROR(INDEX('CoQ Register'!$B:$B,MATCH("P050152|I",'CoQ Register'!$S:$S,0)),"—") | O19: iCoA-PP-2025-0014 | P19: 25.09.2025 | Q19: — not given — | R19: 25.09.2025 | S19: =IFERROR(INDEX('CoQ Register'!$D:$D,MATCH("P050152|I",'CoQ Register'!$S:$S,0)),"") | T19: Conforms | U19: Conforms | V19: Conforms | W19: ППК25279, (19.09.2025) [CNP] | X19: — | Y19: — | Z19: — | AA19: P050152|I | AB19: registered — initial release, issued 03.06.2026
