Workbook

Sheet iCoA Register
A1: No. | B1: iCoA code | C1: Issuable | D1: Issue date (preliminary) | E1: Earliest permissible | F1: Basis — sampling at packaging | G1: Packaging complete | H1: Series | I1: CU Batch | J1: P Batch | K1: Strain | L1: iCoA scope | M1: Master | N1: CNP reference | O1: Ident C — eCoA | P1: CoQ | Q1: Plan reference (31.08.2026) | R1: Key | S1: Status
A2: =IF(C2="yes",COUNT(A$1:A1)+1,"") | B2: =IF(A2="","— at issue —","iCoA-PP_26-"&TEXT(A2,"000")) | C2: yes | D2: =IF(A2="","",E2) | E2: =IF(AND(C2="yes",ISNUMBER(G2)),MAX(DATE(2026,5,13),G2),"") | F2: =IFERROR(INDEX('Batch Dates'!$F:$F,MATCH(J2,'Batch Dates'!$C:$C,0)),IFERROR(INDEX('Batch Dates'!$F:$F,MATCH(I2,'Batch Dates'!$B:$B,0)),"")) | G2: =IFERROR(INDEX('Batch Dates'!$G:$G,MATCH(J2,'Batch Dates'!$C:$C,0)),IFERROR(INDEX('Batch Dates'!$G:$G,MATCH(I2,'Batch Dates'!$B:$B,0)),"")) | H2: initial release | I2: CJ1024 | J2: N/A — no P batch assigned | K2: Cap Junky | L2: Ident A + Ident B | M2: iCoA_P01-02 · Appearance & Identification A/B | N2: — | O2: ППК25052, (26.02.2025) [CNP] | P2: (assigned on issue) | Q2: — | R2: CJ1024|AB|I | S2: registered — preliminary date, QC sets the real date at issue
A3: =IF(C3="yes",COUNT(A$1:A2)+1,"") | B3: =IF(A3="","— at issue —","iCoA-PP_26-"&TEXT(A3,"000")) | C3: yes | D3: =IF(A3="","",E3) | E3: =IF(AND(C3="yes",ISNUMBER(G3)),MAX(DATE(2026,5,13),G3),"") | F3: =IFERROR(INDEX('Batch Dates'!$F:$F,MATCH(J3,'Batch Dates'!$C:$C,0)),IFERROR(INDEX('Batch Dates'!$F:$F,MATCH(I3,'Batch Dates'!$B:$B,0)),"")) | G3: =IFERROR(INDEX('Batch Dates'!$G:$G,MATCH(J3,'Batch Dates'!$C:$C,0)),IFERROR(INDEX('Batch Dates'!$G:$G,MATCH(I3,'Batch Dates'!$B:$B,0)),"")) | H3: initial release | I3: CJ1024 | J3: N/A — no P batch assigned | K3: Cap Junky | L3: Foreign matter | M3: iCoA_P07 · Foreign matter | N3: — | O3: ППК25052, (26.02.2025) [CNP] | P3: (assigned on issue) | Q3: — | R3: CJ1024|FM|I | S3: registered — preliminary date, QC sets the real date at issue
A4: =IF(C4="yes",COUNT(A$1:A3)+1,"") | B4: =IF(A4="","— at issue —","iCoA-PP_26-"&TEXT(A4,"000")) | C4: yes | D4: =IF(A4="","",E4) | E4: =IF(AND(C4="yes",ISNUMBER(G4)),MAX(DATE(2026,5,13),G4),"") | F4: =IFERROR(INDEX('Batch Dates'!$F:$F,MATCH(J4,'Batch Dates'!$C:$C,0)),IFERROR(INDEX('Batch Dates'!$F:$F,MATCH(I4,'Batch Dates'!$B:$B,0)),"")) | G4: =IFERROR(INDEX('Batch Dates'!$G:$G,MATCH(J4,'Batch Dates'!$C:$C,0)),IFERROR(INDEX('Batch Dates'!$G:$G,MATCH(I4,'Batch Dates'!$B:$B,0)),"")) | H4: initial release | I4: BSS1024 | J4: N/A — no P batch assigned | K4: Blue Sunset Sherbet | L4: Ident A + Ident B | M4: iCoA_P01-02 · Appearance & Identification A/B | N4: — | O4: ППК25051, (26.02.2025) [CNP] | P4: CoQ-PP-2025-0001 | Q4: iCoA-PP-2025-0001 | R4: BSS1024|AB|I | S4: registered — preliminary date, QC sets the real date at issue
A5: =IF(C5="yes",COUNT(A$1:A4)+1,"") | B5: =IF(A5="","— at issue —","iCoA-PP_26-"&TEXT(A5,"000")) | C5: yes | D5: =IF(A5="","",E5) | E5: =IF(AND(C5="yes",ISNUMBER(G5)),MAX(DATE(2026,5,13),G5),"") | F5: =IFERROR(INDEX('Batch Dates'!$F:$F,MATCH(J5,'Batch Dates'!$C:$C,0)),IFERROR(INDEX('Batch Dates'!$F:$F,MATCH(I5,'Batch Dates'!$B:$B,0)),"")) | G5: =IFERROR(INDEX('Batch Dates'!$G:$G,MATCH(J5,'Batch Dates'!$C:$C,0)),IFERROR(INDEX('Batch Dates'!$G:$G,MATCH(I5,'Batch Dates'!$B:$B,0)),"")) | H5: initial release | I5: BSS1024 | J5: N/A — no P batch assigned | K5: Blue Sunset Sherbet | L5: Foreign matter | M5: iCoA_P07 · Foreign matter | N5: — | O5: ППК25051, (26.02.2025) [CNP] | P5: CoQ-PP-2025-0001 | Q5: iCoA-PP-2025-0001 | R5: BSS1024|FM|I | S5: registered — preliminary date, QC sets the real date at issue
A6: =IF(C6="yes",COUNT(A$1:A5)+1,"") | B6: =IF(A6="","— at issue —","iCoA-PP_26-"&TEXT(A6,"000")) | C6: yes | D6: =IF(A6="","",E6) | E6: =IF(AND(C6="yes",ISNUMBER(G6)),MAX(DATE(2026,5,13),G6),"") | F6: =IFERROR(INDEX('Batch Dates'!$F:$F,MATCH(J6,'Batch Dates'!$C:$C,0)),IFERROR(INDEX('Batch Dates'!$F:$F,MATCH(I6,'Batch Dates'!$B:$B,0)),"")) | G6: =IFERROR(INDEX('Batch Dates'!$G:$G,MATCH(J6,'Batch Dates'!$C:$C,0)),IFERROR(INDEX('Batch Dates'!$G:$G,MATCH(I6,'Batch Dates'!$B:$B,0)),"")) | H6: initial release | I6: BG1024 | J6: N/A — no P batch assigned | K6: Blue Gelato | L6: Ident A + Ident B | M6: iCoA_P01-02 · Appearance & Identification A/B | N6: — | O6: ППК25050, (26.02.2025) [CNP] | P6: CoQ-PP-2025-0002 | Q6: iCoA-PP-2025-0002 | R6: BG1024|AB|I | S6: registered — preliminary date, QC sets the real date at issue
A7: =IF(C7="yes",COUNT(A$1:A6)+1,"") | B7: =IF(A7="","— at issue —","iCoA-PP_26-"&TEXT(A7,"000")) | C7: yes | D7: =IF(A7="","",E7) | E7: =IF(AND(C7="yes",ISNUMBER(G7)),MAX(DATE(2026,5,13),G7),"") | F7: =IFERROR(INDEX('Batch Dates'!$F:$F,MATCH(J7,'Batch Dates'!$C:$C,0)),IFERROR(INDEX('Batch Dates'!$F:$F,MATCH(I7,'Batch Dates'!$B:$B,0)),"")) | G7: =IFERROR(INDEX('Batch Dates'!$G:$G,MATCH(J7,'Batch Dates'!$C:$C,0)),IFERROR(INDEX('Batch Dates'!$G:$G,MATCH(I7,'Batch Dates'!$B:$B,0)),"")) | H7: initial release | I7: BG1024 | J7: N/A — no P batch assigned | K7: Blue Gelato | L7: Foreign matter | M7: iCoA_P07 · Foreign matter | N7: — | O7: ППК25050, (26.02.2025) [CNP] | P7: CoQ-PP-2025-0002 | Q7: iCoA-PP-2025-0002 | R7: BG1024|FM|I | S7: registered — preliminary date, QC sets the real date at issue
A8: =IF(C8="yes",COUNT(A$1:A7)+1,"") | B8: =IF(A8="","— at issue —","iCoA-PP_26-"&TEXT(A8,"000")) | C8: yes | D8: =IF(A8="","",E8) | E8: =IF(AND(C8="yes",ISNUMBER(G8)),MAX(DATE(2026,5,13),G8),"") | F8: =IFERROR(INDEX('Batch Dates'!$F:$F,MATCH(J8,'Batch Dates'!$C:$C,0)),IFERROR(INDEX('Batch Dates'!$F:$F,MATCH(I8,'Batch Dates'!$B:$B,0)),"")) | G8: =IFERROR(INDEX('Batch Dates'!$G:$G,MATCH(J8,'Batch Dates'!$C:$C,0)),IFERROR(INDEX('Batch Dates'!$G:$G,MATCH(I8,'Batch Dates'!$B:$B,0)),"")) | H8: initial release | I8: GG1024 | J8: N/A — no P batch assigned | K8: Gorilla Glue | L8: Ident A + Ident B | M8: iCoA_P01-02 · Appearance & Identification A/B | N8: — | O8: — no cannabinoid certificate — | P8: CoQ-PP-2025-0003 | Q8: iCoA-PP-2025-0003 | R8: GG1024|AB|I | S8: registered — preliminary date, QC sets the real date at issue
A9: =IF(C9="yes",COUNT(A$1:A8)+1,"") | B9: =IF(A9="","— at issue —","iCoA-PP_26-"&TEXT(A9,"000")) | C9: yes | D9: =IF(A9="","",E9) | E9: =IF(AND(C9="yes",ISNUMBER(G9)),MAX(DATE(2026,5,13),G9),"") | F9: =IFERROR(INDEX('Batch Dates'!$F:$F,MATCH(J9,'Batch Dates'!$C:$C,0)),IFERROR(INDEX('Batch Dates'!$F:$F,MATCH(I9,'Batch Dates'!$B:$B,0)),"")) | G9: =IFERROR(INDEX('Batch Dates'!$G:$G,MATCH(J9,'Batch Dates'!$C:$C,0)),IFERROR(INDEX('Batch Dates'!$G:$G,MATCH(I9,'Batch Dates'!$B:$B,0)),"")) | H9: initial release | I9: GG1024 | J9: N/A — no P batch assigned | K9: Gorilla Glue | L9: Foreign matter | M9: iCoA_P07 · Foreign matter | N9: — | O9: — no cannabinoid certificate — | P9: CoQ-PP-2025-0003 | Q9: iCoA-PP-2025-0003 | R9: GG1024|FM|I | S9: registered — preliminary date, QC sets the real date at issue
A10: =IF(C10="yes",COUNT(A$1:A9)+1,"") | B10: =IF(A10="","— at issue —","iCoA-PP_26-"&TEXT(A10,"000")) | C10: yes | D10: =IF(A10="","",E10) | E10: =IF(AND(C10="yes",ISNUMBER(G10)),MAX(DATE(2026,5,13),G10),"") | F10: =IFERROR(INDEX('Batch Dates'!$F:$F,MATCH(J10,'Batch Dates'!$C:$C,0)),IFERROR(INDEX('Batch Dates'!$F:$F,MATCH(I10,'Batch Dates'!$B:$B,0)),"")) | G10: =IFERROR(INDEX('Batch Dates'!$G:$G,MATCH(J10,'Batch Dates'!$C:$C,0)),IFERROR(INDEX('Batch Dates'!$G:$G,MATCH(I10,'Batch Dates'!$B:$B,0)),"")) | H10: initial release | I10: HPA1024 | J10: N/A — no P batch assigned | K10: HighProAmnesia | L10: Ident A + Ident B | M10: iCoA_P01-02 · Appearance & Identification A/B | N10: — | O10: 197-13-K-26, (07.08.2026) [FHM-K] | P10: CoQ-PP-2025-0004 | Q10: iCoA-PP-2025-0004 | R10: HPA1024|AB|I | S10: registered — preliminary date, QC sets the real date at issue
A11: =IF(C11="yes",COUNT(A$1:A10)+1,"") | B11: =IF(A11="","— at issue —","iCoA-PP_26-"&TEXT(A11,"000")) | C11: yes | D11: =IF(A11="","",E11) | E11: =IF(AND(C11="yes",ISNUMBER(G11)),MAX(DATE(2026,5,13),G11),"") | F11: =IFERROR(INDEX('Batch Dates'!$F:$F,MATCH(J11,'Batch Dates'!$C:$C,0)),IFERROR(INDEX('Batch Dates'!$F:$F,MATCH(I11,'Batch Dates'!$B:$B,0)),"")) | G11: =IFERROR(INDEX('Batch Dates'!$G:$G,MATCH(J11,'Batch Dates'!$C:$C,0)),IFERROR(INDEX('Batch Dates'!$G:$G,MATCH(I11,'Batch Dates'!$B:$B,0)),"")) | H11: initial release | I11: HPA1024 | J11: N/A — no P batch assigned | K11: HighProAmnesia | L11: Foreign matter | M11: iCoA_P07 · Foreign matter | N11: — | O11: 197-13-K-26, (07.08.2026) [FHM-K] | P11: CoQ-PP-2025-0004 | Q11: iCoA-PP-2025-0004 | R11: HPA1024|FM|I | S11: registered — preliminary date, QC sets the real date at issue
A12: =IF(C12="yes",COUNT(A$1:A11)+1,"") | B12: =IF(A12="","— at issue —","iCoA-PP_26-"&TEXT(A12,"000")) | C12: yes | D12: =IF(A12="","",E12) | E12: =IF(AND(C12="yes",ISNUMBER(G12)),MAX(DATE(2026,5,13),G12),"") | F12: =IFERROR(INDEX('Batch Dates'!$F:$F,MATCH(J12,'Batch Dates'!$C:$C,0)),IFERROR(INDEX('Batch Dates'!$F:$F,MATCH(I12,'Batch Dates'!$B:$B,0)),"")) | G12: =IFERROR(INDEX('Batch Dates'!$G:$G,MATCH(J12,'Batch Dates'!$C:$C,0)),IFERROR(INDEX('Batch Dates'!$G:$G,MATCH(I12,'Batch Dates'!$B:$B,0)),"")) | H12: initial release | I12: OPM1024 | J12: N/A — no P batch assigned | K12: OrangePunchMimosa | L12: Ident A + Ident B | M12: iCoA_P01-02 · Appearance & Identification A/B | N12: — | O12: 197-17-K-26, (07.08.2026) [FHM-K] | P12: CoQ-PP-2025-0005 | Q12: iCoA-PP-2025-0005 | R12: OPM1024|AB|I | S12: registered — preliminary date, QC sets the real date at issue
A13: =IF(C13="yes",COUNT(A$1:A12)+1,"") | B13: =IF(A13="","— at issue —","iCoA-PP_26-"&TEXT(A13,"000")) | C13: yes | D13: =IF(A13="","",E13) | E13: =IF(AND(C13="yes",ISNUMBER(G13)),MAX(DATE(2026,5,13),G13),"") | F13: =IFERROR(INDEX('Batch Dates'!$F:$F,MATCH(J13,'Batch Dates'!$C:$C,0)),IFERROR(INDEX('Batch Dates'!$F:$F,MATCH(I13,'Batch Dates'!$B:$B,0)),"")) | G13: =IFERROR(INDEX('Batch Dates'!$G:$G,MATCH(J13,'Batch Dates'!$C:$C,0)),IFERROR(INDEX('Batch Dates'!$G:$G,MATCH(I13,'Batch Dates'!$B:$B,0)),"")) | H13: initial release | I13: OPM1024 | J13: N/A — no P batch assigned | K13: OrangePunchMimosa | L13: Foreign matter | M13: iCoA_P07 · Foreign matter | N13: — | O13: 197-17-K-26, (07.08.2026) [FHM-K] | P13: CoQ-PP-2025-0005 | Q13: iCoA-PP-2025-0005 | R13: OPM1024|FM|I | S13: registered — preliminary date, QC sets the real date at issue
... A87: =IF(C87="yes",COUNT(A$1:A86)+1,"") | B87: =IF(A87="","— at issue —","iCoA-PP_26-"&TEXT(A87,"000")) | C87: yes | D87: =IF(A87="","",E87) | E87: =IF(AND(C87="yes",ISNUMBER(G87)),MAX(DATE(2026,5,13),G87),"") | F87: =IFERROR(INDEX('Batch Dates'!$F:$F,MATCH(J87,'Batch Dates'!$C:$C,0)),IFERROR(INDEX('Batch Dates'!$F:$F,MATCH(I87,'Batch Dates'!$B:$B,0)),"")) | G87: =IFERROR(INDEX('Batch Dates'!$G:$G,MATCH(J87,'Batch Dates'!$C:$C,0)),IFERROR(INDEX('Batch Dates'!$G:$G,MATCH(I87,'Batch Dates'!$B:$B,0)),"")) | H87: initial release | I87: CJ092501 | J87: P060072 | K87: Cap Junky | L87: Foreign matter | M87: iCoA_P07 · Foreign matter | N87: — | O87: ППК26007, (21.01.2026) [CNP] | P87: CoQ-PP-2026-0006 | Q87: iCoA-PP-2026-0006 | R87: P060072|FM|I | S87: registered — preliminary date, QC sets the real date at issue
A88: =IF(C88="yes",COUNT(A$1:A87)+1,"") | B88: =IF(A88="","— at issue —","iCoA-PP_26-"&TEXT(A88,"000")) | C88: yes | D88: =IF(A88="","",E88) | E88: =IF(AND(C88="yes",ISNUMBER(G88)),MAX(DATE(2026,5,13),G88),"") | F88: =IFERROR(INDEX('Batch Dates'!$F:$F,MATCH(J88,'Batch Dates'!$C:$C,0)),IFERROR(INDEX('Batch Dates'!$F:$F,MATCH(I88,'Batch Dates'!$B:$B,0)),"")) | G88: =IFERROR(INDEX('Batch Dates'!$G:$G,MATCH(J88,'Batch Dates'!$C:$C,0)),IFERROR(INDEX('Batch Dates'!$G:$G,MATCH(I88,'Batch Dates'!$B:$B,0)),"")) | H88: initial release | I88: SJ0925021 | J88: P060082 | L88: Ident A + Ident B | M88: iCoA_P01-02 · Appearance & Identification A/B | N88: — | O88: ППК26006, (21.01.2026) [CNP] | P88: CoQ-PP-2026-0007 | Q88: iCoA-PP-2026-0007 | R88: P060082|AB|I | S88: registered — preliminary date, QC sets the real date at issue
A89: =IF(C89="yes",COUNT(A$1:A88)+1,"") | B89: =IF(A89="","— at issue —","iCoA-PP_26-"&TEXT(A89,"000")) | C89: yes | D89: =IF(A89="","",E89) | E89: =IF(AND(C89="yes",ISNUMBER(G89)),MAX(DATE(2026,5,13),G89),"") | F89: =IFERROR(INDEX('Batch Dates'!$F:$F,MATCH(J89,'Batch Dates'!$C:$C,0)),IFERROR(INDEX('Batch Dates'!$F:$F,MATCH(I89,'Batch Dates'!$B:$B,0)),"")) | G89: =IFERROR(INDEX('Batch Dates'!$G:$G,MATCH(J89,'Batch Dates'!$C:$C,0)),IFERROR(INDEX('Batch Dates'!$G:$G,MATCH(I89,'Batch Dates'!$B:$B,0)),"")) | H89: initial release | I89: SJ0925021 | J89: P060082 | L89: Foreign matter | M89: iCoA_P07 · Foreign matter | N89: — | O89: ППК26006, (21.01.2026) [CNP] | P89: CoQ-PP-2026-0007 | Q89: iCoA-PP-2026-0007 | R89: P060082|FM|I | S89: registered — preliminary date, QC sets the real date at issue
A90: =IF(C90="yes",COUNT(A$1:A89)+1,"") | B90: =IF(A90="","— at issue —","iCoA-PP_26-"&TEXT(A90,"000")) | C90: yes | D90: =IF(A90="","",E90) | E90: =IF(AND(C90="yes",ISNUMBER(G90)),MAX(DATE(2026,5,13),G90),"") | F90: =IFERROR(INDEX('Batch Dates'!$F:$F,MATCH(J90,'Batch Dates'!$C:$C,0)),IFERROR(INDEX('Batch Dates'!$F:$F,MATCH(I90,'Batch Dates'!$B:$B,0)),"")) | G90: =IFERROR(INDEX('Batch Dates'!$G:$G,MATCH(J90,'Batch Dates'!$C:$C,0)),IFERROR(INDEX('Batch Dates'!$G:$G,MATCH(I90,'Batch Dates'!$B:$B,0)),"")) | H90: initial release | I90: GP092501 | J90: P060092 | K90: Grape Pie | L90: Ident A + Ident B | M90: iCoA_P01-02 · Appearance & Identification A/B | N90: — | O90: ППК26009, (21.01.2026) [CNP] | P90: CoQ-PP-2026-0008 | Q90: iCoA-PP-2026-0008 | R90: P060092|AB|I | S90: registered — preliminary date, QC sets the real date at issue
A91: =IF(C91="yes",COUNT(A$1:A90)+1,"") | B91: =IF(A91="","— at issue —","iCoA-PP_26-"&TEXT(A91,"000")) | C91: yes | D91: =IF(A91="","",E91) | E91: =IF(AND(C91="yes",ISNUMBER(G91)),MAX(DATE(2026,5,13),G91),"") | F91: =IFERROR(INDEX('Batch Dates'!$F:$F,MATCH(J91,'Batch Dates'!$C:$C,0)),IFERROR(INDEX('Batch Dates'!$F:$F,MATCH(I91,'Batch Dates'!$B:$B,0)),"")) | G91: =IFERROR(INDEX('Batch Dates'!$G:$G,MATCH(J91,'Batch Dates'!$C:$C,0)),IFERROR(INDEX('Batch Dates'!$G:$G,MATCH(I91,'Batch Dates'!$B:$B,0)),"")) | H91: initial release | I91: GP092501 | J91: P060092 | K91: Grape Pie | L91: Foreign matter | M91: iCoA_P07 · Foreign matter | N91: — | O91: ППК26009, (21.01.2026) [CNP] | P91: CoQ-PP-2026-0008 | Q91: iCoA-PP-2026-0008 | R91: P060092|FM|I | S91: registered — preliminary date, QC sets the real date at issue
A92: =IF(C92="yes",COUNT(A$1:A91)+1,"") | B92: =IF(A92="","— at issue —","iCoA-PP_26-"&TEXT(A92,"000")) | C92: yes | D92: =IF(A92="","",E92) | E92: =IF(AND(C92="yes",ISNUMBER(G92)),MAX(DATE(2026,5,13),G92),"") | F92: =IFERROR(INDEX('Batch Dates'!$F:$F,MATCH(J92,'Batch Dates'!$C:$C,0)),IFERROR(INDEX('Batch Dates'!$F:$F,MATCH(I92,'Batch Dates'!$B:$B,0)),"")) | G92: =IFERROR(INDEX('Batch Dates'!$G:$G,MATCH(J92,'Batch Dates'!$C:$C,0)),IFERROR(INDEX('Batch Dates'!$G:$G,MATCH(I92,'Batch Dates'!$B:$B,0)),"")) | H92: initial release | I92: WED102501 (from the list) | J92: P060102 | K92: Wedding Cake | L92: Ident A + Ident B | M92: iCoA_P01-02 · Appearance & Identification A/B | N92: — | O92: — no cannabinoid certificate — | P92: — not in the issuance plan — | Q92: — | R92: P060102|AB|I | S92: registered — preliminary date, QC sets the real date at issue
A93: =IF(C93="yes",COUNT(A$1:A92)+1,"") | B93: =IF(A93="","— at issue —","iCoA-PP_26-"&TEXT(A93,"000")) | C93: yes | D93: =IF(A93="","",E93) | E93: =IF(AND(C93="yes",ISNUMBER(G93)),MAX(DATE(2026,5,13),G93),"") | F93: =IFERROR(INDEX('Batch Dates'!$F:$F,MATCH(J93,'Batch Dates'!$C:$C,0)),IFERROR(INDEX('Batch Dates'!$F:$F,MATCH(I93,'Batch Dates'!$B:$B,0)),"")) | G93: =IFERROR(INDEX('Batch Dates'!$G:$G,MATCH(J93,'Batch Dates'!$C:$C,0)),IFERROR(INDEX('Batch Dates'!$G:$G,MATCH(I93,'Batch Dates'!$B:$B,0)),"")) | H93: initial release | I93: WED102501 (from the list) | J93: P060102 | K93: Wedding Cake | L93: Foreign matter | M93: iCoA_P07 · Foreign matter | N93: — | O93: — no cannabinoid certificate — | P93: — not in the issuance plan — | Q93: — | R93: P060102|FM|I | S93: registered — preliminary date, QC sets the real date at issue
A94: =IF(C94="yes",COUNT(A$1:A93)+1,"") | B94: =IF(A94="","— at issue —","iCoA-PP_26-"&TEXT(A94,"000")) | C94: yes | D94: =IF(A94="","",E94) | E94: =IF(AND(C94="yes",ISNUMBER(G94)),MAX(DATE(2026,5,13),G94),"") | F94: =IFERROR(INDEX('Batch Dates'!$F:$F,MATCH(J94,'Batch Dates'!$C:$C,0)),IFERROR(INDEX('Batch Dates'!$F:$F,MATCH(I94,'Batch Dates'!$B:$B,0)),"")) | G94: =IFERROR(INDEX('Batch Dates'!$G:$G,MATCH(J94,'Batch Dates'!$C:$C,0)),IFERROR(INDEX('Batch Dates'!$G:$G,MATCH(I94,'Batch Dates'!$B:$B,0)),"")) | H94: initial release | I94: GRC102501 | J94: P060142 | K94: Graps & Creme | L94: Ident A + Ident B | M94: iCoA_P01-02 · Appearance & Identification A/B | N94: — | O94: 051-6-K-26, (04.03.2026) [FHM-K] | P94: — not in the issuance plan — | Q94: — | R94: P060142|AB|I | S94: registered — preliminary date, QC sets the real date at issue
A95: =IF(C95="yes",COUNT(A$1:A94)+1,"") | B95: =IF(A95="","— at issue —","iCoA-PP_26-"&TEXT(A95,"000")) | C95: yes | D95: =IF(A95="","",E95) | E95: =IF(AND(C95="yes",ISNUMBER(G95)),MAX(DATE(2026,5,13),G95),"") | F95: =IFERROR(INDEX('Batch Dates'!$F:$F,MATCH(J95,'Batch Dates'!$C:$C,0)),IFERROR(INDEX('Batch Dates'!$F:$F,MATCH(I95,'Batch Dates'!$B:$B,0)),"")) | G95: =IFERROR(INDEX('Batch Dates'!$G:$G,MATCH(J95,'Batch Dates'!$C:$C,0)),IFERROR(INDEX('Batch Dates'!$G:$G,MATCH(I95,'Batch Dates'!$B:$B,0)),"")) | H95: initial release | I95: GRC102501 | J95: P060142 | K95: Graps & Creme | L95: Foreign matter | M95: iCoA_P07 · Foreign matter | N95: — | O95: 051-6-K-26, (04.03.2026) [FHM-K] | P95: — not in the issuance plan — | Q95: — | R95: P060142|FM|I | S95: registered — preliminary date, QC sets the real date at issue
A96: =IF(C96="yes",COUNT(A$1:A95)+1,"") | B96: =IF(A96="","— at issue —","iCoA-PP_26-"&TEXT(A96,"000")) | C96: yes | D96: =IF(A96="","",E96) | E96: =IF(AND(C96="yes",ISNUMBER(G96)),MAX(DATE(2026,5,13),G96),"") | F96: =IFERROR(INDEX('Batch Dates'!$F:$F,MATCH(J96,'Batch Dates'!$C:$C,0)),IFERROR(INDEX('Batch Dates'!$F:$F,MATCH(I96,'Batch Dates'!$B:$B,0)),"")) | G96: =IFERROR(INDEX('Batch Dates'!$G:$G,MATCH(J96,'Batch Dates'!$C:$C,0)),IFERROR(INDEX('Batch Dates'!$G:$G,MATCH(I96,'Batch Dates'!$B:$B,0)),"")) | H96: initial release | I96: J31102501 | J96: P060152 | K96: Jokerz 31 | L96: Ident A + Ident B | M96: iCoA_P01-02 · Appearance & Identification A/B | N96: — | O96: 051-1-K-26, (04.03.2026) [FHM-K] | P96: CoQ-PP-2026-0012 | Q96: iCoA-PP-2026-0012 | R96: P060152|AB|I | S96: registered — preliminary date, QC sets the real date at issue
A97: =IF(C97="yes",COUNT(A$1:A96)+1,"") | B97: =IF(A97="","— at issue —","iCoA-PP_26-"&TEXT(A97,"000")) | C97: yes | D97: =IF(A97="","",E97) | E97: =IF(AND(C97="yes",ISNUMBER(G97)),MAX(DATE(2026,5,13),G97),"") | F97: =IFERROR(INDEX('Batch Dates'!$F:$F,MATCH(J97,'Batch Dates'!$C:$C,0)),IFERROR(INDEX('Batch Dates'!$F:$F,MATCH(I97,'Batch Dates'!$B:$B,0)),"")) | G97: =IFERROR(INDEX('Batch Dates'!$G:$G,MATCH(J97,'Batch Dates'!$C:$C,0)),IFERROR(INDEX('Batch Dates'!$G:$G,MATCH(I97,'Batch Dates'!$B:$B,0)),"")) | H97: initial release | I97: J31102501 | J97: P060152 | K97: Jokerz 31 | L97: Foreign matter | M97: iCoA_P07 · Foreign matter | N97: — | O97: 051-1-K-26, (04.03.2026) [FHM-K] | P97: CoQ-PP-2026-0012 | Q97: iCoA-PP-2026-0012 | R97: P060152|FM|I | S97: registered — preliminary date, QC sets the real date at issue
A98: =IF(C98="yes",COUNT(A$1:A97)+1,"") | B98: =IF(A98="","— at issue —","iCoA-PP_26-"&TEXT(A98,"000")) | C98: yes | D98: =IF(A98="","",E98) | E98: =IF(AND(C98="yes",ISNUMBER(G98)),MAX(DATE(2026,5,13),G98),"") | F98: =IFERROR(INDEX('Batch Dates'!$F:$F,MATCH(J98,'Batch Dates'!$C:$C,0)),IFERROR(INDEX('Batch Dates'!$F:$F,MATCH(I98,'Batch Dates'!$B:$B,0)),"")) | G98: =IFERROR(INDEX('Batch Dates'!$G:$G,MATCH(J98,'Batch Dates'!$C:$C,0)),IFERROR(INDEX('Batch Dates'!$G:$G,MATCH(I98,'Batch Dates'!$B:$B,0)),"")) | H98: initial release | I98: SJ102501 | J98: P060162 | K98: Sleepy Joe | L98: Ident A + Ident B | M98: iCoA_P01-02 · Appearance & Identification A/B | N98: — | O98: 051-3-K-26, (04.03.2026) [FHM-K] | P98: (assigned on issue) | Q98: — | R98: P060162|AB|I | S98: registered — preliminary date, QC sets the real date at issue
A99: =IF(C99="yes",COUNT(A$1:A98)+1,"") | B99: =IF(A99="","— at issue —","iCoA-PP_26-"&TEXT(A99,"000")) | C99: yes | D99: =IF(A99="","",E99) | E99: =IF(AND(C99="yes",ISNUMBER(G99)),MAX(DATE(2026,5,13),G99),"") | F99: =IFERROR(INDEX('Batch Dates'!$F:$F,MATCH(J99,'Batch Dates'!$C:$C,0)),IFERROR(INDEX('Batch Dates'!$F:$F,MATCH(I99,'Batch Dates'!$B:$B,0)),"")) | G99: =IFERROR(INDEX('Batch Dates'!$G:$G,MATCH(J99,'Batch Dates'!$C:$C,0)),IFERROR(INDEX('Batch Dates'!$G:$G,MATCH(I99,'Batch Dates'!$B:$B,0)),"")) | H99: initial release | I99: SJ102501 | J99: P060162 | K99: Sleepy Joe | L99: Foreign matter | M99: iCoA_P07 · Foreign matter | N99: — | O99: 051-3-K-26, (04.03.2026) [FHM-K] | P99: (assigned on issue) | Q99: — | R99: P060162|FM|I | S99: registered — preliminary date, QC sets the real date at issue
A100: =IF(C100="yes",COUNT(A$1:A99)+1,"") | B100: =IF(A100="","— at issue —","iCoA-PP_26-"&TEXT(A100,"000")) | C100: yes | D100: =IF(A100="","",E100) | E100: =IF(AND(C100="yes",ISNUMBER(G100)),MAX(DATE(2026,5,13),G100),"") | F100: =IFERROR(INDEX('Batch Dates'!$F:$F,MATCH(J100,'Batch Dates'!$C:$C,0)),IFERROR(INDEX('Batch Dates'!$F:$F,MATCH(I100,'Batch Dates'!$B:$B,0)),"")) | G100: =IFERROR(INDEX('Batch Dates'!$G:$G,MATCH(J100,'Batch Dates'!$C:$C,0)),IFERROR(INDEX('Batch Dates'!$G:$G,MATCH(I100,'Batch Dates'!$B:$B,0)),"")) | H100: initial release | I100: KC102501 | J100: P060172 | K100: Kush Crasher | L100: Ident A + Ident B | M100: iCoA_P01-02 · Appearance & Identification A/B | N100: — | O100: 051-4-K-26, (04.03.2026) [FHM-K] | P100: CoQ-PP-2026-0013 | Q100: iCoA-PP-2026-0013 | R100: P060172|AB|I | S100: registered — preliminary date, QC sets the real date at issue
A101: =IF(C101="yes",COUNT(A$1:A100)+1,"") | B101: =IF(A101="","— at issue —","iCoA-PP_26-"&TEXT(A101,"000")) | C101: yes | D101: =IF(A101="","",E101) | E101: =IF(AND(C101="yes",ISNUMBER(G101)),MAX(DATE(2026,5,13),G101),"") | F101: =IFERROR(INDEX('Batch Dates'!$F:$F,MATCH(J101,'Batch Dates'!$C:$C,0)),IFERROR(INDEX('Batch Dates'!$F:$F,MATCH(I101,'Batch Dates'!$B:$B,0)),"")) | G101: =IFERROR(INDEX('Batch Dates'!$G:$G,MATCH(J101,'Batch Dates'!$C:$C,0)),IFERROR(INDEX('Batch Dates'!$G:$G,MATCH(I101,'Batch Dates'!$B:$B,0)),"")) | H101: initial release | I101: KC102501 | J101: P060172 | K101: Kush Crasher | L101: Foreign matter | M101: iCoA_P07 · Foreign matter | N101: — | O101: 051-4-K-26, (04.03.2026) [FHM-K] | P101: CoQ-PP-2026-0013 | Q101: iCoA-PP-2026-0013 | R101: P060172|FM|I | S101: registered — preliminary date, QC sets the real date at issue
... A131: =IF(C131="yes",COUNT(A$1:A130)+1,"") | B131: =IF(A131="","— at issue —","iCoA-PP_26-"&TEXT(A131,"000")) | C131: yes | D131: =IF(A131="","",E131) | E131: =IF(AND(C131="yes",ISNUMBER(G131)),MAX(DATE(2026,5,13),G131),"") | F131: =IFERROR(INDEX('Batch Dates'!$F:$F,MATCH(J131,'Batch Dates'!$C:$C,0)),IFERROR(INDEX('Batch Dates'!$F:$F,MATCH(I131,'Batch Dates'!$B:$B,0)),"")) | G131: =IFERROR(INDEX('Batch Dates'!$G:$G,MATCH(J131,'Batch Dates'!$C:$C,0)),IFERROR(INDEX('Batch Dates'!$G:$G,MATCH(I131,'Batch Dates'!$B:$B,0)),"")) | H131: initial release | I131: JD012601＊ | J131: P060312 | K131: Jelly Donutz | L131: Foreign matter | M131: iCoA_P07 · Foreign matter | N131: — | O131: ППК26064, (11.05.2026) [CNP] | P131: (assigned on issue) | Q131: — | R131: P060312|FM|I | S131: registered — preliminary date, QC sets the real date at issue
A132: =IF(C132="yes",COUNT(A$1:A131)+1,"") | B132: =IF(A132="","— at issue —","iCoA-PP_26-"&TEXT(A132,"000")) | C132: yes | D132: =IF(A132="","",E132) | E132: =IF(AND(C132="yes",ISNUMBER(G132)),MAX(DATE(2026,5,13),G132),"") | F132: =IFERROR(INDEX('Batch Dates'!$F:$F,MATCH(J132,'Batch Dates'!$C:$C,0)),IFERROR(INDEX('Batch Dates'!$F:$F,MATCH(I132,'Batch Dates'!$B:$B,0)),"")) | G132: =IFERROR(INDEX('Batch Dates'!$G:$G,MATCH(J132,'Batch Dates'!$C:$C,0)),IFERROR(INDEX('Batch Dates'!$G:$G,MATCH(I132,'Batch Dates'!$B:$B,0)),"")) | H132: initial release | I132: CC012601/1 | J132: P060332 | L132: Ident A + Ident B | M132: iCoA_P01-02 · Appearance & Identification A/B | N132: — | O132: 197-6-K-26, (07.08.2026) [FHM-K] | P132: — not in the issuance plan — | Q132: — | R132: P060332|AB|I | S132: registered — preliminary date, QC sets the real date at issue
A133: =IF(C133="yes",COUNT(A$1:A132)+1,"") | B133: =IF(A133="","— at issue —","iCoA-PP_26-"&TEXT(A133,"000")) | C133: yes | D133: =IF(A133="","",E133) | E133: =IF(AND(C133="yes",ISNUMBER(G133)),MAX(DATE(2026,5,13),G133),"") | F133: =IFERROR(INDEX('Batch Dates'!$F:$F,MATCH(J133,'Batch Dates'!$C:$C,0)),IFERROR(INDEX('Batch Dates'!$F:$F,MATCH(I133,'Batch Dates'!$B:$B,0)),"")) | G133: =IFERROR(INDEX('Batch Dates'!$G:$G,MATCH(J133,'Batch Dates'!$C:$C,0)),IFERROR(INDEX('Batch Dates'!$G:$G,MATCH(I133,'Batch Dates'!$B:$B,0)),"")) | H133: initial release | I133: CC012601/1 | J133: P060332 | L133: Foreign matter | M133: iCoA_P07 · Foreign matter | N133: — | O133: 197-6-K-26, (07.08.2026) [FHM-K] | P133: — not in the issuance plan — | Q133: — | R133: P060332|FM|I | S133: registered — preliminary date, QC sets the real date at issue
A134: =IF(C134="yes",COUNT(A$1:A133)+1,"") | B134: =IF(A134="","— at issue —","iCoA-PP_26-"&TEXT(A134,"000")) | C134: yes | D134: =IF(A134="","",E134) | E134: =IF(AND(C134="yes",ISNUMBER(G134)),MAX(DATE(2026,5,13),G134),"") | F134: =IFERROR(INDEX('Batch Dates'!$F:$F,MATCH(J134,'Batch Dates'!$C:$C,0)),IFERROR(INDEX('Batch Dates'!$F:$F,MATCH(I134,'Batch Dates'!$B:$B,0)),"")) | G134: =IFERROR(INDEX('Batch Dates'!$G:$G,MATCH(J134,'Batch Dates'!$C:$C,0)),IFERROR(INDEX('Batch Dates'!$G:$G,MATCH(I134,'Batch Dates'!$B:$B,0)),"")) | H134: initial release | I134: FB012601_1 | J134: P060322 | K134: Fat Bastard | L134: Ident A + Ident B | M134: iCoA_P01-02 · Appearance & Identification A/B | N134: — | O134: ППК26067, (11.05.2026) [CNP] | P134: CoQ-PP-2026-0019 | Q134: iCoA-PP-2026-0019 | R134: P060322|AB|I | S134: registered — preliminary date, QC sets the real date at issue
A135: =IF(C135="yes",COUNT(A$1:A134)+1,"") | B135: =IF(A135="","— at issue —","iCoA-PP_26-"&TEXT(A135,"000")) | C135: yes | D135: =IF(A135="","",E135) | E135: =IF(AND(C135="yes",ISNUMBER(G135)),MAX(DATE(2026,5,13),G135),"") | F135: =IFERROR(INDEX('Batch Dates'!$F:$F,MATCH(J135,'Batch Dates'!$C:$C,0)),IFERROR(INDEX('Batch Dates'!$F:$F,MATCH(I135,'Batch Dates'!$B:$B,0)),"")) | G135: =IFERROR(INDEX('Batch Dates'!$G:$G,MATCH(J135,'Batch Dates'!$C:$C,0)),IFERROR(INDEX('Batch Dates'!$G:$G,MATCH(I135,'Batch Dates'!$B:$B,0)),"")) | H135: initial release | I135: FB012601_1 | J135: P060322 | K135: Fat Bastard | L135: Foreign matter | M135: iCoA_P07 · Foreign matter | N135: — | O135: ППК26067, (11.05.2026) [CNP] | P135: CoQ-PP-2026-0019 | Q135: iCoA-PP-2026-0019 | R135: P060322|FM|I | S135: registered — preliminary date, QC sets the real date at issue
A136: =IF(C136="yes",COUNT(A$1:A135)+1,"") | B136: =IF(A136="","— at issue —","iCoA-PP_26-"&TEXT(A136,"000")) | C136: yes | D136: =IF(A136="","",E136) | E136: =IF(AND(C136="yes",ISNUMBER(G136)),MAX(DATE(2026,5,13),G136),"") | F136: =IFERROR(INDEX('Batch Dates'!$F:$F,MATCH(J136,'Batch Dates'!$C:$C,0)),IFERROR(INDEX('Batch Dates'!$F:$F,MATCH(I136,'Batch Dates'!$B:$B,0)),"")) | G136: =IFERROR(INDEX('Batch Dates'!$G:$G,MATCH(J136,'Batch Dates'!$C:$C,0)),IFERROR(INDEX('Batch Dates'!$G:$G,MATCH(I136,'Batch Dates'!$B:$B,0)),"")) | H136: initial release | I136: FB012602* | J136: P060352 | K136: Fat Bastard | L136: Ident A + Ident B | M136: iCoA_P01-02 · Appearance & Identification A/B | N136: — | O136: 197-7-K-26, (07.08.2026) [FHM-K] | P136: CoQ-PP-2026-0021 | Q136: iCoA-PP-2026-0021 | R136: P060352|AB|I | S136: registered — preliminary date, QC sets the real date at issue
A137: =IF(C137="yes",COUNT(A$1:A136)+1,"") | B137: =IF(A137="","— at issue —","iCoA-PP_26-"&TEXT(A137,"000")) | C137: yes | D137: =IF(A137="","",E137) | E137: =IF(AND(C137="yes",ISNUMBER(G137)),MAX(DATE(2026,5,13),G137),"") | F137: =IFERROR(INDEX('Batch Dates'!$F:$F,MATCH(J137,'Batch Dates'!$C:$C,0)),IFERROR(INDEX('Batch Dates'!$F:$F,MATCH(I137,'Batch Dates'!$B:$B,0)),"")) | G137: =IFERROR(INDEX('Batch Dates'!$G:$G,MATCH(J137,'Batch Dates'!$C:$C,0)),IFERROR(INDEX('Batch Dates'!$G:$G,MATCH(I137,'Batch Dates'!$B:$B,0)),"")) | H137: initial release | I137: FB012602* | J137: P060352 | K137: Fat Bastard | L137: Foreign matter | M137: iCoA_P07 · Foreign matter | N137: — | O137: 197-7-K-26, (07.08.2026) [FHM-K] | P137: CoQ-PP-2026-0021 | Q137: iCoA-PP-2026-0021 | R137: P060352|FM|I | S137: registered — preliminary date, QC sets the real date at issue
A138: =IF(C138="yes",COUNT(A$1:A137)+1,"") | B138: =IF(A138="","— at issue —","iCoA-PP_26-"&TEXT(A138,"000")) | C138: yes | D138: =IF(A138="","",E138) | E138: =IF(AND(C138="yes",ISNUMBER(G138)),MAX(DATE(2026,5,13),G138),"") | F138: =IFERROR(INDEX('Batch Dates'!$F:$F,MATCH(J138,'Batch Dates'!$C:$C,0)),IFERROR(INDEX('Batch Dates'!$F:$F,MATCH(I138,'Batch Dates'!$B:$B,0)),"")) | G138: =IFERROR(INDEX('Batch Dates'!$G:$G,MATCH(J138,'Batch Dates'!$C:$C,0)),IFERROR(INDEX('Batch Dates'!$G:$G,MATCH(I138,'Batch Dates'!$B:$B,0)),"")) | H138: initial release | I138: SCR012601* (from the list) | J138: P060342 | K138: Scrambler | L138: Ident A + Ident B | M138: iCoA_P01-02 · Appearance & Identification A/B | N138: — | O138: — no cannabinoid certificate — | P138: — not in the issuance plan — | Q138: — | R138: P060342|AB|I | S138: registered — preliminary date, QC sets the real date at issue
A139: =IF(C139="yes",COUNT(A$1:A138)+1,"") | B139: =IF(A139="","— at issue —","iCoA-PP_26-"&TEXT(A139,"000")) | C139: yes | D139: =IF(A139="","",E139) | E139: =IF(AND(C139="yes",ISNUMBER(G139)),MAX(DATE(2026,5,13),G139),"") | F139: =IFERROR(INDEX('Batch Dates'!$F:$F,MATCH(J139,'Batch Dates'!$C:$C,0)),IFERROR(INDEX('Batch Dates'!$F:$F,MATCH(I139,'Batch Dates'!$B:$B,0)),"")) | G139: =IFERROR(INDEX('Batch Dates'!$G:$G,MATCH(J139,'Batch Dates'!$C:$C,0)),IFERROR(INDEX('Batch Dates'!$G:$G,MATCH(I139,'Batch Dates'!$B:$B,0)),"")) | H139: initial release | I139: SCR012601* (from the list) | J139: P060342 | K139: Scrambler | L139: Foreign matter | M139: iCoA_P07 · Foreign matter | N139: — | O139: — no cannabinoid certificate — | P139: — not in the issuance plan — | Q139: — | R139: P060342|FM|I | S139: registered — preliminary date, QC sets the real date at issue
A140: =IF(C140="yes",COUNT(A$1:A139)+1,"") | B140: =IF(A140="","— at issue —","iCoA-PP_26-"&TEXT(A140,"000")) | C140: yes | D140: =IF(A140="","",E140) | E140: =IF(AND(C140="yes",ISNUMBER(G140)),MAX(DATE(2026,5,13),G140),"") | F140: =IFERROR(INDEX('Batch Dates'!$F:$F,MATCH(J140,'Batch Dates'!$C:$C,0)),IFERROR(INDEX('Batch Dates'!$F:$F,MATCH(I140,'Batch Dates'!$B:$B,0)),"")) | G140: =IFERROR(INDEX('Batch Dates'!$G:$G,MATCH(J140,'Batch Dates'!$C:$C,0)),IFERROR(INDEX('Batch Dates'!$G:$G,MATCH(I140,'Batch Dates'!$B:$B,0)),"")) | H140: initial release | I140: SCR012603 | J140: P060382 | K140: Scrambler | L140: Ident A + Ident B | M140: iCoA_P01-02 · Appearance & Identification A/B | N140: — | O140: 197-21-K-26, (07.08.2026) [FHM-K] | P140: CoQ-PP-2026-0026 | Q140: iCoA-PP-2026-0026 | R140: P060382|AB|I | S140: registered — preliminary date, QC sets the real date at issue
A141: =IF(C141="yes",COUNT(A$1:A140)+1,"") | B141: =IF(A141="","— at issue —","iCoA-PP_26-"&TEXT(A141,"000")) | C141: yes | D141: =IF(A141="","",E141) | E141: =IF(AND(C141="yes",ISNUMBER(G141)),MAX(DATE(2026,5,13),G141),"") | F141: =IFERROR(INDEX('Batch Dates'!$F:$F,MATCH(J141,'Batch Dates'!$C:$C,0)),IFERROR(INDEX('Batch Dates'!$F:$F,MATCH(I141,'Batch Dates'!$B:$B,0)),"")) | G141: =IFERROR(INDEX('Batch Dates'!$G:$G,MATCH(J141,'Batch Dates'!$C:$C,0)),IFERROR(INDEX('Batch Dates'!$G:$G,MATCH(I141,'Batch Dates'!$B:$B,0)),"")) | H141: initial release | I141: SCR012603 | J141: P060382 | K141: Scrambler | L141: Foreign matter | M141: iCoA_P07 · Foreign matter | N141: — | O141: 197-21-K-26, (07.08.2026) [FHM-K] | P141: CoQ-PP-2026-0026 | Q141: iCoA-PP-2026-0026 | R141: P060382|FM|I | S141: registered — preliminary date, QC sets the real date at issue
A142: =IF(C142="yes",COUNT(A$1:A141)+1,"") | B142: =IF(A142="","— at issue —","iCoA-PP_26-"&TEXT(A142,"000")) | C142: no | D142: =IF(A142="","",E142) | E142: =IF(AND(C142="yes",ISNUMBER(G142)),MAX(DATE(2026,5,13),G142),"") | F142: =IFERROR(INDEX('Batch Dates'!$F:$F,MATCH(J142,'Batch Dates'!$C:$C,0)),IFERROR(INDEX('Batch Dates'!$F:$F,MATCH(I142,'Batch Dates'!$B:$B,0)),"")) | G142: =IFERROR(INDEX('Batch Dates'!$G:$G,MATCH(J142,'Batch Dates'!$C:$C,0)),IFERROR(INDEX('Batch Dates'!$G:$G,MATCH(I142,'Batch Dates'!$B:$B,0)),"")) | H142: retest — QP campaign | I142: BSS1024 | J142: N/A — no P batch assigned | K142: Blue Sunset Sherbet | L142: Ident A + Ident B | M142: iCoA_P01-02 · Appearance & Identification A/B | N142: — | O142: 197-2-K-26, (07.08.2026) [FHM-K] | P142: CoQ-PP-2026-0027 | Q142: — | R142: BSS1024|AB|R | S142: not yet issuable — retest assay on file; identification A and B to test at the retest sampling
...

Sheet Batch Dates
A1: Seq | B1: Batch (as listed) | C1: P Batch | D1: Harvest from | E1: Harvest to | F1: Packaging from | G1: Packaging to | H1: iCoA basis (first day of packaging) | I1: Tracker lot | J1: Note
A2: 1 | B2: CJ1024 | D2: 45677 | E2: 45677 | F2: 45719 | G2: 45719 | H2: =F2 | I2: CJ1024 | J2: listed as 'CJ1024 - R&D'
A3: 2 | B3: GG1024 | D3: 45677 | E3: 45677 | F3: 45727 | G3: 45727 | H3: =F3 | I3: GG1024 | J3: listed as 'GG1024- R&D'
A4: 3 | B4: OPM1024 | D4: 45678 | E4: 45678 | F4: 45771 | G4: 45772 | H4: =F4 | I4: OPM1024 | J4: listed as 'OPM1024- R&D'
A5: 4 | B5: BG1024 | D5: 45678 | E5: 45678 | F5: 45723 | G5: 45723 | H5: =F5 | I5: BG1024 | J5: listed as 'BG1024- R&D'
A6: 5 | B6: BSS1024 | D6: 45679 | E6: 45679 | F6: 45720 | G6: 45720 | H6: =F6 | I6: BSS1024 | J6: listed as 'BSS1024- R&D'
A7: 6 | B7: HPA1024 | D7: 45679 | E7: 45679 | F7: 45758 | G7: 45758 | H7: =F7 | I7: HPA1024 | J7: listed as 'HPA1024- R&D'
A8: 7 | B8: GG1024_01 | C8: P050092 | D8: 45733 | E8: 45734 | F8: 45869 | G8: 45874 | H8: =F8 | I8: GG1024_01 | J8: packaging: year 2025 inferred (not printed)
A9: 8 | B9: GP0824_01 | C9: P050102 | D9: 45736 | E9: 45737 | F9: 45874 | G9: 45876 | H9: =F9 | I9: GP0824_01 | J9: packaging: year 2025 inferred (not printed)
A10: 9 | B10: OMP1024_01 | C10: P050042 | D10: 45742 | E10: 45743 | F10: 45828 | G10: 45828 | H10: =F10 | I10: OMP1024_01
A11: 10 | B11: MB0824_04 | C11: P050032 | D11: 45749 | E11: 45750 | F11: 45824 | G11: 45827 | H11: =F11 | I11: MB0824_04
A12: 11 | B12: GG1024_02 | C12: P050012 | D12: 45761 | E12: 45762 | F12: 45819 | G12: 45824 | H12: =F12 | I12: GG1024_02
A13: 12 | B13: GP0824_02 | C13: P050022 | D13: 45769 | E13: 45770 | F13: 45811 | G13: 45819 | H13: =F13 | I13: GP0824_02
A14: 13 | B14: HPA1024_01 | C14: P050052 | D14: 45804 | E14: 45805 | F14: 45835 | G14: 45842 | H14: =F14 | I14: HPA1024_01
A15: 14 | B15: OPM1024_02 | C15: P050062 | D15: 45806 | E15: 45807 | F15: 45842 | G15: 45848 | H15: =F15 | I15: OPM1024_02
A16: 15 | B16: BSS1024_01/1 | C16: P050122 | D16: 45812 | E16: 45813 | F16: 45901 | G16: 45909 | H16: =F16 | I16: BSS1024_01/1 | J16: packaging: year 2025 inferred (not printed)
A17: 16 | B17: BSS1024_01/2 | C17: P050142 | D17: — not given — | E17: — not given — | F17: 45930 | G17: 45930 | H17: =F17 | I17: P050142 | J17: harvest: no date given; packaging: year 2025 inferred (not printed)
A18: 17 | B18: GP0824_03 | C18: P050072 | D18: 45817 | E18: 45818 | F18: 45852 | G18: 45855 | H18: =F18 | I18: GP0824_03 | J18: packaging: year 2025 inferred (not printed)
A19: 18 | B19: OPM1024_03 | C19: P050082 | D19: 45839 | E19: 45840 | F19: 45860 | G19: 45868 | H19: =F19 | I19: OPM1024_03
A20: 19 | B20: MB0824_05 | C20: P050112 | D20: 45846 | E20: 45847 | F20: 45894 | G20: 45900 | H20: =F20 | I20: MB0824_05 | J20: packaging: year 2025 inferred (not printed)
A21: 20 | B21: OPM052501 | C21: P050132 | D21: 45880 | E21: 45882 | F21: 45909 | G21: 45915 | H21: =F21 | I21: OPM052501 | J21: packaging: year 2025 inferred (not printed)
A22: 21 | B22: GP052501 | C22: P050152 | D22: — not given — | E22: — not given — | F22: 45925 | G22: 45925 | H22: =F22 | I22: GP052501 | J22: harvest: no date given
A23: 22 | B23: CJ052501/01 | C23: P050162 | D23: 45889 | E23: 45889 | F23: 45930 | G23: 45931 | H23: =F23 | I23: CJ052501/01
A24: 23 | B24: CJ052501/02 | C24: P050172 | D24: 45889 | E24: 45889 | F24: 45931 | G24: 45932 | H24: =F24 | I24: CJ052501/02
A25: 24 | B25: HPA052501 | C25: P050182 | D25: 45890 | E25: 45892 | F25: 45933 | G25: 45939 | H25: =F25 | I25: HPA052501
A26: 25 | B26: BSS052501 | C26: P050192 | D26: 45901 | E26: 45903 | F26: 45940 | G26: 45951 | H26: =F26 | I26: BSS052501
A27: 26 | B27: GP062501 | C27: P050202 | D27: 45915 | E27: 45917 | F27: 45960 | G27: 45968 | H27: =F27 | I27: GP062501
A28: 27 | B28: SC062501 | C28: P050242 | D28: 45917 | E28: 45917 | F28: 45988 | G28: 45988 | H28: =F28 | I28: — not on the tracker —
A29: 28 | B29: GOG062501 | C29: P050232 | D29: 45917 | E29: 45917 | F29: 45988 | G29: 45988 | H29: =F29 | I29: — not on the tracker —
A30: 29 | B30: CJ062501/1 | C30: P050222 | D30: 45923 | E30: 45923 | F30: 45985 | G30: 45986 | H30: =F30 | I30: CJ062501/1
A31: 30 | B31: CJ062501/2 | C31: P050212 | D31: 45923 | E31: 45924 | F31: 45979 | G31: 45985 | H31: =F31 | I31: CJ062501/2
A32: 31 | B32: CJ072501 | C32: P050252 | D32: 45957 | E32: 45957 | F32: 45988 | G32: 45989 | H32: =F32 | I32: CJ072501
A33: 32 | B33: PM072501 | C33: P050272 | D33: 45957 | E33: 45957 | F33: 45993 | G33: 45994 | H33: =F33 | I33: PM072501
A34: 33 | B34: WC072501 | C34: P050262 | D34: 45957 | E34: 45958 | F34: 45992 | G34: 45992 | H34: =F34 | I34: WC072501
A35: 34 | B35: CLE072501 | C35: P050282 | D35: 45958 | E35: 45958 | F35: 45994 | G35: 45995 | H35: =F35 | I35: CLE072501
A36: 35 | B36: GP072501/1 | C36: P050292 | D36: 45972 | E36: 45974 | F36: 46006 | G36: 46012 | H36: =F36 | I36: GP072501/1 | J36: harvest: printed 11-13-11.2025, read as 11-13.11.2025
A37: 36 | B37: GP072501/2 | C37: P050302 | D37: 45974 | E37: 45974 | F37: 46013 | G37: 46013 | H37: =F37 | I37: GP072501/2
A38: 37 | B38: GP082501/1 | C38: P050312 | D38: 45980 | E38: 45981 | F38: 46014 | G38: 46017 | H38: =F38 | I38: GP082501/1
A39: 38 | B39: GP082501/2 | C39: P050322 | D39: 45981 | E39: 45981 | F39: 46017 | G39: 46017 | H39: =F39 | I39: GP082501/2
A40: 39 | B40: WC082501 | C40: P060012 | D40: 46000 | E40: 46000 | F40: 46035 | G40: 46036 | H40: =F40 | I40: WC082501
...

Sheet Read Me
A1: iCoA Issuance Register — preliminary — built with CoQ Analysis Master v11 on 05.09.2026
A2: Head of QC, 05.09.2026: preliminary iCoA issuance register. Document codes iCoA-PP_26-nnn (nnn = 001 … 999), one series for the year of issue, assigned in the order the certificates can be issued: by the earliest permissible issue date, then by the basis date (the first day of packaging, when the sample is taken). Every printed issue date lies in [11.05.2026 … the day of signing] — the CoQ SOP came into use on 11.05.2026 and no document is post-dated — and, Head of QC 05.09.2026, every certificate whose lot was packed before the SOP floor is issued on ONE day, 13.05.2026 (a Wednesday), in chronological order of packaging; the lots packed after it follow, each on its last day of packaging, the numbers running on. No number is reserved for a row that cannot be issued yet: a lot without a packaging date, a held result, and every retest iCoA (identification A, B and foreign matter are tested at the retest sampling, whose date is not on the desk). Where a CNP certificate reports all three, no iCoA is needed. The plan's references of 31.08.2026 (iCoA-PP-YYYY-NNNN) are superseded by these codes and kept beside them. Identification C is not on the iCoA: the CoQ cites the cannabinoid-assay eCoA named here. TWO CERTIFICATES PER P LOT (05.09.2026): identification A and B on the P01-02 master, foreign matter on the P07 master. FORMULAS: No. counts the issuable rows above it, the code is built from No., the earliest and preliminary dates from the SOP floor and the packaging dates looked up on Batch Dates by P batch (or CU batch); insert a row, set Issuable to yes, and every code beneath moves by one — the iCoA Issuance sheet and the tracker cite the register by KEY, so they follow. Rows are not re-sorted by a formula: a changed date is a manual move.
A3: Source: CoQ_Analysis_Master_v11.xlsx, sheets iCoA Issuance and Batch Dates; dates from the Head of QC's list of 04.09.2026; the issuance plan of 31.08.2026 for the CoQ numbers.
