Workbook

Sheet iCoA Register
A1: No. | B1: iCoA code | C1: Issuable | D1: Issue date (planned) | E1: Test date (packaging) | F1: Packaging complete | G1: Group | H1: Series | I1: CU Batch | J1: P Batch | K1: Strain | L1: iCoA scope | M1: CNP reference | N1: CoQ (register) | O1: Plan reference (31.08.2026) | P1: Basis date | Q1: Harvest | R1: Packaging | S1: CoQ issue (planned) | T1: #1 Ident. A | U1: #2 Ident. B | V1: #7 Foreign matter | W1: Ident C — covered by (eCoA) | X1: Retest assay #4–#6 (eCoA) | Y1: Retest mycotoxins #10 (eCoA) | Z1: Carried forward | AA1: Key | AB1: Status
A2: 1 | B2: iCoA-PP_26-001 | C2: yes | D2: =IF(A2="","",IF(ISNUMBER(E2),MAX(DATE(2026,6,3),E2),DATE(2026,6,3))) | E2: =IFERROR(INDEX('Batch Dates'!$F:$F,MATCH(J2,'Batch Dates'!$C:$C,0)),IFERROR(INDEX('Batch Dates'!$F:$F,MATCH(I2,'Batch Dates'!$B:$B,0)),"")) | F2: =IFERROR(INDEX('Batch Dates'!$G:$G,MATCH(J2,'Batch Dates'!$C:$C,0)),IFERROR(INDEX('Batch Dates'!$G:$G,MATCH(I2,'Batch Dates'!$B:$B,0)),"")) | G2: legacy | H2: initial release | I2: CJ1024 | J2: N/A — no P batch assigned | K2: Cap Junky | L2: Ident A + Ident B + Foreign matter | M2: — | N2: =IFERROR(INDEX('CoQ Register'!$B:$B,MATCH("CJ1024|I",'CoQ Register'!$S:$S,0)),"—") | O2: — | P2: 27.02.2025 | Q2: 20.01.2025 | R2: 03.03.2025 (the issuance plan's basis: 27.02.2025) | S2: =IFERROR(INDEX('CoQ Register'!$D:$D,MATCH("CJ1024|I",'CoQ Register'!$S:$S,0)),"") | T2: Conforms | U2: Conforms | V2: Conforms | W2: ППК25052, (26.02.2025) [CNP] | X2: — | Y2: — | Z2: — | AA2: CJ1024|I | AB2: registered — initial release, issued 03.06.2026
A3: 2 | B3: iCoA-PP_26-002 | C3: yes | D3: =IF(A3="","",IF(ISNUMBER(E3),MAX(DATE(2026,6,3),E3),DATE(2026,6,3))) | E3: =IFERROR(INDEX('Batch Dates'!$F:$F,MATCH(J3,'Batch Dates'!$C:$C,0)),IFERROR(INDEX('Batch Dates'!$F:$F,MATCH(I3,'Batch Dates'!$B:$B,0)),"")) | F3: =IFERROR(INDEX('Batch Dates'!$G:$G,MATCH(J3,'Batch Dates'!$C:$C,0)),IFERROR(INDEX('Batch Dates'!$G:$G,MATCH(I3,'Batch Dates'!$B:$B,0)),"")) | G3: legacy | H3: initial release | I3: BSS1024 | J3: N/A — no P batch assigned | K3: Blue Sunset Sherbet | L3: Ident A + Ident B + Foreign matter | M3: — | N3: =IFERROR(INDEX('CoQ Register'!$B:$B,MATCH("BSS1024|I",'CoQ Register'!$S:$S,0)),"—") | O3: iCoA-PP-2025-0001 | P3: 04.03.2025 | Q3: 22.01.2025 | R3: 04.03.2025 | S3: =IFERROR(INDEX('CoQ Register'!$D:$D,MATCH("BSS1024|I",'CoQ Register'!$S:$S,0)),"") | T3: Conforms | U3: Conforms | V3: Conforms | W3: ППК25051, (26.02.2025) [CNP] | X3: — | Y3: — | Z3: — | AA3: BSS1024|I | AB3: registered — initial release, issued 03.06.2026
A4: 3 | B4: iCoA-PP_26-003 | C4: yes | D4: =IF(A4="","",IF(ISNUMBER(E4),MAX(DATE(2026,6,3),E4),DATE(2026,6,3))) | E4: =IFERROR(INDEX('Batch Dates'!$F:$F,MATCH(J4,'Batch Dates'!$C:$C,0)),IFERROR(INDEX('Batch Dates'!$F:$F,MATCH(I4,'Batch Dates'!$B:$B,0)),"")) | F4: =IFERROR(INDEX('Batch Dates'!$G:$G,MATCH(J4,'Batch Dates'!$C:$C,0)),IFERROR(INDEX('Batch Dates'!$G:$G,MATCH(I4,'Batch Dates'!$B:$B,0)),"")) | G4: legacy | H4: initial release | I4: BG1024 | J4: N/A — no P batch assigned | K4: Blue Gelato | L4: Ident A + Ident B + Foreign matter | M4: — | N4: =IFERROR(INDEX('CoQ Register'!$B:$B,MATCH("BG1024|I",'CoQ Register'!$S:$S,0)),"—") | O4: iCoA-PP-2025-0002 | P4: 07.03.2025 | Q4: 21.01.2025 | R4: 07.03.2025 | S4: =IFERROR(INDEX('CoQ Register'!$D:$D,MATCH("BG1024|I",'CoQ Register'!$S:$S,0)),"") | T4: Conforms | U4: Conforms | V4: Conforms | W4: ППК25050, (26.02.2025) [CNP] | X4: — | Y4: — | Z4: — | AA4: BG1024|I | AB4: registered — initial release, issued 03.06.2026
A5: 4 | B5: iCoA-PP_26-004 | C5: yes | D5: =IF(A5="","",IF(ISNUMBER(E5),MAX(DATE(2026,6,3),E5),DATE(2026,6,3))) | E5: =IFERROR(INDEX('Batch Dates'!$F:$F,MATCH(J5,'Batch Dates'!$C:$C,0)),IFERROR(INDEX('Batch Dates'!$F:$F,MATCH(I5,'Batch Dates'!$B:$B,0)),"")) | F5: =IFERROR(INDEX('Batch Dates'!$G:$G,MATCH(J5,'Batch Dates'!$C:$C,0)),IFERROR(INDEX('Batch Dates'!$G:$G,MATCH(I5,'Batch Dates'!$B:$B,0)),"")) | G5: legacy | H5: initial release | I5: GG1024 | J5: N/A — no P batch assigned | K5: Gorilla Glue | L5: Ident A + Ident B + Foreign matter | M5: — | N5: =IFERROR(INDEX('CoQ Register'!$B:$B,MATCH("GG1024|I",'CoQ Register'!$S:$S,0)),"—") | O5: iCoA-PP-2025-0003 | P5: 11.03.2025 | Q5: 20.01.2025 | R5: 11.03.2025 | S5: =IFERROR(INDEX('CoQ Register'!$D:$D,MATCH("GG1024|I",'CoQ Register'!$S:$S,0)),"") | T5: Conforms | U5: Conforms | V5: Conforms | W5: — no cannabinoid certificate from the initial testing — | X5: — | Y5: — | Z5: — | AA5: GG1024|I | AB5: registered — initial release, issued 03.06.2026
A6: 5 | B6: iCoA-PP_26-005 | C6: yes | D6: =IF(A6="","",IF(ISNUMBER(E6),MAX(DATE(2026,6,3),E6),DATE(2026,6,3))) | E6: =IFERROR(INDEX('Batch Dates'!$F:$F,MATCH(J6,'Batch Dates'!$C:$C,0)),IFERROR(INDEX('Batch Dates'!$F:$F,MATCH(I6,'Batch Dates'!$B:$B,0)),"")) | F6: =IFERROR(INDEX('Batch Dates'!$G:$G,MATCH(J6,'Batch Dates'!$C:$C,0)),IFERROR(INDEX('Batch Dates'!$G:$G,MATCH(I6,'Batch Dates'!$B:$B,0)),"")) | G6: legacy | H6: initial release | I6: HPA1024 | J6: N/A — no P batch assigned | K6: High Pro Amnesia | L6: Ident A + Ident B + #4 + #5 + Foreign matter + #9.1 + #9.2 + #9.3 + #9.4 + #9.5 + #10.2 + #11.1 + #11.2 + #11.3 + #11.4 + #12 | M6: — | N6: =IFERROR(INDEX('CoQ Register'!$B:$B,MATCH("HPA1024|I",'CoQ Register'!$S:$S,0)),"—") | O6: iCoA-PP-2025-0004 | P6: 11.04.2025 | Q6: 22.01.2025 | R6: 11.04.2025 | S6: =IFERROR(INDEX('CoQ Register'!$D:$D,MATCH("HPA1024|I",'CoQ Register'!$S:$S,0)),"") | T6: Conforms | U6: Conforms | V6: Conforms | W6: — no cannabinoid certificate from the initial testing — | X6: — | Y6: — | Z6: — | AA6: HPA1024|I | AB6: registered — initial release, issued 03.06.2026
A7: 6 | B7: iCoA-PP_26-006 | C7: yes | D7: =IF(A7="","",IF(ISNUMBER(E7),MAX(DATE(2026,6,3),E7),DATE(2026,6,3))) | E7: =IFERROR(INDEX('Batch Dates'!$F:$F,MATCH(J7,'Batch Dates'!$C:$C,0)),IFERROR(INDEX('Batch Dates'!$F:$F,MATCH(I7,'Batch Dates'!$B:$B,0)),"")) | F7: =IFERROR(INDEX('Batch Dates'!$G:$G,MATCH(J7,'Batch Dates'!$C:$C,0)),IFERROR(INDEX('Batch Dates'!$G:$G,MATCH(I7,'Batch Dates'!$B:$B,0)),"")) | G7: legacy | H7: initial release | I7: OPM1024 | J7: N/A — no P batch assigned | K7: Orange Punch Mimosa | L7: Ident A + Ident B + #4 + #5 + Foreign matter + #9.1 + #9.2 + #9.3 + #9.4 + #9.5 + #10.2 + #11.1 + #11.2 + #11.3 + #11.4 + #12 | M7: — | N7: =IFERROR(INDEX('CoQ Register'!$B:$B,MATCH("OPM1024|I",'CoQ Register'!$S:$S,0)),"—") | O7: iCoA-PP-2025-0005 | P7: 24.04.2025 | Q7: 21.01.2025 | R7: 24.04.2025 – 25.04.2025 | S7: =IFERROR(INDEX('CoQ Register'!$D:$D,MATCH("OPM1024|I",'CoQ Register'!$S:$S,0)),"") | T7: Conforms | U7: Conforms | V7: Conforms | W7: — no cannabinoid certificate from the initial testing — | X7: — | Y7: — | Z7: — | AA7: OPM1024|I | AB7: registered — initial release, issued 03.06.2026
A8: 7 | B8: iCoA-PP_26-007 | C8: yes | D8: =IF(A8="","",IF(ISNUMBER(E8),MAX(DATE(2026,6,3),E8),DATE(2026,6,3))) | E8: =IFERROR(INDEX('Batch Dates'!$F:$F,MATCH(J8,'Batch Dates'!$C:$C,0)),IFERROR(INDEX('Batch Dates'!$F:$F,MATCH(I8,'Batch Dates'!$B:$B,0)),"")) | F8: =IFERROR(INDEX('Batch Dates'!$G:$G,MATCH(J8,'Batch Dates'!$C:$C,0)),IFERROR(INDEX('Batch Dates'!$G:$G,MATCH(I8,'Batch Dates'!$B:$B,0)),"")) | G8: legacy | H8: initial release | I8: GP0824_02 | J8: P050022 | K8: Grape Pie | L8: Ident A + Ident B + Foreign matter | M8: — | N8: =IFERROR(INDEX('CoQ Register'!$B:$B,MATCH("P050022|I",'CoQ Register'!$S:$S,0)),"—") | O8: iCoA-PP-2025-0006 | P8: 03.06.2025 | Q8: 22.04.2025 – 23.04.2025 | R8: 03.06.2025 – 11.06.2025 | S8: =IFERROR(INDEX('CoQ Register'!$D:$D,MATCH("P050022|I",'CoQ Register'!$S:$S,0)),"") | T8: Conforms | U8: Conforms | V8: Conforms | W8: ППК25139, (22.05.2025) [CNP] | X8: — | Y8: — | Z8: — | AA8: P050022|I | AB8: registered — initial release, issued 03.06.2026
A9: 8 | B9: iCoA-PP_26-008 | C9: yes | D9: =IF(A9="","",IF(ISNUMBER(E9),MAX(DATE(2026,6,3),E9),DATE(2026,6,3))) | E9: =IFERROR(INDEX('Batch Dates'!$F:$F,MATCH(J9,'Batch Dates'!$C:$C,0)),IFERROR(INDEX('Batch Dates'!$F:$F,MATCH(I9,'Batch Dates'!$B:$B,0)),"")) | F9: =IFERROR(INDEX('Batch Dates'!$G:$G,MATCH(J9,'Batch Dates'!$C:$C,0)),IFERROR(INDEX('Batch Dates'!$G:$G,MATCH(I9,'Batch Dates'!$B:$B,0)),"")) | G9: legacy | H9: initial release | I9: GG1024_02 | J9: P050012 | K9: Gorilla Glue | L9: Ident A + Ident B + Foreign matter | M9: — | N9: =IFERROR(INDEX('CoQ Register'!$B:$B,MATCH("P050012|I",'CoQ Register'!$S:$S,0)),"—") | O9: — | P9: 30.05.2025 | Q9: 14.04.2025 – 15.04.2025 | R9: 11.06.2025 – 16.06.2025 (the issuance plan's basis: 30.05.2025) | S9: =IFERROR(INDEX('CoQ Register'!$D:$D,MATCH("P050012|I",'CoQ Register'!$S:$S,0)),"") | T9: Conforms | U9: Conforms | V9: Conforms | W9: ППК25140, (22.05.2025) [CNP] | X9: — | Y9: — | Z9: — | AA9: P050012|I | AB9: registered — initial release, issued 03.06.2026
A10: 9 | B10: iCoA-PP_26-009 | C10: yes | D10: =IF(A10="","",IF(ISNUMBER(E10),MAX(DATE(2026,6,3),E10),DATE(2026,6,3))) | E10: =IFERROR(INDEX('Batch Dates'!$F:$F,MATCH(J10,'Batch Dates'!$C:$C,0)),IFERROR(INDEX('Batch Dates'!$F:$F,MATCH(I10,'Batch Dates'!$B:$B,0)),"")) | F10: =IFERROR(INDEX('Batch Dates'!$G:$G,MATCH(J10,'Batch Dates'!$C:$C,0)),IFERROR(INDEX('Batch Dates'!$G:$G,MATCH(I10,'Batch Dates'!$B:$B,0)),"")) | G10: legacy | H10: initial release | I10: MB0824_04 | J10: P050032 | K10: Motor Breath | L10: Ident A + Ident B + Foreign matter | M10: — | N10: =IFERROR(INDEX('CoQ Register'!$B:$B,MATCH("P050032|I",'CoQ Register'!$S:$S,0)),"—") | O10: — | P10: 07.05.2025 | Q10: 02.04.2025 – 03.04.2025 | R10: 16.06.2025 – 19.06.2025 (the issuance plan's basis: 07.05.2025) | S10: =IFERROR(INDEX('CoQ Register'!$D:$D,MATCH("P050032|I",'CoQ Register'!$S:$S,0)),"") | T10: Conforms | U10: Conforms | V10: Conforms | W10: ППК25118, (06.05.2025) [CNP] | X10: — | Y10: — | Z10: — | AA10: P050032|I | AB10: registered — initial release, issued 03.06.2026
A11: 10 | B11: iCoA-PP_26-010 | C11: yes | D11: =IF(A11="","",IF(ISNUMBER(E11),MAX(DATE(2026,6,3),E11),DATE(2026,6,3))) | E11: =IFERROR(INDEX('Batch Dates'!$F:$F,MATCH(J11,'Batch Dates'!$C:$C,0)),IFERROR(INDEX('Batch Dates'!$F:$F,MATCH(I11,'Batch Dates'!$B:$B,0)),"")) | F11: =IFERROR(INDEX('Batch Dates'!$G:$G,MATCH(J11,'Batch Dates'!$C:$C,0)),IFERROR(INDEX('Batch Dates'!$G:$G,MATCH(I11,'Batch Dates'!$B:$B,0)),"")) | G11: legacy | H11: initial release | I11: HPA1024_01 | J11: P050052 | K11: High Pro Amnesia | L11: Ident A + Ident B + Foreign matter | M11: — | N11: =IFERROR(INDEX('CoQ Register'!$B:$B,MATCH("P050052|I",'CoQ Register'!$S:$S,0)),"—") | O11: iCoA-PP-2025-0008 | P11: 27.06.2025 | Q11: 27.05.2025 – 28.05.2025 | R11: 27.06.2025 – 04.07.2025 | S11: =IFERROR(INDEX('CoQ Register'!$D:$D,MATCH("P050052|I",'CoQ Register'!$S:$S,0)),"") | T11: Conforms | U11: Conforms | V11: Conforms | W11: ППК25155, (24.06.2025) [CNP] | X11: — | Y11: — | Z11: — | AA11: P050052|I | AB11: registered — initial release, issued 03.06.2026
A12: 11 | B12: iCoA-PP_26-011 | C12: yes | D12: =IF(A12="","",IF(ISNUMBER(E12),MAX(DATE(2026,6,3),E12),DATE(2026,6,3))) | E12: =IFERROR(INDEX('Batch Dates'!$F:$F,MATCH(J12,'Batch Dates'!$C:$C,0)),IFERROR(INDEX('Batch Dates'!$F:$F,MATCH(I12,'Batch Dates'!$B:$B,0)),"")) | F12: =IFERROR(INDEX('Batch Dates'!$G:$G,MATCH(J12,'Batch Dates'!$C:$C,0)),IFERROR(INDEX('Batch Dates'!$G:$G,MATCH(I12,'Batch Dates'!$B:$B,0)),"")) | G12: legacy | H12: initial release | I12: OPM1024_02 | J12: P050062 | K12: Orange Punch Mimosa | L12: Ident A + Ident B + Foreign matter | M12: — | N12: =IFERROR(INDEX('CoQ Register'!$B:$B,MATCH("P050062|I",'CoQ Register'!$S:$S,0)),"—") | O12: iCoA-PP-2025-0009 | P12: 04.07.2025 | Q12: 29.05.2025 – 30.05.2025 | R12: 04.07.2025 – 10.07.2025 | S12: =IFERROR(INDEX('CoQ Register'!$D:$D,MATCH("P050062|I",'CoQ Register'!$S:$S,0)),"") | T12: Conforms | U12: Conforms | V12: Conforms | W12: ППК25154, (24.06.2025) [CNP] | X12: — | Y12: — | Z12: — | AA12: P050062|I | AB12: registered — initial release, issued 03.06.2026
A13: 12 | B13: iCoA-PP_26-012 | C13: yes | D13: =IF(A13="","",IF(ISNUMBER(E13),MAX(DATE(2026,6,3),E13),DATE(2026,6,3))) | E13: =IFERROR(INDEX('Batch Dates'!$F:$F,MATCH(J13,'Batch Dates'!$C:$C,0)),IFERROR(INDEX('Batch Dates'!$F:$F,MATCH(I13,'Batch Dates'!$B:$B,0)),"")) | F13: =IFERROR(INDEX('Batch Dates'!$G:$G,MATCH(J13,'Batch Dates'!$C:$C,0)),IFERROR(INDEX('Batch Dates'!$G:$G,MATCH(I13,'Batch Dates'!$B:$B,0)),"")) | G13: legacy | H13: initial release | I13: GP0824_03 | J13: P050072 | K13: Grape Pie | L13: Ident A + Ident B + Foreign matter | M13: — | N13: =IFERROR(INDEX('CoQ Register'!$B:$B,MATCH("P050072|I",'CoQ Register'!$S:$S,0)),"—") | O13: iCoA-PP-2025-0010 | P13: 14.07.2025 | Q13: 09.06.2025 – 10.06.2025 | R13: 14.07.2025 – 17.07.2025 | S13: =IFERROR(INDEX('CoQ Register'!$D:$D,MATCH("P050072|I",'CoQ Register'!$S:$S,0)),"") | T13: Conforms | U13: Conforms | V13: Conforms | W13: ППК25175, (10.07.2025) [CNP] | X13: — | Y13: — | Z13: — | AA13: P050072|I | AB13: registered — initial release, issued 03.06.2026
A14: 13 | B14: iCoA-PP_26-013 | C14: yes | D14: =IF(A14="","",IF(ISNUMBER(E14),MAX(DATE(2026,6,3),E14),DATE(2026,6,3))) | E14: =IFERROR(INDEX('Batch Dates'!$F:$F,MATCH(J14,'Batch Dates'!$C:$C,0)),IFERROR(INDEX('Batch Dates'!$F:$F,MATCH(I14,'Batch Dates'!$B:$B,0)),"")) | F14: =IFERROR(INDEX('Batch Dates'!$G:$G,MATCH(J14,'Batch Dates'!$C:$C,0)),IFERROR(INDEX('Batch Dates'!$G:$G,MATCH(I14,'Batch Dates'!$B:$B,0)),"")) | G14: legacy | H14: initial release | I14: OPM1024_03 | J14: P050082 | K14: Orange Punch Mimosa | L14: Ident A + Ident B + Foreign matter | M14: — | N14: =IFERROR(INDEX('CoQ Register'!$B:$B,MATCH("P050082|I",'CoQ Register'!$S:$S,0)),"—") | O14: iCoA-PP-2025-0011 | P14: 22.07.2025 | Q14: 01.07.2025 – 02.07.2025 | R14: 22.07.2025 – 30.07.2025 | S14: =IFERROR(INDEX('CoQ Register'!$D:$D,MATCH("P050082|I",'CoQ Register'!$S:$S,0)),"") | T14: Conforms | U14: Conforms | V14: Conforms | W14: ППК25210, (28.07.2025) [CNP] | X14: — | Y14: — | Z14: — | AA14: P050082|I | AB14: registered — initial release, issued 03.06.2026
A15: 14 | B15: iCoA-PP_26-014 | C15: yes | D15: =IF(A15="","",IF(ISNUMBER(E15),MAX(DATE(2026,6,3),E15),DATE(2026,6,3))) | E15: =IFERROR(INDEX('Batch Dates'!$F:$F,MATCH(J15,'Batch Dates'!$C:$C,0)),IFERROR(INDEX('Batch Dates'!$F:$F,MATCH(I15,'Batch Dates'!$B:$B,0)),"")) | F15: =IFERROR(INDEX('Batch Dates'!$G:$G,MATCH(J15,'Batch Dates'!$C:$C,0)),IFERROR(INDEX('Batch Dates'!$G:$G,MATCH(I15,'Batch Dates'!$B:$B,0)),"")) | G15: legacy | H15: initial release | I15: GG1024_01 | J15: P050092 | K15: Gorilla Glue | L15: Ident A + Ident B + Foreign matter | M15: — | N15: =IFERROR(INDEX('CoQ Register'!$B:$B,MATCH("P050092|I",'CoQ Register'!$S:$S,0)),"—") | O15: iCoA-PP-2025-0012 | P15: 31.07.2025 | Q15: 17.03.2025 – 18.03.2025 | R15: 31.07.2025 – 05.08.2025 | S15: =IFERROR(INDEX('CoQ Register'!$D:$D,MATCH("P050092|I",'CoQ Register'!$S:$S,0)),"") | T15: Conforms | U15: Conforms | V15: Conforms | W15: ППК25104, (17.04.2025) [CNP] | X15: — | Y15: — | Z15: — | AA15: P050092|I | AB15: registered — initial release, issued 03.06.2026
A16: 15 | B16: iCoA-PP_26-015 | C16: yes | D16: =IF(A16="","",IF(ISNUMBER(E16),MAX(DATE(2026,6,3),E16),DATE(2026,6,3))) | E16: =IFERROR(INDEX('Batch Dates'!$F:$F,MATCH(J16,'Batch Dates'!$C:$C,0)),IFERROR(INDEX('Batch Dates'!$F:$F,MATCH(I16,'Batch Dates'!$B:$B,0)),"")) | F16: =IFERROR(INDEX('Batch Dates'!$G:$G,MATCH(J16,'Batch Dates'!$C:$C,0)),IFERROR(INDEX('Batch Dates'!$G:$G,MATCH(I16,'Batch Dates'!$B:$B,0)),"")) | G16: legacy | H16: initial release | I16: GP0824_01 | J16: P050102 | K16: Grape Pie | L16: Ident A + Ident B + Foreign matter | M16: — | N16: =IFERROR(INDEX('CoQ Register'!$B:$B,MATCH("P050102|I",'CoQ Register'!$S:$S,0)),"—") | O16: — | P16: 17.04.2025 | Q16: 20.03.2025 – 21.03.2025 | R16: 05.08.2025 – 07.08.2025 (the issuance plan's basis: 17.04.2025) | S16: =IFERROR(INDEX('CoQ Register'!$D:$D,MATCH("P050102|I",'CoQ Register'!$S:$S,0)),"") | T16: Conforms | U16: Conforms | V16: Conforms | W16: ППК25105, (17.04.2025) [CNP] | X16: — | Y16: — | Z16: — | AA16: P050102|I | AB16: registered — initial release, issued 03.06.2026
A17: 16 | B17: iCoA-PP_26-016 | C17: yes | D17: =IF(A17="","",IF(ISNUMBER(E17),MAX(DATE(2026,6,3),E17),DATE(2026,6,3))) | E17: =IFERROR(INDEX('Batch Dates'!$F:$F,MATCH(J17,'Batch Dates'!$C:$C,0)),IFERROR(INDEX('Batch Dates'!$F:$F,MATCH(I17,'Batch Dates'!$B:$B,0)),"")) | F17: =IFERROR(INDEX('Batch Dates'!$G:$G,MATCH(J17,'Batch Dates'!$C:$C,0)),IFERROR(INDEX('Batch Dates'!$G:$G,MATCH(I17,'Batch Dates'!$B:$B,0)),"")) | G17: legacy | H17: initial release | I17: MB0824_05 | J17: P050112 | K17: Motor Breath | L17: Ident A + Ident B + Foreign matter | M17: — | N17: =IFERROR(INDEX('CoQ Register'!$B:$B,MATCH("P050112|I",'CoQ Register'!$S:$S,0)),"—") | O17: iCoA-PP-2025-0013 | P17: 25.08.2025 | Q17: 08.07.2025 – 09.07.2025 | R17: 25.08.2025 – 31.08.2025 | S17: =IFERROR(INDEX('CoQ Register'!$D:$D,MATCH("P050112|I",'CoQ Register'!$S:$S,0)),"") | T17: Conforms | U17: Conforms | V17: Conforms | W17: ППК25211, (28.07.2025) [CNP] | X17: — | Y17: — | Z17: — | AA17: P050112|I | AB17: registered — initial release, issued 03.06.2026
A18: 17 | B18: iCoA-PP_26-017 | C18: yes | D18: =IF(A18="","",IF(ISNUMBER(E18),MAX(DATE(2026,6,3),E18),DATE(2026,6,3))) | E18: =IFERROR(INDEX('Batch Dates'!$F:$F,MATCH(J18,'Batch Dates'!$C:$C,0)),IFERROR(INDEX('Batch Dates'!$F:$F,MATCH(I18,'Batch Dates'!$B:$B,0)),"")) | F18: =IFERROR(INDEX('Batch Dates'!$G:$G,MATCH(J18,'Batch Dates'!$C:$C,0)),IFERROR(INDEX('Batch Dates'!$G:$G,MATCH(I18,'Batch Dates'!$B:$B,0)),"")) | G18: legacy | H18: initial release | I18: OPM052501 | J18: P050132 | K18: Orange Punch Mimosa | L18: Ident A + Ident B + Foreign matter | M18: — | N18: =IFERROR(INDEX('CoQ Register'!$B:$B,MATCH("P050132|I",'CoQ Register'!$S:$S,0)),"—") | O18: — | P18: 05.09.2025 | Q18: 11.08.2025 – 13.08.2025 | R18: 09.09.2025 – 15.09.2025 (the issuance plan's basis: 05.09.2025) | S18: =IFERROR(INDEX('CoQ Register'!$D:$D,MATCH("P050132|I",'CoQ Register'!$S:$S,0)),"") | T18: Conforms | U18: Conforms | V18: Conforms | W18: ППК25257, (05.09.2025) [CNP] | X18: — | Y18: — | Z18: — | AA18: P050132|I | AB18: registered — initial release, issued 03.06.2026
A19: 18 | B19: iCoA-PP_26-018 | C19: yes | D19: =IF(A19="","",IF(ISNUMBER(E19),MAX(DATE(2026,6,3),E19),DATE(2026,6,3))) | E19: =IFERROR(INDEX('Batch Dates'!$F:$F,MATCH(J19,'Batch Dates'!$C:$C,0)),IFERROR(INDEX('Batch Dates'!$F:$F,MATCH(I19,'Batch Dates'!$B:$B,0)),"")) | F19: =IFERROR(INDEX('Batch Dates'!$G:$G,MATCH(J19,'Batch Dates'!$C:$C,0)),IFERROR(INDEX('Batch Dates'!$G:$G,MATCH(I19,'Batch Dates'!$B:$B,0)),"")) | G19: legacy | H19: initial release | I19: GP052501 | J19: P050152 | K19: Grape Pie | L19: Ident A + Ident B + Foreign matter | M19: — | N19: =IFERROR(INDEX('CoQ Register'!$B:$B,MATCH("P050152|I",'CoQ Register'!$S:$S,0)),"—") | O19: iCoA-PP-2025-0014 | P19: 25.09.2025 | Q19: — not given — | R19: 25.09.2025 | S19: =IFERROR(INDEX('CoQ Register'!$D:$D,MATCH("P050152|I",'CoQ Register'!$S:$S,0)),"") | T19: Conforms | U19: Conforms | V19: Conforms | W19: ППК25279, (19.09.2025) [CNP] | X19: — | Y19: — | Z19: — | AA19: P050152|I | AB19: registered — initial release, issued 03.06.2026
A20: 19 | B20: iCoA-PP_26-019 | C20: yes | D20: =IF(A20="","",IF(ISNUMBER(E20),MAX(DATE(2026,6,3),E20),DATE(2026,6,3))) | E20: =IFERROR(INDEX('Batch Dates'!$F:$F,MATCH(J20,'Batch Dates'!$C:$C,0)),IFERROR(INDEX('Batch Dates'!$F:$F,MATCH(I20,'Batch Dates'!$B:$B,0)),"")) | F20: =IFERROR(INDEX('Batch Dates'!$G:$G,MATCH(J20,'Batch Dates'!$C:$C,0)),IFERROR(INDEX('Batch Dates'!$G:$G,MATCH(I20,'Batch Dates'!$B:$B,0)),"")) | G20: legacy | H20: initial release | I20: BSS1024_01/2 | J20: P050142 | K20: Blue Sunset Sherbet | L20: Ident A + Ident B + Foreign matter | M20: — | N20: =IFERROR(INDEX('CoQ Register'!$B:$B,MATCH("P050142|I",'CoQ Register'!$S:$S,0)),"—") | O20: — | P20: 30.09.2025 | Q20: — not given — | R20: 30.09.2025 | S20: =IFERROR(INDEX('CoQ Register'!$D:$D,MATCH("P050142|I",'CoQ Register'!$S:$S,0)),"") | T20: Conforms | U20: Conforms | V20: Conforms | W20: — no cannabinoid certificate from the initial testing — | X20: — | Y20: — | Z20: — | AA20: P050142|I | AB20: registered — initial release, issued 03.06.2026
A21: 20 | B21: iCoA-PP_26-020 | C21: yes | D21: =IF(A21="","",IF(ISNUMBER(E21),MAX(DATE(2026,6,3),E21),DATE(2026,6,3))) | E21: =IFERROR(INDEX('Batch Dates'!$F:$F,MATCH(J21,'Batch Dates'!$C:$C,0)),IFERROR(INDEX('Batch Dates'!$F:$F,MATCH(I21,'Batch Dates'!$B:$B,0)),"")) | F21: =IFERROR(INDEX('Batch Dates'!$G:$G,MATCH(J21,'Batch Dates'!$C:$C,0)),IFERROR(INDEX('Batch Dates'!$G:$G,MATCH(I21,'Batch Dates'!$B:$B,0)),"")) | G21: legacy | H21: initial release | I21: CJ052501/01 | J21: P050162 | K21: Cap Junky | L21: Ident A + Ident B + Foreign matter | M21: — | N21: =IFERROR(INDEX('CoQ Register'!$B:$B,MATCH("P050162|I",'CoQ Register'!$S:$S,0)),"—") | O21: iCoA-PP-2025-0015 | P21: 30.09.2025 | Q21: 20.08.2025 | R21: 30.09.2025 – 01.10.2025 | S21: =IFERROR(INDEX('CoQ Register'!$D:$D,MATCH("P050162|I",'CoQ Register'!$S:$S,0)),"") | T21: Conforms | U21: Conforms | V21: Conforms | W21: ППК25280, (17.09.2025) [CNP] | X21: — | Y21: — | Z21: — | AA21: P050162|I | AB21: registered — initial release, issued 03.06.2026
A22: 21 | B22: iCoA-PP_26-021 | C22: yes | D22: =IF(A22="","",IF(ISNUMBER(E22),MAX(DATE(2026,6,3),E22),DATE(2026,6,3))) | E22: =IFERROR(INDEX('Batch Dates'!$F:$F,MATCH(J22,'Batch Dates'!$C:$C,0)),IFERROR(INDEX('Batch Dates'!$F:$F,MATCH(I22,'Batch Dates'!$B:$B,0)),"")) | F22: =IFERROR(INDEX('Batch Dates'!$G:$G,MATCH(J22,'Batch Dates'!$C:$C,0)),IFERROR(INDEX('Batch Dates'!$G:$G,MATCH(I22,'Batch Dates'!$B:$B,0)),"")) | G22: legacy | H22: initial release | I22: CJ052501/02 | J22: P050172 | K22: Cap Junky | L22: Ident A + Ident B + Foreign matter | M22: — | N22: =IFERROR(INDEX('CoQ Register'!$B:$B,MATCH("P050172|I",'CoQ Register'!$S:$S,0)),"—") | O22: — | P22: 17.09.2025 | Q22: 20.08.2025 | R22: 01.10.2025 – 02.10.2025 (the issuance plan's basis: 17.09.2025) | S22: =IFERROR(INDEX('CoQ Register'!$D:$D,MATCH("P050172|I",'CoQ Register'!$S:$S,0)),"") | T22: Conforms | U22: Conforms | V22: Conforms | W22: ППК25281, (17.09.2025) [CNP] | X22: — | Y22: — | Z22: — | AA22: P050172|I | AB22: registered — initial release, issued 03.06.2026
A23: 22 | B23: iCoA-PP_26-022 | C23: yes | D23: =IF(A23="","",IF(ISNUMBER(E23),MAX(DATE(2026,6,3),E23),DATE(2026,6,3))) | E23: =IFERROR(INDEX('Batch Dates'!$F:$F,MATCH(J23,'Batch Dates'!$C:$C,0)),IFERROR(INDEX('Batch Dates'!$F:$F,MATCH(I23,'Batch Dates'!$B:$B,0)),"")) | F23: =IFERROR(INDEX('Batch Dates'!$G:$G,MATCH(J23,'Batch Dates'!$C:$C,0)),IFERROR(INDEX('Batch Dates'!$G:$G,MATCH(I23,'Batch Dates'!$B:$B,0)),"")) | G23: legacy | H23: initial release | I23: HPA052501 | J23: P050182 | K23: High Pro Amnesia | L23: Ident A + Ident B + Foreign matter | M23: — | N23: =IFERROR(INDEX('CoQ Register'!$B:$B,MATCH("P050182|I",'CoQ Register'!$S:$S,0)),"—") | O23: iCoA-PP-2025-0016 | P23: 03.10.2025 | Q23: 21.08.2025 – 23.08.2025 | R23: 03.10.2025 – 09.10.2025 | S23: =IFERROR(INDEX('CoQ Register'!$D:$D,MATCH("P050182|I",'CoQ Register'!$S:$S,0)),"") | T23: Conforms | U23: Conforms | V23: Conforms | W23: ППК25278, (19.09.2025) [CNP] | X23: — | Y23: — | Z23: — | AA23: P050182|I | AB23: registered — initial release, issued 03.06.2026
A24: 23 | B24: iCoA-PP_26-023 | C24: yes | D24: =IF(A24="","",IF(ISNUMBER(E24),MAX(DATE(2026,6,3),E24),DATE(2026,6,3))) | E24: =IFERROR(INDEX('Batch Dates'!$F:$F,MATCH(J24,'Batch Dates'!$C:$C,0)),IFERROR(INDEX('Batch Dates'!$F:$F,MATCH(I24,'Batch Dates'!$B:$B,0)),"")) | F24: =IFERROR(INDEX('Batch Dates'!$G:$G,MATCH(J24,'Batch Dates'!$C:$C,0)),IFERROR(INDEX('Batch Dates'!$G:$G,MATCH(I24,'Batch Dates'!$B:$B,0)),"")) | G24: legacy | H24: initial release | I24: BSS052501 | J24: P050192 | K24: Blue Sunset Sherbet | L24: Ident A + Ident B + #4 + #5 + Foreign matter + #8 | M24: — | N24: =IFERROR(INDEX('CoQ Register'!$B:$B,MATCH("P050192|I",'CoQ Register'!$S:$S,0)),"—") | O24: iCoA-PP-2025-0017 | P24: 10.10.2025 | Q24: 01.09.2025 – 03.09.2025 | R24: 10.10.2025 – 21.10.2025 | S24: =IFERROR(INDEX('CoQ Register'!$D:$D,MATCH("P050192|I",'CoQ Register'!$S:$S,0)),"") | T24: Conforms | U24: Conforms | V24: Conforms | W24: NGP-QCG-SOP-024 F3, (28.11.2025) [NGP] | X24: — | Y24: — | Z24: — | AA24: P050192|I | AB24: registered — initial release, issued 03.06.2026
A25: 24 | B25: iCoA-PP_26-024 | C25: yes | D25: =IF(A25="","",IF(ISNUMBER(E25),MAX(DATE(2026,6,3),E25),DATE(2026,6,3))) | E25: =IFERROR(INDEX('Batch Dates'!$F:$F,MATCH(J25,'Batch Dates'!$C:$C,0)),IFERROR(INDEX('Batch Dates'!$F:$F,MATCH(I25,'Batch Dates'!$B:$B,0)),"")) | F25: =IFERROR(INDEX('Batch Dates'!$G:$G,MATCH(J25,'Batch Dates'!$C:$C,0)),IFERROR(INDEX('Batch Dates'!$G:$G,MATCH(I25,'Batch Dates'!$B:$B,0)),"")) | G25: legacy | H25: initial release | I25: GP062501 | J25: P050202 | K25: Grape Pie | L25: Ident A + Ident B + #4 + #5 + Foreign matter + #8 | M25: — | N25: =IFERROR(INDEX('CoQ Register'!$B:$B,MATCH("P050202|I",'CoQ Register'!$S:$S,0)),"—") | O25: — | P25: 11.05.2026 | Q25: 15.09.2025 – 17.09.2025 | R25: 30.10.2025 – 07.11.2025 (the issuance plan's basis: 11.05.2026) | S25: =IFERROR(INDEX('CoQ Register'!$D:$D,MATCH("P050202|I",'CoQ Register'!$S:$S,0)),"") | T25: Conforms | U25: Conforms | V25: Conforms | W25: NGP-QCG-SOP-024 F3, (28.11.2025) [NGP] | X25: — | Y25: — | Z25: — | AA25: P050202|I | AB25: registered — initial release, issued 03.06.2026
A26: 25 | B26: iCoA-PP_26-025 | C26: yes | D26: =IF(A26="","",IF(ISNUMBER(E26),MAX(DATE(2026,6,3),E26),DATE(2026,6,3))) | E26: =IFERROR(INDEX('Batch Dates'!$F:$F,MATCH(J26,'Batch Dates'!$C:$C,0)),IFERROR(INDEX('Batch Dates'!$F:$F,MATCH(I26,'Batch Dates'!$B:$B,0)),"")) | F26: =IFERROR(INDEX('Batch Dates'!$G:$G,MATCH(J26,'Batch Dates'!$C:$C,0)),IFERROR(INDEX('Batch Dates'!$G:$G,MATCH(I26,'Batch Dates'!$B:$B,0)),"")) | G26: legacy | H26: initial release | I26: CJ062501/2 | J26: P050212 | K26: Cap Junky | L26: Ident A + Ident B + Foreign matter | M26: — | N26: =IFERROR(INDEX('CoQ Register'!$B:$B,MATCH("P050212|I",'CoQ Register'!$S:$S,0)),"—") | O26: — | P26: 24.01.2026 | Q26: 23.09.2025 – 24.09.2025 | R26: 18.11.2025 – 24.11.2025 (the issuance plan's basis: 24.01.2026) | S26: =IFERROR(INDEX('CoQ Register'!$D:$D,MATCH("P050212|I",'CoQ Register'!$S:$S,0)),"") | T26: Conforms | U26: Conforms | V26: Conforms | W26: ППК25322, (23.10.2025) [CNP] | X26: — | Y26: — | Z26: — | AA26: P050212|I | AB26: registered — initial release, issued 03.06.2026
A27: 26 | B27: iCoA-PP_26-026 | C27: yes | D27: =IF(A27="","",IF(ISNUMBER(E27),MAX(DATE(2026,6,3),E27),DATE(2026,6,3))) | E27: =IFERROR(INDEX('Batch Dates'!$F:$F,MATCH(J27,'Batch Dates'!$C:$C,0)),IFERROR(INDEX('Batch Dates'!$F:$F,MATCH(I27,'Batch Dates'!$B:$B,0)),"")) | F27: =IFERROR(INDEX('Batch Dates'!$G:$G,MATCH(J27,'Batch Dates'!$C:$C,0)),IFERROR(INDEX('Batch Dates'!$G:$G,MATCH(I27,'Batch Dates'!$B:$B,0)),"")) | G27: legacy | H27: initial release | I27: CJ062501/1 | J27: P050222 | K27: Cap Junky | L27: Ident A + Ident B + Foreign matter | M27: — | N27: =IFERROR(INDEX('CoQ Register'!$B:$B,MATCH("P050222|I",'CoQ Register'!$S:$S,0)),"—") | O27: iCoA-PP-2025-0018 | P27: 24.11.2025 | Q27: 23.09.2025 | R27: 24.11.2025 – 25.11.2025 | S27: =IFERROR(INDEX('CoQ Register'!$D:$D,MATCH("P050222|I",'CoQ Register'!$S:$S,0)),"") | T27: Conforms | U27: Conforms | V27: Conforms | W27: ППК25321, (23.10.2025) [CNP] | X27: — | Y27: — | Z27: — | AA27: P050222|I | AB27: registered — initial release, issued 03.06.2026
A28: 27 | B28: iCoA-PP_26-027 | C28: yes | D28: =IF(A28="","",IF(ISNUMBER(E28),MAX(DATE(2026,6,3),E28),DATE(2026,6,3))) | E28: =IFERROR(INDEX('Batch Dates'!$F:$F,MATCH(J28,'Batch Dates'!$C:$C,0)),IFERROR(INDEX('Batch Dates'!$F:$F,MATCH(I28,'Batch Dates'!$B:$B,0)),"")) | F28: =IFERROR(INDEX('Batch Dates'!$G:$G,MATCH(J28,'Batch Dates'!$C:$C,0)),IFERROR(INDEX('Batch Dates'!$G:$G,MATCH(I28,'Batch Dates'!$B:$B,0)),"")) | G28: legacy | H28: initial release | I28: CJ072501 | J28: P050252 | K28: Cap Junky | L28: Ident A + Ident B + Foreign matter | M28: — | N28: =IFERROR(INDEX('CoQ Register'!$B:$B,MATCH("P050252|I",'CoQ Register'!$S:$S,0)),"—") | O28: — | P28: 02.12.2025 | Q28: 27.10.2025 | R28: 27.11.2025 – 28.11.2025 (the issuance plan's basis: 02.12.2025) | S28: =IFERROR(INDEX('CoQ Register'!$D:$D,MATCH("P050252|I",'CoQ Register'!$S:$S,0)),"") | T28: Conforms | U28: Conforms | V28: Conforms | W28: ППК25367, (28.11.2025) [CNP] | X28: — | Y28: — | Z28: — | AA28: P050252|I | AB28: registered — initial release, issued 03.06.2026
A29: 28 | B29: iCoA-PP_26-028 | C29: yes | D29: =IF(A29="","",IF(ISNUMBER(E29),MAX(DATE(2026,6,3),E29),DATE(2026,6,3))) | E29: =IFERROR(INDEX('Batch Dates'!$F:$F,MATCH(J29,'Batch Dates'!$C:$C,0)),IFERROR(INDEX('Batch Dates'!$F:$F,MATCH(I29,'Batch Dates'!$B:$B,0)),"")) | F29: =IFERROR(INDEX('Batch Dates'!$G:$G,MATCH(J29,'Batch Dates'!$C:$C,0)),IFERROR(INDEX('Batch Dates'!$G:$G,MATCH(I29,'Batch Dates'!$B:$B,0)),"")) | G29: legacy | H29: initial release | I29: WC072501 | J29: P050262 | K29: Wedding Crasher | L29: Ident A + Ident B + Foreign matter | M29: — | N29: =IFERROR(INDEX('CoQ Register'!$B:$B,MATCH("P050262|I",'CoQ Register'!$S:$S,0)),"—") | O29: — | P29: 02.12.2025 | Q29: 27.10.2025 – 28.10.2025 | R29: 01.12.2025 (the issuance plan's basis: 02.12.2025) | S29: =IFERROR(INDEX('CoQ Register'!$D:$D,MATCH("P050262|I",'CoQ Register'!$S:$S,0)),"") | T29: Conforms | U29: Conforms | V29: Conforms | W29: ППК25369, (28.11.2025) [CNP] | X29: — | Y29: — | Z29: — | AA29: P050262|I | AB29: registered — initial release, issued 03.06.2026
A30: 29 | B30: iCoA-PP_26-029 | C30: yes | D30: =IF(A30="","",IF(ISNUMBER(E30),MAX(DATE(2026,6,3),E30),DATE(2026,6,3))) | E30: =IFERROR(INDEX('Batch Dates'!$F:$F,MATCH(J30,'Batch Dates'!$C:$C,0)),IFERROR(INDEX('Batch Dates'!$F:$F,MATCH(I30,'Batch Dates'!$B:$B,0)),"")) | F30: =IFERROR(INDEX('Batch Dates'!$G:$G,MATCH(J30,'Batch Dates'!$C:$C,0)),IFERROR(INDEX('Batch Dates'!$G:$G,MATCH(I30,'Batch Dates'!$B:$B,0)),"")) | G30: legacy | H30: initial release | I30: PM072501 | J30: P050272 | K30: Permanent Market | L30: Ident A + Ident B + Foreign matter | M30: — | N30: =IFERROR(INDEX('CoQ Register'!$B:$B,MATCH("P050272|I",'CoQ Register'!$S:$S,0)),"—") | O30: — | P30: 21.01.2026 | Q30: 27.10.2025 | R30: 02.12.2025 – 03.12.2025 (the issuance plan's basis: 21.01.2026) | S30: =IFERROR(INDEX('CoQ Register'!$D:$D,MATCH("P050272|I",'CoQ Register'!$S:$S,0)),"") | T30: Conforms | U30: Conforms | V30: Conforms | W30: ППК25368, (28.11.2025) [CNP] | X30: — | Y30: — | Z30: — | AA30: P050272|I | AB30: registered — initial release, issued 03.06.2026
A31: 30 | B31: iCoA-PP_26-030 | C31: yes | D31: =IF(A31="","",IF(ISNUMBER(E31),MAX(DATE(2026,6,3),E31),DATE(2026,6,3))) | E31: =IFERROR(INDEX('Batch Dates'!$F:$F,MATCH(J31,'Batch Dates'!$C:$C,0)),IFERROR(INDEX('Batch Dates'!$F:$F,MATCH(I31,'Batch Dates'!$B:$B,0)),"")) | F31: =IFERROR(INDEX('Batch Dates'!$G:$G,MATCH(J31,'Batch Dates'!$C:$C,0)),IFERROR(INDEX('Batch Dates'!$G:$G,MATCH(I31,'Batch Dates'!$B:$B,0)),"")) | G31: legacy | H31: initial release | I31: CLE072501 | J31: P050282 | K31: Clemosa a bud | L31: Ident A + Ident B + Foreign matter | M31: — | N31: =IFERROR(INDEX('CoQ Register'!$B:$B,MATCH("P050282|I",'CoQ Register'!$S:$S,0)),"—") | O31: iCoA-PP-2025-0019 | P31: 03.12.2025 | Q31: 28.10.2025 | R31: 03.12.2025 – 04.12.2025 | S31: =IFERROR(INDEX('CoQ Register'!$D:$D,MATCH("P050282|I",'CoQ Register'!$S:$S,0)),"") | T31: Conforms | U31: Conforms | V31: Conforms | W31: ППК25370, (28.11.2025) [CNP] | X31: — | Y31: — | Z31: — | AA31: P050282|I | AB31: registered — initial release, issued 03.06.2026
A32: 31 | B32: iCoA-PP_26-031 | C32: yes | D32: =IF(A32="","",IF(ISNUMBER(E32),MAX(DATE(2026,6,3),E32),DATE(2026,6,3))) | E32: =IFERROR(INDEX('Batch Dates'!$F:$F,MATCH(J32,'Batch Dates'!$C:$C,0)),IFERROR(INDEX('Batch Dates'!$F:$F,MATCH(I32,'Batch Dates'!$B:$B,0)),"")) | F32: =IFERROR(INDEX('Batch Dates'!$G:$G,MATCH(J32,'Batch Dates'!$C:$C,0)),IFERROR(INDEX('Batch Dates'!$G:$G,MATCH(I32,'Batch Dates'!$B:$B,0)),"")) | G32: legacy | H32: initial release | I32: GP072501/1 | J32: P050292 | K32: Grape Pie | L32: Ident A + Ident B + Foreign matter | M32: — | N32: =IFERROR(INDEX('CoQ Register'!$B:$B,MATCH("P050292|I",'CoQ Register'!$S:$S,0)),"—") | O32: — | P32: 21.01.2026 | Q32: 11.11.2025 – 13.11.2025 | R32: 15.12.2025 – 21.12.2025 (the issuance plan's basis: 21.01.2026) | S32: =IFERROR(INDEX('CoQ Register'!$D:$D,MATCH("P050292|I",'CoQ Register'!$S:$S,0)),"") | T32: Conforms | U32: Conforms | V32: Conforms | W32: ППК25378, (12.12.2025) [CNP] | X32: — | Y32: — | Z32: — | AA32: P050292|I | AB32: registered — initial release, issued 03.06.2026
A33: 32 | B33: iCoA-PP_26-032 | C33: yes | D33: =IF(A33="","",IF(ISNUMBER(E33),MAX(DATE(2026,6,3),E33),DATE(2026,6,3))) | E33: =IFERROR(INDEX('Batch Dates'!$F:$F,MATCH(J33,'Batch Dates'!$C:$C,0)),IFERROR(INDEX('Batch Dates'!$F:$F,MATCH(I33,'Batch Dates'!$B:$B,0)),"")) | F33: =IFERROR(INDEX('Batch Dates'!$G:$G,MATCH(J33,'Batch Dates'!$C:$C,0)),IFERROR(INDEX('Batch Dates'!$G:$G,MATCH(I33,'Batch Dates'!$B:$B,0)),"")) | G33: legacy | H33: initial release | I33: GP072501/2 | J33: P050302 | K33: Grape Pie | L33: Ident A + Ident B + Foreign matter | M33: — | N33: =IFERROR(INDEX('CoQ Register'!$B:$B,MATCH("P050302|I",'CoQ Register'!$S:$S,0)),"—") | O33: iCoA-PP-2025-0020 | P33: 22.12.2025 | Q33: 13.11.2025 | R33: 22.12.2025 | S33: =IFERROR(INDEX('CoQ Register'!$D:$D,MATCH("P050302|I",'CoQ Register'!$S:$S,0)),"") | T33: Conforms | U33: Conforms | V33: Conforms | W33: ППК25379, (12.12.2025) [CNP] | X33: — | Y33: — | Z33: — | AA33: P050302|I | AB33: registered — initial release, issued 03.06.2026
A34: 33 | B34: iCoA-PP_26-033 | C34: yes | D34: =IF(A34="","",IF(ISNUMBER(E34),MAX(DATE(2026,6,3),E34),DATE(2026,6,3))) | E34: =IFERROR(INDEX('Batch Dates'!$F:$F,MATCH(J34,'Batch Dates'!$C:$C,0)),IFERROR(INDEX('Batch Dates'!$F:$F,MATCH(I34,'Batch Dates'!$B:$B,0)),"")) | F34: =IFERROR(INDEX('Batch Dates'!$G:$G,MATCH(J34,'Batch Dates'!$C:$C,0)),IFERROR(INDEX('Batch Dates'!$G:$G,MATCH(I34,'Batch Dates'!$B:$B,0)),"")) | G34: legacy | H34: initial release | I34: GP082501/1 | J34: P050312 | K34: Grape Pie | L34: Ident A + Ident B + Foreign matter | M34: — | N34: =IFERROR(INDEX('CoQ Register'!$B:$B,MATCH("P050312|I",'CoQ Register'!$S:$S,0)),"—") | O34: iCoA-PP-2025-0021 | P34: 23.12.2025 | Q34: 19.11.2025 – 20.11.2025 | R34: 23.12.2025 – 26.12.2025 | S34: =IFERROR(INDEX('CoQ Register'!$D:$D,MATCH("P050312|I",'CoQ Register'!$S:$S,0)),"") | T34: Conforms | U34: Conforms | V34: Conforms | W34: ППК25380, (12.12.2025) [CNP] | X34: — | Y34: — | Z34: — | AA34: P050312|I | AB34: registered — initial release, issued 03.06.2026
A35: 34 | B35: iCoA-PP_26-034 | C35: yes | D35: =IF(A35="","",IF(ISNUMBER(E35),MAX(DATE(2026,6,3),E35),DATE(2026,6,3))) | E35: =IFERROR(INDEX('Batch Dates'!$F:$F,MATCH(J35,'Batch Dates'!$C:$C,0)),IFERROR(INDEX('Batch Dates'!$F:$F,MATCH(I35,'Batch Dates'!$B:$B,0)),"")) | F35: =IFERROR(INDEX('Batch Dates'!$G:$G,MATCH(J35,'Batch Dates'!$C:$C,0)),IFERROR(INDEX('Batch Dates'!$G:$G,MATCH(I35,'Batch Dates'!$B:$B,0)),"")) | G35: legacy | H35: initial release | I35: GP082501/2 | J35: P050322 | K35: Grape Pie | L35: Ident A + Ident B + Foreign matter | M35: — | N35: =IFERROR(INDEX('CoQ Register'!$B:$B,MATCH("P050322|I",'CoQ Register'!$S:$S,0)),"—") | O35: iCoA-PP-2025-0022 | P35: 26.12.2025 | Q35: 20.11.2025 | R35: 26.12.2025 | S35: =IFERROR(INDEX('CoQ Register'!$D:$D,MATCH("P050322|I",'CoQ Register'!$S:$S,0)),"") | T35: Conforms | U35: Conforms | V35: Conforms | W35: ППК25381, (12.12.2025) [CNP] | X35: — | Y35: — | Z35: — | AA35: P050322|I | AB35: registered — initial release, issued 03.06.2026
A36: 35 | B36: iCoA-PP_26-035 | C36: yes | D36: =IF(A36="","",IF(ISNUMBER(E36),MAX(DATE(2026,6,3),E36),DATE(2026,6,3))) | E36: =IFERROR(INDEX('Batch Dates'!$F:$F,MATCH(J36,'Batch Dates'!$C:$C,0)),IFERROR(INDEX('Batch Dates'!$F:$F,MATCH(I36,'Batch Dates'!$B:$B,0)),"")) | F36: =IFERROR(INDEX('Batch Dates'!$G:$G,MATCH(J36,'Batch Dates'!$C:$C,0)),IFERROR(INDEX('Batch Dates'!$G:$G,MATCH(I36,'Batch Dates'!$B:$B,0)),"")) | G36: legacy | H36: initial release | I36: WC082501 | J36: P060012 | K36: Wedding Crasher | L36: Ident A + Ident B + Foreign matter | M36: — | N36: =IFERROR(INDEX('CoQ Register'!$B:$B,MATCH("P060012|I",'CoQ Register'!$S:$S,0)),"—") | O36: iCoA-PP-2026-0001 | P36: 13.01.2026 | Q36: 09.12.2025 | R36: 13.01.2026 – 14.01.2026 | S36: =IFERROR(INDEX('CoQ Register'!$D:$D,MATCH("P060012|I",'CoQ Register'!$S:$S,0)),"") | T36: Conforms | U36: Conforms | V36: Conforms | W36: ППК26001, (21.01.2026) [CNP] | X36: — | Y36: — | Z36: — | AA36: P060012|I | AB36: registered — initial release, issued 03.06.2026
A37: 36 | B37: iCoA-PP_26-036 | C37: yes | D37: =IF(A37="","",IF(ISNUMBER(E37),MAX(DATE(2026,6,3),E37),DATE(2026,6,3))) | E37: =IFERROR(INDEX('Batch Dates'!$F:$F,MATCH(J37,'Batch Dates'!$C:$C,0)),IFERROR(INDEX('Batch Dates'!$F:$F,MATCH(I37,'Batch Dates'!$B:$B,0)),"")) | F37: =IFERROR(INDEX('Batch Dates'!$G:$G,MATCH(J37,'Batch Dates'!$C:$C,0)),IFERROR(INDEX('Batch Dates'!$G:$G,MATCH(I37,'Batch Dates'!$B:$B,0)),"")) | G37: legacy | H37: initial release | I37: CJ082501/1 | J37: P060022 | K37: Cap Junky | L37: Ident A + Ident B + Foreign matter | M37: — | N37: =IFERROR(INDEX('CoQ Register'!$B:$B,MATCH("P060022|I",'CoQ Register'!$S:$S,0)),"—") | O37: iCoA-PP-2026-0002 | P37: 16.01.2026 | Q37: 09.12.2025 – 10.12.2025 | R37: 16.01.2026 | S37: =IFERROR(INDEX('CoQ Register'!$D:$D,MATCH("P060022|I",'CoQ Register'!$S:$S,0)),"") | T37: Conforms | U37: Conforms | V37: Conforms | W37: ППК26002, (21.01.2026) [CNP] | X37: — | Y37: — | Z37: — | AA37: P060022|I | AB37: registered — initial release, issued 03.06.2026
A38: 37 | B38: iCoA-PP_26-037 | C38: yes | D38: =IF(A38="","",IF(ISNUMBER(E38),MAX(DATE(2026,6,3),E38),DATE(2026,6,3))) | E38: =IFERROR(INDEX('Batch Dates'!$F:$F,MATCH(J38,'Batch Dates'!$C:$C,0)),IFERROR(INDEX('Batch Dates'!$F:$F,MATCH(I38,'Batch Dates'!$B:$B,0)),"")) | F38: =IFERROR(INDEX('Batch Dates'!$G:$G,MATCH(J38,'Batch Dates'!$C:$C,0)),IFERROR(INDEX('Batch Dates'!$G:$G,MATCH(I38,'Batch Dates'!$B:$B,0)),"")) | G38: legacy | H38: initial release | I38: CJ082501/2 | J38: P060032 | K38: Cap Junky | L38: Ident A + Ident B + Foreign matter | M38: — | N38: =IFERROR(INDEX('CoQ Register'!$B:$B,MATCH("P060032|I",'CoQ Register'!$S:$S,0)),"—") | O38: iCoA-PP-2026-0003 | P38: 29.01.2026 | Q38: 10.12.2025 | R38: 29.01.2026 | S38: =IFERROR(INDEX('CoQ Register'!$D:$D,MATCH("P060032|I",'CoQ Register'!$S:$S,0)),"") | T38: Conforms | U38: Conforms | V38: Conforms | W38: ППК26003, (21.01.2026) [CNP] | X38: — | Y38: — | Z38: — | AA38: P060032|I | AB38: registered — initial release, issued 03.06.2026
A39: 38 | B39: iCoA-PP_26-038 | C39: yes | D39: =IF(A39="","",IF(ISNUMBER(E39),MAX(DATE(2026,6,3),E39),DATE(2026,6,3))) | E39: =IFERROR(INDEX('Batch Dates'!$F:$F,MATCH(J39,'Batch Dates'!$C:$C,0)),IFERROR(INDEX('Batch Dates'!$F:$F,MATCH(I39,'Batch Dates'!$B:$B,0)),"")) | F39: =IFERROR(INDEX('Batch Dates'!$G:$G,MATCH(J39,'Batch Dates'!$C:$C,0)),IFERROR(INDEX('Batch Dates'!$G:$G,MATCH(I39,'Batch Dates'!$B:$B,0)),"")) | G39: legacy | H39: initial release | I39: OPM092501 | J39: P060042 | K39: Orange Punch Mimosa | L39: Ident A + Ident B + Foreign matter | M39: — | N39: =IFERROR(INDEX('CoQ Register'!$B:$B,MATCH("P060042|I",'CoQ Register'!$S:$S,0)),"—") | O39: iCoA-PP-2026-0004 | P39: 29.01.2026 | Q39: 12.12.2025 | R39: 29.01.2026 | S39: =IFERROR(INDEX('CoQ Register'!$D:$D,MATCH("P060042|I",'CoQ Register'!$S:$S,0)),"") | T39: Conforms | U39: Conforms | V39: Conforms | W39: ППК26008, (21.01.2026) [CNP] | X39: — | Y39: — | Z39: — | AA39: P060042|I | AB39: registered — initial release, issued 03.06.2026
A40: 39 | B40: iCoA-PP_26-039 | C40: yes | D40: =IF(A40="","",IF(ISNUMBER(E40),MAX(DATE(2026,6,3),E40),DATE(2026,6,3))) | E40: =IFERROR(INDEX('Batch Dates'!$F:$F,MATCH(J40,'Batch Dates'!$C:$C,0)),IFERROR(INDEX('Batch Dates'!$F:$F,MATCH(I40,'Batch Dates'!$B:$B,0)),"")) | F40: =IFERROR(INDEX('Batch Dates'!$G:$G,MATCH(J40,'Batch Dates'!$C:$C,0)),IFERROR(INDEX('Batch Dates'!$G:$G,MATCH(I40,'Batch Dates'!$B:$B,0)),"")) | G40: legacy | H40: initial release | I40: AB092501 | J40: P060052 | K40: Apple and Banana | L40: Ident A + Ident B + Foreign matter | M40: — | N40: =IFERROR(INDEX('CoQ Register'!$B:$B,MATCH("P060052|I",'CoQ Register'!$S:$S,0)),"—") | O40: — | P40: 20.02.2026 | Q40: 11.12.2025 | R40: 30.01.2026 (the issuance plan's basis: 20.02.2026) | S40: =IFERROR(INDEX('CoQ Register'!$D:$D,MATCH("P060052|I",'CoQ Register'!$S:$S,0)),"") | T40: Conforms | U40: Conforms | V40: Conforms | W40: ППК26005, (21.01.2026) [CNP] | X40: — | Y40: — | Z40: — | AA40: P060052|I | AB40: registered — initial release, issued 03.06.2026
...

Sheet CoQ Register
A1: No. | B1: CoQ code | C1: Issuable | D1: Issue date (planned) | E1: Rule date | F1: Latest eCoA cited (date) | G1: Latest eCoA cited (code) | H1: iCoA (register) | I1: iCoA issue date | J1: Group | K1: Series | L1: CU Batch | M1: P Batch | N1: Strain | O1: Ident C — eCoA (Total THC) | P1: CNP references | Q1: Supersedes (old in-house CoA) | R1: Plan reference (31.08.2026) | S1: Key | T1: Status | U1: Supersedes (initial CoQ) | V1: Total THC (%) | W1: THC certificate | X1: Grade nominal ± tol. (numeral) | Y1: Grade window | Z1: Product code | AA1: Specification code | AB1: Specification status | AC1: Grading note
A2: =IF(OR(C2="yes",C2="allocated"),COUNT(A$1:A1)+1,"") | B2: =IF(A2<>"","CoQ-PP_26-"&TEXT(A2,"000"),"— at issue —") | C2: yes | D2: =IF(OR(A2="",C2="allocated"),"",MAX(E2,IF(ISNUMBER(I2),I2,0),IFERROR(IF(ISNUMBER(INDEX('iCoA Register'!$F:$F,MATCH(S2,'iCoA Register'!$AA:$AA,0))),INDEX('iCoA Register'!$F:$F,MATCH(S2,'iCoA Register'!$AA:$AA,0)),0),0))) | E2: =IF(ISNUMBER(F2),MAX(DATE(2026,6,6),F2+7),DATE(2026,6,6)) | F2: 45715 | G2: 750-2025 | H2: =IFERROR(INDEX('iCoA Register'!$B:$B,MATCH("CJ1024|I",'iCoA Register'!$AA:$AA,0)),"—") | I2: =IFERROR(INDEX('iCoA Register'!$D:$D,MATCH("CJ1024|I",'iCoA Register'!$AA:$AA,0)),"") | J2: legacy | K2: initial release | L2: CJ1024 | M2: N/A — no P batch assigned | N2: Cap Junky | O2: ППК25052, (26.02.2025) [CNP] | P2: — | Q2: — | R2: (assigned on issue) | S2: CJ1024|I | T2: registered — legacy series, issued 06.06.2026 | U2: n/a — initial certificate | V2: 23 | W2: ППК25052 | X2: 24.00 ± 2.40 (II) | Y2: 21.60 – 26.39 % | Z2: CJ_THC24 : CBD1 | AA2: QCSP_001_CJ-II_v.01 | AB2: for review — replaces the issued QCSP_001_CJ-II_v.01 (was CJ_THC26 : CBD1, 25.01 – 26.99 %); now CJ_THC24 : CBD1 21.60 – 26.39 %
A3: =IF(OR(C3="yes",C3="allocated"),COUNT(A$1:A2)+1,"") | B3: =IF(A3<>"","CoQ-PP_26-"&TEXT(A3,"000"),"— at issue —") | C3: yes | D3: =IF(OR(A3="",C3="allocated"),"",MAX(E3,IF(ISNUMBER(I3),I3,0),IFERROR(IF(ISNUMBER(INDEX('iCoA Register'!$F:$F,MATCH(S3,'iCoA Register'!$AA:$AA,0))),INDEX('iCoA Register'!$F:$F,MATCH(S3,'iCoA Register'!$AA:$AA,0)),0),0))) | E3: =IF(ISNUMBER(F3),MAX(DATE(2026,6,6),F3+7),DATE(2026,6,6)) | F3: 45715 | G3: 751-2025 | H3: =IFERROR(INDEX('iCoA Register'!$B:$B,MATCH("BSS1024|I",'iCoA Register'!$AA:$AA,0)),"—") | I3: =IFERROR(INDEX('iCoA Register'!$D:$D,MATCH("BSS1024|I",'iCoA Register'!$AA:$AA,0)),"") | J3: legacy | K3: initial release | L3: BSS1024 | M3: N/A — no P batch assigned | N3: Blue Sunset Sherbet | O3: ППК25051, (26.02.2025) [CNP] | P3: — | Q3: — | R3: CoQ-PP-2025-0001 | S3: BSS1024|I | T3: registered — legacy series, issued 06.06.2026 | U3: n/a — initial certificate | V3: 21.03 | W3: ППК25051 | X3: 20.00 ± 1.89 (III) | Y3: 18.11 – 21.88 % | Z3: BSS_THC20 : CBD1 | AA3: QCSP_001_BSS-III_v.01 | AB3: for review — new
A4: =IF(OR(C4="yes",C4="allocated"),COUNT(A$1:A3)+1,"") | B4: =IF(A4<>"","CoQ-PP_26-"&TEXT(A4,"000"),"— at issue —") | C4: yes | D4: =IF(OR(A4="",C4="allocated"),"",MAX(E4,IF(ISNUMBER(I4),I4,0),IFERROR(IF(ISNUMBER(INDEX('iCoA Register'!$F:$F,MATCH(S4,'iCoA Register'!$AA:$AA,0))),INDEX('iCoA Register'!$F:$F,MATCH(S4,'iCoA Register'!$AA:$AA,0)),0),0))) | E4: =IF(ISNUMBER(F4),MAX(DATE(2026,6,6),F4+7),DATE(2026,6,6)) | F4: 45715 | G4: 752-2025 | H4: =IFERROR(INDEX('iCoA Register'!$B:$B,MATCH("BG1024|I",'iCoA Register'!$AA:$AA,0)),"—") | I4: =IFERROR(INDEX('iCoA Register'!$D:$D,MATCH("BG1024|I",'iCoA Register'!$AA:$AA,0)),"") | J4: legacy | K4: initial release | L4: BG1024 | M4: N/A — no P batch assigned | N4: Blue Gelato | O4: ППК25050, (26.02.2025) [CNP] | P4: — | Q4: — | R4: CoQ-PP-2025-0002 | S4: BG1024|I | T4: registered — legacy series, issued 06.06.2026 | U4: n/a — initial certificate | V4: 21.8 | W4: ППК25050 | X4: 22.00 ± 2.20 (II) | Y4: 19.80 – 24.19 % | Z4: BG_THC22 : CBD1 | AA4: QCSP_001_BG-II_v.01 | AB4: for review — new
A5: =IF(OR(C5="yes",C5="allocated"),COUNT(A$1:A4)+1,"") | B5: =IF(A5<>"","CoQ-PP_26-"&TEXT(A5,"000"),"— at issue —") | C5: yes | D5: =IF(OR(A5="",C5="allocated"),"",MAX(E5,IF(ISNUMBER(I5),I5,0),IFERROR(IF(ISNUMBER(INDEX('iCoA Register'!$F:$F,MATCH(S5,'iCoA Register'!$AA:$AA,0))),INDEX('iCoA Register'!$F:$F,MATCH(S5,'iCoA Register'!$AA:$AA,0)),0),0))) | E5: =IF(ISNUMBER(F5),MAX(DATE(2026,6,6),F5+7),DATE(2026,6,6)) | F5: — | G5: — | H5: =IFERROR(INDEX('iCoA Register'!$B:$B,MATCH("GG1024|I",'iCoA Register'!$AA:$AA,0)),"—") | I5: =IFERROR(INDEX('iCoA Register'!$D:$D,MATCH("GG1024|I",'iCoA Register'!$AA:$AA,0)),"") | J5: legacy | K5: initial release | L5: GG1024 | M5: N/A — no P batch assigned | N5: Gorilla Glue | O5: — no cannabinoid certificate from the initial testing — | P5: — | Q5: — | R5: CoQ-PP-2025-0003 | S5: GG1024|I | T5: registered — legacy series, issued 06.06.2026 · initial certificate to locate: #3 (CNP), #4 (CNP), #5 (CNP), #6 (CNP), #8 (CNP), #9 (IJZ), #10 (CNP), #11 (CNP), #12 (CNP) | U5: n/a — initial certificate | V5: — | W5: — | X5: — | Y5: — | Z5: — | AA5: — | AB5: — | AC5: no Total THC result on this certificate
A6: =IF(OR(C6="yes",C6="allocated"),COUNT(A$1:A5)+1,"") | B6: =IF(A6<>"","CoQ-PP_26-"&TEXT(A6,"000"),"— at issue —") | C6: yes | D6: =IF(OR(A6="",C6="allocated"),"",MAX(E6,IF(ISNUMBER(I6),I6,0),IFERROR(IF(ISNUMBER(INDEX('iCoA Register'!$F:$F,MATCH(S6,'iCoA Register'!$AA:$AA,0))),INDEX('iCoA Register'!$F:$F,MATCH(S6,'iCoA Register'!$AA:$AA,0)),0),0))) | E6: =IF(ISNUMBER(F6),MAX(DATE(2026,6,6),F6+7),DATE(2026,6,6)) | F6: — | G6: — | H6: =IFERROR(INDEX('iCoA Register'!$B:$B,MATCH("HPA1024|I",'iCoA Register'!$AA:$AA,0)),"—") | I6: =IFERROR(INDEX('iCoA Register'!$D:$D,MATCH("HPA1024|I",'iCoA Register'!$AA:$AA,0)),"") | J6: legacy | K6: initial release | L6: HPA1024 | M6: N/A — no P batch assigned | N6: High Pro Amnesia | O6: — no cannabinoid certificate from the initial testing — | P6: — | Q6: — | R6: CoQ-PP-2025-0004 | S6: HPA1024|I | T6: registered — legacy series, issued 06.06.2026 · initial certificate to locate: #3 (CNP), #4 (CNP), #5 (CNP), #6 (CNP), #8 (CNP), #9 (IJZ), #10 (CNP), #11 (CNP), #12 (CNP) | U6: n/a — initial certificate | V6: 14.97 | W6: iCoA-PP_26-005 | X6: 15.00 ± 1.20 (III) | Y6: 13.80 – 16.19 % | Z6: HPA_THC15 : CBD1 | AA6: QCSP_001_HPA-III_v.01 | AB6: for review — replaces the issued QCSP_001_HPA-III_v.01 (was HPA_THC18 : CBD1, 17.00 – 19.00 %); now HPA_THC15 : CBD1 13.80 – 16.19 %
A7: =IF(OR(C7="yes",C7="allocated"),COUNT(A$1:A6)+1,"") | B7: =IF(A7<>"","CoQ-PP_26-"&TEXT(A7,"000"),"— at issue —") | C7: yes | D7: =IF(OR(A7="",C7="allocated"),"",MAX(E7,IF(ISNUMBER(I7),I7,0),IFERROR(IF(ISNUMBER(INDEX('iCoA Register'!$F:$F,MATCH(S7,'iCoA Register'!$AA:$AA,0))),INDEX('iCoA Register'!$F:$F,MATCH(S7,'iCoA Register'!$AA:$AA,0)),0),0))) | E7: =IF(ISNUMBER(F7),MAX(DATE(2026,6,6),F7+7),DATE(2026,6,6)) | F7: — | G7: — | H7: =IFERROR(INDEX('iCoA Register'!$B:$B,MATCH("OPM1024|I",'iCoA Register'!$AA:$AA,0)),"—") | I7: =IFERROR(INDEX('iCoA Register'!$D:$D,MATCH("OPM1024|I",'iCoA Register'!$AA:$AA,0)),"") | J7: legacy | K7: initial release | L7: OPM1024 | M7: N/A — no P batch assigned | N7: Orange Punch Mimosa | O7: — no cannabinoid certificate from the initial testing — | P7: — | Q7: — | R7: CoQ-PP-2025-0005 | S7: OPM1024|I | T7: registered — legacy series, issued 06.06.2026 · initial certificate to locate: #3 (CNP), #4 (CNP), #5 (CNP), #6 (CNP), #8 (CNP), #9 (IJZ), #10 (CNP), #11 (CNP), #12 (CNP) | U7: n/a — initial certificate | V7: 19.96 | W7: iCoA-PP_26-006 | X7: 20.00 ± 1.40 (I) | Y7: 18.60 – 21.39 % | Z7: OPM_THC20 : CBD1 | AA7: QCSP_001_OPM-I_v.01 | AB7: for review — replaces the issued QCSP_001_OPM-I_v.01 (was OPM_THC22 : CBD1, 19.81 – 24.19 %); now OPM_THC20 : CBD1 18.60 – 21.39 %
A8: =IF(OR(C8="yes",C8="allocated"),COUNT(A$1:A7)+1,"") | B8: =IF(A8<>"","CoQ-PP_26-"&TEXT(A8,"000"),"— at issue —") | C8: yes | D8: =IF(OR(A8="",C8="allocated"),"",MAX(E8,IF(ISNUMBER(I8),I8,0),IFERROR(IF(ISNUMBER(INDEX('iCoA Register'!$F:$F,MATCH(S8,'iCoA Register'!$AA:$AA,0))),INDEX('iCoA Register'!$F:$F,MATCH(S8,'iCoA Register'!$AA:$AA,0)),0),0))) | E8: =IF(ISNUMBER(F8),MAX(DATE(2026,6,6),F8+7),DATE(2026,6,6)) | F8: 45807 | G8: 2471-2025 | H8: =IFERROR(INDEX('iCoA Register'!$B:$B,MATCH("P050022|I",'iCoA Register'!$AA:$AA,0)),"—") | I8: =IFERROR(INDEX('iCoA Register'!$D:$D,MATCH("P050022|I",'iCoA Register'!$AA:$AA,0)),"") | J8: legacy | K8: initial release | L8: GP0824_02 | M8: P050022 | N8: Grape Pie | O8: ППК25139, (22.05.2025) [CNP] | P8: — | Q8: — | R8: CoQ-PP-2025-0006 | S8: P050022|I | T8: registered — legacy series, issued 06.06.2026 | U8: n/a — initial certificate | V8: 23.79 | W8: ППК25139 | X8: 24.00 ± 2.00 (II) | Y8: 22.00 – 25.99 % | Z8: GP_THC24 : CBD1 | AA8: QCSP_001_GP-II_v.01 | AB8: for review — replaces the issued QCSP_001_GP-II_v.01 (was GP_THC26 : CBD1, 25.40 – 26.60 %); now GP_THC24 : CBD1 22.00 – 25.99 %
A9: =IF(OR(C9="yes",C9="allocated"),COUNT(A$1:A8)+1,"") | B9: =IF(A9<>"","CoQ-PP_26-"&TEXT(A9,"000"),"— at issue —") | C9: yes | D9: =IF(OR(A9="",C9="allocated"),"",MAX(E9,IF(ISNUMBER(I9),I9,0),IFERROR(IF(ISNUMBER(INDEX('iCoA Register'!$F:$F,MATCH(S9,'iCoA Register'!$AA:$AA,0))),INDEX('iCoA Register'!$F:$F,MATCH(S9,'iCoA Register'!$AA:$AA,0)),0),0))) | E9: =IF(ISNUMBER(F9),MAX(DATE(2026,6,6),F9+7),DATE(2026,6,6)) | F9: 45807 | G9: 2472-2025 | H9: =IFERROR(INDEX('iCoA Register'!$B:$B,MATCH("P050012|I",'iCoA Register'!$AA:$AA,0)),"—") | I9: =IFERROR(INDEX('iCoA Register'!$D:$D,MATCH("P050012|I",'iCoA Register'!$AA:$AA,0)),"") | J9: legacy | K9: initial release | L9: GG1024_02 | M9: P050012 | N9: Gorilla Glue | O9: ППК25140, (22.05.2025) [CNP] | P9: — | Q9: — | R9: (assigned on issue) | S9: P050012|I | T9: registered — legacy series, issued 06.06.2026 | U9: n/a — initial certificate | V9: 15.95 | W9: ППК25140 | X9: 15.00 ± 1.23 (II) | Y9: 13.77 – 16.22 % | Z9: GG_THC15 : CBD1 | AA9: QCSP_001_GG-II_v.01 | AB9: for review — replaces the issued QCSP_001_GG-II_v.01 (was GG_THC16 : CBD1, 15.00 – 17.00 %); now GG_THC15 : CBD1 13.77 – 16.22 %
A10: =IF(OR(C10="yes",C10="allocated"),COUNT(A$1:A9)+1,"") | B10: =IF(A10<>"","CoQ-PP_26-"&TEXT(A10,"000"),"— at issue —") | C10: yes | D10: =IF(OR(A10="",C10="allocated"),"",MAX(E10,IF(ISNUMBER(I10),I10,0),IFERROR(IF(ISNUMBER(INDEX('iCoA Register'!$F:$F,MATCH(S10,'iCoA Register'!$AA:$AA,0))),INDEX('iCoA Register'!$F:$F,MATCH(S10,'iCoA Register'!$AA:$AA,0)),0),0))) | E10: =IF(ISNUMBER(F10),MAX(DATE(2026,6,6),F10+7),DATE(2026,6,6)) | F10: 45784 | G10: 2157-2025 | H10: =IFERROR(INDEX('iCoA Register'!$B:$B,MATCH("P050032|I",'iCoA Register'!$AA:$AA,0)),"—") | I10: =IFERROR(INDEX('iCoA Register'!$D:$D,MATCH("P050032|I",'iCoA Register'!$AA:$AA,0)),"") | J10: legacy | K10: initial release | L10: MB0824_04 | M10: P050032 | N10: Motor Breath | O10: ППК25118, (06.05.2025) [CNP] | P10: — | Q10: — | R10: (assigned on issue) | S10: P050032|I | T10: registered — legacy series, issued 06.06.2026 | U10: n/a — initial certificate | V10: 18.67 | W10: ППК25118 | X10: 18.00 ± 1.80 (I) | Y10: 16.20 – 19.79 % | Z10: MB_THC18 : CBD1 | AA10: QCSP_001_MB-I_v.01 | AB10: for review — replaces the issued QCSP_001_MB-I_v.01 (was MB_THC18 : CBD1, 16.20 – 19.80 %); now MB_THC18 : CBD1 16.20 – 19.79 %
A11: =IF(OR(C11="yes",C11="allocated"),COUNT(A$1:A10)+1,"") | B11: =IF(A11<>"","CoQ-PP_26-"&TEXT(A11,"000"),"— at issue —") | C11: yes | D11: =IF(OR(A11="",C11="allocated"),"",MAX(E11,IF(ISNUMBER(I11),I11,0),IFERROR(IF(ISNUMBER(INDEX('iCoA Register'!$F:$F,MATCH(S11,'iCoA Register'!$AA:$AA,0))),INDEX('iCoA Register'!$F:$F,MATCH(S11,'iCoA Register'!$AA:$AA,0)),0),0))) | E11: =IF(ISNUMBER(F11),MAX(DATE(2026,6,6),F11+7),DATE(2026,6,6)) | F11: 45784 | G11: 2156-2025 | H11: =IFERROR(INDEX('iCoA Register'!$B:$B,MATCH("P050042|I",'iCoA Register'!$AA:$AA,0)),"—") | I11: =IFERROR(INDEX('iCoA Register'!$D:$D,MATCH("P050042|I",'iCoA Register'!$AA:$AA,0)),"") | J11: legacy | K11: initial release | L11: OMP1024_01 | M11: P050042 | N11: Orange Punch Mimosa | O11: ППК25117, (06.05.2025) [CNP] | P11: — | Q11: — | R11: CoQ-PP-2025-0007 | S11: P050042|I | T11: registered — legacy series, issued 06.06.2026 | U11: n/a — initial certificate | V11: 15.38 | W11: ППК25117 | X11: 14.00 ± 1.40 (III) | Y11: 12.60 – 15.39 % | Z11: OPM_THC14 : CBD1 | AA11: QCSP_001_OPM-III_v.01 | AB11: for review — new
A12: =IF(OR(C12="yes",C12="allocated"),COUNT(A$1:A11)+1,"") | B12: =IF(A12<>"","CoQ-PP_26-"&TEXT(A12,"000"),"— at issue —") | C12: yes | D12: =IF(OR(A12="",C12="allocated"),"",MAX(E12,IF(ISNUMBER(I12),I12,0),IFERROR(IF(ISNUMBER(INDEX('iCoA Register'!$F:$F,MATCH(S12,'iCoA Register'!$AA:$AA,0))),INDEX('iCoA Register'!$F:$F,MATCH(S12,'iCoA Register'!$AA:$AA,0)),0),0))) | E12: =IF(ISNUMBER(F12),MAX(DATE(2026,6,6),F12+7),DATE(2026,6,6)) | F12: 45832 | G12: ППК25155 | H12: =IFERROR(INDEX('iCoA Register'!$B:$B,MATCH("P050052|I",'iCoA Register'!$AA:$AA,0)),"—") | I12: =IFERROR(INDEX('iCoA Register'!$D:$D,MATCH("P050052|I",'iCoA Register'!$AA:$AA,0)),"") | J12: legacy | K12: initial release | L12: HPA1024_01 | M12: P050052 | N12: High Pro Amnesia | O12: ППК25155, (24.06.2025) [CNP] | P12: — | Q12: — | R12: CoQ-PP-2025-0008 | S12: P050052|I | T12: registered — legacy series, issued 06.06.2026 | U12: n/a — initial certificate | V12: 22.43 | W12: ППК25155 | X12: 22.00 ± 2.20 (I) | Y12: 19.80 – 24.19 % | Z12: HPA_THC22 : CBD1 | AA12: QCSP_001_HPA-I_v.01 | AB12: for review — replaces the issued QCSP_001_HPA-I_v.01 (was HPA_THC22 : CBD1, 21.00 – 23.00 %); now HPA_THC22 : CBD1 19.80 – 24.19 %
A13: =IF(OR(C13="yes",C13="allocated"),COUNT(A$1:A12)+1,"") | B13: =IF(A13<>"","CoQ-PP_26-"&TEXT(A13,"000"),"— at issue —") | C13: yes | D13: =IF(OR(A13="",C13="allocated"),"",MAX(E13,IF(ISNUMBER(I13),I13,0),IFERROR(IF(ISNUMBER(INDEX('iCoA Register'!$F:$F,MATCH(S13,'iCoA Register'!$AA:$AA,0))),INDEX('iCoA Register'!$F:$F,MATCH(S13,'iCoA Register'!$AA:$AA,0)),0),0))) | E13: =IF(ISNUMBER(F13),MAX(DATE(2026,6,6),F13+7),DATE(2026,6,6)) | F13: 45832 | G13: ППК25154 | H13: =IFERROR(INDEX('iCoA Register'!$B:$B,MATCH("P050062|I",'iCoA Register'!$AA:$AA,0)),"—") | I13: =IFERROR(INDEX('iCoA Register'!$D:$D,MATCH("P050062|I",'iCoA Register'!$AA:$AA,0)),"") | J13: legacy | K13: initial release | L13: OPM1024_02 | M13: P050062 | N13: Orange Punch Mimosa | O13: ППК25154, (24.06.2025) [CNP] | P13: — | Q13: — | R13: CoQ-PP-2025-0009 | S13: P050062|I | T13: registered — legacy series, issued 06.06.2026 | U13: n/a — initial certificate | V13: 18.27 | W13: ППК25154 | X13: 17.00 ± 1.60 (II) | Y13: 15.40 – 18.59 % | Z13: OPM_THC17 : CBD1 | AA13: QCSP_001_OPM-II_v.01 | AB13: for review — replaces the issued QCSP_001_OPM-II_v.01 (was OPM_THC18 : CBD1, 16.20 – 19.80 %); now OPM_THC17 : CBD1 15.40 – 18.59 %
A14: =IF(OR(C14="yes",C14="allocated"),COUNT(A$1:A13)+1,"") | B14: =IF(A14<>"","CoQ-PP_26-"&TEXT(A14,"000"),"— at issue —") | C14: yes | D14: =IF(OR(A14="",C14="allocated"),"",MAX(E14,IF(ISNUMBER(I14),I14,0),IFERROR(IF(ISNUMBER(INDEX('iCoA Register'!$F:$F,MATCH(S14,'iCoA Register'!$AA:$AA,0))),INDEX('iCoA Register'!$F:$F,MATCH(S14,'iCoA Register'!$AA:$AA,0)),0),0))) | E14: =IF(ISNUMBER(F14),MAX(DATE(2026,6,6),F14+7),DATE(2026,6,6)) | F14: 45848 | G14: ППК25175 | H14: =IFERROR(INDEX('iCoA Register'!$B:$B,MATCH("P050072|I",'iCoA Register'!$AA:$AA,0)),"—") | I14: =IFERROR(INDEX('iCoA Register'!$D:$D,MATCH("P050072|I",'iCoA Register'!$AA:$AA,0)),"") | J14: legacy | K14: initial release | L14: GP0824_03 | M14: P050072 | N14: Grape Pie | O14: ППК25175, (10.07.2025) [CNP] | P14: — | Q14: — | R14: CoQ-PP-2025-0010 | S14: P050072|I | T14: registered — legacy series, issued 06.06.2026 | U14: n/a — initial certificate | V14: 25.45 | W14: ППК25175 | X14: 24.00 ± 2.00 (II) | Y14: 22.00 – 25.99 % | Z14: GP_THC24 : CBD1 | AA14: QCSP_001_GP-II_v.01 | AB14: for review — replaces the issued QCSP_001_GP-II_v.01 (was GP_THC26 : CBD1, 25.40 – 26.60 %); now GP_THC24 : CBD1 22.00 – 25.99 %
A15: =IF(OR(C15="yes",C15="allocated"),COUNT(A$1:A14)+1,"") | B15: =IF(A15<>"","CoQ-PP_26-"&TEXT(A15,"000"),"— at issue —") | C15: yes | D15: =IF(OR(A15="",C15="allocated"),"",MAX(E15,IF(ISNUMBER(I15),I15,0),IFERROR(IF(ISNUMBER(INDEX('iCoA Register'!$F:$F,MATCH(S15,'iCoA Register'!$AA:$AA,0))),INDEX('iCoA Register'!$F:$F,MATCH(S15,'iCoA Register'!$AA:$AA,0)),0),0))) | E15: =IF(ISNUMBER(F15),MAX(DATE(2026,6,6),F15+7),DATE(2026,6,6)) | F15: 45867 | G15: 766-1375-25 | H15: =IFERROR(INDEX('iCoA Register'!$B:$B,MATCH("P050082|I",'iCoA Register'!$AA:$AA,0)),"—") | I15: =IFERROR(INDEX('iCoA Register'!$D:$D,MATCH("P050082|I",'iCoA Register'!$AA:$AA,0)),"") | J15: legacy | K15: initial release | L15: OPM1024_03 | M15: P050082 | N15: Orange Punch Mimosa | O15: ППК25210, (28.07.2025) [CNP] | P15: — | Q15: — | R15: CoQ-PP-2025-0011 | S15: P050082|I | T15: registered — legacy series, issued 06.06.2026 | U15: n/a — initial certificate | V15: 16.55 | W15: ППК25210 | X15: 17.00 ± 1.60 (II) | Y15: 15.40 – 18.59 % | Z15: OPM_THC17 : CBD1 | AA15: QCSP_001_OPM-II_v.01 | AB15: for review — replaces the issued QCSP_001_OPM-II_v.01 (was OPM_THC18 : CBD1, 16.20 – 19.80 %); now OPM_THC17 : CBD1 15.40 – 18.59 %
A16: =IF(OR(C16="yes",C16="allocated"),COUNT(A$1:A15)+1,"") | B16: =IF(A16<>"","CoQ-PP_26-"&TEXT(A16,"000"),"— at issue —") | C16: yes | D16: =IF(OR(A16="",C16="allocated"),"",MAX(E16,IF(ISNUMBER(I16),I16,0),IFERROR(IF(ISNUMBER(INDEX('iCoA Register'!$F:$F,MATCH(S16,'iCoA Register'!$AA:$AA,0))),INDEX('iCoA Register'!$F:$F,MATCH(S16,'iCoA Register'!$AA:$AA,0)),0),0))) | E16: =IF(ISNUMBER(F16),MAX(DATE(2026,6,6),F16+7),DATE(2026,6,6)) | F16: 45764 | G16: ППК25104 | H16: =IFERROR(INDEX('iCoA Register'!$B:$B,MATCH("P050092|I",'iCoA Register'!$AA:$AA,0)),"—") | I16: =IFERROR(INDEX('iCoA Register'!$D:$D,MATCH("P050092|I",'iCoA Register'!$AA:$AA,0)),"") | J16: legacy | K16: initial release | L16: GG1024_01 | M16: P050092 | N16: Gorilla Glue | O16: ППК25104, (17.04.2025) [CNP] | P16: — | Q16: — | R16: CoQ-PP-2025-0012 | S16: P050092|I | T16: registered — legacy series, issued 06.06.2026 | U16: n/a — initial certificate | V16: 17.22 | W16: ППК25104 | X16: 18.00 ± 1.77 (I) | Y16: 16.23 – 19.76 % | Z16: GG_THC18 : CBD1 | AA16: QCSP_001_GG-I_v.01 | AB16: for review — replaces the issued QCSP_001_GG-I_v.01 (was GG_THC18 : CBD1, 17.01 – 18.99 %); now GG_THC18 : CBD1 16.23 – 19.76 %
