Workbook

Sheet T1&T2_G2=3dec. 
B1: Ph.Eur 2.2.32. LoD (>1.00000g | 40°C | 20mBar | 24h); | N1: Ph.Eur 2.2.32. LoD (40°C | 20mBar | 24h)
B3: Sample Size (N) | C3: 46 | E3: 051026_AM02.2_s1_GG1024 | N3: Sample Size (N) | O3: =C3 -> 46
E4: Sample ID | F4: Batch No. | G4: %MCDO | I4: %MCDO-MEAN | K4: (%MCDO-MEAN)2 | L4: Delta G2-G2 | P4: Sample ID | Q4: Vegeglassi (g) | S4: Net (g) | U4: G1 = Gross 1 (g) | W4: G2 = Gross 2 (g) | Y4: G1 - G1 | AA4: Net - (G1 - G2) | AC4: %[Net - (G1-G2)]
B5: T1&T2; 05.10.2026 | C5: n1 | E5: 051026_AM02.2_S1 | G5: =100-AC5 -> 9.6014493 | I5: =G5-G53 -> 1.1820351 | K5: =POWER(I5,2) -> 1.397207 | L5: =G5-'T1&T2_G2=4dec.'!G5 -> -0.060688406 | N5: =B5 -> T1&T2; 05.10.2026 | O5: =C5 -> n1 | P5: =E5 -> 051026_AM02.2_S1 | Q5: 18.078 | S5: 1.104 | U5: =Q5+S5 -> 19.182 | W5: 19.076 | Y5: =U5-W5 -> 0.106 | AA5: =S5-Y5 -> 0.998 | AC5: =AA5*100/S5 -> 90.398551
C6: n2 | E6: 051026_AM02.2_S2 | G6: =100-AC6 -> 8.6635945 | I6: =G6-G53 -> 0.24418032 | K6: =POWER(I6,2) -> 0.059624029 | L6: =G6-'T1&T2_G2=4dec.'!G6 -> 0.0064516129 | O6: =C6 -> n2 | P6: =E6 -> 051026_AM02.2_S2 | Q6: 18.322 | S6: 1.085 | U6: =Q6+S6 -> 19.407 | W6: 19.313 | Y6: =U6-W6 -> 0.094 | AA6: =S6-Y6 -> 0.991 | AC6: =AA6*100/S6 -> 91.336406
C7: n3 | E7: 051026_AM02.2_S3 | G7: =100-AC7 -> 7.5536481 | I7: =G7-G53 -> -0.86576608 | K7: =POWER(I7,2) -> 0.74955091 | L7: =G7-'T1&T2_G2=4dec.'!G7 -> -0.032618026 | O7: =C7 -> n3 | P7: =E7 -> 051026_AM02.2_S3 | Q7: 17.86 | S7: 1.165 | U7: =Q7+S7 -> 19.025 | W7: 18.937 | Y7: =U7-W7 -> 0.088 | AA7: =S7-Y7 -> 1.077 | AC7: =AA7*100/S7 -> 92.446352
C8: n4 | E8: 051026_AM02.2_S4 | G8: =100-AC8 -> 8.5477941 | I8: =G8-G53 -> 0.12837997 | K8: =POWER(I8,2) -> 0.016481416 | L8: =G8-'T1&T2_G2=4dec.'!G8 -> -0.041360294 | O8: =C8 -> n4 | P8: =E8 -> 051026_AM02.2_S4 | Q8: 18.08 | S8: 1.088 | U8: =Q8+S8 -> 19.168 | W8: 19.075 | Y8: =U8-W8 -> 0.093 | AA8: =S8-Y8 -> 0.995 | AC8: =AA8*100/S8 -> 91.452206
C9: n5 | E9: 051026_AM02.2_S5 | G9: =100-AC9 -> 5.4493308 | I9: =G9-G53 -> -2.9700834 | K9: =POWER(I9,2) -> 8.8213952 | L9: =G9-'T1&T2_G2=4dec.'!G9 -> -0.096558317 | O9: =C9 -> n5 | P9: =E9 -> 051026_AM02.2_S5 | Q9: 18.385 | S9: 1.046 | U9: =Q9+S9 -> 19.431 | W9: 19.374 | Y9: =U9-W9 -> 0.057 | AA9: =S9-Y9 -> 0.989 | AC9: =AA9*100/S9 -> 94.550669
C10: n6 | E10: 051026_AM02.2_S6 | G10: =100-AC10 -> 7.2878229 | I10: =G10-G53 -> -1.1315913 | K10: =POWER(I10,2) -> 1.2804988 | L10: =G10-'T1&T2_G2=4dec.'!G10 -> -0.10793358 | O10: =C10 -> n6 | P10: =E10 -> 051026_AM02.2_S6 | Q10: 19.76 | S10: 1.084 | U10: =Q10+S10 -> 20.844 | W10: 20.765 | Y10: =U10-W10 -> 0.079 | AA10: =S10-Y10 -> 1.005 | AC10: =AA10*100/S10 -> 92.712177
C11: n7 | E11: 051026_AM02.2_S7 | G11: =100-AC11 -> 9.8605578 | I11: =G11-G53 -> 1.4411436 | K11: =POWER(I11,2) -> 2.0768949 | L11: =G11-'T1&T2_G2=4dec.'!G11 -> 0.0079681275 | O11: =C11 -> n7 | P11: =E11 -> 051026_AM02.2_S7 | Q11: 18.772 | S11: 1.004 | U11: =Q11+S11 -> 19.776 | W11: 19.677 | Y11: =U11-W11 -> 0.099 | AA11: =S11-Y11 -> 0.905 | AC11: =AA11*100/S11 -> 90.139442
C12: n8 | E12: 051026_AM02.2_S8 | G12: =100-AC12 -> 9.5327103 | I12: =G12-G53 -> 1.1132961 | K12: =POWER(I12,2) -> 1.2394283 | L12: =G12-'T1&T2_G2=4dec.'!G12 -> 0.0065420561 | O12: =C12 -> n8 | P12: =E12 -> 051026_AM02.2_S8 | Q12: 18.037 | S12: 1.07 | U12: =Q12+S12 -> 19.107 | W12: 19.005 | Y12: =U12-W12 -> 0.102 | AA12: =S12-Y12 -> 0.968 | AC12: =AA12*100/S12 -> 90.46729
C13: n9 | E13: 051026_AM02.2_S9 | G13: =100-AC13 -> 7.9923882 | I13: =G13-G53 -> -0.42702595 | K13: =POWER(I13,2) -> 0.18235116 | L13: =G13-'T1&T2_G2=4dec.'!G13 -> 0.029495718 | O13: =C13 -> n9 | P13: =E13 -> 051026_AM02.2_S9 | Q13: 18.719 | S13: 1.051 | U13: =Q13+S13 -> 19.77 | W13: 19.686 | Y13: =U13-W13 -> 0.084 | AA13: =S13-Y13 -> 0.967 | AC13: =AA13*100/S13 -> 92.007612
C14: n10 | E14: 051026_AM02.2_S10 | G14: =100-AC14 -> 8.0691643 | I14: =G14-G53 -> -0.35024989 | K14: =POWER(I14,2) -> 0.12267498 | L14: =G14-'T1&T2_G2=4dec.'!G14 -> 0.032660903 | O14: =C14 -> n10 | P14: =E14 -> 051026_AM02.2_S10 | Q14: 18.535 | S14: 1.041 | U14: =Q14+S14 -> 19.576 | W14: 19.492 | Y14: =U14-W14 -> 0.084 | AA14: =S14-Y14 -> 0.957 | AC14: =AA14*100/S14 -> 91.930836
C15: n11 | E15: 051026_AM02.2_S11 | G15: =100-AC15 -> 6.8665377 | I15: =G15-G53 -> -1.5528764 | K15: =POWER(I15,2) -> 2.4114252 | L15: =G15-'T1&T2_G2=4dec.'!G15 -> 0.025145068 | O15: =C15 -> n11 | P15: =E15 -> 051026_AM02.2_S11 | Q15: 18.471 | S15: 1.034 | U15: =Q15+S15 -> 19.505 | W15: 19.434 | Y15: =U15-W15 -> 0.071 | AA15: =S15-Y15 -> 0.963 | AC15: =AA15*100/S15 -> 93.133462
C16: n12 | E16: 051026_AM02.2_S12 | G16: =100-AC16 -> 9.0729783 | I16: =G16-G53 -> 0.65356415 | K16: =POWER(I16,2) -> 0.4271461 | L16: =G16-'T1&T2_G2=4dec.'!G16 -> 0.039447732 | O16: =C16 -> n12 | P16: =E16 -> 051026_AM02.2_S12 | Q16: 17.878 | S16: 1.014 | U16: =Q16+S16 -> 18.892 | W16: 18.8 | Y16: =U16-W16 -> 0.092 | AA16: =S16-Y16 -> 0.922 | AC16: =AA16*100/S16 -> 90.927022
C17: n13 | E17: 051026_AM02.2_S13 | G17: =100-AC17 -> 10.186092 | I17: =G17-G53 -> 1.7666779 | K17: =POWER(I17,2) -> 3.1211509 | L17: =G17-'T1&T2_G2=4dec.'!G17 -> 0.039177277 | O17: =C17 -> n13 | P17: =E17 -> 051026_AM02.2_S13 | Q17: 18.41 | S17: 1.021 | U17: =Q17+S17 -> 19.431 | W17: 19.327 | Y17: =U17-W17 -> 0.104 | AA17: =S17-Y17 -> 0.917 | AC17: =AA17*100/S17 -> 89.813908
C18: n14 | E18: 051026_AM02.2_S14 | G18: =100-AC18 -> 8.5009141 | I18: =G18-G53 -> 0.081499927 | K18: =POWER(I18,2) -> 0.006642238 | L18: =G18-'T1&T2_G2=4dec.'!G18 -> -0.045703839 | O18: =C18 -> n14 | P18: =E18 -> 051026_AM02.2_S14 | Q18: 18.099 | S18: 1.094 | U18: =Q18+S18 -> 19.193 | W18: 19.1 | Y18: =U18-W18 -> 0.093 | AA18: =S18-Y18 -> 1.001 | AC18: =AA18*100/S18 -> 91.499086
C19: n15 | E19: 051026_AM02.2_S15 | G19: =100-AC19 -> 8.8669951 | I19: =G19-G53 -> 0.44758092 | K19: =POWER(I19,2) -> 0.20032868 | L19: =G19-'T1&T2_G2=4dec.'!G19 -> 0.049261084 | O19: =C19 -> n15 | P19: =E19 -> 051026_AM02.2_S15 | Q19: 18.516 | S19: 1.015 | U19: =Q19+S19 -> 19.531 | W19: 19.441 | Y19: =U19-W19 -> 0.09 | AA19: =S19-Y19 -> 0.925 | AC19: =AA19*100/S19 -> 91.133005
C20: n16 | E20: 051026_AM02.2_S16 | G20: =100-AC20 -> 7.1630537 | I20: =G20-G53 -> -1.2563604 | K20: =POWER(I20,2) -> 1.5784415 | L20: =G20-'T1&T2_G2=4dec.'!G20 -> -0.084825636 | O20: =C20 -> n16 | P20: =E20 -> 051026_AM02.2_S16 | Q20: 17.706 | S20: 1.061 | U20: =Q20+S20 -> 18.767 | W20: 18.691 | Y20: =U20-W20 -> 0.076 | AA20: =S20-Y20 -> 0.985 | AC20: =AA20*100/S20 -> 92.836946
C21: n17 | E21: 051026_AM02.2_S17 | G21: =100-AC21 -> 9.3150685 | I21: =G21-G53 -> 0.89565434 | K21: =POWER(I21,2) -> 0.8021967 | L21: =G21-'T1&T2_G2=4dec.'!G21 -> 0.054794521 | O21: =C21 -> n17 | P21: =E21 -> 051026_AM02.2_S17 | Q21: 18.714 | S21: 1.095 | U21: =Q21+S21 -> 19.809 | W21: 19.707 | Y21: =U21-W21 -> 0.102 | AA21: =S21-Y21 -> 0.993 | AC21: =AA21*100/S21 -> 90.684932
C22: n18 | E22: 051026_AM02.2_S18 | G22: =100-AC22 -> 10.037175 | I22: =G22-G53 -> 1.6177606 | K22: =POWER(I22,2) -> 2.6171493 | L22: =G22-'T1&T2_G2=4dec.'!G22 -> 0.027881041 | O22: =C22 -> n18 | P22: =E22 -> 051026_AM02.2_S18 | Q22: 18.076 | S22: 1.076 | U22: =Q22+S22 -> 19.152 | W22: 19.044 | Y22: =U22-W22 -> 0.108 | AA22: =S22-Y22 -> 0.968 | AC22: =AA22*100/S22 -> 89.962825
C23: n19 | E23: 051026_AM02.2_S19 | G23: =100-AC23 -> 6.3314711 | I23: =G23-G53 -> -2.087943 | K23: =POWER(I23,2) -> 4.359506 | L23: =G23-'T1&T2_G2=4dec.'!G23 -> 0.009310987 | O23: =C23 -> n19 | P23: =E23 -> 051026_AM02.2_S19 | Q23: 19.059 | S23: 1.074 | U23: =Q23+S23 -> 20.133 | W23: 20.065 | Y23: =U23-W23 -> 0.068 | AA23: =S23-Y23 -> 1.006 | AC23: =AA23*100/S23 -> 93.668529
C24: n20 | E24: 051026_AM02.2_S20 | G24: =100-AC24 -> 6.9767442 | I24: =G24-G53 -> -1.44267 | K24: =POWER(I24,2) -> 2.0812966 | L24: =G24-'T1&T2_G2=4dec.'!G24 -> 0.018604651 | O24: =C24 -> n20 | P24: =E24 -> 051026_AM02.2_S20 | Q24: 18.118 | S24: 1.075 | U24: =Q24+S24 -> 19.193 | W24: 19.118 | Y24: =U24-W24 -> 0.075 | AA24: =S24-Y24 -> 1 | AC24: =AA24*100/S24 -> 93.023256
C25: n21 | E25: 051026_AM02.2_S21 | G25: =100-AC25 -> 7.4257426 | I25: =G25-G53 -> -0.99367158 | K25: =POWER(I25,2) -> 0.9873832 | L25: =G25-'T1&T2_G2=4dec.'!G25 -> -0.01980198 | O25: =C25 -> n21 | P25: =E25 -> 051026_AM02.2_S21 | Q25: 17.875 | S25: 1.01 | U25: =Q25+S25 -> 18.885 | W25: 18.81 | Y25: =U25-W25 -> 0.075 | AA25: =S25-Y25 -> 0.935 | AC25: =AA25*100/S25 -> 92.574257
C26: n22 | E26: 051026_AM02.2_S22 | G26: =100-AC26 -> 8 | I26: =G26-G53 -> -0.41941415 | K26: =POWER(I26,2) -> 0.17590823 | L26: =G26-'T1&T2_G2=4dec.'!G26 -> 0.093023256 | O26: =C26 -> n22 | P26: =E26 -> 051026_AM02.2_S22 | Q26: 17.783 | S26: 1.075 | U26: =Q26+S26 -> 18.858 | W26: 18.772 | Y26: =U26-W26 -> 0.086 | AA26: =S26-Y26 -> 0.989 | AC26: =AA26*100/S26 -> 92
C27: n23 | E27: 051026_AM02.2_S23 | G27: =100-AC27 -> 8.8206145 | I27: =G27-G53 -> 0.40120032 | K27: =POWER(I27,2) -> 0.1609617 | L27: =G27-'T1&T2_G2=4dec.'!G27 -> -0.049554014 | O27: =C27 -> n23 | P27: =E27 -> 051026_AM02.2_S23 | Q27: 17.362 | S27: 1.009 | U27: =Q27+S27 -> 18.371 | W27: 18.282 | Y27: =U27-W27 -> 0.089 | AA27: =S27-Y27 -> 0.92 | AC27: =AA27*100/S27 -> 91.179386
C28: n24 | E28: 051026_AM02.2_S24 | G28: =100-AC28 -> 8.0708661 | I28: =G28-G53 -> -0.34854801 | K28: =POWER(I28,2) -> 0.12148571 | L28: =G28-'T1&T2_G2=4dec.'!G28 -> 0.059055118 | O28: =C28 -> n24 | P28: =E28 -> 051026_AM02.2_S24 | Q28: 19.018 | S28: 1.016 | U28: =Q28+S28 -> 20.034 | W28: 19.952 | Y28: =U28-W28 -> 0.082 | AA28: =S28-Y28 -> 0.934 | AC28: =AA28*100/S28 -> 91.929134
C29: n25 | E29: 051026_AM02.2_S25 | G29: =100-AC29 -> 8.4313725 | I29: =G29-G53 -> 0.011958399 | K29: =POWER(I29,2) -> 0.0001430033 | L29: =G29-'T1&T2_G2=4dec.'!G29 -> -0.049019608 | O29: =C29 -> n25 | P29: =E29 -> 051026_AM02.2_S25 | Q29: 17.924 | S29: 1.02 | U29: =Q29+S29 -> 18.944 | W29: 18.858 | Y29: =U29-W29 -> 0.086 | AA29: =S29-Y29 -> 0.934 | AC29: =AA29*100/S29 -> 91.568627
C30: n26 | E30: 051026_AM02.2_S26 | G30: =100-AC30 -> 8.3412322 | I30: =G30-G53 -> -0.078181923 | K30: =POWER(I30,2) -> 0.006112413 | L30: =G30-'T1&T2_G2=4dec.'!G30 -> -0.009478673 | O30: =C30 -> n26 | P30: =E30 -> 051026_AM02.2_S26 | Q30: 18.205 | S30: 1.055 | U30: =Q30+S30 -> 19.26 | W30: 19.172 | Y30: =U30-W30 -> 0.088 | AA30: =S30-Y30 -> 0.967 | AC30: =AA30*100/S30 -> 91.658768
C31: n27 | E31: 051026_AM02.2_S27 | G31: =100-AC31 -> 7.2978304 | I31: =G31-G53 -> -1.1215838 | K31: =POWER(I31,2) -> 1.2579502 | L31: =G31-'T1&T2_G2=4dec.'!G31 -> -0.0098619329 | O31: =C31 -> n27 | P31: =E31 -> 051026_AM02.2_S27 | Q31: 18.141 | S31: 1.014 | U31: =Q31+S31 -> 19.155 | W31: 19.081 | Y31: =U31-W31 -> 0.074 | AA31: =S31-Y31 -> 0.94 | AC31: =AA31*100/S31 -> 92.70217
C32: n28 | E32: 051026_AM02.2_S28 | G32: =100-AC32 -> 9.5643939 | I32: =G32-G53 -> 1.1449798 | K32: =POWER(I32,2) -> 1.3109787 | L32: =G32-'T1&T2_G2=4dec.'!G32 -> 0.018939394 | O32: =C32 -> n28 | P32: =E32 -> 051026_AM02.2_S28 | Q32: 18.61 | S32: 1.056 | U32: =Q32+S32 -> 19.666 | W32: 19.565 | Y32: =U32-W32 -> 0.101 | AA32: =S32-Y32 -> 0.955 | AC32: =AA32*100/S32 -> 90.435606
C33: n29 | E33: 051026_AM02.2_S29 | G33: =100-AC33 -> 7.3193916 | I33: =G33-G53 -> -1.1000225 | K33: =POWER(I33,2) -> 1.2100495 | L33: =G33-'T1&T2_G2=4dec.'!G33 -> 0.076045627 | O33: =C33 -> n29 | P33: =E33 -> 051026_AM02.2_S29 | Q33: 18.093 | S33: 1.052 | U33: =Q33+S33 -> 19.145 | W33: 19.068 | Y33: =U33-W33 -> 0.077 | AA33: =S33-Y33 -> 0.975 | AC33: =AA33*100/S33 -> 92.680608
C34: n30 | E34: 051026_AM02.2_S30 | G34: =100-AC34 -> 10.604559 | I34: =G34-G53 -> 2.1851448 | K34: =POWER(I34,2) -> 4.7748579 | L34: =G34-'T1&T2_G2=4dec.'!G34 -> -0.059464817 | O34: =C34 -> n30 | P34: =E34 -> 051026_AM02.2_S30 | Q34: 18.602 | S34: 1.009 | U34: =Q34+S34 -> 19.611 | W34: 19.504 | Y34: =U34-W34 -> 0.107 | AA34: =S34-Y34 -> 0.902 | AC34: =AA34*100/S34 -> 89.395441
C35: n31 | E35: 051026_AM02.2_S31 | G35: =100-AC35 -> 6.743738 | I35: =G35-G53 -> -1.6756762 | K35: =POWER(I35,2) -> 2.8078907 | L35: =G35-'T1&T2_G2=4dec.'!G35 -> 0.028901734 | O35: =C35 -> n31 | P35: =E35 -> 051026_AM02.2_S31 | Q35: 17.56 | S35: 1.038 | U35: =Q35+S35 -> 18.598 | W35: 18.528 | Y35: =U35-W35 -> 0.07 | AA35: =S35-Y35 -> 0.968 | AC35: =AA35*100/S35 -> 93.256262
C36: n32 | E36: 051026_AM02.2_S32 | G36: =100-AC36 -> 10.377358 | I36: =G36-G53 -> 1.9579443 | K36: =POWER(I36,2) -> 3.833546 | L36: =G36-'T1&T2_G2=4dec.'!G36 -> 0.10377358 | O36: =C36 -> n32 | P36: =E36 -> 051026_AM02.2_S32 | Q36: 18.589 | S36: 1.06 | U36: =Q36+S36 -> 19.649 | W36: 19.539 | Y36: =U36-W36 -> 0.11 | AA36: =S36-Y36 -> 0.95 | AC36: =AA36*100/S36 -> 89.622642
C37: n33 | E37: 051026_AM02.2_S33 | G37: =100-AC37 -> 9.221902 | I37: =G37-G53 -> 0.80248787 | K37: =POWER(I37,2) -> 0.64398678 | L37: =G37-'T1&T2_G2=4dec.'!G37 -> 0.0096061479 | O37: =C37 -> n33 | P37: =E37 -> 051026_AM02.2_S33 | Q37: 18.987 | S37: 1.041 | U37: =Q37+S37 -> 20.028 | W37: 19.932 | Y37: =U37-W37 -> 0.096 | AA37: =S37-Y37 -> 0.945 | AC37: =AA37*100/S37 -> 90.778098
C38: n34 | E38: 051026_AM02.2_S34 | G38: =100-AC38 -> 9.3253968 | I38: =G38-G53 -> 0.90598268 | K38: =POWER(I38,2) -> 0.82080461 | L38: =G38-'T1&T2_G2=4dec.'!G38 -> 0.03968254 | O38: =C38 -> n34 | P38: =E38 -> 051026_AM02.2_S34 | Q38: 18.517 | S38: 1.008 | U38: =Q38+S38 -> 19.525 | W38: 19.431 | Y38: =U38-W38 -> 0.094 | AA38: =S38-Y38 -> 0.914 | AC38: =AA38*100/S38 -> 90.674603
C39: n35 | E39: 051026_AM02.2_S35 | G39: =100-AC39 -> 6.2317429 | I39: =G39-G53 -> -2.1876712 | K39: =POWER(I39,2) -> 4.7859053 | L39: =G39-'T1&T2_G2=4dec.'!G39 -> -0.038948393 | O39: =C39 -> n35 | P39: =E39 -> 051026_AM02.2_S35 | Q39: 17.622 | S39: 1.027 | U39: =Q39+S39 -> 18.649 | W39: 18.585 | Y39: =U39-W39 -> 0.064 | AA39: =S39-Y39 -> 0.963 | AC39: =AA39*100/S39 -> 93.768257
C40: n36 | E40: 051026_AM02.2_S36 | G40: =100-AC40 -> 6.7505721 | I40: =G40-G53 -> -1.6688421 | K40: =POWER(I40,2) -> 2.7850338 | L40: =G40-'T1&T2_G2=4dec.'!G40 -> -0.022883295 | O40: =C40 -> n36 | P40: =E40 -> 051026_AM02.2_S36 | Q40: 13.712 | S40: 0.874 | U40: =Q40+S40 -> 14.586 | W40: 14.527 | Y40: =U40-W40 -> 0.059 | AA40: =S40-Y40 -> 0.815 | AC40: =AA40*100/S40 -> 93.249428
C41: n37 | E41: 051026_AM02.2_S37 | G41: =100-AC41 -> 9.6806387 | I41: =G41-G53 -> 1.2612246 | K41: =POWER(I41,2) -> 1.5906874 | L41: =G41-'T1&T2_G2=4dec.'!G41 -> -0.01996008 | O41: =C41 -> n37 | P41: =E41 -> 051026_AM02.2_S37 | Q41: 13.581 | S41: 1.002 | U41: =Q41+S41 -> 14.583 | W41: 14.486 | Y41: =U41-W41 -> 0.097 | AA41: =S41-Y41 -> 0.905 | AC41: =AA41*100/S41 -> 90.319361
...

Sheet T1&T2_G2=4dec.
B1: Ph.Eur 2.2.32. LoD (>1.00000g | 40°C | 20mBar | 24h); | N1: Ph.Eur 2.2.32. LoD (40°C | 20mBar | 24h)
B3: Sample Size (N) | C3: 46 | E3: 051026_AM02.2_s1_GG1024 | G3: 0.0001g | N3: Sample Size (N) | O3: =C3 -> 46
E4: Sample ID | F4: Batch No. | G4: %MCDO | I4: %MCDO-MEAN | K4: (%MCDO-MEAN)2 | L4: Delta G2-G2 | P4: Sample ID | Q4: Vegeglassi (g) | S4: Net (g) | U4: G1 = Gross 1 (g) | W4: G2 = Gross 2 (g) | Y4: G1 - G1 | AA4: Net - (G1 - G2) | AC4: %[Net - (G1-G2)]
B5: T1&T2; 05.10.2026 | C5: n1 | E5: 051026_AM02.2_S1 | F5: ='T1&T2_G2=3dec. '!F5 -> 0 | G5: =100-AC5 -> 9.6621377 | I5: =G5-G53 -> 1.2461921 | K5: =POWER(I5,2) -> 1.5529949 | L5: =G5-'T1&T2_G2=3dec. '!G5 -> 0.060688406 | N5: =B5 -> T1&T2; 05.10.2026 | O5: =C5 -> n1 | P5: =E5 -> 051026_AM02.2_S1 | Q5: 18.078 | S5: 1.104 | U5: =Q5+S5 -> 19.182 | W5: 19.07533 | Y5: =U5-W5 -> 0.10667 | AA5: =S5-Y5 -> 0.99733 | AC5: =AA5*100/S5 -> 90.337862
C6: n2 | E6: 051026_AM02.2_S2 | F6: ='T1&T2_G2=3dec. '!F6 -> 0 | G6: =100-AC6 -> 8.6571429 | I6: =G6-G53 -> 0.24119732 | K6: =POWER(I6,2) -> 0.058176147 | L6: =G6-'T1&T2_G2=3dec. '!G6 -> -0.0064516129 | O6: =C6 -> n2 | P6: =E6 -> 051026_AM02.2_S2 | Q6: 18.322 | S6: 1.085 | U6: =Q6+S6 -> 19.407 | W6: 19.31307 | Y6: =U6-W6 -> 0.09393 | AA6: =S6-Y6 -> 0.99107 | AC6: =AA6*100/S6 -> 91.342857
C7: n3 | E7: 051026_AM02.2_S3 | F7: ='T1&T2_G2=3dec. '!F7 -> 0 | G7: =100-AC7 -> 7.5862661 | I7: =G7-G53 -> -0.82967944 | K7: =POWER(I7,2) -> 0.68836798 | L7: =G7-'T1&T2_G2=3dec. '!G7 -> 0.032618026 | O7: =C7 -> n3 | P7: =E7 -> 051026_AM02.2_S3 | Q7: 17.86 | S7: 1.165 | U7: =Q7+S7 -> 19.025 | W7: 18.93662 | Y7: =U7-W7 -> 0.08838 | AA7: =S7-Y7 -> 1.07662 | AC7: =AA7*100/S7 -> 92.413734
C8: n4 | E8: 051026_AM02.2_S4 | F8: ='T1&T2_G2=3dec. '!F8 -> 0 | G8: =100-AC8 -> 8.5891544 | I8: =G8-G53 -> 0.17320887 | K8: =POWER(I8,2) -> 0.030001314 | L8: =G8-'T1&T2_G2=3dec. '!G8 -> 0.041360294 | O8: =C8 -> n4 | P8: =E8 -> 051026_AM02.2_S4 | Q8: 18.08 | S8: 1.088 | U8: =Q8+S8 -> 19.168 | W8: 19.07455 | Y8: =U8-W8 -> 0.09345 | AA8: =S8-Y8 -> 0.99455 | AC8: =AA8*100/S8 -> 91.410846
C9: n5 | E9: 051026_AM02.2_S5 | F9: ='T1&T2_G2=3dec. '!F9 -> 0 | G9: =100-AC9 -> 5.5458891 | I9: =G9-G53 -> -2.8700564 | K9: =POWER(I9,2) -> 8.2372239 | L9: =G9-'T1&T2_G2=3dec. '!G9 -> 0.096558317 | O9: =C9 -> n5 | P9: =E9 -> 051026_AM02.2_S5 | Q9: 18.385 | S9: 1.046 | U9: =Q9+S9 -> 19.431 | W9: 19.37299 | Y9: =U9-W9 -> 0.05801 | AA9: =S9-Y9 -> 0.98799 | AC9: =AA9*100/S9 -> 94.454111
C10: n6 | E10: 051026_AM02.2_S6 | F10: ='T1&T2_G2=3dec. '!F10 -> 0 | G10: =100-AC10 -> 7.3957565 | I10: =G10-G53 -> -1.0201891 | K10: =POWER(I10,2) -> 1.0407858 | L10: =G10-'T1&T2_G2=3dec. '!G10 -> 0.10793358 | O10: =C10 -> n6 | P10: =E10 -> 051026_AM02.2_S6 | Q10: 19.76 | S10: 1.084 | U10: =Q10+S10 -> 20.844 | W10: 20.76383 | Y10: =U10-W10 -> 0.08017 | AA10: =S10-Y10 -> 1.00383 | AC10: =AA10*100/S10 -> 92.604244
C11: n7 | E11: 051026_AM02.2_S7 | F11: ='T1&T2_G2=3dec. '!F11 -> 0 | G11: =100-AC11 -> 9.8525896 | I11: =G11-G53 -> 1.4366441 | K11: =POWER(I11,2) -> 2.0639463 | L11: =G11-'T1&T2_G2=3dec. '!G11 -> -0.0079681275 | O11: =C11 -> n7 | P11: =E11 -> 051026_AM02.2_S7 | Q11: 18.772 | S11: 1.004 | U11: =Q11+S11 -> 19.776 | W11: 19.67708 | Y11: =U11-W11 -> 0.09892 | AA11: =S11-Y11 -> 0.90508 | AC11: =AA11*100/S11 -> 90.14741
C12: n8 | E12: 051026_AM02.2_S8 | F12: ='T1&T2_G2=3dec. '!F12 -> 0 | G12: =100-AC12 -> 9.5261682 | I12: =G12-G53 -> 1.1102227 | K12: =POWER(I12,2) -> 1.2325944 | L12: =G12-'T1&T2_G2=3dec. '!G12 -> -0.0065420561 | O12: =C12 -> n8 | P12: =E12 -> 051026_AM02.2_S8 | Q12: 18.037 | S12: 1.07 | U12: =Q12+S12 -> 19.107 | W12: 19.00507 | Y12: =U12-W12 -> 0.10193 | AA12: =S12-Y12 -> 0.96807 | AC12: =AA12*100/S12 -> 90.473832
C13: n9 | E13: 051026_AM02.2_S9 | F13: ='T1&T2_G2=3dec. '!F13 -> 0 | G13: =100-AC13 -> 7.9628925 | I13: =G13-G53 -> -0.45305305 | K13: =POWER(I13,2) -> 0.20525707 | L13: =G13-'T1&T2_G2=3dec. '!G13 -> -0.029495718 | O13: =C13 -> n9 | P13: =E13 -> 051026_AM02.2_S9 | Q13: 18.719 | S13: 1.051 | U13: =Q13+S13 -> 19.77 | W13: 19.68631 | Y13: =U13-W13 -> 0.08369 | AA13: =S13-Y13 -> 0.96731 | AC13: =AA13*100/S13 -> 92.037108
C14: n10 | E14: 051026_AM02.2_S10 | F14: ='T1&T2_G2=3dec. '!F14 -> 0 | G14: =100-AC14 -> 8.0365034 | I14: =G14-G53 -> -0.37944217 | K14: =POWER(I14,2) -> 0.14397636 | L14: =G14-'T1&T2_G2=3dec. '!G14 -> -0.032660903 | O14: =C14 -> n10 | P14: =E14 -> 051026_AM02.2_S10 | Q14: 18.535 | S14: 1.041 | U14: =Q14+S14 -> 19.576 | W14: 19.49234 | Y14: =U14-W14 -> 0.08366 | AA14: =S14-Y14 -> 0.95734 | AC14: =AA14*100/S14 -> 91.963497
C15: n11 | E15: 051026_AM02.2_S11 | F15: ='T1&T2_G2=3dec. '!F15 -> 0 | G15: =100-AC15 -> 6.8413926 | I15: =G15-G53 -> -1.5745529 | K15: =POWER(I15,2) -> 2.4792168 | L15: =G15-'T1&T2_G2=3dec. '!G15 -> -0.025145068 | O15: =C15 -> n11 | P15: =E15 -> 051026_AM02.2_S11 | Q15: 18.471 | S15: 1.034 | U15: =Q15+S15 -> 19.505 | W15: 19.43426 | Y15: =U15-W15 -> 0.07074 | AA15: =S15-Y15 -> 0.96326 | AC15: =AA15*100/S15 -> 93.158607
C16: n12 | E16: 051026_AM02.2_S12 | F16: ='T1&T2_G2=3dec. '!F16 -> 0 | G16: =100-AC16 -> 9.0335306 | I16: =G16-G53 -> 0.61758503 | K16: =POWER(I16,2) -> 0.38141128 | L16: =G16-'T1&T2_G2=3dec. '!G16 -> -0.039447732 | O16: =C16 -> n12 | P16: =E16 -> 051026_AM02.2_S12 | Q16: 17.878 | S16: 1.014 | U16: =Q16+S16 -> 18.892 | W16: 18.8004 | Y16: =U16-W16 -> 0.0916 | AA16: =S16-Y16 -> 0.9224 | AC16: =AA16*100/S16 -> 90.966469
C17: n13 | E17: 051026_AM02.2_S13 | F17: ='T1&T2_G2=3dec. '!F17 -> 0 | G17: =100-AC17 -> 10.146915 | I17: =G17-G53 -> 1.7309693 | K17: =POWER(I17,2) -> 2.9962546 | L17: =G17-'T1&T2_G2=3dec. '!G17 -> -0.039177277 | O17: =C17 -> n13 | P17: =E17 -> 051026_AM02.2_S13 | Q17: 18.41 | S17: 1.021 | U17: =Q17+S17 -> 19.431 | W17: 19.3274 | Y17: =U17-W17 -> 0.1036 | AA17: =S17-Y17 -> 0.9174 | AC17: =AA17*100/S17 -> 89.853085
C18: n14 | E18: 051026_AM02.2_S14 | F18: ='T1&T2_G2=3dec. '!F18 -> 0 | G18: =100-AC18 -> 8.5466179 | I18: =G18-G53 -> 0.13067238 | K18: =POWER(I18,2) -> 0.017075271 | L18: =G18-'T1&T2_G2=3dec. '!G18 -> 0.045703839 | O18: =C18 -> n14 | P18: =E18 -> 051026_AM02.2_S14 | Q18: 18.099 | S18: 1.094 | U18: =Q18+S18 -> 19.193 | W18: 19.0995 | Y18: =U18-W18 -> 0.0935 | AA18: =S18-Y18 -> 1.0005 | AC18: =AA18*100/S18 -> 91.453382
C19: n15 | E19: 051026_AM02.2_S15 | F19: ='T1&T2_G2=3dec. '!F19 -> 0 | G19: =100-AC19 -> 8.817734 | I19: =G19-G53 -> 0.40178845 | K19: =POWER(I19,2) -> 0.16143396 | L19: =G19-'T1&T2_G2=3dec. '!G19 -> -0.049261084 | O19: =C19 -> n15 | P19: =E19 -> 051026_AM02.2_S15 | Q19: 18.516 | S19: 1.015 | U19: =Q19+S19 -> 19.531 | W19: 19.4415 | Y19: =U19-W19 -> 0.0895 | AA19: =S19-Y19 -> 0.9255 | AC19: =AA19*100/S19 -> 91.182266
C20: n16 | E20: 051026_AM02.2_S16 | F20: ='T1&T2_G2=3dec. '!F20 -> 0 | G20: =100-AC20 -> 7.2478794 | I20: =G20-G53 -> -1.1680662 | K20: =POWER(I20,2) -> 1.3643786 | L20: =G20-'T1&T2_G2=3dec. '!G20 -> 0.084825636 | O20: =C20 -> n16 | P20: =E20 -> 051026_AM02.2_S16 | Q20: 17.706 | S20: 1.061 | U20: =Q20+S20 -> 18.767 | W20: 18.6901 | Y20: =U20-W20 -> 0.0769 | AA20: =S20-Y20 -> 0.9841 | AC20: =AA20*100/S20 -> 92.752121
C21: n17 | E21: 051026_AM02.2_S17 | F21: ='T1&T2_G2=3dec. '!F21 -> 0 | G21: =100-AC21 -> 9.260274 | I21: =G21-G53 -> 0.84432844 | K21: =POWER(I21,2) -> 0.71289051 | L21: =G21-'T1&T2_G2=3dec. '!G21 -> -0.054794521 | O21: =C21 -> n17 | P21: =E21 -> 051026_AM02.2_S17 | Q21: 18.714 | S21: 1.095 | U21: =Q21+S21 -> 19.809 | W21: 19.7076 | Y21: =U21-W21 -> 0.1014 | AA21: =S21-Y21 -> 0.9936 | AC21: =AA21*100/S21 -> 90.739726
C22: n18 | E22: 051026_AM02.2_S18 | F22: ='T1&T2_G2=3dec. '!F22 -> 0 | G22: =100-AC22 -> 10.009294 | I22: =G22-G53 -> 1.5933481 | K22: =POWER(I22,2) -> 2.5387583 | L22: =G22-'T1&T2_G2=3dec. '!G22 -> -0.027881041 | O22: =C22 -> n18 | P22: =E22 -> 051026_AM02.2_S18 | Q22: 18.076 | S22: 1.076 | U22: =Q22+S22 -> 19.152 | W22: 19.0443 | Y22: =U22-W22 -> 0.1077 | AA22: =S22-Y22 -> 0.9683 | AC22: =AA22*100/S22 -> 89.990706
C23: n19 | E23: 051026_AM02.2_S19 | F23: ='T1&T2_G2=3dec. '!F23 -> 0 | G23: =100-AC23 -> 6.3221601 | I23: =G23-G53 -> -2.0937854 | K23: =POWER(I23,2) -> 4.3839373 | L23: =G23-'T1&T2_G2=3dec. '!G23 -> -0.009310987 | O23: =C23 -> n19 | P23: =E23 -> 051026_AM02.2_S19 | Q23: 19.059 | S23: 1.074 | U23: =Q23+S23 -> 20.133 | W23: 20.0651 | Y23: =U23-W23 -> 0.0679 | AA23: =S23-Y23 -> 1.0061 | AC23: =AA23*100/S23 -> 93.67784
C24: n20 | E24: 051026_AM02.2_S20 | F24: ='T1&T2_G2=3dec. '!F24 -> 0 | G24: =100-AC24 -> 6.9581395 | I24: =G24-G53 -> -1.457806 | K24: =POWER(I24,2) -> 2.1251983 | L24: =G24-'T1&T2_G2=3dec. '!G24 -> -0.018604651 | O24: =C24 -> n20 | P24: =E24 -> 051026_AM02.2_S20 | Q24: 18.118 | S24: 1.075 | U24: =Q24+S24 -> 19.193 | W24: 19.1182 | Y24: =U24-W24 -> 0.0748 | AA24: =S24-Y24 -> 1.0002 | AC24: =AA24*100/S24 -> 93.04186
C25: n21 | E25: 051026_AM02.2_S21 | F25: ='T1&T2_G2=3dec. '!F25 -> 0 | G25: =100-AC25 -> 7.4455446 | I25: =G25-G53 -> -0.97040098 | K25: =POWER(I25,2) -> 0.94167807 | L25: =G25-'T1&T2_G2=3dec. '!G25 -> 0.01980198 | O25: =C25 -> n21 | P25: =E25 -> 051026_AM02.2_S21 | Q25: 17.875 | S25: 1.01 | U25: =Q25+S25 -> 18.885 | W25: 18.8098 | Y25: =U25-W25 -> 0.0752 | AA25: =S25-Y25 -> 0.9348 | AC25: =AA25*100/S25 -> 92.554455
C26: n22 | E26: 051026_AM02.2_S22 | F26: ='T1&T2_G2=3dec. '!F26 -> 0 | G26: =100-AC26 -> 7.9069767 | I26: =G26-G53 -> -0.50896879 | K26: =POWER(I26,2) -> 0.25904923 | L26: =G26-'T1&T2_G2=3dec. '!G26 -> -0.093023256 | O26: =C26 -> n22 | P26: =E26 -> 051026_AM02.2_S22 | Q26: 17.783 | S26: 1.075 | U26: =Q26+S26 -> 18.858 | W26: 18.773 | Y26: =U26-W26 -> 0.085 | AA26: =S26-Y26 -> 0.99 | AC26: =AA26*100/S26 -> 92.093023
C27: n23 | E27: 051026_AM02.2_S23 | F27: ='T1&T2_G2=3dec. '!F27 -> 0 | G27: =100-AC27 -> 8.8701685 | I27: =G27-G53 -> 0.45422295 | K27: =POWER(I27,2) -> 0.20631849 | L27: =G27-'T1&T2_G2=3dec. '!G27 -> 0.049554014 | O27: =C27 -> n23 | P27: =E27 -> 051026_AM02.2_S23 | Q27: 17.362 | S27: 1.009 | U27: =Q27+S27 -> 18.371 | W27: 18.2815 | Y27: =U27-W27 -> 0.0895 | AA27: =S27-Y27 -> 0.9195 | AC27: =AA27*100/S27 -> 91.129832
C28: n24 | E28: 051026_AM02.2_S24 | F28: ='T1&T2_G2=3dec. '!F28 -> 0 | G28: =100-AC28 -> 8.011811 | I28: =G28-G53 -> -0.40413451 | K28: =POWER(I28,2) -> 0.1633247 | L28: =G28-'T1&T2_G2=3dec. '!G28 -> -0.059055118 | O28: =C28 -> n24 | P28: =E28 -> 051026_AM02.2_S24 | Q28: 19.018 | S28: 1.016 | U28: =Q28+S28 -> 20.034 | W28: 19.9526 | Y28: =U28-W28 -> 0.0814 | AA28: =S28-Y28 -> 0.9346 | AC28: =AA28*100/S28 -> 91.988189
C29: n25 | E29: 051026_AM02.2_S25 | F29: ='T1&T2_G2=3dec. '!F29 -> 0 | G29: =100-AC29 -> 8.4803922 | I29: =G29-G53 -> 0.06444662 | K29: =POWER(I29,2) -> 0.0041533668 | L29: =G29-'T1&T2_G2=3dec. '!G29 -> 0.049019608 | O29: =C29 -> n25 | P29: =E29 -> 051026_AM02.2_S25 | Q29: 17.924 | S29: 1.02 | U29: =Q29+S29 -> 18.944 | W29: 18.8575 | Y29: =U29-W29 -> 0.0865 | AA29: =S29-Y29 -> 0.9335 | AC29: =AA29*100/S29 -> 91.519608
C30: n26 | E30: 051026_AM02.2_S26 | F30: ='T1&T2_G2=3dec. '!F30 -> 0 | G30: =100-AC30 -> 8.3507109 | I30: =G30-G53 -> -0.065234637 | K30: =POWER(I30,2) -> 0.0042555578 | L30: =G30-'T1&T2_G2=3dec. '!G30 -> 0.009478673 | O30: =C30 -> n26 | P30: =E30 -> 051026_AM02.2_S26 | Q30: 18.205 | S30: 1.055 | U30: =Q30+S30 -> 19.26 | W30: 19.1719 | Y30: =U30-W30 -> 0.0881 | AA30: =S30-Y30 -> 0.9669 | AC30: =AA30*100/S30 -> 91.649289
C31: n27 | E31: 051026_AM02.2_S27 | F31: ='T1&T2_G2=3dec. '!F31 -> 0 | G31: =100-AC31 -> 7.3076923 | I31: =G31-G53 -> -1.1082532 | K31: =POWER(I31,2) -> 1.2282252 | L31: =G31-'T1&T2_G2=3dec. '!G31 -> 0.0098619329 | O31: =C31 -> n27 | P31: =E31 -> 051026_AM02.2_S27 | Q31: 18.141 | S31: 1.014 | U31: =Q31+S31 -> 19.155 | W31: 19.0809 | Y31: =U31-W31 -> 0.0741 | AA31: =S31-Y31 -> 0.9399 | AC31: =AA31*100/S31 -> 92.692308
C32: n28 | E32: 051026_AM02.2_S28 | F32: ='T1&T2_G2=3dec. '!F32 -> 0 | G32: =100-AC32 -> 9.5454545 | I32: =G32-G53 -> 1.129509 | K32: =POWER(I32,2) -> 1.2757906 | L32: =G32-'T1&T2_G2=3dec. '!G32 -> -0.018939394 | O32: =C32 -> n28 | P32: =E32 -> 051026_AM02.2_S28 | Q32: 18.61 | S32: 1.056 | U32: =Q32+S32 -> 19.666 | W32: 19.5652 | Y32: =U32-W32 -> 0.1008 | AA32: =S32-Y32 -> 0.9552 | AC32: =AA32*100/S32 -> 90.454545
C33: n29 | E33: 051026_AM02.2_S29 | F33: ='T1&T2_G2=3dec. '!F33 -> 0 | G33: =100-AC33 -> 7.243346 | I33: =G33-G53 -> -1.1725995 | K33: =POWER(I33,2) -> 1.3749897 | L33: =G33-'T1&T2_G2=3dec. '!G33 -> -0.076045627 | O33: =C33 -> n29 | P33: =E33 -> 051026_AM02.2_S29 | Q33: 18.093 | S33: 1.052 | U33: =Q33+S33 -> 19.145 | W33: 19.0688 | Y33: =U33-W33 -> 0.0762 | AA33: =S33-Y33 -> 0.9758 | AC33: =AA33*100/S33 -> 92.756654
C34: n30 | E34: 051026_AM02.2_S30 | F34: ='T1&T2_G2=3dec. '!F34 -> 0 | G34: =100-AC34 -> 10.664024 | I34: =G34-G53 -> 2.2480782 | K34: =POWER(I34,2) -> 5.0538558 | L34: =G34-'T1&T2_G2=3dec. '!G34 -> 0.059464817 | O34: =C34 -> n30 | P34: =E34 -> 051026_AM02.2_S30 | Q34: 18.602 | S34: 1.009 | U34: =Q34+S34 -> 19.611 | W34: 19.5034 | Y34: =U34-W34 -> 0.1076 | AA34: =S34-Y34 -> 0.9014 | AC34: =AA34*100/S34 -> 89.335976
C35: n31 | E35: 051026_AM02.2_S31 | F35: ='T1&T2_G2=3dec. '!F35 -> 0 | G35: =100-AC35 -> 6.7148362 | I35: =G35-G53 -> -1.7011093 | K35: =POWER(I35,2) -> 2.8937729 | L35: =G35-'T1&T2_G2=3dec. '!G35 -> -0.028901734 | O35: =C35 -> n31 | P35: =E35 -> 051026_AM02.2_S31 | Q35: 17.56 | S35: 1.038 | U35: =Q35+S35 -> 18.598 | W35: 18.5283 | Y35: =U35-W35 -> 0.0697 | AA35: =S35-Y35 -> 0.9683 | AC35: =AA35*100/S35 -> 93.285164
C36: n32 | E36: 051026_AM02.2_S32 | F36: ='T1&T2_G2=3dec. '!F36 -> 0 | G36: =100-AC36 -> 10.273585 | I36: =G36-G53 -> 1.8576394 | K36: =POWER(I36,2) -> 3.450824 | L36: =G36-'T1&T2_G2=3dec. '!G36 -> -0.10377358 | O36: =C36 -> n32 | P36: =E36 -> 051026_AM02.2_S32 | Q36: 18.589 | S36: 1.06 | U36: =Q36+S36 -> 19.649 | W36: 19.5401 | Y36: =U36-W36 -> 0.1089 | AA36: =S36-Y36 -> 0.9511 | AC36: =AA36*100/S36 -> 89.726415
C37: n33 | E37: 051026_AM02.2_S33 | F37: ='T1&T2_G2=3dec. '!F37 -> 0 | G37: =100-AC37 -> 9.2122959 | I37: =G37-G53 -> 0.79635033 | K37: =POWER(I37,2) -> 0.63417385 | L37: =G37-'T1&T2_G2=3dec. '!G37 -> -0.0096061479 | O37: =C37 -> n33 | P37: =E37 -> 051026_AM02.2_S33 | Q37: 18.987 | S37: 1.041 | U37: =Q37+S37 -> 20.028 | W37: 19.9321 | Y37: =U37-W37 -> 0.0959 | AA37: =S37-Y37 -> 0.9451 | AC37: =AA37*100/S37 -> 90.787704
C38: n34 | E38: 051026_AM02.2_S34 | F38: ='T1&T2_G2=3dec. '!F38 -> 0 | G38: =100-AC38 -> 9.2857143 | I38: =G38-G53 -> 0.86976875 | K38: =POWER(I38,2) -> 0.75649768 | L38: =G38-'T1&T2_G2=3dec. '!G38 -> -0.03968254 | O38: =C38 -> n34 | P38: =E38 -> 051026_AM02.2_S34 | Q38: 18.517 | S38: 1.008 | U38: =Q38+S38 -> 19.525 | W38: 19.4314 | Y38: =U38-W38 -> 0.0936 | AA38: =S38-Y38 -> 0.9144 | AC38: =AA38*100/S38 -> 90.714286
C39: n35 | E39: 051026_AM02.2_S35 | F39: ='T1&T2_G2=3dec. '!F39 -> 0 | G39: =100-AC39 -> 6.2706913 | I39: =G39-G53 -> -2.1452542 | K39: =POWER(I39,2) -> 4.6021156 | L39: =G39-'T1&T2_G2=3dec. '!G39 -> 0.038948393 | O39: =C39 -> n35 | P39: =E39 -> 051026_AM02.2_S35 | Q39: 17.622 | S39: 1.027 | U39: =Q39+S39 -> 18.649 | W39: 18.5846 | Y39: =U39-W39 -> 0.0644 | AA39: =S39-Y39 -> 0.9626 | AC39: =AA39*100/S39 -> 93.729309
C40: n36 | E40: 051026_AM02.2_S36 | F40: ='T1&T2_G2=3dec. '!F40 -> 0 | G40: =100-AC40 -> 6.7734554 | I40: =G40-G53 -> -1.6424902 | K40: =POWER(I40,2) -> 2.6977739 | L40: =G40-'T1&T2_G2=3dec. '!G40 -> 0.022883295 | O40: =C40 -> n36 | P40: =E40 -> 051026_AM02.2_S36 | Q40: 13.712 | S40: 0.874 | U40: =Q40+S40 -> 14.586 | W40: 14.5268 | Y40: =U40-W40 -> 0.0592 | AA40: =S40-Y40 -> 0.8148 | AC40: =AA40*100/S40 -> 93.226545
C41: n37 | E41: 051026_AM02.2_S37 | F41: ='T1&T2_G2=3dec. '!F41 -> 0 | G41: =100-AC41 -> 9.7005988 | I41: =G41-G53 -> 1.2846533 | K41: =POWER(I41,2) -> 1.650334 | L41: =G41-'T1&T2_G2=3dec. '!G41 -> 0.01996008 | O41: =C41 -> n37 | P41: =E41 -> 051026_AM02.2_S37 | Q41: 13.581 | S41: 1.002 | U41: =Q41+S41 -> 14.583 | W41: 14.4858 | Y41: =U41-W41 -> 0.0972 | AA41: =S41-Y41 -> 0.9048 | AC41: =AA41*100/S41 -> 90.299401
...
